File: 研究/抵抗測定/PPMS/181106/181106_cernox5.dat
[Header]
TITLE, default name
FILEOPENTIME,14224341.89,11/6/2018,8:31 PM
BYAPP, Resistivity, 2.1, 1.0
INFO, APPNAME, PPMS MultiVu Application, 1.5.11
INFO, , Sample1 Name
INFO, 1, Sample1 Cross Section
INFO, 1, Sample1 Length
INFO, Ohm, Sample1 Units
INFO, , Sample2 Name
INFO, 1, Sample2 Cross Section
INFO, 1, Sample2 Length
INFO, Ohm, Sample2 Units
INFO, , Sample3 Name
INFO, 1, Sample3 Cross Section
INFO, 1, Sample3 Length
INFO, Ohm-m, Sample3 Units
INFO, , Sample4 Name
INFO, 1, Sample4 Cross Section
INFO, 1, Sample4 Length
INFO, Ohm-m, Sample4 Units
FIELDGROUP, Resistivity,2,3,4,5,6,7,8,9,10,11,12,13,14,15,16,17,18,19,20,21,22,23,24,25,26,27,28,29,30,31,32,33,34,35,36,37,38,39,40,41
STARTUPGROUP, Resistivity
STARTUPAXIS, X, 2, LINEAR, AUTO
STARTUPAXIS, Y1, 7, LINEAR, AUTO
STARTUPAXIS, Y2, 9, LINEAR, AUTO
STARTUPAXIS, Y3, 11, LINEAR, AUTO
PLOT_APPEARANCE, ALL, HORZ_GRID_ON, VERT_GRID_ON, MARKERS_AND_LINES, ALL_LINES
DATATYPE, TIME, 2
DATATYPE, COMMENT, 1
[Data]
Comment,Time Stamp (sec),Status (code),Temperature (K),Magnetic Field (Oe),Sample Position (deg),Bridge 1 Resistivity (Ohm),Bridge 1 Excitation (uA),Bridge 2 Resistivity (Ohm),Bridge 2 Excitation (uA),Bridge 3 Resistivity (Ohm-m),Bridge 3 Excitation (uA),Bridge 4 Resistivity (Ohm-m),Bridge 4 Excitation (uA),Bridge 1 Std. Dev. (Ohm),Bridge 2 Std. Dev. (Ohm),Bridge 3 Std. Dev. (Ohm-m),Bridge 4 Std. Dev. (Ohm-m),Number of Readings,Bridge 1 Resistance (Ohms),Bridge 2 Resistance (Ohms),Bridge 3 Resistance (Ohms),Bridge 4 Resistance (Ohms),Signal 1 Vin (V),Signal 2 Vin (V),Digital Inputs (code),Drive 1 Iout (mA),Drive 1 Ipower (watts),Drive 2 Iout (mA),Drive 2 Ipower (watts),Pressure (),Map 20 (),Map 21 (),Map 22 (),Map 23 (),Map 24 (),Map 25 (),Map 26 (),Map 27 (),Map 28 (),Map 29 ()
,14224424.55,4370,300.021041870117,0,0,78.1449520874023,97.0051603698731,69.1114910888672,97.0051603698731,,,,,0.00139444241869837,0.00106473541262499,,,25,78.1449520874023,69.1114910888672,,
,14224652.00,4370,303.857559204102,0,0,77.3147088623047,97.0051603698731,68.4364999389648,97.0051603698731,,,,,0.00815921287894418,0.00664496592473433,,,25,77.3147088623047,68.4364999389648,,
,14224877.14,4370,307.602600097656,0,0,76.443366394043,97.0051603698731,67.7385739135742,96.839080657959,,,,,0.00825771545755947,0.00673439284433729,,,25,76.443366394043,67.7385739135742,,
,14225101.97,4370,311.352645874023,0,0,75.5883053588867,97.0246803283691,67.0580950927734,96.8195207214356,,,,,0.00766839460352752,0.00616060137232368,,,25,75.5883053588867,67.0580950927734,,
,14225330.14,4370,315.150085449219,0,0,74.7482736206055,97.0246803283691,66.3864569091797,96.9856004333496,,,,,0.00664037721974552,0.0050271343890382,,,25,74.7482736206055,66.3864569091797,,
,14225554.13,4370,318.880462646484,0,0,73.9474792480469,97.0246803283691,65.7414782714844,96.9856004333496,,,,,0.00633501112381946,0.0054930088398778,,,25,73.9474792480469,65.7414782714844,,
,14225779.19,4370,322.617813110352,0,0,73.1716595458984,97.0246803283691,65.1046020507813,96.9856004333496,,,,,0.0071666802530984,0.00587537206618103,,,25,73.1716595458984,65.1046020507813,,
,14226005.02,4370,326.379104614258,0,0,72.4112463378906,97.0246803283691,64.4816232299805,96.839080657959,,,,,0.00690011654625281,0.00554443496037856,,,25,72.4112463378906,64.4816232299805,,
,14226234.80,4370,330.201843261719,0,0,71.6587451171875,97.0246803283691,63.8630131530762,97.0051603698731,,,,,0.00523236296960508,0.0041929308918969,,,25,71.6587451171875,63.8630131530762,,
,14226463.69,4370,334.024551391602,0,0,70.9215023803711,96.8195207214356,63.254987487793,97.0246803283691,,,,,0.00600168448121751,0.00510881421988364,,,25,70.9215023803711,63.254987487793,,
,14226692.13,4370,337.823654174805,0,0,70.2158538818359,97.0246803283691,62.6665615844727,96.839080657959,,,,,0.0050034087433769,0.00434178365593724,,,25,70.2158538818359,62.6665615844727,,
,14226923.00,4370,341.659851074219,0,0,69.5181781005859,97.0051603698731,62.0831480407715,97.0051603698731,,,,,0.00559812916165266,0.00463169720152101,,,25,69.5181781005859,62.0831480407715,,
,14227155.56,4370,345.535202026367,0,0,68.8306451416016,97.0246803283691,61.5050216674805,96.9856004333496,,,,,0.00692699302977055,0.00610594593032168,,,25,68.8306451416016,61.5050216674805,,
,14227382.89,4370,349.323806762695,0,0,68.1796475219727,97.0051603698731,60.9572985839844,96.839080657959,,,,,0.00582758046313031,0.00485909459945199,,,25,68.1796475219727,60.9572985839844,,
,14227609.69,4370,353.091949462891,0,0,67.54369140625,97.0246803283691,60.4204229736328,96.9856004333496,,,,,0.00545090306810344,0.00453444343661794,,,25,67.54369140625,60.4204229736328,,
,14227836.14,4370,356.875640869141,0,0,66.9224792480469,97.0246803283691,59.8945750427246,96.8195207214356,,,,,0.00544557771746001,0.00473425932479758,,,25,66.9224792480469,59.8945750427246,,
,14228065.47,4370,360.674301147461,0,0,66.3123937988281,97.0246803283691,59.3776554870605,96.9856004333496,,,,,0.00594788497994585,0.00494916634946584,,,25,66.3123937988281,59.3776554870605,,
,14228297.39,4370,364.539810180664,0,0,65.7058233642578,96.9856004333496,58.8645315551758,97.0246803283691,,,,,0.00533122299506116,0.00446401506020709,,,25,65.7058233642578,58.8645315551758,,
,14228520.23,4370,368.261657714844,0,0,65.1399392700195,97.0246803283691,58.3844128417969,96.9856004333496,,,,,0.00605506839594781,0.00516310322017717,,,25,65.1399392700195,58.3844128417969,,
,14228742.63,4370,371.959197998047,0,0,64.5877844238281,97.0246803283691,57.9166705322266,96.9856004333496,,,,,0.00477367897305653,0.00410721349358007,,,25,64.5877844238281,57.9166705322266,,
,14228971.22,4370,375.757949829102,0,0,64.0310955810547,97.0051603698731,57.4413735961914,97.0051603698731,,,,,0.0042773994148306,0.00363353187316012,,,25,64.0310955810547,57.4413735961914,,
,14229195.91,4370,379.497894287109,0,0,63.5015673828125,97.0246803283691,56.9831582641602,96.9856004333496,,,,,0.00373297955983403,0.0030989875460978,,,25,63.5015673828125,56.9831582641602,,
,14229423.45,4370,383.274353027344,0,0,62.9694982910156,97.0246803283691,56.5245812988281,96.8195207214356,,,,,0.00435817361500775,0.00376488824839643,,,25,62.9694982910156,56.5245812988281,,
,14229647.56,4370,387.018402099609,0,0,62.4578395080566,97.0246803283691,56.0894421386719,97.0051603698731,,,,,0.00506803304327634,0.00418716174208272,,,25,62.4578395080566,56.0894421386719,,
,14229877.09,4370,390.844802856445,0,0,61.9454573059082,97.0246803283691,55.6590815734863,96.8195207214356,,,,,0.00513388949127091,0.0042923065656522,,,25,61.9454573059082,55.6590815734863,,
,14230106.94,4370,394.666946411133,0,0,61.4442114257812,97.0051603698731,55.2350604248047,96.839080657959,,,,,0.00403295625219804,0.00336668916158578,,,25,61.4442114257812,55.2350604248047,,
,14230330.30,4370,398.3876953125,0,0,60.9641983032227,97.0246803283691,54.8272731018066,96.8195207214356,,,,,0.00550507861021786,0.00472152375035996,,,25,60.9641983032227,54.8272731018066,,
,14230636.27,4370,398.294494628906,0,0,60.8926287841797,97.0051603698731,54.7666337585449,96.9856004333496,,,,,0.00293999602392087,0.00326278458808695,,,25,60.8926287841797,54.7666337585449,,
,14230863.30,4370,394.482009887695,0,0,61.3947581481934,97.0246803283691,55.1959371948242,96.9856004333496,,,,,0.00384193175708729,0.00329775152443084,,,25,61.3947581481934,55.1959371948242,,
,14231090.47,4370,390.722305297852,0,0,61.8638479614258,97.0051603698731,55.5949649047852,96.9856004333496,,,,,0.00543587383426263,0.0048920114021325,,,25,61.8638479614258,55.5949649047852,,
,14231316.94,4370,386.944549560547,0,0,62.3563804626465,97.0246803283691,56.0138708496094,96.839080657959,,,,,0.00426988603921092,0.00346217022500077,,,25,62.3563804626465,56.0138708496094,,
,14231543.86,4370,383.161697387695,0,0,62.8702018737793,97.0051603698731,56.4507830810547,97.0051603698731,,,,,0.00437460721054266,0.003599478493842,,,25,62.8702018737793,56.4507830810547,,
,14231767.09,4370,379.415802001953,0,0,63.402279510498,96.9856004333496,56.9027281188965,97.0246803283691,,,,,0.005488005838874,0.00472692333085293,,,25,63.402279510498,56.9027281188965,,
,14231996.78,4370,375.610046386719,0,0,63.9466102600098,97.0246803283691,57.3654837036133,96.9856004333496,,,,,0.00527509364370587,0.00457382162378865,,,25,63.9466102600098,57.3654837036133,,
,14232221.22,4370,371.896743774414,0,0,64.4814120483398,97.0051603698731,57.8190625,97.0051603698731,,,,,0.00514329246634702,0.00449260595208774,,,25,64.4814120483398,57.8190625,,
,14232450.80,4370,368.066955566406,0,0,65.0438705444336,97.0246803283691,58.2965396118164,97.0051603698731,,,,,0.00538913820923182,0.00479539300760314,,,25,65.0438705444336,58.2965396118164,,
,14232681.16,4370,364.224838256836,0,0,65.6275988769531,97.0246803283691,58.7917167663574,96.8195207214356,,,,,0.00617588803291389,0.00521817466837946,,,25,65.6275988769531,58.7917167663574,,
,14232906.06,4370,360.480651855469,0,0,66.2073681640625,97.0051603698731,59.2829769897461,96.839080657959,,,,,0.00538540393119129,0.00448921927908251,,,25,66.2073681640625,59.2829769897461,,
,14233136.55,4370,356.637298583984,0,0,66.8194808959961,97.0051603698731,59.8011590576172,97.0246803283691,,,,,0.00468961750060166,0.0039719121342253,,,25,66.8194808959961,59.8011590576172,,
,14233364.83,4370,352.846755981445,0,0,67.4424111938477,97.0246803283691,60.3296405029297,96.9856004333496,,,,,0.00532486366795756,0.00476809381629643,,,25,67.4424111938477,60.3296405029297,,
,14233592.70,4370,349.053604125977,0,0,68.0754156494141,97.0246803283691,60.8655891418457,96.9856004333496,,,,,0.00562556482059487,0.00464575026091847,,,25,68.0754156494141,60.8655891418457,,
,14233818.11,4370,345.302001953125,0,0,68.7121151733398,97.0246803283691,61.404073638916,96.9856004333496,,,,,0.00600191277174398,0.0049149920632135,,,25,68.7121151733398,61.404073638916,,
,14234045.22,4370,341.517059326172,0,0,69.3745782470703,97.0051603698731,61.9636918640137,97.0051603698731,,,,,0.00653586553071532,0.00544704178538638,,,25,69.3745782470703,61.9636918640137,,
,14234272.02,4370,337.747497558594,0,0,70.0443231201172,96.8195207214356,62.529702911377,97.0246803283691,,,,,0.00539291855610272,0.00433105796617421,,,25,70.0443231201172,62.529702911377,,
,14234500.91,4370,333.93115234375,0,0,70.7404122924805,97.0246803283691,63.1182170104981,96.839080657959,,,,,0.00616798638574914,0.00514860416493333,,,25,70.7404122924805,63.1182170104981,,
,14234728.50,4370,330.147842407227,0,0,71.4490274047852,97.0246803283691,63.7163136291504,96.9856004333496,,,,,0.00648374692928723,0.00537249144099483,,,25,71.4490274047852,63.7163136291504,,
,14234957.00,4370,326.338958740234,0,0,72.174157409668,96.839080657959,64.3272637939453,97.0246803283691,,,,,0.00552632205512948,0.0044892729158663,,,25,72.174157409668,64.3272637939453,,
,14235183.20,4370,322.570098876953,0,0,72.9061557006836,97.0246803283691,64.9451071166992,96.8195207214356,,,,,0.00552966923847449,0.00463251557087632,,,25,72.9061557006836,64.9451071166992,,
,14235412.48,4370,318.756256103516,0,0,73.6675018310547,97.0246803283691,65.5864617919922,96.8390406799316,,,,,0.00649115409289231,0.00532220977611178,,,25,73.6675018310547,65.5864617919922,,
,14235638.00,4370,315.00520324707,0,0,74.4339364624023,97.0246803283691,66.231325378418,96.9856004333496,,,,,0.00681607626625877,0.00546478425783393,,,25,74.4339364624023,66.231325378418,,
,14235865.13,4370,311.219696044922,0,0,75.2328744506836,97.0246803283691,66.9038836669922,96.9856004333496,,,,,0.00813985035368539,0.00702796659034005,,,25,75.2328744506836,66.9038836669922,,
,14236094.72,4370,307.398101806641,0,0,76.0526168823242,97.0246803283691,67.5930996704102,96.839080657959,,,,,0.00652623604670616,0.0057333211277494,,,25,76.0526168823242,67.5930996704102,,
,14236325.63,4370,303.552947998047,0,0,76.9040551757813,97.0246803283691,68.308190612793,96.839080657959,,,,,0.00688420240676273,0.00566477799636548,,,25,76.9040551757813,68.308190612793,,
,14236551.73,4370,299.789840698242,0,0,77.7593881225586,97.0246803283691,69.0262484741211,96.9856004333496,,,,,0.0081004719747912,0.00674003573050056,,,25,77.7593881225586,69.0262484741211,,
,14236781.09,4370,295.973052978516,0,0,78.6546896362305,97.0246803283691,69.7762307739258,96.9856004333496,,,,,0.0069153115165885,0.00599301111642849,,,25,78.6546896362305,69.7762307739258,,
,14237011.06,4370,292.148300170898,0,0,79.5614529418945,97.7379203796387,70.486848449707,97.5522807312012,,,,,0.007179027659006,0.00619272726024438,,,25,79.5614529418945,70.486848449707,,
,14237242.77,4370,288.282455444336,0,0,80.484323425293,97.7183604431152,71.2687503051758,97.5522807312012,,,,,0.00830386866756733,0.00749994324353236,,,25,80.484323425293,71.2687503051758,,
,14237472.80,4370,284.453750610352,0,0,81.4758383178711,97.7379203796387,72.1143557739258,97.7183604431152,,,,,0.00831197794738225,0.00727334208698297,,,25,81.4758383178711,72.1143557739258,,
,14237704.86,4370,280.590545654297,0,0,82.5476519775391,97.7379203796387,73.0074377441406,97.7183604431152,,,,,0.0090925255365114,0.00792446432812086,,,25,82.5476519775391,73.0074377441406,,
,14237939.16,4370,276.69140625,0,0,83.6211038208008,97.7183604431152,73.9119439697266,97.5522807312012,,,,,0.0103011992450532,0.00930522462168445,,,25,83.6211038208008,73.9119439697266,,
,14238167.36,4370,272.892349243164,0,0,84.6764434814453,97.7183604431152,74.7972320556641,97.5522807312012,,,,,0.00792500189489101,0.00665023010779822,,,25,84.6764434814453,74.7972320556641,,
,14238397.42,4370,269.070343017578,0,0,85.7660308837891,97.7183604431152,75.708991394043,97.5522807312012,,,,,0.00784639552954345,0.00673004383900896,,,25,85.7660308837891,75.708991394043,,
,14238631.75,4370,265.124252319336,0,0,86.9596481323242,97.7183604431152,76.7141748046875,97.5522807312012,,,,,0.00680908341867673,0.00601911542911042,,,25,86.9596481323242,76.7141748046875,,
,14238862.75,4370,261.329238891602,0,0,88.114677734375,97.7574403381348,77.6822970581055,97.0051603698731,,,,,0.00851897324111183,0.00729428073543639,,,25,88.114677734375,77.6822970581055,,
,14239092.64,4370,257.50129699707,0,0,89.299176940918,97.7183604431152,78.6670666503906,97.5522807312012,,,,,0.0094483009140644,0.0084340580411176,,,25,89.299176940918,78.6670666503906,,
,14239325.69,4370,253.608596801758,0,0,90.5522872924805,97.7574403381348,79.710315246582,97.7183604431152,,,,,0.011503882698172,0.0097918357528556,,,25,90.5522872924805,79.710315246582,,
,14239554.66,4370,249.780349731445,0,0,91.8219396972656,97.7574403381348,80.764772644043,97.7183604431152,,,,,0.00981725441041316,0.00814463985747911,,,25,91.8219396972656,80.764772644043,,
,14239785.95,4370,245.925247192383,0,0,93.1479946899414,97.7379203796387,81.86447265625,97.7183604431152,,,,,0.0108103876545836,0.00892475619577439,,,25,93.1479946899414,81.86447265625,,
,14240016.53,4370,242.079444885254,0,0,94.5148684692383,97.7183604431152,82.9957009887695,97.7574403381348,,,,,0.0110531718075441,0.00937975827962072,,,25,94.5148684692383,82.9957009887695,,
,14240248.91,4370,238.197898864746,0,0,95.943635559082,97.7574403381348,84.1702792358398,97.7379203796387,,,,,0.0153692875816814,0.00924287032146731,,,25,95.943635559082,84.1702792358398,,
,14240479.11,4370,234.362747192383,0,0,97.3928833007813,97.7574403381348,85.3716888427734,97.7183604431152,,,,,0.0129959089705343,0.00895673762430121,,,25,97.3928833007813,85.3716888427734,,
,14240709.17,4370,230.525100708008,0,0,98.897712097168,97.7574403381348,86.6130020141602,97.7183604431152,,,,,0.0153496872575615,0.0105095750836504,,,25,98.897712097168,86.6130020141602,,
,14240939.05,4370,226.692451477051,0,0,100.436059875488,91.0945202636719,87.8910256958008,97.6792805480957,,,,,0.0127732837394833,0.0104035614760227,,,25,100.436059875488,87.8910256958008,,
,14241167.64,4370,222.877853393555,0,0,102.035838623047,89.3454411315918,89.2083285522461,97.7379203796387,,,,,0.0129778128645206,0.0114595132872083,,,25,102.035838623047,89.2083285522461,,
,14241398.13,4370,219.025253295898,0,0,103.702923583984,87.9087577819824,90.5818237304688,97.7379203796387,,,,,0.0139144162071411,0.0112426407756012,,,25,103.702923583984,90.5818237304688,,
,14241626.39,4370,215.219200134277,0,0,105.403409729004,86.7805572509766,91.9865863037109,97.7183604431152,,,,,0.0140412198201941,0.0117753186708172,,,25,105.403409729004,91.9865863037109,,
,14241856.67,4370,211.374603271484,0,0,107.195843811035,85.3448806762695,93.4527606201172,97.7183604431152,,,,,0.0145954470019531,0.0105150956407318,,,25,107.195843811035,93.4527606201172,,
,14242085.94,4370,207.545501708984,0,0,109.037519226074,83.9033174133301,94.9788220214844,97.7183604431152,,,,,0.0156810101668647,0.0172277416468162,,,25,109.037519226074,94.9788220214844,,
,14242313.02,4370,203.764801025391,0,0,110.926019592285,82.4666415405273,96.5197979736328,97.7183604431152,,,,,0.0164414706745362,0.0168032235294157,,,25,110.926019592285,96.5197979736328,,
,14242541.70,4370,199.946403503418,0,0,112.890386047363,81.0260375976563,98.1330163574219,97.7378804016113,,,,,0.0176757735997751,0.0176155904685159,,,25,112.890386047363,98.1330163574219,,
,14242772.47,4370,196.095199584961,0,0,114.945419311523,79.5893617248535,99.8158712768555,97.7379203796387,,,,,0.0165447444945983,0.0158015795418627,,,25,114.945419311523,99.8158712768555,,
,14242994.27,4370,192.402801513672,0,0,116.994045410156,78.1536378479004,101.476804199219,90.1370426940918,,,,,0.0163044690688195,0.0133432588713852,,,25,116.994045410156,101.476804199219,,
,14243216.47,4370,188.69229888916,0,0,119.14034942627,76.712121887207,103.224734191895,88.1488404846191,,,,,0.0177899727520439,0.013765569171921,,,25,119.14034942627,103.224734191895,,
,14243433.83,4370,185.06795501709,0,0,121.310817565918,75.2763981628418,104.99550201416,87.0246003723145,,,,,0.0186958163155692,0.0142525619306735,,,25,121.310817565918,104.99550201416,,
,14243651.95,4370,181.430053710938,0,0,123.566584777832,73.8397221374512,106.833231201172,85.5839965820312,,,,,0.0186438614573476,0.0152202020548071,,,25,123.566584777832,106.833231201172,,
,14243870.83,4370,177.772850036621,0,0,125.932319946289,72.6382415771484,108.77244934082,87.5866020202637,,,,,0.0195999308382251,0.0179773440886176,,,25,125.932319946289,108.77244934082,,
,14244089.19,4370,174.130897521973,0,0,128.385306396484,71.2015582275391,110.739292602539,82.4666415405273,,,,,0.020414317399303,0.0167873021247911,,,25,128.385306396484,110.739292602539,,
,14244307.47,4370,170.491249084473,0,0,130.923949584961,69.761001739502,112.798588867188,81.0309176635742,,,,,0.0225357820817061,0.016862501100047,,,25,130.923949584961,112.798588867188,,
,14244526.27,4370,166.836196899414,0,0,133.585042114258,68.3243185424805,114.956975097656,79.355118560791,,,,,0.0226476597660845,0.0183106208342807,,,25,133.585042114258,114.956975097656,,
,14244741.91,4370,163.243499755859,0,0,136.30436340332,67.1228378295898,117.157838134766,77.9135626220703,,,,,0.0222751953903194,0.0189530186985187,,,25,136.30436340332,117.157838134766,,
,14244956.66,4370,159.658546447754,0,0,139.140590209961,65.6861618041992,119.430241088867,76.4778787231445,,,,,0.025052160125454,0.0188422752303788,,,25,139.140590209961,119.430241088867,,
,14245174.27,4370,156.027000427246,0,0,142.116528930664,64.250438079834,121.833578491211,75.0363227844238,,,,,0.0236859267020938,0.0196756780330274,,,25,142.116528930664,121.833578491211,,
,14245392.31,4370,152.388702392578,0,0,145.235883178711,62.8137985229492,124.328695068359,73.3614831542969,,,,,0.026818983330403,0.020350291481497,,,25,145.235883178711,124.328695068359,,
,14245608.72,4370,148.772499084473,0,0,148.476295776367,61.3243182373047,126.956138305664,75.1395980834961,,,,,0.0292847526325657,0.0247033853530124,,,25,148.476295776367,126.956138305664,,
,14245826.19,4370,145.149749755859,0,0,151.856622314453,60.1707582092285,129.653376464844,70.478356628418,,,,,0.0277785848896471,0.0220394973060006,,,25,151.856622314453,129.653376464844,,
,14246045.88,4370,141.486305236816,0,0,155.469292602539,58.7350416564941,132.536162719727,69.0426400756836,,,,,0.0287647579307509,0.0230348265948946,,,25,155.469292602539,132.536162719727,,
,14246259.36,4370,137.917251586914,0,0,159.139952392578,57.2495184326172,135.479110717773,70.3562365722656,,,,,0.0359268986410866,0.0294937067033333,,,25,159.139952392578,135.479110717773,,
,14246483.73,4370,134.178298950195,0,0,163.18501159668,55.8626782989502,138.686768798828,65.9252777099609,,,,,0.0339538977318627,0.0277298493448588,,,25,163.18501159668,138.686768798828,,
,14246701.72,4370,130.542053222656,0,0,167.338389892578,54.3771586608887,141.970693359375,64.1967181396484,,,,,0.03313242913532,0.0265441455794652,,,25,167.338389892578,141.970693359375,,
,14246919.58,4370,126.900199890137,0,0,171.719881591797,55.5199993133545,145.444231567383,62.8089184570312,,,,,0.0380865262345972,0.0305444993842294,,,25,171.719881591797,145.444231567383,,
,14247139.05,4370,123.248001098633,0,0,176.298458862305,51.7829583740234,149.075195922852,61.0793592834473,,,,,0.0370632494446319,0.0302822871357591,,,25,176.298458862305,149.075195922852,,
,14247357.84,4370,119.59965133667,0,0,181.155589599609,50.3032782745361,152.942306518555,62.2231594085693,,,,,0.0427112099378053,0.0379377045743973,,,25,181.155589599609,152.942306518555,,
,14247574.28,4370,115.996852874756,0,0,186.209432373047,49.1448417663574,156.890964355469,58.2558395385742,,,,,0.0426091305871855,0.0329667548009093,,,25,186.209432373047,156.890964355469,,
,14247799.63,4370,112.238899230957,0,0,191.805886230469,47.7272799682617,161.281401977539,56.580040435791,,,,,0.0446897590524599,0.0349332332477979,,,25,191.805886230469,161.281401977539,,
,14248019.61,4370,108.57474899292,0,0,197.588895874023,46.3376401519775,165.816635131836,55.1394403076172,,,,,0.0466140694530656,0.0356617883327206,,,25,197.588895874023,165.816635131836,,
,14248238.38,4370,104.926349639893,0,0,203.711887817383,44.79471824646,170.612649536133,53.463641204834,,,,,0.0529856302800728,0.0383680864742352,,,25,203.711887817383,170.612649536133,,
,14248459.81,4370,101.239597320557,0,0,210.281337890625,43.5593199920654,175.744507446289,52.02208152771,,,,,0.0529281164571572,0.0402078295010625,,,25,210.281337890625,175.744507446289,,
,14248679.63,4370,97.5772018432617,0,0,217.277375488281,42.1677601623535,181.18303894043,50.3472382354736,,,,,0.0588330260913209,0.044596488095637,,,25,217.277375488281,181.18303894043,,
,14248898.39,4370,93.9289016723633,0,0,224.688217163086,40.754118347168,186.940793457031,48.9757604217529,,,,,0.0647710821039641,0.0472329033679858,,,25,224.688217163086,186.940793457031,,
,14249119.81,4370,90.2412528991699,0,0,232.713463134766,39.3634784698486,193.164264526367,47.4180786895752,,,,,0.0652204588715768,0.0500243678885145,,,25,232.713463134766,193.164264526367,,
,14249345.80,4370,86.4754524230957,0,0,241.5565234375,37.925838394165,199.987944946289,45.7844393920898,,,,,0.0735424616375344,0.0557822377020989,,,25,241.5565234375,199.987944946289,,
,14249570.75,4370,82.7216491699219,0,0,251.101793212891,36.463200378418,207.326754150391,44.1825983428955,,,,,0.0782242075682784,0.0600605680002617,,,25,251.101793212891,207.326754150391,,
,14249789.75,4370,79.0728492736816,0,0,261.151395263672,35.0725605773926,215.029284057617,42.5999188232422,,,,,0.0849984846683736,0.0648127721347517,,,25,261.151395263672,215.029284057617,,
,14250017.33,4370,75.2800979614258,0,0,272.571654052734,33.6099189758301,223.7428125,40.7938800811768,,,,,0.0929611540544275,0.0689006954200681,,,25,272.571654052734,223.7428125,,
,14250233.81,4370,71.6726989746094,0,0,284.377272949219,32.1962808227539,232.735510864258,39.3634784698486,,,,,0.100872597218418,0.0765570911854043,,,25,284.377272949219,232.735510864258,,
,14250462.17,4370,67.869701385498,0,0,298.080279541016,30.7336392211914,243.115676269531,37.6857188415527,,,,,0.116908137182753,0.0849845583803903,,,25,298.080279541016,243.115676269531,,
,14250682.72,4370,64.194450378418,0,0,312.7465625,29.2005196380615,254.175686645508,35.9086016082764,,,,,0.12440164313309,0.090883727807875,,,25,312.7465625,254.175686645508,,
,14250909.36,4370,60.4171504974365,0,0,329.430173339844,27.8083596420288,266.727104492187,34.3532789611816,,,,,0.141467506363423,0.103295376380637,,,25,329.430173339844,266.727104492187,,
,14251136.53,4370,56.6269493103027,0,0,348.099936523438,26.3226797103882,280.691850585938,32.6274794769287,,,,,0.154288068445349,0.114522062398415,,,25,348.099936523438,280.691850585938,,
,14251360.61,4370,52.9015502929688,0,0,368.909031982422,24.7454403305054,296.188150634766,30.9257202148438,,,,,0.174453801165338,0.128862143314311,,,25,368.909031982422,296.188150634766,,
,14251584.31,4370,49.1676006317139,0,0,392.469779052734,23.3253607177734,313.620433349609,29.199959487915,,,,,0.197732170405715,0.14564383607602,,,25,392.469779052734,313.620433349609,,
,14251806.89,4370,45.4636993408203,0,0,419.319326171875,21.8396807861328,333.348487548828,27.4732005691528,,,,,0.227576743009733,0.167766277649784,,,25,419.319326171875,333.348487548828,,
,14252031.63,4370,41.7158508300781,0,0,450.607806396484,20.3290393829346,356.243269042969,25.7233996582031,,,,,0.264546424504036,0.192170545976978,,,25,450.607806396484,356.243269042969,,
,14252258.86,4370,37.9274005889893,0,0,487.810375976563,18.7713194656372,383.212687988281,23.9016006088257,,,,,0.314240013150669,0.227508654424896,,,25,487.810375976563,383.212687988281,,
,14252482.53,4370,34.1994514465332,0,0,531.297231445312,17.2366402816772,414.494455566406,22.039160118103,,,,,0.369108649507618,0.264559139625374,,,25,531.297231445312,414.494455566406,,
,14252704.89,4370,30.4952001571655,0,0,583.976264648437,15.6789603805542,452.097203369141,20.2579594039917,,,,,0.46360578524941,0.329419851307156,,,25,583.976264648437,452.097203369141,,
,14252924.89,4370,26.8266496658325,0,0,648.27375,14.0855204391479,497.441739501953,18.3744805908203,,,,,0.576874580154707,0.403836157218698,,,25,648.27375,497.441739501953,,
,14253148.64,4370,23.1050500869751,0,0,731.741433105469,12.5135600090027,555.534091796875,16.493320274353,,,,,0.751984876420593,0.520883766938743,,,25,731.741433105469,555.534091796875,,
,14253376.25,4370,19.3022003173828,0,0,846.147719726563,10.8368003463745,634.114387207031,14.4564000892639,,,,,1.05240815556485,0.708778704299908,,,25,846.147719726563,634.114387207031,,
,14253599.88,4370,15.5808501243591,0,0,1007.35346435547,9.11003959655762,742.744230957031,12.3464804458618,,,,,1.60170073239766,1.04644382305859,,,25,1007.35346435547,742.744230957031,,
,14253824.80,4370,11.8276500701904,0,0,1269.74373046875,7.21620022773743,915.311484375,9.99155986785889,,,,,2.73725585561365,1.7112327731117,,,25,1269.74373046875,915.311484375,,
,14254067.91,4370,7.84730005264282,0,0,1845.4025390625,4.98719985961914,1279.5234375,7.19268006324768,,,,,6.67280289785604,4.32087910749615,,,25,1845.4025390625,1279.5234375,,
,14254298.09,4370,4.0048999786377,0,0,3929.4995703125,2.34835990428925,2498.91959960937,3.73295997619629,,,,,44.9671942805323,26.3932216098003,,,25,3929.4995703125,2498.91959960937,,
,14254582.78,4370,3.46280002593994,0,0,4757.732265625,1.94772008180618,2952.2912109375,3.15335995674133,,,,,63.2673698299155,33.7127715226579,,,25,4757.732265625,2952.2912109375,,
,14254817.31,4370,7.36844992637634,0,0,1960.63576660156,4.81724012374878,1350.44259277344,6.98268022537231,,,,,8.17015303544182,5.08584102537375,,,25,1960.63576660156,1350.44259277344,,
,14255046.47,4370,11.1867499351501,0,0,1332.43845703125,6.99375997543335,955.780083007813,9.77411996841431,,,,,3.58480536593663,2.16866941293499,,,25,1332.43845703125,955.780083007813,,
,14255274.81,4370,14.9871501922607,0,0,1040.34832519531,8.94155977249146,764.632277832031,12.0764001846313,,,,,1.70952780039979,1.12173150506807,,,25,1040.34832519531,764.632277832031,,
,14255501.70,4370,18.7691497802734,0,0,866.008657226562,10.6047996711731,647.557780761719,14.0933204460144,,,,,1.14637047481702,0.761098285560448,,,25,866.008657226562,647.557780761719,,
,14255722.34,4370,22.4474506378174,0,0,749.150083007813,12.6564402008057,567.636342773437,16.0831994247437,,,,,0.8270660094582,0.553100573466698,,,25,749.150083007813,567.636342773437,,
,14255948.44,4370,26.215350151062,0,0,660.91568359375,13.8062002372742,506.288117675781,18.0260400390625,,,,,0.6389784834774,0.428462471423908,,,25,660.91568359375,506.288117675781,,
,14256172.84,4370,29.9556999206543,0,0,593.007512207031,15.388879776001,458.479672851563,19.9198803329468,,,,,0.498012200427067,0.338887456423783,,,25,593.007512207031,458.479672851563,,
,14256392.52,4370,33.615650177002,0,0,539.31515625,16.9235607910156,420.281922607422,21.7407193374634,,,,,0.400342763534823,0.286002436542518,,,25,539.31515625,420.281922607422,,
,14256616.14,4370,37.3431510925293,0,0,494.643389892578,18.4582405471802,388.163916015625,23.539520072937,,,,,0.314590490551837,0.227628094357076,,,25,494.643389892578,388.163916015625,,
,14256835.89,4370,41.0067005157471,0,0,457.746940917969,19.9679201126099,361.434046630859,25.2892791366577,,,,,0.274088037651828,0.199723870564561,,,25,457.746940917969,361.434046630859,,
,14257057.47,4370,44.7028007507324,0,0,425.947786865234,21.4949201965332,338.223614501953,27.0400395202637,,,,,0.240187549958346,0.173733811856588,,,25,425.947786865234,338.223614501953,,
,14257279.61,4370,48.4049491882324,0,0,398.431580810547,22.9411994552612,318.012282714844,28.7418006134033,,,,,0.202302022365542,0.14862714195956,,,25,398.431580810547,318.012282714844,,
,14257501.17,4370,52.0966014862061,0,0,374.483394775391,24.4028792572021,300.320643310547,30.4435598754883,,,,,0.185650671376908,0.13242006970762,,,25,374.483394775391,300.320643310547,,
,14257721.67,4370,55.7674007415771,0,0,353.512891845703,25.8655208587646,284.727535400391,32.1222790527344,,,,,0.157306196351413,0.117229781184984,,,25,353.512891845703,284.727535400391,,
,14257937.08,4370,59.35719871521,0,0,335.284129638672,27.2801208496094,271.117850341797,33.7280405426025,,,,,0.139343893427342,0.103891014227086,,,25,335.284129638672,271.117850341797,,
,14258160.78,4370,63.0874996185303,0,0,318.33056640625,28.7177991485596,258.394375,35.3827613830566,,,,,0.130072797186547,0.0953735762333241,,,25,318.33056640625,258.394375,,
,14258379.94,4370,66.7381973266602,0,0,303.312124023437,30.1564405822754,247.092434692383,37.0124806976318,,,,,0.111277544981577,0.0850308051950485,,,25,303.312124023437,247.092434692383,,
,14258601.34,4370,70.426700592041,0,0,289.635778808594,31.5710387420654,236.726559448242,38.642200012207,,,,,0.104552363970048,0.0788206616919302,,,25,289.635778808594,236.726559448242,,
,14258821.98,4370,74.1071014404297,0,0,277.232017822266,32.9847206115723,227.305245361328,40.2479615020752,,,,,0.0977866044118934,0.073795167947962,,,25,277.232017822266,227.305245361328,,
,14259038.89,4370,77.724048614502,0,0,266.047038574219,34.3753204345703,218.779538574219,41.8065990447998,,,,,0.091487485284065,0.0700427245326709,,,25,266.047038574219,218.779538574219,,
,14259258.56,4370,81.3752479553223,0,0,255.662759399414,35.7668802642822,210.8293359375,43.2350806427002,,,,,0.0804354234188032,0.0616693878896358,,,25,255.662759399414,210.8293359375,,
,14259483.16,4370,85.1195030212402,0,0,245.910494995117,37.2036003875732,203.346694946289,44.9959996032715,,,,,0.0788703819138437,0.0574156466053168,,,25,245.910494995117,203.346694946289,,
,14259704.19,4370,88.8054466247559,0,0,236.879583129883,38.6181985473633,196.38713684082,46.5777191162109,,,,,0.0712028959005335,0.0534320885617866,,,25,236.879583129883,196.38713684082,,
,14259922.06,4370,92.4347496032715,0,0,228.686860961914,39.9857600402832,190.06303894043,48.135440826416,,,,,0.0669466747262748,0.051698002285615,,,25,228.686860961914,190.06303894043,,
,14260142.44,4370,96.111499786377,0,0,220.983998413086,41.3994381713867,184.091217041016,51.6901583862305,,,,,0.063743622184577,0.0464022965531577,,,25,220.983998413086,184.091217041016,,
,14260364.31,4370,99.80615234375,0,0,213.730714111328,42.8140399932861,178.42698059082,51.0646404266357,,,,,0.0576398387477405,0.0452064356252534,,,25,213.730714111328,178.42698059082,,
,14260580.33,4370,103.406799316406,0,0,207.141179199219,44.1566400146484,173.288419189453,52.7355595397949,,,,,0.052277900206137,0.0429685609411014,,,25,207.141179199219,173.288419189453,,
,14260799.02,4370,107.053302764893,0,0,200.854712524414,45.5462803649902,168.37797668457,54.1770791625977,,,,,0.0518939905058591,0.0402788971366007,,,25,200.854712524414,168.37797668457,,
,14261019.28,4370,110.718200683594,0,0,194.914266967773,46.7797186279297,163.739989624023,55.568839263916,,,,,0.0453591246661302,0.0374384706077908,,,25,194.914266967773,163.739989624023,,
,14261233.27,4370,114.285549163818,0,0,189.46123046875,48.2765602111816,159.444522705078,57.2934783935547,,,,,0.0440755405463693,0.0347046746990241,,,25,189.46123046875,159.444522705078,,
,14261453.97,4370,117.96354675293,0,0,184.142608642578,49.6240402984619,155.271881713867,58.7350416564941,,,,,0.0417518658417987,0.0330088814448231,,,25,184.142608642578,155.271881713867,,
,14261675.55,4370,121.660499572754,0,0,179.07130065918,51.0597604370117,151.282048950195,60.4098812866211,,,,,0.0408698136267545,0.031518277263824,,,25,179.07130065918,151.282048950195,,
,14261896.34,4370,125.339248657227,0,0,174.30763671875,52.2182005310059,147.522124633789,64.3772412109375,,,,,0.0381744634276905,0.0287298974123235,,,25,174.30763671875,147.522124633789,,
,14262114.89,4370,128.982246398926,0,0,169.814067382813,53.6978807067871,143.964432373047,63.5272364807129,,,,,0.0369598443418966,0.0267810204812687,,,25,169.814067382813,143.964432373047,,
,14262334.14,4370,132.64510345459,0,0,165.515064086914,55.1345603179932,140.548762817383,64.9629602050781,,,,,0.0365811988464698,0.0269260171402544,,,25,165.515064086914,140.548762817383,,
,14262552.22,4370,136.277351379395,0,0,161.465805664062,56.575160446167,137.340332641602,66.4045234680176,,,,,0.032393566280994,0.0247795716782973,,,25,161.465805664062,137.340332641602,,
,14262773.56,4370,139.974449157715,0,0,157.572114257813,57.7776005554199,134.208475952148,68.0803225708008,,,,,0.0301873524089247,0.0259797914229654,,,25,157.572114257813,134.208475952148,,
,14262995.41,4370,143.6748046875,0,0,153.84000793457,59.1644406890869,131.24744934082,69.5208790588379,,,,,0.0298031631351136,0.0229052661090881,,,25,153.84000793457,131.24744934082,,
,14263214.77,4370,147.335800170898,0,0,150.32190612793,60.6548403930664,128.427152099609,71.196678314209,,,,,0.0273199217079846,0.0220836192771069,,,25,150.32190612793,128.427152099609,,
,14263430.75,4370,150.940650939941,0,0,147.022619628906,62.0905604553223,125.775808105469,72.6382415771484,,,,,0.0278099738887806,0.0216543882568348,,,25,147.022619628906,125.775808105469,,
,14263650.88,4370,154.61009979248,0,0,143.802080078125,63.5272364807129,123.198531799316,74.0788380432129,,,,,0.0252497297402411,0.0196513252141564,,,25,143.802080078125,123.198531799316,,
,14263870.39,4370,158.27140045166,0,0,140.723557128906,64.9629602050781,120.723824157715,75.5155212402344,,,,,0.0244266243743954,0.019086317324221,,,25,140.723557128906,120.723824157715,,
,14264092.86,4370,161.988052368164,0,0,137.737887573242,66.1653604125977,118.307510681152,77.1913203430176,,,,,0.0235006820639255,0.0190218299408575,,,25,137.737887573242,118.307510681152,,
,14264312.94,4370,165.655151367188,0,0,134.909802246094,67.6059568786621,116.025820617676,78.6319169616699,,,,,0.021635746804001,0.0176059152219829,,,25,134.909802246094,116.025820617676,,
,14264530.94,4370,169.298698425293,0,0,132.207222900391,69.0426400756836,113.84331451416,80.3077233886719,,,,,0.0212114437175521,0.017762765426853,,,25,132.207222900391,113.84331451416,,
,14264747.63,4370,172.910499572754,0,0,129.633485107422,70.478356628418,111.761038818359,81.440796661377,,,,,0.0211735948676702,0.0163873967310831,,,25,129.633485107422,111.761038818359,,
,14264966.45,4370,176.565498352051,0,0,127.136820373535,71.617276763916,109.735078430176,84.2060800170898,,,,,0.0207784052424517,0.013324621581199,,,25,127.136820373535,109.735078430176,,
,14265189.58,4370,180.28295135498,0,0,124.674417419434,73.0530004882813,107.736796875,84.5532391357422,,,,,0.0201332146620263,0.0157005068430637,,,25,124.674417419434,107.736796875,,
,14265403.98,4370,183.86644744873,0,0,122.426268920898,77.7719226074219,105.904488220215,86.3023181152344,,,,,0.0186694526234994,0.0149159703937824,,,25,122.426268920898,105.904488220215,,
,14265624.14,4370,187.539001464844,0,0,120.174945678711,75.9937602233887,104.078669128418,87.7429220581055,,,,,0.0189221724919556,0.0144197919992728,,,25,120.174945678711,104.078669128418,,
,14265840.69,4370,191.151252746582,0,0,118.060649719238,77.430443572998,102.353404846191,89.1795979309082,,,,,0.0174756483047646,0.0131918192464573,,,25,118.060649719238,102.353404846191,,
,14266060.39,4370,194.818099975586,0,0,115.98678527832,78.8671195983887,100.662824707031,90.5420417785645,,,,,0.0172868566182688,0.0135434974777149,,,25,115.98678527832,100.662824707031,,
,14266287.67,4370,198.612449645996,0,0,113.917662963867,80.3077233886719,98.9760681152344,97.7378804016113,,,,,0.0173705727615605,0.0126526862307185,,,25,113.917662963867,98.9760681152344,,
,14266515.14,4370,202.409454345703,0,0,111.938737182617,84.9533180236816,97.3479583740234,97.7379203796387,,,,,0.0140466074631727,0.0109518278508337,,,25,111.938737182617,97.3479583740234,,
,14266744.13,4370,206.227798461914,0,0,109.993081359863,82.9458399963379,95.7634313964844,97.7183604431152,,,,,0.0152091004057796,0.0103643998785878,,,25,109.993081359863,95.7634313964844,,
,14266975.56,4370,210.091499328613,0,0,108.103539733887,84.3131564331055,94.2048419189453,97.7379203796387,,,,,0.014272354442689,0.0127338963039979,,,25,108.103539733887,94.2048419189453,,
,14267200.70,4370,213.846199035645,0,0,106.322901306152,85.8231196594238,92.7507327270508,97.7183604431152,,,,,0.0148699264008465,0.0112037524748304,,,25,106.322901306152,92.7507327270508,,
,14267426.58,4370,217.61824798584,0,0,104.601396179199,87.2646829223633,91.3335507202148,97.7379203796387,,,,,0.0139183943136607,0.0111315970184734,,,25,104.601396179199,91.3335507202148,,
,14267656.91,4370,221.457153320313,0,0,102.89800567627,88.7003994750977,89.9322567749023,97.7379203796387,,,,,0.0140045276730332,0.0111494027215163,,,25,102.89800567627,89.9322567749023,,
,14267887.66,4370,225.308403015137,0,0,101.257026367188,90.1370426940918,88.578466796875,97.7183604431152,,,,,0.012996743772769,0.0112836119097007,,,25,101.257026367188,88.578466796875,,
,14268117.86,4370,229.155700683594,0,0,99.6848495483398,97.7574403381348,87.2773083496094,97.7379203796387,,,,,0.0118784944198857,0.0107321091639497,,,25,99.6848495483398,87.2773083496094,,
,14268345.45,4370,232.951850891113,0,0,98.1808694458008,97.7574403381348,86.0352270507812,97.7183604431152,,,,,0.00889061898128409,0.0097539301318983,,,25,98.1808694458008,86.0352270507812,,
,14268574.88,4370,236.778503417969,0,0,96.7233401489258,97.7574403381348,84.8348498535156,97.7183604431152,,,,,0.0107651273887036,0.00993636835437679,,,25,96.7233401489258,84.8348498535156,,
,14268799.78,4370,240.535346984863,0,0,95.3424127197266,97.7574403381348,83.697424621582,97.7183604431152,,,,,0.0105867491102566,0.00928685194556799,,,25,95.3424127197266,83.697424621582,,
,14269031.70,4370,244.404502868652,0,0,94.0511245727539,97.7183604431152,82.6171173095703,97.7574403381348,,,,,0.0122554784752161,0.00865607493324193,,,25,94.0511245727539,82.6171173095703,,
,14269260.58,4370,248.21849822998,0,0,92.6210079956055,97.7574403381348,81.4005270385742,97.7379203796387,,,,,0.0120302837192267,0.00988908502406706,,,25,92.6210079956055,81.4005270385742,,
,14269490.77,4370,252.061347961426,0,0,91.3062509155273,97.7574403381348,80.3201617431641,97.7379203796387,,,,,0.0095202178831084,0.00773981476214002,,,25,91.3062509155273,80.3201617431641,,
,14269717.70,4370,255.852897644043,0,0,90.0535488891602,97.7574403381348,79.281242980957,97.7379203796387,,,,,0.0106218510615465,0.0084741156857129,,,25,90.0535488891602,79.281242980957,,
,14269948.75,4370,259.696197509766,0,0,88.8275891113281,97.7379203796387,78.2633670043945,97.5522807312012,,,,,0.0102094096541941,0.00924109118394762,,,25,88.8275891113281,78.2633670043945,,
,14270176.36,4370,263.486190795898,0,0,87.6583087158203,97.7183604431152,77.2912243652344,97.5522807312012,,,,,0.00955633016451449,0.00847462182099429,,,25,87.6583087158203,77.2912243652344,,
,14270407.00,4370,267.327896118164,0,0,86.5071078491211,97.7379203796387,76.331953125,97.5522807312012,,,,,0.00886897179164192,0.00832771572021673,,,25,86.5071078491211,76.331953125,,
,14270637.81,4370,271.16520690918,0,0,85.3821466064453,97.7379203796387,75.3946719360352,97.7574403381348,,,,,0.0081894685615685,0.00728572175548295,,,25,85.3821466064453,75.3946719360352,,
,14270866.69,4370,274.975387573242,0,0,84.3035659790039,97.7183604431152,74.4950595092773,97.7183604431152,,,,,0.0105025501316479,0.00918436821583267,,,25,84.3035659790039,74.4950595092773,,
,14271098.00,4370,278.823913574219,0,0,83.2429641723633,97.7183604431152,73.6098049926758,97.5522807312012,,,,,0.00859736126789292,0.00760468660404138,,,25,83.2429641723633,73.6098049926758,,
,14271327.91,4370,282.648254394531,0,0,82.2242825317383,97.7379203796387,72.7582595825195,97.5522807312012,,,,,0.00761559776706635,0.00708253093224715,,,25,82.2242825317383,72.7582595825195,,
,14271556.72,4370,286.463897705078,0,0,81.2256671142578,97.7183604431152,71.924033203125,97.7183604431152,,,,,0.00841916730846229,0.00760142121464421,,,25,81.2256671142578,71.924033203125,,
,14271783.34,4370,290.235900878906,0,0,80.2738388061523,97.7183604431152,71.1274768066406,97.5522807312012,,,,,0.00794407379720442,0.006853305623629,,,25,80.2738388061523,71.1274768066406,,
,14272012.50,4370,294.0478515625,0,0,79.3379614257812,97.7183604431152,70.340617980957,97.5522807312012,,,,,0.00454784393934496,0.0065991547699576,,,25,79.3379614257812,70.340617980957,,
,14272237.67,4370,297.79280090332,0,0,78.4358120727539,97.0246803283691,69.5877172851562,96.839080657959,,,,,0.00907072405182807,0.00823426036438166,,,25,78.4358120727539,69.5877172851562,,
,14272460.48,4370,301.503753662109,0,0,77.5732290649414,97.0246803283691,68.8639331054687,97.0051603698731,,,,,0.00752091999948595,0.00644634565185941,,,25,77.5732290649414,68.8639331054687,,
,14272687.11,4370,305.274353027344,0,0,76.720920715332,97.0246803283691,68.149130859375,96.9856004333496,,,,,0.00706689431561816,0.00575382175584527,,,25,76.720920715332,68.149130859375,,
,14272916.02,4370,309.090454101563,0,0,75.8837683105469,97.0246803283691,67.4462921142578,97.0051603698731,,,,,0.00769135326750911,0.00654808342046316,,,25,75.8837683105469,67.4462921142578,,
,14273139.13,4370,312.804107666016,0,0,75.0911849975586,97.0246803283691,66.7882736206055,97.0051603698731,,,,,0.0066082881814154,0.00441667498194096,,,25,75.0911849975586,66.7882736206055,,
,14273367.45,4370,316.604949951172,0,0,74.2920056152344,97.0246803283691,66.1084826660156,96.839080657959,,,,,0.00713584033528605,0.00613557583534574,,,25,74.2920056152344,66.1084826660156,,
,14273598.44,4370,320.447052001953,0,0,73.5081762695312,97.0246803283691,65.4487493896484,96.839080657959,,,,,0.00717682111646968,0.00595310664940193,,,25,73.5081762695312,65.4487493896484,,
,14273823.05,4370,324.188613891602,0,0,72.7650765991211,97.0246803283691,64.8232482910156,97.0051603698731,,,,,0.00585351436049439,0.00489957686410841,,,25,72.7650765991211,64.8232482910156,,
,14274050.36,4370,327.972702026367,0,0,72.0308489990234,97.0246803283691,64.2045755004883,96.9856004333496,,,,,0.00607353985588385,0.00509541047589022,,,25,72.0308489990234,64.2045755004883,,
,14274276.86,4370,331.738800048828,0,0,71.3175149536133,97.0246803283691,63.6031135559082,97.0051603698731,,,,,0.00644577831660809,0.0055582162081259,,,25,71.3175149536133,63.6031135559082,,
,14274499.55,4370,335.446701049805,0,0,70.6237475585937,96.8195207214356,63.0184582519531,97.0246803283691,,,,,0.00595807309816193,0.00500020593315379,,,25,70.6237475585937,63.0184582519531,,
,14274729.03,4370,339.268951416016,0,0,69.9292752075195,97.0246803283691,62.4317709350586,97.0051603698731,,,,,0.00672649833136951,0.00580472794264094,,,25,69.9292752075195,62.4317709350586,,
,14274950.94,4370,342.966247558594,0,0,69.2720843505859,97.0246803283691,61.8769209289551,97.0051603698731,,,,,0.00586191866592659,0.00490535551142729,,,25,69.2720843505859,61.8769209289551,,
,14275177.80,4370,346.733947753906,0,0,68.6174176025391,97.0246803283691,61.3233581542969,96.9856004333496,,,,,0.00565950596672519,0.00477280320228647,,,25,68.6174176025391,61.3233581542969,,
,14275403.64,4370,350.498336791992,0,0,67.9758322143555,96.839080657959,60.7808755493164,97.0246803283691,,,,,0.00511371835805308,0.00437629963076748,,,25,67.9758322143555,60.7808755493164,,
,14275628.84,4370,354.251098632813,0,0,67.3531945800781,98.8370806884766,60.2526274108887,97.0051603698731,,,,,0.00506686006541467,0.00387545539117433,,,25,67.3531945800781,60.2526274108887,,
,14275853.89,4370,357.997955322266,0,0,66.7424957275391,97.0051603698731,59.7347357177734,96.9856004333496,,,,,0.00549755210917481,0.00455639959407374,,,25,66.7424957275391,59.7347357177734,,
,14276081.06,4370,361.778137207031,0,0,66.1388067626953,97.0246803283691,59.2217736816406,97.0051603698731,,,,,0.005447876531642,0.0046213439680087,,,25,66.1388067626953,59.2217736816406,,
,14276304.92,4370,365.498687744141,0,0,65.563161315918,97.0246803283691,58.7332423400879,96.9856004333496,,,,,0.00469232486833344,0.00384573735412796,,,25,65.563161315918,58.7332423400879,,
,14276534.56,4370,369.332153320313,0,0,64.9889828491211,9.62515979766846,58.2456669616699,9.63027985572815,,,,,0.00578014057144458,0.005729989855585,,,25,64.9889828491211,58.2456669616699,,
,14276759.20,4370,373.06575012207,0,0,64.4291906738281,9.63195980072022,57.7722802734375,9.57747982025147,,,,,0.00891193366289627,0.00937774202093352,,,25,64.4291906738281,57.7722802734375,,
,14276989.42,4370,376.880996704102,0,0,63.8807643127441,9.98999977111816,57.3073649597168,9.98999977111816,,,,,0.00469264927343762,0.00432967625000097,,,25,63.8807643127441,57.3073649597168,,
,14277212.05,4370,380.584243774414,0,0,63.3494502258301,9.98999977111816,56.8559487915039,9.98999977111816,,,,,0.00539114048008022,0.00440453365403389,,,25,63.3494502258301,56.8559487915039,,
,14277434.84,4370,384.3310546875,0,0,62.8281271362305,9.98999977111816,56.415,9.58151982307434,,,,,0.00554783035611362,0.00767045389798738,,,25,62.8281271362305,56.415,,
,14277663.63,4370,388.102600097656,0,0,62.3210890197754,9.98999977111816,55.9816821289063,9.98999977111816,,,,,0.00427665174958756,0.00374905354943523,,,25,62.3210890197754,55.9816821289063,,
,14277894.06,4370,391.939193725586,0,0,61.8175648498535,9.98999977111816,55.554663848877,9.98999977111816,,,,,0.00385114365523775,0.00347929681937736,,,25,61.8175648498535,55.554663848877,,
,14278118.84,4370,395.691146850586,0,0,61.302254486084,9.98999977111816,55.1161450195313,9.64803984642029,,,,,0.00452033572990377,0.0123171238969733,,,25,61.302254486084,55.1161450195313,,
,14278346.02,4370,399.499755859375,0,0,60.828705291748,9.63387982368469,54.7092976379395,9.58951984405518,,,,,0.00961443570631244,0.0088903778866307,,,25,60.828705291748,54.7092976379395,,
,14278690.89,4374,388.071151733398,0,0,61.9544041442871,97.0246803283691,55.6841542053223,97.0051603698731,,,,,0.0394250966174492,0.0339501455663417,,,25,61.9544041442871,55.6841542053223,,
,14278911.59,4374,343.458892822266,0,0,68.4745831298828,97.0246803283691,61.2353253173828,97.0051603698731,,,,,0.0734722347615207,0.0600736537594385,,,25,68.4745831298828,61.2353253173828,,
,14279132.02,4374,296.242691040039,0,0,77.8785818481445,97.0051603698731,69.165202331543,97.0246803283691,,,,,0.0995455934103946,0.0835880319061826,,,25,77.8785818481445,69.165202331543,,
,14279359.59,4374,251.391151428223,0,0,90.3905419921875,97.7574403381348,79.6505609130859,97.7379203796387,,,,,0.114062264508943,0.0935770402916771,,,25,90.3905419921875,79.6505609130859,,
,14279588.80,4374,210.757499694824,0,0,106.392693786621,86.0671228027344,92.9028057861328,97.7379203796387,,,,,0.145921184155418,0.116215455727551,,,25,106.392693786621,92.9028057861328,,
,14279816.53,4374,175.037353515625,0,0,126.568485717773,72.3981588745117,109.392738647461,83.6690815734863,,,,,0.177168359379773,0.143128995839922,,,25,126.568485717773,109.392738647461,,
,14280039.98,4374,143.629600524902,0,0,151.91750793457,6.57476001739502,129.810563354492,7.69711982727051,,,,,0.240154730840523,0.191386852742004,,,25,151.91750793457,129.810563354492,,
,14280261.73,4374,115.214752197266,0,0,185.642922973633,5.37875999450684,156.579892578125,6.38104001998901,,,,,0.326974469060858,0.257595537341345,,,25,185.642922973633,156.579892578125,,
,14280490.48,4374,87.7184982299805,0,0,236.632113647461,4.00747989654541,196.341734619141,5.0857599067688,,,,,0.519674610768886,0.397594044437456,,,25,236.632113647461,196.341734619141,,
,14280765.61,4374,53.122049331665,0,0,364.653236083984,2.74616002082825,293.287166748047,3.41591998100281,,,,,3.1867365152639,2.47591013443521,,,25,364.653236083984,293.287166748047,,
,14281071.56,4375,9.54244995117188,0,0,1543.91423828125,0.647000014781952,1090.78889648438,0.917519989013672,,,,,0.837496897861621,0.55176184365817,,,25,1543.91423828125,1090.78889648438,,
,14281316.20,4375,8.97359991073608,0,0,1635.734375,0.611000001430511,1148.73563476563,0.87175998210907,,,,,0.899944265892856,0.639882030676666,,,25,1635.734375,1148.73563476563,,
,14281556.63,4375,8.49090003967285,0,0,1721.96009277344,0.580599975585937,1202.53285644531,0.757519995570183,,,,,4.90445411005461,2.96787631596191,,,25,1721.96009277344,1202.53285644531,,
,14281802.16,4375,8.12805032730103,0,0,1801.40576660156,0.553279986381531,1252.29069824219,0.797320003509521,,,,,4.24250340498448,2.60382487215212,,,25,1801.40576660156,1252.29069824219,,
,14282059.59,4375,7.79019999504089,0,0,1878.20757324219,0.478839983046055,1299.72198242188,0.767480013370514,,,,,5.70385580144891,3.49831336237447,,,25,1878.20757324219,1299.72198242188,,
,14282319.66,4375,7.50620007514954,0,0,1946.89426757813,0.468559991419315,1342.51158691406,0.74259997844696,,,,,8.10832765653541,4.89363516383779,,,25,1946.89426757813,1342.51158691406,,
,14282570.64,4375,7.32754993438721,0,0,2002.470859375,0.495999991893768,1376.61537109375,0.661039996147156,,,,,8.97055305954574,5.50432939456194,,,25,2002.470859375,1376.61537109375,,
,14282849.44,4375,7.13529992103577,0,0,2063.53172363281,0.481960003376007,1413.09434082031,0.703959996700287,,,,,9.53670877049462,5.64953142411443,,,25,2063.53172363281,1413.09434082031,,
,14283335.30,4374,2.20449995994568,0,0,9872.2598046875,0.101720000505447,5571.8111328125,0.17947999894619,,,,,151.917987273512,75.2152188032205,,,25,9872.2598046875,5571.8111328125,,
,14283748.73,4374,1.82894998788834,0,0,14114.73546875,0.0647200032696128,7589.09572265625,0.118960003107786,,,,,2.30985584389277,1.26825229191568,,,25,14114.73546875,7589.09572265625,,