File: 研究/MPMS/190510/190510_PlatedSn_onSi_3.rso.raw
[Header]
TITLE,MPMS RSO Measurement
BYAPP,MPMS Measurement,2.1,Raw with ABS
FILEOPENTIME, 1557466750.483000 5/10/2019, 2:39:10 PM

INFO, APPNAME, MPMS MultiVu Application, Revision 1.60,  Build 081

INFO, NAME,
INFO, WEIGHT, 1.000
INFO, AREA, 1.000
INFO, LENGTH, 1.000
INFO, SHAPE, 0
INFO, COMMENT,
INFO, SEQUENCE FILE: 190519_PlatedSn_onSi_4_SweepH.seq


INFO, BACKGROUND DATA FILE:, None


STARTUPAXIS,X,8,LINEAR,AUTO,0.000000,0.000000
STARTUPAXIS,Y1,9,LINEAR,AUTO,0.000000,0.000000


STARTUPGROUP,Longitudinal
FIELDGROUP,Longitudinal,1,2,3,4,5,6,7,8,9,10,11,12,13,14,15,16,17,18,19,20,21,22
FIELDGROUP,Transverse,1,2,3,4,5,6,7,8,23,24,25,26,27,28,29,30,31,32,33,34,35,36

PLOT_APPEARANCE,ALL,HORZ_GRID_ON,VERT_GRID_ON,MARKERS_ONLY

[Data]
Time,Comment,Field (Oe),Start Temperature (K),End Temperature (K),Scan,Rejected,Position (cm),Long Voltage,Long Average Voltage,Long Detrended Voltage,Long Demeaned Voltage,Long Reg Fit,Long Detrended Fit,Long Demeaned Fit,Long Scaled Response,Long Avg. Scaled Response,Long Background Response,Long Response [w/ABS],Long Detrended Resp. [w/ABS],Long Fit [w/ABS],Long Detrended Fit [w/ABS],Trans Voltage,Trans Average Voltage,Trans Detrended Voltage,Trans Demeaned Voltage,Trans Reg Fit,Trans Detrended Fit,Trans Demeaned Fit,Trans Scaled Response,Trans Avg. Scaled Response,Trans Background Response,Trans Response [w/ABS],Trans Detrended Resp. [w/ABS],Trans Adjusted Fit,Trans Detrended Fit [w/ABS],
1557466750.483,,0.000000e+000,1.808000e+000,1.807504e+000,1,0,2.034379e+000,-1.144444e-002,,,,,,,-2.598567e-007,,,,,,,,,,,,,,,,,,,,,
1557466750.483,,0.000000e+000,1.808000e+000,1.807504e+000,1,0,-3.598825e-003,-9.796441e-002,,,,,,,-2.224373e-006,,,,,,,,,,,,,,,,,,,,,
1557466750.483,,0.000000e+000,1.808000e+000,1.807504e+000,1,0,1.967028e+000,-8.087405e-003,,,,,,,-1.836321e-007,,,,,,,,,,,,,,,,,,,,,
1557466750.483,,0.000000e+000,1.808000e+000,1.807504e+000,1,0,4.005006e+000,-9.369183e-002,,,,,,,-2.127360e-006,,,,,,,,,,,,,,,,,,,,,
1557466750.483,,0.000000e+000,1.807504e+000,1.809797e+000,2,0,2.034386e+000,-1.754814e-002,-1.449629e-002,6.616218e-002,6.616218e-002,-1.881688e-002,6.184159e-002,6.184159e-002,-3.984469e-007,-3.291518e-007,,,,,,,,,,,,,,,,,,,,
1557466750.483,,0.000000e+000,1.807504e+000,1.809797e+000,2,0,-3.615560e-003,-1.101718e-001,-1.040681e-001,-2.533961e-002,-2.340965e-002,-1.026943e-001,-2.396576e-002,-2.203580e-002,-2.501554e-006,-2.362963e-006,,,,,,,,,,,,,,,,,,,,
1557466750.483,,0.000000e+000,1.807504e+000,1.809797e+000,2,0,1.967005e+000,-1.648000e-002,-1.228370e-002,6.451485e-002,6.837477e-002,-1.328726e-002,6.351128e-002,6.737120e-002,-3.741936e-007,-2.789128e-007,,,,,,,,,,,,,,,,,,,,
1557466750.483,,0.000000e+000,1.807504e+000,1.809797e+000,2,0,4.005006e+000,-1.075777e-001,-1.006348e-001,-2.576620e-002,-1.997632e-002,-9.391462e-002,-1.904604e-002,-1.325615e-002,-2.442653e-006,-2.285006e-006,,,,,,,,,,,,,,,,,,,,
1557466832.473,,1.515152e-001,1.804111e+000,1.806848e+000,1,0,2.034982e+000,-5.819880e-001,,,,,,,-1.321458e-005,,,,,,,,,,,,,,,,,,,,,
1557466832.473,,1.515152e-001,1.804111e+000,1.806848e+000,1,0,-2.985190e-003,-7.226783e-001,,,,,,,-1.640908e-005,,,,,,,,,,,,,,,,,,,,,
1557466832.473,,1.515152e-001,1.804111e+000,1.806848e+000,1,0,1.967760e+000,-6.666768e-001,,,,,,,-1.513752e-005,,,,,,,,,,,,,,,,,,,,,
1557466832.473,,1.515152e-001,1.804111e+000,1.806848e+000,1,0,4.005727e+000,-7.762383e-001,,,,,,,-1.762521e-005,,,,,,,,,,,,,,,,,,,,,
1557466832.473,,1.515152e-001,1.806848e+000,1.807575e+000,2,0,2.034662e+000,-1.034577e-001,-3.427229e-001,7.076970e-002,7.076970e-002,-3.532970e-001,6.019560e-002,6.019560e-002,-2.349104e-006,-7.781841e-006,,,,,,,,,,,,,,,,,,,,
1557466832.473,,1.515152e-001,1.806848e+000,1.807575e+000,2,0,-3.387522e-003,-2.014222e-001,-4.620502e-001,-2.726921e-002,-4.855767e-002,-4.572646e-001,-2.248359e-002,-4.377204e-002,-4.573477e-006,-1.049128e-005,,,,,,,,,,,,,,,,,,,,
1557466832.473,,1.515152e-001,1.806848e+000,1.807575e+000,2,0,1.967547e+000,-1.274148e-001,-3.970458e-001,5.902365e-002,1.644674e-002,-3.946701e-001,6.139937e-002,1.882246e-002,-2.893071e-006,-9.015294e-006,,,,,,,,,,,,,,,,,,,,
1557466832.473,,1.515152e-001,1.806848e+000,1.807575e+000,2,0,4.005597e+000,-2.157659e-001,-4.960021e-001,-1.864415e-002,-8.250952e-002,-4.962905e-001,-1.893261e-002,-8.279797e-002,-4.899165e-006,-1.126219e-005,,,,,,,,,,,,,,,,,,,,
1557466910.513,,3.030303e-001,1.802599e+000,1.804040e+000,1,0,2.034392e+000,-3.709525e-001,,,,,,,-8.422821e-006,,,,,,,,,,,,,,,,,,,,,
1557466910.513,,3.030303e-001,1.802599e+000,1.804040e+000,1,0,-3.796736e-003,-4.925688e-001,,,,,,,-1.118423e-005,,,,,,,,,,,,,,,,,,,,,
1557466910.513,,3.030303e-001,1.802599e+000,1.804040e+000,1,0,1.967257e+000,-4.458754e-001,,,,,,,-1.012402e-005,,,,,,,,,,,,,,,,,,,,,
1557466910.513,,3.030303e-001,1.802599e+000,1.804040e+000,1,0,4.005446e+000,-5.442976e-001,,,,,,,-1.235878e-005,,,,,,,,,,,,,,,,,,,,,
1557466910.513,,3.030303e-001,1.804040e+000,1.805469e+000,2,0,2.034698e+000,-7.538072e-002,-2.231666e-001,6.530951e-002,6.530951e-002,-2.319428e-001,5.653328e-002,5.653328e-002,-1.711589e-006,-5.067205e-006,,,,,,,,,,,,,,,,,,,,
1557466910.513,,3.030303e-001,1.804040e+000,1.805469e+000,2,0,-3.398068e-003,-1.774651e-001,-3.350169e-001,-2.558112e-002,-4.654083e-002,-3.312076e-001,-2.177182e-002,-4.273152e-002,-4.029511e-006,-7.606871e-006,,,,,,,,,,,,,,,,,,,,
1557466910.513,,3.030303e-001,1.804040e+000,1.805469e+000,2,0,1.967488e+000,-1.066622e-001,-2.762688e-001,5.412671e-002,1.220730e-002,-2.724035e-001,5.799201e-002,1.607260e-002,-2.421864e-006,-6.272940e-006,,,,,,,,,,,,,,,,,,,,
1557466910.513,,3.030303e-001,1.804040e+000,1.805469e+000,2,0,4.005585e+000,-1.950133e-001,-3.696555e-001,-1.830024e-002,-8.117935e-002,-3.688200e-001,-1.746479e-002,-8.034390e-002,-4.427958e-006,-8.393370e-006,,,,,,,,,,,,,,,,,,,,
1557466996.233,,4.545455e-001,1.801511e+000,1.803530e+000,1,0,2.034235e+000,-1.535081e-001,,,,,,,-3.485544e-006,,,,,,,,,,,,,,,,,,,,,
1557466996.233,,4.545455e-001,1.801511e+000,1.803530e+000,1,0,-3.960788e-003,-2.565081e-001,,,,,,,-5.824254e-006,,,,,,,,,,,,,,,,,,,,,
1557466996.233,,4.545455e-001,1.801511e+000,1.803530e+000,1,0,1.966830e+000,-1.828059e-001,,,,,,,-4.150777e-006,,,,,,,,,,,,,,,,,,,,,
1557466996.233,,4.545455e-001,1.801511e+000,1.803530e+000,1,0,4.005026e+000,-2.720725e-001,,,,,,,-6.177660e-006,,,,,,,,,,,,,,,,,,,,,
1557466996.233,,4.545455e-001,1.803530e+000,1.805080e+000,2,0,2.034310e+000,-9.002960e-002,-1.217689e-001,6.529322e-002,6.529322e-002,-1.254877e-001,6.157438e-002,6.157438e-002,-2.044206e-006,-2.764875e-006,,,,,,,,,,,,,,,,,,,,
1557466996.233,,4.545455e-001,1.803530e+000,1.805080e+000,2,0,-3.878047e-003,-1.840266e-001,-2.202673e-001,-2.459855e-002,-3.320527e-002,-2.186034e-001,-2.293464e-002,-3.154136e-002,-4.178495e-006,-5.001375e-006,,,,,,,,,,,,,,,,,,,,
1557466996.233,,4.545455e-001,1.803530e+000,1.805080e+000,2,0,1.967060e+000,-1.033052e-001,-1.430555e-001,6.122001e-002,4.400656e-002,-1.414995e-001,6.277606e-002,4.556261e-002,-2.345640e-006,-3.248208e-006,,,,,,,,,,,,,,,,,,,,
1557466996.233,,4.545455e-001,1.803530e+000,1.805080e+000,2,0,4.005248e+000,-1.898251e-001,-2.309488e-001,-1.806657e-002,-4.388675e-002,-2.322797e-001,-1.939746e-002,-4.521763e-002,-4.310156e-006,-5.243908e-006,,,,,,,,,,,,,,,,,,,,
1557467079.373,,6.060606e-001,1.800706e+000,1.801985e+000,1,0,2.034463e+000,-3.990295e-001,,,,,,,-9.060336e-006,,,,,,,,,,,,,,,,,,,,,
1557467079.373,,6.060606e-001,1.800706e+000,1.801985e+000,1,0,-3.775918e-003,-5.246132e-001,,,,,,,-1.191183e-005,,,,,,,,,,,,,,,,,,,,,
1557467079.373,,6.060606e-001,1.800706e+000,1.801985e+000,1,0,1.967226e+000,-4.766991e-001,,,,,,,-1.082390e-005,,,,,,,,,,,,,,,,,,,,,
1557467079.373,,6.060606e-001,1.800706e+000,1.801985e+000,1,0,4.005464e+000,-5.856502e-001,,,,,,,-1.329773e-005,,,,,,,,,,,,,,,,,,,,,
1557467079.373,,6.060606e-001,1.801985e+000,1.803284e+000,2,0,2.034203e+000,-4.150517e-002,-2.202673e-001,6.952606e-002,6.952606e-002,-2.283729e-001,6.142054e-002,6.142054e-002,-9.424135e-007,-5.001375e-006,,,,,,,,,,,,,,,,,,,,
1557467079.373,,6.060606e-001,1.801985e+000,1.803284e+000,2,0,-4.043970e-003,-1.413007e-001,-3.329569e-001,-2.419806e-002,-4.316354e-002,-3.317799e-001,-2.302099e-002,-4.198647e-002,-3.208364e-006,-7.560097e-006,,,,,,,,,,,,,,,,,,,,
1557467079.373,,6.060606e-001,1.801985e+000,1.803284e+000,2,0,1.966946e+000,-6.241035e-002,-2.695547e-001,5.816962e-002,2.023867e-002,-2.650310e-001,6.269331e-002,2.476236e-002,-1.417085e-006,-6.120491e-006,,,,,,,,,,,,,,,,,,,,
1557467079.373,,6.060606e-001,1.801985e+000,1.803284e+000,2,0,4.005193e+000,-1.521348e-001,-3.688925e-001,-2.220266e-002,-7.909909e-002,-3.659630e-001,-1.927315e-002,-7.616958e-002,-3.454361e-006,-8.376047e-006,,,,,,,,,,,,,,,,,,,,
1557467162.623,,7.575758e-001,1.799048e+000,1.800147e+000,1,0,2.034304e+000,-4.931791e-001,,,,,,,-1.119809e-005,,,,,,,,,,,,,,,,,,,,,
1557467162.623,,7.575758e-001,1.799048e+000,1.800147e+000,1,0,-3.647161e-003,-6.201361e-001,,,,,,,-1.408077e-005,,,,,,,,,,,,,,,,,,,,,
1557467162.623,,7.575758e-001,1.799048e+000,1.800147e+000,1,0,1.967046e+000,-5.748161e-001,,,,,,,-1.305173e-005,,,,,,,,,,,,,,,,,,,,,
1557467162.623,,7.575758e-001,1.799048e+000,1.800147e+000,1,0,4.004997e+000,-6.785790e-001,,,,,,,-1.540777e-005,,,,,,,,,,,,,,,,,,,,,
1557467162.623,,7.575758e-001,1.800147e+000,1.800916e+000,2,0,2.034585e+000,-4.165776e-002,-2.674184e-001,7.349530e-002,7.349530e-002,-2.770267e-001,6.388706e-002,6.388706e-002,-9.458783e-007,-6.071984e-006,,,,,,,,,,,,,,,,,,,,
1557467162.623,,7.575758e-001,1.800147e+000,1.800916e+000,2,0,-3.285415e-003,-1.432844e-001,-3.817103e-001,-2.325699e-002,-4.079652e-002,-3.824868e-001,-2.403351e-002,-4.157305e-002,-3.253406e-006,-8.667086e-006,,,,,,,,,,,,,,,,,,,,
1557467162.623,,7.575758e-001,1.800147e+000,1.800916e+000,2,0,1.967465e+000,-5.890072e-002,-3.168584e-001,5.913440e-002,2.405533e-002,-3.107437e-001,6.524915e-002,3.017008e-002,-1.337396e-006,-7.194565e-006,,,,,,,,,,,,,,,,,,,,
1557467162.623,,7.575758e-001,1.800147e+000,1.800916e+000,2,0,4.005335e+000,-1.486251e-001,-4.136021e-001,-2.006977e-002,-7.268837e-002,-4.135466e-001,-2.001425e-002,-7.263285e-002,-3.374672e-006,-9.391220e-006,,,,,,,,,,,,,,,,,,,,
1557467245.393,,9.090909e-001,1.798996e+000,1.800811e+000,1,0,2.034427e+000,-3.180029e-001,,,,,,,-7.220550e-006,,,,,,,,,,,,,,,,,,,,,
1557467245.393,,9.090909e-001,1.798996e+000,1.800811e+000,1,0,-3.835336e-003,-4.373302e-001,,,,,,,-9.929990e-006,,,,,,,,,,,,,,,,,,,,,
1557467245.393,,9.090909e-001,1.798996e+000,1.800811e+000,1,0,1.966806e+000,-3.680532e-001,,,,,,,-8.356990e-006,,,,,,,,,,,,,,,,,,,,,
1557467245.393,,9.090909e-001,1.798996e+000,1.800811e+000,1,0,4.005068e+000,-4.593036e-001,,,,,,,-1.042891e-005,,,,,,,,,,,,,,,,,,,,,
1557467245.393,,9.090909e-001,1.800811e+000,1.800776e+000,2,0,2.034321e+000,-9.292886e-002,-2.054659e-001,7.105534e-002,7.105534e-002,-2.122234e-001,6.429785e-002,6.429785e-002,-2.110036e-006,-4.665293e-006,,,,,,,,,,,,,,,,,,,,
1557467245.393,,9.090909e-001,1.800811e+000,1.800776e+000,2,0,-3.876292e-003,-1.890622e-001,-3.131962e-001,-2.683082e-002,-3.667501e-002,-3.105908e-001,-2.422538e-002,-3.406957e-002,-4.292832e-006,-7.111411e-006,,,,,,,,,,,,,,,,,,,,
1557467245.393,,9.090909e-001,1.800811e+000,1.800776e+000,2,0,1.966821e+000,-1.033052e-001,-2.356792e-001,6.053038e-002,4.084201e-002,-2.305134e-001,6.569614e-002,4.600777e-002,-2.345639e-006,-5.351315e-006,,,,,,,,,,,,,,,,,,,,
1557467245.393,,9.090909e-001,1.800811e+000,1.800776e+000,2,0,4.005018e+000,-1.872311e-001,-3.232673e-001,-1.721356e-002,-4.674610e-002,-3.261754e-001,-2.012161e-002,-4.965416e-002,-4.251255e-006,-7.340084e-006,,,,,,,,,,,,,,,,,,,,
1557467329.153,,1.060606e+000,1.799414e+000,1.801599e+000,1,0,2.034258e+000,-1.124607e-001,,,,,,,-2.553525e-006,,,,,,,,,,,,,,,,,,,,,
1557467329.153,,1.060606e+000,1.799414e+000,1.801599e+000,1,0,-3.730632e-003,-2.238533e-001,,,,,,,-5.082796e-006,,,,,,,,,,,,,,,,,,,,,
1557467329.153,,1.060606e+000,1.799414e+000,1.801599e+000,1,0,1.967426e+000,-1.454207e-001,,,,,,,-3.301912e-006,,,,,,,,,,,,,,,,,,,,,
1557467329.153,,1.060606e+000,1.799414e+000,1.801599e+000,1,0,4.005415e+000,-2.264473e-001,,,,,,,-5.141697e-006,,,,,,,,,,,,,,,,,,,,,
1557467329.153,,1.060606e+000,1.801599e+000,1.802423e+000,2,0,2.034182e+000,-7.965331e-002,-9.605701e-002,6.937338e-002,6.937338e-002,-1.054979e-001,5.993249e-002,5.993249e-002,-1.808602e-006,-2.181064e-006,,,,,,,,,,,,,,,,,,,,
1557467329.153,,1.060606e+000,1.801599e+000,1.802423e+000,2,0,-3.824223e-003,-1.825007e-001,-2.031770e-001,-3.001767e-002,-3.774659e-002,-1.966209e-001,-2.346158e-002,-3.119050e-002,-4.143847e-006,-4.613322e-006,,,,,,,,,,,,,,,,,,,,
1557467329.153,,1.060606e+000,1.801599e+000,1.802423e+000,2,0,1.967200e+000,-1.063570e-001,-1.258889e-001,5.499937e-002,3.954153e-002,-1.192316e-001,6.165667e-002,4.619883e-002,-2.414935e-006,-2.858423e-006,,,,,,,,,,,,,,,,,,,,
1557467329.153,,1.060606e+000,1.801599e+000,1.802423e+000,2,0,4.005207e+000,-1.933348e-001,-2.098911e-001,-2.127390e-002,-4.446067e-002,-2.069631e-001,-1.834597e-002,-4.153274e-002,-4.389845e-006,-4.765771e-006,,,,,,,,,,,,,,,,,,,,
1557467412.644,,1.212121e+000,1.798595e+000,1.798839e+000,1,0,2.034335e+000,-2.700888e-001,,,,,,,-6.132617e-006,,,,,,,,,,,,,,,,,,,,,
1557467412.644,,1.212121e+000,1.798595e+000,1.798839e+000,1,0,-3.674913e-003,-3.909421e-001,,,,,,,-8.876704e-006,,,,,,,,,,,,,,,,,,,,,
1557467412.644,,1.212121e+000,1.798595e+000,1.798839e+000,1,0,1.967029e+000,-3.518784e-001,,,,,,,-7.989726e-006,,,,,,,,,,,,,,,,,,,,,
1557467412.644,,1.212121e+000,1.798595e+000,1.798839e+000,1,0,4.005039e+000,-4.660176e-001,,,,,,,-1.058136e-005,,,,,,,,,,,,,,,,,,,,,
1557467412.644,,1.212121e+000,1.798839e+000,1.799676e+000,2,0,2.034088e+000,-8.041628e-002,-1.752525e-001,6.669973e-002,6.669973e-002,-1.818781e-001,6.007412e-002,6.007412e-002,-1.825926e-006,-3.979272e-006,,,,,,,,,,,,,,,,,,,,
1557467412.644,,1.212121e+000,1.798839e+000,1.799676e+000,2,0,-3.977466e-003,-1.837214e-001,-2.873318e-001,-2.147434e-002,-4.537949e-002,-2.884068e-001,-2.254942e-002,-4.645458e-002,-4.171566e-006,-6.524135e-006,,,,,,,,,,,,,,,,,,,,
1557467412.644,,1.212121e+000,1.798839e+000,1.799676e+000,2,0,1.966890e+000,-1.118503e-001,-2.318644e-001,5.789820e-002,1.008789e-002,-2.284296e-001,6.133298e-002,1.352267e-002,-2.539666e-006,-5.264696e-006,,,,,,,,,,,,,,,,,,,,
1557467412.644,,1.212121e+000,1.798839e+000,1.799676e+000,2,0,4.004956e+000,-2.044740e-001,-3.352458e-001,-2.157808e-002,-9.329355e-002,-3.325070e-001,-1.883928e-002,-9.055474e-002,-4.642772e-006,-7.612068e-006,,,,,,,,,,,,,,,,,,,,
1557467498.384,,1.363636e+000,1.798630e+000,1.799449e+000,1,0,2.035030e+000,-1.132237e-001,,,,,,,-2.570849e-006,,,,,,,,,,,,,,,,,,,,,
1557467498.384,,1.363636e+000,1.798630e+000,1.799449e+000,1,0,-3.072310e-003,-2.088992e-001,,,,,,,-4.743250e-006,,,,,,,,,,,,,,,,,,,,,
1557467498.384,,1.363636e+000,1.798630e+000,1.799449e+000,1,0,1.967616e+000,-1.361126e-001,,,,,,,-3.090562e-006,,,,,,,,,,,,,,,,,,,,,
1557467498.384,,1.363636e+000,1.798630e+000,1.799449e+000,1,0,4.005718e+000,-2.241585e-001,,,,,,,-5.089726e-006,,,,,,,,,,,,,,,,,,,,,
1557467498.384,,1.363636e+000,1.799449e+000,1.800636e+000,2,0,2.034984e+000,-7.263405e-002,-9.292886e-002,6.599436e-002,6.599436e-002,-9.763663e-002,6.128659e-002,6.128659e-002,-1.649224e-006,-2.110036e-006,,,,,,,,,,,,,,,,,,,,
1557467498.384,,1.363636e+000,1.799449e+000,1.800636e+000,2,0,-2.992126e-003,-1.678518e-001,-1.883755e-001,-2.186120e-002,-2.945228e-002,-1.892062e-001,-2.269194e-002,-3.028302e-002,-3.811231e-006,-4.277241e-006,,,,,,,,,,,,,,,,,,,,
1557467498.384,,1.363636e+000,1.799449e+000,1.800636e+000,2,0,1.967724e+000,-8.713035e-002,-1.116214e-001,6.248393e-002,4.730178e-002,-1.116952e-001,6.241018e-002,4.722802e-002,-1.978375e-006,-2.534469e-006,,,,,,,,,,,,,,,,,,,,
1557467498.384,,1.363636e+000,1.799449e+000,1.800636e+000,2,0,4.005700e+000,-1.800592e-001,-2.021088e-001,-2.041237e-002,-4.318561e-002,-2.010832e-001,-1.938676e-002,-4.215999e-002,-4.088412e-006,-4.589068e-006,,,,,,,,,,,,,,,,,,,,
1557467581.104,,1.515152e+000,1.799066e+000,1.799571e+000,1,0,2.033680e+000,-5.178991e-001,,,,,,,-1.175938e-005,,,,,,,,,,,,,,,,,,,,,
1557467581.104,,1.515152e+000,1.799066e+000,1.799571e+000,1,0,-4.265628e-003,-6.465346e-001,,,,,,,-1.468017e-005,,,,,,,,,,,,,,,,,,,,,
1557467581.104,,1.515152e+000,1.799066e+000,1.799571e+000,1,0,1.966933e+000,-6.064028e-001,,,,,,,-1.376894e-005,,,,,,,,,,,,,,,,,,,,,
1557467581.104,,1.515152e+000,1.799066e+000,1.799571e+000,1,0,4.004879e+000,-7.107761e-001,,,,,,,-1.613883e-005,,,,,,,,,,,,,,,,,,,,,
1557467581.104,,1.515152e+000,1.799571e+000,1.800741e+000,2,0,2.033872e+000,-7.095553e-002,-2.944273e-001,6.894183e-002,6.894183e-002,-3.032587e-001,6.011045e-002,6.011045e-002,-1.611111e-006,-6.685246e-006,,,,,,,,,,,,,,,,,,,,
1557467581.104,,1.515152e+000,1.799571e+000,1.800741e+000,2,0,-4.007322e-003,-1.652577e-001,-4.058962e-001,-2.179699e-002,-4.252705e-002,-4.064825e-001,-2.238332e-002,-4.311338e-002,-3.752330e-006,-9.216249e-006,,,,,,,,,,,,,,,,,,,,
1557467581.104,,1.515152e+000,1.799571e+000,1.800741e+000,2,0,1.967267e+000,-8.697775e-002,-3.466903e-001,5.813899e-002,1.667887e-002,-3.435584e-001,6.127086e-002,1.981074e-002,-1.974911e-006,-7.871925e-006,,,,,,,,,,,,,,,,,,,,
1557467581.104,,1.515152e+000,1.799571e+000,1.800741e+000,2,0,4.005146e+000,-1.742607e-001,-4.425184e-001,-1.695907e-002,-7.914925e-002,-4.444940e-001,-1.893469e-002,-8.112487e-002,-3.956751e-006,-1.004779e-005,,,,,,,,,,,,,,,,,,,,
1557467665.114,,1.666667e+000,1.798822e+000,1.799815e+000,1,0,2.033756e+000,-2.035585e-001,,,,,,,-4.621984e-006,,,,,,,,,,,,,,,,,,,,,
1557467665.114,,1.666667e+000,1.798822e+000,1.799815e+000,1,0,-4.247891e-003,-3.215125e-001,,,,,,,-7.300240e-006,,,,,,,,,,,,,,,,,,,,,
1557467665.114,,1.666667e+000,1.798822e+000,1.799815e+000,1,0,1.966858e+000,-2.618488e-001,,,,,,,-5.945521e-006,,,,,,,,,,,,,,,,,,,,,
1557467665.114,,1.666667e+000,1.798822e+000,1.799815e+000,1,0,4.004861e+000,-3.566088e-001,,,,,,,-8.097133e-006,,,,,,,,,,,,,,,,,,,,,
1557467665.114,,1.666667e+000,1.799815e+000,1.800689e+000,2,0,2.034296e+000,-2.761925e-002,-1.155889e-001,6.547681e-002,6.547681e-002,-1.225656e-001,5.850006e-002,5.850006e-002,-6.271208e-007,-2.624552e-006,,,,,,,,,,,,,,,,,,,,
1557467665.114,,1.666667e+000,1.799815e+000,1.800689e+000,2,0,-3.586959e-003,-1.211585e-001,-2.213355e-001,-2.794886e-002,-4.026982e-002,-2.155530e-001,-2.216639e-002,-3.448735e-002,-2.751016e-006,-5.025628e-006,,,,,,,,,,,,,,,,,,,,
1557467665.114,,1.666667e+000,1.799815e+000,1.800689e+000,2,0,1.967385e+000,-4.089480e-002,-1.513718e-001,5.433579e-002,2.969386e-002,-1.458827e-001,5.982490e-002,3.518297e-002,-9.285545e-007,-3.437038e-006,,,,,,,,,,,,,,,,,,,,
1557467665.114,,1.666667e+000,1.799815e+000,1.800689e+000,2,0,4.005268e+000,-1.205481e-001,-2.385785e-001,-2.054990e-002,-5.751279e-002,-2.362710e-001,-1.824248e-002,-5.520537e-002,-2.737157e-006,-5.417145e-006,,,,,,,,,,,,,,,,,,,,
1557467755.084,,1.818182e+000,1.797708e+000,1.798473e+000,1,0,2.034920e+000,-3.839229e-001,,,,,,,-8.717325e-006,,,,,,,,,,,,,,,,,,,,,
1557467755.084,,1.818182e+000,1.797708e+000,1.798473e+000,1,0,-2.920883e-003,-5.081332e-001,,,,,,,-1.153764e-005,,,,,,,,,,,,,,,,,,,,,
1557467755.084,,1.818182e+000,1.797708e+000,1.798473e+000,1,0,1.967837e+000,-4.507584e-001,,,,,,,-1.023489e-005,,,,,,,,,,,,,,,,,,,,,
1557467755.084,,1.818182e+000,1.797708e+000,1.798473e+000,1,0,4.005677e+000,-5.647450e-001,,,,,,,-1.282306e-005,,,,,,,,,,,,,,,,,,,,,
1557467755.084,,1.818182e+000,1.798473e+000,1.799170e+000,2,0,2.034599e+000,-1.709037e-002,-2.005066e-001,6.612219e-002,6.612219e-002,-2.030245e-001,6.360427e-002,6.360427e-002,-3.880526e-007,-4.552689e-006,,,,,,,,,,,,,,,,,,,,
1557467755.084,,1.818182e+000,1.798473e+000,1.799170e+000,2,0,-3.306992e-003,-1.136815e-001,-3.109073e-001,-3.071906e-002,-4.427850e-002,-3.044150e-001,-2.422674e-002,-3.778619e-002,-2.581243e-006,-7.059440e-006,,,,,,,,,,,,,,,,,,,,
1557467755.084,,1.818182e+000,1.798473e+000,1.799170e+000,2,0,1.967449e+000,-8.697775e-003,-2.297281e-001,6.401961e-002,3.690073e-002,-2.286370e-001,6.511071e-002,3.799182e-002,-1.974911e-007,-5.216189e-006,,,,,,,,,,,,,,,,,,,,
1557467755.084,,1.818182e+000,1.798473e+000,1.799170e+000,2,0,4.005355e+000,-9.247109e-002,-3.286080e-001,-2.130090e-002,-6.197923e-002,-3.270864e-001,-1.977923e-002,-6.045756e-002,-2.099642e-006,-7.461351e-006,,,,,,,,,,,,,,,,,,,,
1557467830.084,,1.969697e+000,1.796667e+000,1.798056e+000,1,0,2.034890e+000,-5.827510e-001,,,,,,,-1.323190e-005,,,,,,,,,,,,,,,,,,,,,
1557467830.084,,1.969697e+000,1.796667e+000,1.798056e+000,1,0,-2.957721e-003,-7.158116e-001,,,,,,,-1.625317e-005,,,,,,,,,,,,,,,,,,,,,
1557467830.084,,1.969697e+000,1.796667e+000,1.798056e+000,1,0,1.967848e+000,-6.704917e-001,,,,,,,-1.522414e-005,,,,,,,,,,,,,,,,,,,,,
1557467830.084,,1.969697e+000,1.796667e+000,1.798056e+000,1,0,4.005696e+000,-7.844782e-001,,,,,,,-1.781231e-005,,,,,,,,,,,,,,,,,,,,,
1557467830.084,,1.969697e+000,1.798056e+000,1.799414e+000,2,0,2.034349e+000,-1.048311e-001,-3.437910e-001,7.192785e-002,7.192785e-002,-3.529695e-001,6.274939e-002,6.274939e-002,-2.380287e-006,-7.806094e-006,,,,,,,,,,,,,,,,,,,,
1557467830.084,,1.969697e+000,1.798056e+000,1.799414e+000,2,0,-3.621769e-003,-2.056947e-001,-4.607532e-001,-2.209206e-002,-4.503435e-002,-4.621062e-001,-2.344509e-002,-4.638737e-002,-4.670490e-006,-1.046183e-005,,,,,,,,,,,,,,,,,,,,
1557467830.084,,1.969697e+000,1.798056e+000,1.799414e+000,2,0,1.967320e+000,-1.322977e-001,-4.013947e-001,6.020873e-002,1.432416e-002,-3.975972e-001,6.400627e-002,1.812169e-002,-3.003943e-006,-9.114039e-006,,,,,,,,,,,,,,,,,,,,
1557467830.084,,1.969697e+000,1.798056e+000,1.799414e+000,2,0,4.005291e+000,-2.264473e-001,-5.054628e-001,-2.091711e-002,-8.974397e-002,-5.042784e-001,-1.973270e-002,-8.855957e-002,-5.141697e-006,-1.147700e-005,,,,,,,,,,,,,,,,,,,,
1557467921.304,,2.121212e+000,1.801406e+000,1.801616e+000,1,0,2.034934e+000,-1.738029e-001,,,,,,,-3.946357e-006,,,,,,,,,,,,,,,,,,,,,
1557467921.304,,2.121212e+000,1.801406e+000,1.801616e+000,1,0,-2.947642e-003,-2.784814e-001,,,,,,,-6.323179e-006,,,,,,,,,,,,,,,,,,,,,
1557467921.304,,2.121212e+000,1.801406e+000,1.801616e+000,1,0,1.967811e+000,-2.038636e-001,,,,,,,-4.628913e-006,,,,,,,,,,,,,,,,,,,,,
1557467921.304,,2.121212e+000,1.801406e+000,1.801616e+000,1,0,4.005693e+000,-3.057955e-001,,,,,,,-6.943370e-006,,,,,,,,,,,,,,,,,,,,,
1557467921.304,,2.121212e+000,1.801616e+000,1.803301e+000,2,0,2.034384e+000,-9.277627e-002,-1.332896e-001,6.670006e-002,6.670006e-002,-1.367069e-001,6.328277e-002,6.328277e-002,-2.106571e-006,-3.026464e-006,,,,,,,,,,,,,,,,,,,,
1557467921.304,,2.121212e+000,1.801616e+000,1.803301e+000,2,0,-3.608723e-003,-1.974548e-001,-2.379681e-001,-2.936243e-002,-3.797843e-002,-2.323449e-001,-2.373924e-002,-3.235523e-002,-4.483394e-006,-5.403286e-006,,,,,,,,,,,,,,,,,,,,
1557467921.304,,2.121212e+000,1.801616e+000,1.803301e+000,2,0,1.967301e+000,-1.045259e-001,-1.541948e-001,6.302686e-002,4.579487e-002,-1.526223e-001,6.459929e-002,4.736730e-002,-2.373358e-006,-3.501135e-006,,,,,,,,,,,,,,,,,,,,
1557467921.304,,2.121212e+000,1.801616e+000,1.803301e+000,2,0,4.005293e+000,-1.969970e-001,-2.513962e-001,-2.555858e-002,-5.140656e-002,-2.456903e-001,-1.985269e-002,-4.570067e-002,-4.472999e-006,-5.708184e-006,,,,,,,,,,,,,,,,,,,,
1557467999.026,,2.272727e+000,1.801616e+000,1.801144e+000,1,0,2.034787e+000,-3.082369e-001,,,,,,,-6.998806e-006,,,,,,,,,,,,,,,,,,,,,
1557467999.026,,2.272727e+000,1.801616e+000,1.801144e+000,1,0,-2.943908e-003,-4.380932e-001,,,,,,,-9.947313e-006,,,,,,,,,,,,,,,,,,,,,
1557467999.026,,2.272727e+000,1.801616e+000,1.801144e+000,1,0,1.967955e+000,-3.881954e-001,,,,,,,-8.814338e-006,,,,,,,,,,,,,,,,,,,,,
1557467999.026,,2.272727e+000,1.801616e+000,1.801144e+000,1,0,4.005686e+000,-4.853969e-001,,,,,,,-1.102139e-005,,,,,,,,,,,,,,,,,,,,,
1557467999.026,,2.272727e+000,1.802177e+000,1.802546e+000,2,0,2.034792e+000,-5.569628e-002,-1.819666e-001,6.737004e-002,6.737004e-002,-1.895455e-001,5.979115e-002,5.979115e-002,-1.264636e-006,-4.131721e-006,,,,,,,,,,,,,,,,,,,,
1557467999.026,,2.272727e+000,1.802177e+000,1.802546e+000,2,0,-2.945454e-003,-1.596118e-001,-2.988525e-001,-3.051217e-002,-4.951584e-002,-2.908389e-001,-2.249853e-002,-4.150221e-002,-3.624134e-006,-6.785724e-006,,,,,,,,,,,,,,,,,,,,
1557467999.026,,2.272727e+000,1.802177e+000,1.802546e+000,2,0,1.967959e+000,-7.293924e-002,-2.305673e-001,5.677668e-002,1.876932e-002,-2.262798e-001,6.106419e-002,2.305683e-002,-1.656153e-006,-5.235246e-006,,,,,,,,,,,,,,,,,,,,
1557467999.026,,2.272727e+000,1.802177e+000,1.802546e+000,2,0,4.005696e+000,-1.609851e-001,-3.231910e-001,-1.684332e-002,-7.385436e-002,-3.250735e-001,-1.872579e-002,-7.573682e-002,-3.655317e-006,-7.338352e-006,,,,,,,,,,,,,,,,,,,,
1557468088.547,,2.424242e+000,1.797969e+000,1.798978e+000,1,0,2.034248e+000,-3.650014e-001,,,,,,,-8.287695e-006,,,,,,,,,,,,,,,,,,,,,
1557468088.547,,2.424242e+000,1.797969e+000,1.798978e+000,1,0,-3.751147e-003,-4.945524e-001,,,,,,,-1.122927e-005,,,,,,,,,,,,,,,,,,,,,
1557468088.547,,2.424242e+000,1.797969e+000,1.798978e+000,1,0,1.967437e+000,-4.539628e-001,,,,,,,-1.030765e-005,,,,,,,,,,,,,,,,,,,,,
1557468088.547,,2.424242e+000,1.797969e+000,1.798978e+000,1,0,4.005436e+000,-5.706961e-001,,,,,,,-1.295818e-005,,,,,,,,,,,,,,,,,,,,,
1557468088.547,,2.424242e+000,1.798978e+000,1.799990e+000,2,0,2.034150e+000,-5.920591e-002,-2.121036e-001,6.551570e-002,6.551570e-002,-2.179446e-001,5.967472e-002,5.967472e-002,-1.344325e-006,-4.816010e-006,,,,,,,,,,,,,,,,,,,,
1557468088.547,,2.424242e+000,1.798978e+000,1.799990e+000,2,0,-3.815521e-003,-1.542711e-001,-3.244117e-001,-2.489015e-002,-4.679242e-002,-3.228891e-001,-2.336752e-002,-4.526979e-002,-3.502867e-006,-7.366069e-006,,,,,,,,,,,,,,,,,,,,
1557468088.547,,2.424242e+000,1.798978e+000,1.799990e+000,2,0,1.967239e+000,-6.897183e-002,-2.614673e-001,5.995653e-002,1.615199e-002,-2.600308e-001,6.139303e-002,1.758850e-002,-1.566069e-006,-5.936859e-006,,,,,,,,,,,,,,,,,,,,
1557468088.547,,2.424242e+000,1.798978e+000,1.799990e+000,2,0,4.005205e+000,-1.532029e-001,-3.619495e-001,-1.862339e-002,-8.433020e-002,-3.615899e-001,-1.826380e-002,-8.397061e-002,-3.478614e-006,-8.218400e-006,,,,,,,,,,,,,,,,,,,,
1557468171.957,,2.575758e+000,1.797291e+000,1.797274e+000,1,0,2.034205e+000,-3.711051e-001,,,,,,,-8.426285e-006,,,,,,,,,,,,,,,,,,,,,
1557468171.957,,2.575758e+000,1.797291e+000,1.797274e+000,1,0,-3.779623e-003,-4.972991e-001,,,,,,,-1.129164e-005,,,,,,,,,,,,,,,,,,,,,
1557468171.957,,2.575758e+000,1.797291e+000,1.797274e+000,1,0,1.967060e+000,-4.419080e-001,,,,,,,-1.003393e-005,,,,,,,,,,,,,,,,,,,,,
1557468171.957,,2.575758e+000,1.797291e+000,1.797274e+000,1,0,4.005044e+000,-5.528428e-001,,,,,,,-1.255281e-005,,,,,,,,,,,,,,,,,,,,,
1557468171.957,,2.575758e+000,1.797274e+000,1.798682e+000,2,0,2.034440e+000,-5.554369e-002,-2.133244e-001,7.254960e-002,7.254960e-002,-2.226152e-001,6.325874e-002,6.325874e-002,-1.261171e-006,-4.843728e-006,,,,,,,,,,,,,,,,,,,,
1557468171.957,,2.575758e+000,1.797274e+000,1.798682e+000,2,0,-3.357932e-003,-1.594592e-001,-3.283792e-001,-2.490628e-002,-4.250517e-002,-3.270828e-001,-2.360991e-002,-4.120880e-002,-3.620669e-006,-7.456154e-006,,,,,,,,,,,,,,,,,,,,
1557468171.957,,2.575758e+000,1.797274e+000,1.798682e+000,2,0,1.967562e+000,-8.270516e-002,-2.623066e-001,5.876517e-002,2.356738e-002,-2.565627e-001,6.450912e-002,2.931133e-002,-1.877897e-006,-5.955914e-006,,,,,,,,,,,,,,,,,,,,
1557468171.957,,2.575758e+000,1.797274e+000,1.798682e+000,2,0,4.005360e+000,-1.669362e-001,-3.598895e-001,-2.121888e-002,-7.401556e-002,-3.585795e-001,-1.990889e-002,-7.270557e-002,-3.790442e-006,-8.171625e-006,,,,,,,,,,,,,,,,,,,,
1557468255.777,,2.727273e+000,1.799920e+000,1.800776e+000,1,0,2.034206e+000,-1.876888e-001,,,,,,,-4.261649e-006,,,,,,,,,,,,,,,,,,,,,
1557468255.777,,2.727273e+000,1.799920e+000,1.800776e+000,1,0,-3.642169e-003,-2.958770e-001,,,,,,,-6.718160e-006,,,,,,,,,,,,,,,,,,,,,
1557468255.777,,2.727273e+000,1.799920e+000,1.800776e+000,1,0,1.967148e+000,-2.221747e-001,,,,,,,-5.044684e-006,,,,,,,,,,,,,,,,,,,,,
1557468255.777,,2.727273e+000,1.799920e+000,1.800776e+000,1,0,4.004996e+000,-3.172399e-001,,,,,,,-7.203226e-006,,,,,,,,,,,,,,,,,,,,,
1557468255.777,,2.727273e+000,1.800776e+000,1.802020e+000,2,0,2.034478e+000,-5.996887e-002,-1.238289e-001,7.331539e-002,7.331539e-002,-1.325919e-001,6.455237e-002,6.455237e-002,-1.361649e-006,-2.811649e-006,,,,,,,,,,,,,,,,,,,,
1557468255.777,,2.727273e+000,1.800776e+000,1.802020e+000,2,0,-3.371493e-003,-1.734977e-001,-2.346873e-001,-2.678579e-002,-3.754310e-002,-2.316234e-001,-2.372183e-002,-3.447914e-002,-3.939427e-006,-5.328794e-006,,,,,,,,,,,,,,,,,,,,
1557468255.777,,2.727273e+000,1.800776e+000,1.802020e+000,2,0,1.967527e+000,-8.972441e-002,-1.559496e-001,6.270929e-002,4.119466e-002,-1.530205e-001,6.563842e-002,4.412378e-002,-2.037276e-006,-3.540980e-006,,,,,,,,,,,,,,,,,,,,
1557468255.777,,2.727273e+000,1.800776e+000,1.802020e+000,2,0,4.005377e+000,-1.861629e-001,-2.517014e-001,-2.228523e-002,-5.455717e-002,-2.499300e-001,-2.051384e-002,-5.278578e-002,-4.227001e-006,-5.715114e-006,,,,,,,,,,,,,,,,,,,,
1557468339.747,,2.878788e+000,1.800322e+000,1.801774e+000,1,0,2.034677e+000,-2.649007e-001,,,,,,,-6.014815e-006,,,,,,,,,,,,,,,,,,,,,
1557468339.747,,2.878788e+000,1.800322e+000,1.801774e+000,1,0,-2.957731e-003,-3.752251e-001,,,,,,,-8.519834e-006,,,,,,,,,,,,,,,,,,,,,
1557468339.747,,2.878788e+000,1.800322e+000,1.801774e+000,1,0,1.968086e+000,-3.134251e-001,,,,,,,-7.116607e-006,,,,,,,,,,,,,,,,,,,,,
1557468339.747,,2.878788e+000,1.800322e+000,1.801774e+000,1,0,4.005721e+000,-4.124576e-001,,,,,,,-9.365233e-006,,,,,,,,,,,,,,,,,,,,,
1557468339.747,,2.878788e+000,1.801774e+000,1.801424e+000,2,0,2.034091e+000,-5.813776e-002,-1.615192e-001,6.829160e-002,6.829160e-002,-1.680676e-001,6.174326e-002,6.174326e-002,-1.320072e-006,-3.667443e-006,,,,,,,,,,,,,,,,,,,,
1557468339.747,,2.878788e+000,1.801774e+000,1.801424e+000,2,0,-3.603589e-003,-1.647999e-001,-2.700125e-001,-2.609114e-002,-4.020168e-002,-2.675372e-001,-2.361587e-002,-3.772642e-002,-3.741936e-006,-6.130885e-006,,,,,,,,,,,,,,,,,,,,
1557468339.747,,2.878788e+000,1.801774e+000,1.801424e+000,2,0,1.967589e+000,-8.667257e-002,-2.000488e-001,5.798307e-002,2.976198e-002,-1.947896e-001,6.324233e-002,3.502125e-002,-1.967981e-006,-4.542294e-006,,,,,,,,,,,,,,,,,,,,
1557468339.747,,2.878788e+000,1.801774e+000,1.801424e+000,2,0,4.005283e+000,-1.762444e-001,-2.943510e-001,-2.220856e-002,-6.454019e-002,-2.912878e-001,-1.914533e-002,-6.147696e-002,-4.001792e-006,-6.683513e-006,,,,,,,,,,,,,,,,,,,,
1557468424.747,,3.030303e+000,1.798073e+000,1.798822e+000,1,0,2.034590e+000,-1.518296e-001,,,,,,,-3.447431e-006,,,,,,,,,,,,,,,,,,,,,
1557468424.747,,3.030303e+000,1.798073e+000,1.798822e+000,1,0,-2.890257e-003,-2.650532e-001,,,,,,,-6.018280e-006,,,,,,,,,,,,,,,,,,,,,
1557468424.747,,3.030303e+000,1.798073e+000,1.798822e+000,1,0,1.968142e+000,-1.948607e-001,,,,,,,-4.424493e-006,,,,,,,,,,,,,,,,,,,,,
1557468424.747,,3.030303e+000,1.798073e+000,1.798822e+000,1,0,4.005621e+000,-3.036592e-001,,,,,,,-6.894863e-006,,,,,,,,,,,,,,,,,,,,,
1557468424.747,,3.030303e+000,1.798822e+000,1.799257e+000,2,0,2.034225e+000,-1.525925e-003,-7.667775e-002,6.414360e-002,6.414360e-002,-7.728957e-002,6.353179e-002,6.353179e-002,-3.464755e-008,-1.741040e-006,,,,,,,,,,,,,,,,,,,,
1557468424.747,,3.030303e+000,1.798822e+000,1.799257e+000,2,0,-3.369062e-003,-9.979553e-002,-1.824244e-001,-2.727921e-002,-4.160304e-002,-1.789258e-001,-2.378057e-002,-3.810440e-002,-2.265950e-006,-4.142115e-006,,,,,,,,,,,,,,,,,,,,
1557468424.747,,3.030303e+000,1.798822e+000,1.799257e+000,2,0,1.967684e+000,-2.182073e-002,-1.083407e-001,6.112830e-002,3.248064e-002,-1.046527e-001,6.481634e-002,3.616868e-002,-4.954600e-007,-2.459976e-006,,,,,,,,,,,,,,,,,,,,
1557468424.747,,3.030303e+000,1.798822e+000,1.799257e+000,2,0,4.005278e+000,-1.098666e-001,-2.067629e-001,-2.297005e-002,-6.594154e-002,-2.037514e-001,-1.995853e-002,-6.293002e-002,-2.494624e-006,-4.694743e-006,,,,,,,,,,,,,,,,,,,,
1557468509.237,,3.181818e+000,1.800776e+000,1.801634e+000,1,0,2.034618e+000,-1.605274e-001,,,,,,,-3.644923e-006,,,,,,,,,,,,,,,,,,,,,
1557468509.237,,3.181818e+000,1.800776e+000,1.801634e+000,1,0,-2.876782e-003,-2.772607e-001,,,,,,,-6.295460e-006,,,,,,,,,,,,,,,,,,,,,
1557468509.237,,3.181818e+000,1.800776e+000,1.801634e+000,1,0,1.968152e+000,-2.113407e-001,,,,,,,-4.798686e-006,,,,,,,,,,,,,,,,,,,,,
1557468509.237,,3.181818e+000,1.800776e+000,1.801634e+000,1,0,4.005647e+000,-3.265481e-001,,,,,,,-7.414576e-006,,,,,,,,,,,,,,,,,,,,,
1557468509.237,,3.181818e+000,1.801634e+000,1.803090e+000,2,0,2.034622e+000,1.632740e-002,-7.209998e-002,6.792981e-002,6.792981e-002,-7.542390e-002,6.460588e-002,6.460588e-002,3.707288e-007,-1.637097e-006,,,,,,,,,,,,,,,,,,,,
1557468509.237,,3.181818e+000,1.801634e+000,1.803090e+000,2,0,-2.883774e-003,-7.126072e-002,-1.742607e-001,-2.753677e-002,-3.423090e-002,-1.709882e-001,-2.426424e-002,-3.095837e-002,-1.618041e-006,-3.956751e-006,,,,,,,,,,,,,,,,,,,,
1557468509.237,,3.181818e+000,1.801634e+000,1.803090e+000,2,0,1.968149e+000,3.250221e-002,-8.941923e-002,6.399882e-002,5.061056e-002,-8.746678e-002,6.595127e-002,5.256301e-002,7.379929e-007,-2.030346e-006,,,,,,,,,,,,,,,,,,,,
1557468509.237,,3.181818e+000,1.801634e+000,1.803090e+000,2,0,4.005654e+000,-3.738517e-002,-1.819666e-001,-2.185443e-002,-4.193683e-002,-1.803684e-001,-2.025624e-002,-4.033864e-002,-8.488651e-007,-4.131721e-006,,,,,,,,,,,,,,,,,,,,
1557468608.717,,3.333333e+000,1.803653e+000,1.804111e+000,1,0,2.034497e+000,-4.673910e-001,,,,,,,-1.061255e-005,,,,,,,,,,,,,,,,,,,,,
1557468608.717,,3.333333e+000,1.803653e+000,1.804111e+000,1,0,-2.908056e-003,-5.949584e-001,,,,,,,-1.350908e-005,,,,,,,,,,,,,,,,,,,,,
1557468608.717,,3.333333e+000,1.803653e+000,1.804111e+000,1,0,1.968270e+000,-5.278176e-001,,,,,,,-1.198459e-005,,,,,,,,,,,,,,,,,,,,,
1557468608.717,,3.333333e+000,1.803653e+000,1.804111e+000,1,0,4.005675e+000,-6.244087e-001,,,,,,,-1.417778e-005,,,,,,,,,,,,,,,,,,,,,
1557468608.717,,3.333333e+000,1.804111e+000,1.803477e+000,2,0,2.034513e+000,-4.043702e-002,-2.539140e-001,7.029143e-002,7.029143e-002,-2.599194e-001,6.428602e-002,6.428602e-002,-9.181601e-007,-5.765353e-006,,,,,,,,,,,,,,,,,,,,
1557468608.717,,3.333333e+000,1.804111e+000,1.803477e+000,2,0,-2.903769e-003,-1.396222e-001,-3.672903e-001,-3.158620e-002,-4.308483e-002,-3.598072e-001,-2.410316e-002,-3.560179e-002,-3.170251e-006,-8.339666e-006,,,,,,,,,,,,,,,,,,,,
1557468608.717,,3.333333e+000,1.804111e+000,1.803477e+000,2,0,1.968246e+000,-4.699850e-002,-2.874081e-001,5.979464e-002,3.679737e-002,-2.816018e-001,6.560085e-002,4.260358e-002,-1.067145e-006,-6.525866e-006,,,,,,,,,,,,,,,,,,,,
1557468608.717,,3.333333e+000,1.804111e+000,1.803477e+000,2,0,4.005663e+000,-1.329081e-001,-3.786584e-001,-1.995709e-002,-5.445299e-002,-3.788759e-001,-2.017459e-002,-5.467048e-002,-3.017802e-006,-8.597790e-006,,,,,,,,,,,,,,,,,,,,
1557468711.217,,3.484848e+000,1.797882e+000,1.798613e+000,1,0,2.034777e+000,-1.069674e-001,,,,,,,-2.428793e-006,,,,,,,,,,,,,,,,,,,,,
1557468711.217,,3.484848e+000,1.797882e+000,1.798613e+000,1,0,-3.094811e-003,-2.212592e-001,,,,,,,-5.023895e-006,,,,,,,,,,,,,,,,,,,,,
1557468711.217,,3.484848e+000,1.797882e+000,1.798613e+000,1,0,1.967876e+000,-1.414533e-001,,,,,,,-3.211828e-006,,,,,,,,,,,,,,,,,,,,,
1557468711.217,,3.484848e+000,1.797882e+000,1.798613e+000,1,0,4.005748e+000,-2.337718e-001,,,,,,,-5.308005e-006,,,,,,,,,,,,,,,,,,,,,
1557468711.217,,3.484848e+000,1.798613e+000,1.798804e+000,2,0,2.034414e+000,-3.387554e-002,-7.042146e-002,6.759612e-002,6.759612e-002,-7.379185e-002,6.422573e-002,6.422573e-002,-7.691756e-007,-1.598984e-006,,,,,,,,,,,,,,,,,,,,
1557468711.217,,3.484848e+000,1.798613e+000,1.798804e+000,2,0,-3.434053e-003,-1.243629e-001,-1.728111e-001,-2.713849e-002,-3.479348e-002,-1.692149e-001,-2.354229e-002,-3.119728e-002,-2.823776e-006,-3.923835e-006,,,,,,,,,,,,,,,,,,,,
1557468711.217,,3.484848e+000,1.798613e+000,1.798804e+000,2,0,1.967541e+000,-4.135258e-002,-9.140293e-002,6.192462e-002,4.661465e-002,-8.805297e-002,6.527458e-002,4.996461e-002,-9.389487e-007,-2.075388e-006,,,,,,,,,,,,,,,,,,,,
1557468711.217,,3.484848e+000,1.798613e+000,1.798804e+000,2,0,4.005389e+000,-1.260414e-001,-1.799066e-001,-1.892406e-002,-4.188903e-002,-1.814235e-001,-2.044094e-002,-4.340591e-002,-2.861888e-006,-4.084946e-006,,,,,,,,,,,,,,,,,,,,
1557468812.838,,3.636364e+000,1.799031e+000,1.799676e+000,1,0,2.034029e+000,-8.972441e-002,,,,,,,-2.037276e-006,,,,,,,,,,,,,,,,,,,,,
1557468812.838,,3.636364e+000,1.799031e+000,1.799676e+000,1,0,-3.611742e-003,-1.942503e-001,,,,,,,-4.410633e-006,,,,,,,,,,,,,,,,,,,,,
1557468812.838,,3.636364e+000,1.799031e+000,1.799676e+000,1,0,1.967343e+000,-1.191748e-001,,,,,,,-2.705974e-006,,,,,,,,,,,,,,,,,,,,,
1557468812.838,,3.636364e+000,1.799031e+000,1.799676e+000,1,0,4.004983e+000,-2.153081e-001,,,,,,,-4.888770e-006,,,,,,,,,,,,,,,,,,,,,
1557468812.838,,3.636364e+000,1.799676e+000,1.800095e+000,2,0,2.034321e+000,-3.204443e-003,-4.646443e-002,6.654918e-002,6.654918e-002,-4.945883e-002,6.355478e-002,6.355478e-002,-7.275986e-008,-1.055018e-006,,,,,,,,,,,,,,,,,,,,
1557468812.838,,3.636364e+000,1.799676e+000,1.800095e+000,2,0,-3.267793e-003,-1.055940e-001,-1.499222e-001,-2.819900e-002,-3.690857e-002,-1.458444e-001,-2.412118e-002,-3.283074e-002,-2.397611e-006,-3.404122e-006,,,,,,,,,,,,,,,,,,,,
1557468812.838,,3.636364e+000,1.799676e+000,1.800095e+000,2,0,1.967745e+000,-2.365184e-002,-7.141332e-002,5.901942e-002,4.160029e-002,-6.542708e-002,6.500566e-002,4.758653e-002,-5.370371e-007,-1.621505e-006,,,,,,,,,,,,,,,,,,,,
1557468812.838,,3.636364e+000,1.799676e+000,1.800095e+000,2,0,4.005333e+000,-1.063570e-001,-1.608325e-001,-2.169024e-002,-4.781893e-002,-1.589444e-001,-1.980213e-002,-4.593082e-002,-2.414934e-006,-3.651852e-006,,,,,,,,,,,,,,,,,,,,
1557468906.810,,3.787879e+000,1.797986e+000,1.798334e+000,1,0,2.034631e+000,-5.203406e-001,,,,,,,-1.181482e-005,,,,,,,,,,,,,,,,,,,,,
1557468906.810,,3.787879e+000,1.797986e+000,1.798334e+000,1,0,-2.890305e-003,-6.781213e-001,,,,,,,-1.539737e-005,,,,,,,,,,,,,,,,,,,,,
1557468906.810,,3.787879e+000,1.797986e+000,1.798334e+000,1,0,1.968136e+000,-6.506547e-001,,,,,,,-1.477372e-005,,,,,,,,,,,,,,,,,,,,,
1557468906.810,,3.787879e+000,1.797986e+000,1.798334e+000,1,0,4.005657e+000,-7.937864e-001,,,,,,,-1.802366e-005,,,,,,,,,,,,,,,,,,,,,
1557468906.810,,3.787879e+000,1.799746e+000,1.800899e+000,2,0,2.034676e+000,-1.487777e-001,-3.345592e-001,7.240316e-002,7.240316e-002,-3.437087e-001,6.325367e-002,6.325367e-002,-3.378136e-006,-7.596476e-006,,,,,,,,,,,,,,,,,,,,
1557468906.810,,3.787879e+000,1.799746e+000,1.800899e+000,2,0,-2.900936e-003,-2.655110e-001,-4.718162e-001,-2.523307e-002,-6.485382e-002,-4.706930e-001,-2.410991e-002,-6.373066e-002,-6.028674e-006,-1.071302e-005,,,,,,,,,,,,,,,,,,,,
1557468906.810,,3.787879e+000,1.799746e+000,1.800899e+000,2,0,1.968084e+000,-2.021851e-001,-4.264199e-001,5.978394e-002,-1.945755e-002,-4.214554e-001,6.474838e-002,-1.449311e-002,-4.590800e-006,-9.682259e-006,,,,,,,,,,,,,,,,,,,,
1557468906.810,,3.787879e+000,1.799746e+000,1.800899e+000,2,0,4.005661e+000,-3.012177e-001,-5.475020e-001,-2.167747e-002,-1.405397e-001,-5.454845e-001,-1.965997e-002,-1.385222e-001,-6.839427e-006,-1.243154e-005,,,,,,,,,,,,,,,,,,,,
1557469002.104,,3.939394e+000,1.799013e+000,1.800514e+000,1,0,2.033624e+000,-1.786859e+000,,,,,,,-4.057228e-005,,,,,,,,,,,,,,,,,,,,,
1557469002.104,,3.939394e+000,1.799013e+000,1.800514e+000,1,0,-4.224448e-003,-2.059237e+000,,,,,,,-4.675687e-005,,,,,,,,,,,,,,,,,,,,,
1557469002.104,,3.939394e+000,1.799013e+000,1.800514e+000,1,0,1.966982e+000,-2.114933e+000,,,,,,,-4.802151e-005,,,,,,,,,,,,,,,,,,,,,
1557469002.104,,3.939394e+000,1.799013e+000,1.800514e+000,1,0,4.004831e+000,-2.317728e+000,,,,,,,-5.262616e-005,,,,,,,,,,,,,,,,,,,,,
1557469002.104,,3.939394e+000,1.800514e+000,1.800549e+000,2,0,2.034112e+000,-7.110813e-002,-9.289834e-001,8.665621e-002,8.665621e-002,-9.458048e-001,6.983483e-002,6.983483e-002,-1.614576e-006,-2.109343e-005,,,,,,,,,,,,,,,,,,,,
1557469002.104,,3.939394e+000,1.800514e+000,1.800549e+000,2,0,-3.546864e-003,-1.823481e-001,-1.120792e+000,-3.120302e-002,-1.051526e-001,-1.115188e+000,-2.559887e-002,-9.954846e-002,-4.140382e-006,-2.544863e-005,,,,,,,,,,,,,,,,,,,,
1557469002.104,,3.939394e+000,1.800514e+000,1.800549e+000,2,0,1.967574e+000,-1.051363e-001,-1.110034e+000,5.350438e-002,-9.439480e-002,-1.092569e+000,7.097033e-002,-7.692885e-002,-2.387216e-006,-2.520436e-005,,,,,,,,,,,,,,,,,,,,
1557469002.104,,3.939394e+000,1.800514e+000,1.800549e+000,2,0,4.005233e+000,-1.957762e-001,-1.256752e+000,-1.926382e-002,-2.411126e-001,-1.259713e+000,-2.222438e-002,-2.440732e-001,-4.445281e-006,-2.853572e-005,,,,,,,,,,,,,,,,,,,,
1557469103.084,,4.090909e+000,1.799920e+000,1.799920e+000,1,0,2.034725e+000,-8.178961e-002,,,,,,,-1.857109e-006,,,,,,,,,,,,,,,,,,,,,
1557469103.084,,4.090909e+000,1.799920e+000,1.799920e+000,1,0,-2.914360e-003,-1.948607e-001,,,,,,,-4.424492e-006,,,,,,,,,,,,,,,,,,,,,
1557469103.084,,4.090909e+000,1.799920e+000,1.799920e+000,1,0,1.968028e+000,-1.149022e-001,,,,,,,-2.608961e-006,,,,,,,,,,,,,,,,,,,,,
1557469103.084,,4.090909e+000,1.799920e+000,1.799920e+000,1,0,4.005667e+000,-2.212592e-001,,,,,,,-5.023895e-006,,,,,,,,,,,,,,,,,,,,,
1557469103.084,,4.090909e+000,1.799920e+000,1.800165e+000,2,0,2.034187e+000,-1.541185e-002,-4.860073e-002,6.997493e-002,6.997493e-002,-5.305833e-002,6.551732e-002,6.551732e-002,-3.499403e-007,-1.103524e-006,,,,,,,,,,,,,,,,,,,,
1557469103.084,,4.090909e+000,1.799920e+000,1.800165e+000,2,0,-3.586873e-003,-1.220740e-001,-1.584674e-001,-3.107492e-002,-3.989171e-002,-1.519910e-001,-2.459850e-002,-3.341530e-002,-2.771804e-006,-3.598148e-006,,,,,,,,,,,,,,,,,,,,
1557469103.084,,4.090909e+000,1.799920e+000,1.800165e+000,2,0,1.967506e+000,-2.639851e-002,-7.065035e-002,6.555890e-002,4.792531e-002,-6.932569e-002,6.688356e-002,4.924997e-002,-5.994026e-007,-1.604182e-006,,,,,,,,,,,,,,,,,,,,
1557469103.084,,4.090909e+000,1.799920e+000,1.800165e+000,2,0,4.005280e+000,-1.217689e-001,-1.715140e-001,-2.648798e-002,-5.293836e-002,-1.655669e-001,-2.054083e-002,-4.699121e-002,-2.764875e-006,-3.894384e-006,,,,,,,,,,,,,,,,,,,,
1557469201.744,,4.242424e+000,1.799188e+000,1.799973e+000,1,0,2.034574e+000,-2.751244e-001,,,,,,,-6.246953e-006,,,,,,,,,,,,,,,,,,,,,
1557469201.744,,4.242424e+000,1.799188e+000,1.799973e+000,1,0,-2.905386e-003,-4.097110e-001,,,,,,,-9.302868e-006,,,,,,,,,,,,,,,,,,,,,
1557469201.744,,4.242424e+000,1.799188e+000,1.799973e+000,1,0,1.968179e+000,-3.569140e-001,,,,,,,-8.104062e-006,,,,,,,,,,,,,,,,,,,,,
1557469201.744,,4.242424e+000,1.799188e+000,1.799973e+000,1,0,4.005658e+000,-4.715109e-001,,,,,,,-1.070609e-005,,,,,,,,,,,,,,,,,,,,,
1557469201.744,,4.242424e+000,1.799973e+000,1.799554e+000,2,0,2.034598e+000,-9.125035e-002,-1.831874e-001,7.068594e-002,7.068594e-002,-1.915632e-001,6.231010e-002,6.231010e-002,-2.071924e-006,-4.159439e-006,,,,,,,,,,,,,,,,,,,,
1557469201.744,,4.242424e+000,1.799973e+000,1.799554e+000,2,0,-2.922980e-003,-1.988281e-001,-3.042696e-001,-2.809328e-002,-5.039626e-002,-3.000138e-001,-2.383757e-002,-4.614055e-002,-4.514576e-006,-6.908722e-006,,,,,,,,,,,,,,,,,,,,
1557469201.744,,4.242424e+000,1.799973e+000,1.799554e+000,2,0,1.968142e+000,-1.193274e-001,-2.381207e-001,6.035857e-002,1.575261e-002,-2.346567e-001,6.382258e-002,1.921663e-002,-2.709438e-006,-5.406750e-006,,,,,,,,,,,,,,,,,,,,
1557469201.744,,4.242424e+000,1.799973e+000,1.799554e+000,2,0,4.005663e+000,-2.166814e-001,-3.440962e-001,-2.331396e-002,-9.022290e-002,-3.401065e-001,-1.932423e-002,-8.623317e-002,-4.919952e-006,-7.813022e-006,,,,,,,,,,,,,,,,,,,,
1557469296.518,,4.393939e+000,1.797500e+000,1.798648e+000,1,0,2.034721e+000,-7.422101e-001,,,,,,,-1.685257e-005,,,,,,,,,,,,,,,,,,,,,
1557469296.518,,4.393939e+000,1.797500e+000,1.798648e+000,1,0,-2.915894e-003,-9.624012e-001,,,,,,,-2.185221e-005,,,,,,,,,,,,,,,,,,,,,
1557469296.518,,4.393939e+000,1.797500e+000,1.798648e+000,1,0,1.968043e+000,-9.982604e-001,,,,,,,-2.266643e-005,,,,,,,,,,,,,,,,,,,,,
1557469296.518,,4.393939e+000,1.797500e+000,1.798648e+000,1,0,4.005679e+000,-1.206092e+000,,,,,,,-2.738542e-005,,,,,,,,,,,,,,,,,,,,,
1557469296.518,,4.393939e+000,1.798648e+000,1.799153e+000,2,0,2.034370e+000,-1.017792e-001,-4.219947e-001,6.553847e-002,6.553847e-002,-4.246608e-001,6.287235e-002,6.287235e-002,-2.310992e-006,-9.581780e-006,,,,,,,,,,,,,,,,,,,,
1557469296.518,,4.393939e+000,1.798648e+000,1.799153e+000,2,0,-3.273593e-003,-2.134770e-001,-5.879391e-001,-2.935818e-002,-1.004059e-001,-5.817816e-001,-2.320066e-002,-9.424841e-002,-4.847192e-006,-1.334970e-005,,,,,,,,,,,,,,,,,,,,
1557469296.518,,4.393939e+000,1.798648e+000,1.799153e+000,2,0,1.967692e+000,-1.402325e-001,-5.692465e-001,6.038219e-002,-8.171332e-002,-5.656533e-001,6.397539e-002,-7.812011e-002,-3.184110e-006,-1.292527e-005,,,,,,,,,,,,,,,,,,,,
1557469296.518,,4.393939e+000,1.798648e+000,1.799153e+000,2,0,4.005336e+000,-2.368236e-001,-7.214575e-001,-2.078113e-002,-2.339244e-001,-7.206048e-001,-1.992837e-002,-2.330716e-001,-5.377300e-006,-1.638136e-005,,,,,,,,,,,,,,,,,,,,
1557469396.858,,4.545455e+000,1.799763e+000,1.800095e+000,1,0,2.034710e+000,-1.358074e-001,,,,,,,-3.083632e-006,,,,,,,,,,,,,,,,,,,,,
1557469396.858,,4.545455e+000,1.799763e+000,1.800095e+000,1,0,-3.054319e-003,-2.487259e-001,,,,,,,-5.647551e-006,,,,,,,,,,,,,,,,,,,,,
1557469396.858,,4.545455e+000,1.799763e+000,1.800095e+000,1,0,1.967950e+000,-1.814325e-001,,,,,,,-4.119594e-006,,,,,,,,,,,,,,,,,,,,,
1557469396.858,,4.545455e+000,1.799763e+000,1.800095e+000,1,0,4.005714e+000,-2.789392e-001,,,,,,,-6.333572e-006,,,,,,,,,,,,,,,,,,,,,
1557469396.858,,4.545455e+000,1.800095e+000,1.800409e+000,2,0,2.034352e+000,-9.033479e-002,-1.130711e-001,6.904275e-002,6.904275e-002,-1.191414e-001,6.297240e-002,6.297240e-002,-2.051135e-006,-2.567383e-006,,,,,,,,,,,,,,,,,,,,
1557469396.858,,4.545455e+000,1.800095e+000,1.800409e+000,2,0,-3.416023e-003,-2.067629e-001,-2.277444e-001,-3.048178e-002,-4.563054e-002,-2.213304e-001,-2.406784e-002,-3.921661e-002,-4.694743e-006,-5.171147e-006,,,,,,,,,,,,,,,,,,,,
1557469396.858,,4.545455e+000,1.800095e+000,1.800409e+000,2,0,1.967804e+000,-1.240577e-001,-1.527451e-001,5.966622e-002,2.936868e-002,-1.479173e-001,6.449403e-002,3.419650e-002,-2.816846e-006,-3.468220e-006,,,,,,,,,,,,,,,,,,,,
1557469396.858,,4.545455e+000,1.800095e+000,1.800409e+000,2,0,4.005572e+000,-2.299570e-001,-2.544481e-001,-2.688796e-002,-7.233426e-002,-2.470934e-001,-1.953331e-002,-6.497961e-002,-5.221386e-006,-5.777479e-006,,,,,,,,,,,,,,,,,,,,
1557469490.313,,4.696970e+000,1.797014e+000,1.798334e+000,1,0,2.034112e+000,-7.884457e-001,,,,,,,-1.790239e-005,,,,,,,,,,,,,,,,,,,,,
1557469490.313,,4.696970e+000,1.797014e+000,1.798334e+000,1,0,-3.729641e-003,-9.791864e-001,,,,,,,-2.223333e-005,,,,,,,,,,,,,,,,,,,,,
1557469490.313,,4.696970e+000,1.797014e+000,1.798334e+000,1,0,1.967577e+000,-9.697256e-001,,,,,,,-2.201852e-005,,,,,,,,,,,,,,,,,,,,,
1557469490.313,,4.696970e+000,1.797014e+000,1.798334e+000,1,0,4.005418e+000,-1.133915e+000,,,,,,,-2.574659e-005,,,,,,,,,,,,,,,,,,,,,
1557469490.313,,4.696970e+000,1.798334e+000,1.798874e+000,2,0,2.034071e+000,-3.016755e-001,-5.450606e-001,6.585884e-002,6.585884e-002,-5.488020e-001,6.211740e-002,6.211740e-002,-6.849821e-006,-1.237611e-005,,,,,,,,,,,,,,,,,,,,
1557469490.313,,4.696970e+000,1.798334e+000,1.798874e+000,2,0,-3.665475e-003,-4.329051e-001,-7.060457e-001,-3.239788e-002,-9.512627e-002,-6.968555e-001,-2.320774e-002,-8.593613e-002,-9.829510e-006,-1.603142e-005,,,,,,,,,,,,,,,,,,,,
1557469490.313,,4.696970e+000,1.798334e+000,1.798874e+000,2,0,1.967454e+000,-3.814814e-001,-6.756035e-001,6.077269e-002,-6.468409e-002,-6.730222e-001,6.335399e-002,-6.210279e-002,-8.661887e-006,-1.534020e-005,,,,,,,,,,,,,,,,,,,,
1557469490.313,,4.696970e+000,1.798334e+000,1.798874e+000,2,0,4.005190e+000,-5.114902e-001,-8.227027e-001,-2.359812e-002,-2.117833e-001,-8.186374e-001,-1.953278e-002,-2.077180e-001,-1.161386e-005,-1.868023e-005,,,,,,,,,,,,,,,,,,,,
1557469586.117,,4.848485e+000,1.797656e+000,1.797465e+000,1,0,2.034157e+000,-7.150487e-001,,,,,,,-1.623584e-005,,,,,,,,,,,,,,,,,,,,,
1557469586.117,,4.848485e+000,1.797656e+000,1.797465e+000,1,0,-3.588086e-003,-8.938871e-001,,,,,,,-2.029653e-005,,,,,,,,,,,,,,,,,,,,,
1557469586.117,,4.848485e+000,1.797656e+000,1.797465e+000,1,0,1.967236e+000,-8.784753e-001,,,,,,,-1.994659e-005,,,,,,,,,,,,,,,,,,,,,
1557469586.117,,4.848485e+000,1.797656e+000,1.797465e+000,1,0,4.004981e+000,-1.048311e+000,,,,,,,-2.380287e-005,,,,,,,,,,,,,,,,,,,,,
1557469586.117,,4.848485e+000,1.797465e+000,1.798578e+000,2,0,2.034157e+000,-1.773126e-001,-4.461806e-001,6.854013e-002,6.854013e-002,-4.473104e-001,6.741038e-002,6.741038e-002,-4.026045e-006,-1.013094e-005,,,,,,,,,,,,,,,,,,,,
1557469586.117,,4.848485e+000,1.797465e+000,1.798578e+000,2,0,-3.606735e-003,-2.916044e-001,-5.927457e-001,-3.087417e-002,-7.802498e-002,-5.869746e-001,-2.510307e-002,-7.225388e-002,-6.621147e-006,-1.345884e-005,,,,,,,,,,,,,,,,,,,,
1557469586.117,,4.848485e+000,1.797465e+000,1.798578e+000,2,0,1.967232e+000,-2.075259e-001,-5.430006e-001,6.602178e-002,-2.827984e-002,-5.403082e-001,6.871412e-002,-2.558750e-002,-4.712067e-006,-1.232933e-005,,,,,,,,,,,,,,,,,,,,
1557469586.117,,4.848485e+000,1.797465e+000,1.798578e+000,2,0,4.004996e+000,-3.114414e-001,-6.798761e-001,-2.370292e-002,-1.651554e-001,-6.774207e-001,-2.124757e-002,-1.627000e-001,-7.071565e-006,-1.543722e-005,,,,,,,,,,,,,,,,,,,,
1557469686.931,,5.000000e+000,1.799240e+000,1.800409e+000,1,0,2.034792e+000,-7.112339e-001,,,,,,,-1.614922e-005,,,,,,,,,,,,,,,,,,,,,
1557469686.931,,5.000000e+000,1.799240e+000,1.800409e+000,1,0,-2.908479e-003,-8.870205e-001,,,,,,,-2.014062e-005,,,,,,,,,,,,,,,,,,,,,
1557469686.931,,5.000000e+000,1.799240e+000,1.800409e+000,1,0,1.967975e+000,-8.624530e-001,,,,,,,-1.958280e-005,,,,,,,,,,,,,,,,,,,,,
1557469686.931,,5.000000e+000,1.799240e+000,1.800409e+000,1,0,4.005675e+000,-1.027711e+000,,,,,,,-2.333513e-005,,,,,,,,,,,,,,,,,,,,,
1557469686.931,,5.000000e+000,1.800409e+000,1.800846e+000,2,0,2.034754e+000,-1.728874e-001,-4.420606e-001,6.749663e-002,6.749663e-002,-4.456890e-001,6.386825e-002,6.386825e-002,-3.925567e-006,-1.003739e-005,,,,,,,,,,,,,,,,,,,,
1557469686.931,,5.000000e+000,1.800409e+000,1.800846e+000,2,0,-2.902537e-003,-2.938932e-001,-5.904568e-001,-3.309949e-002,-8.089960e-002,-5.814567e-001,-2.409937e-002,-7.189947e-002,-6.673118e-006,-1.340687e-005,,,,,,,,,,,,,,,,,,,,
1557469686.931,,5.000000e+000,1.800409e+000,1.800846e+000,2,0,1.968002e+000,-2.269051e-001,-5.446791e-001,6.047834e-002,-3.512186e-002,-5.398980e-001,6.525947e-002,-3.034073e-002,-5.152091e-006,-1.236744e-005,,,,,,,,,,,,,,,,,,,,
1557469686.931,,5.000000e+000,1.800409e+000,1.800846e+000,2,0,4.005659e+000,-3.323466e-001,-6.800287e-001,-2.707113e-002,-1.704714e-001,-6.729282e-001,-1.997066e-002,-1.633710e-001,-7.546236e-006,-1.544068e-005,,,,,,,,,,,,,,,,,,,,
1557469686.931,,5.000000e+000,1.800409e+000,1.800846e+000,2,0,2.208109e+000,-2.734458e-001,-6.447035e-001,5.306664e-002,-1.351463e-001,-6.423988e-001,5.537137e-002,-1.328415e-001,-6.208841e-006,-1.463859e-005,,,,,,,,,,,,,,,,,,,,