File: 研究/MPMS/190510/190510_PlatedSn_onSi_2.rso.raw
[Header]
TITLE,MPMS RSO Measurement
BYAPP,MPMS Measurement,2.1,Raw with ABS
FILEOPENTIME, 1557464550.098000 5/10/2019, 2:02:30 PM

INFO, APPNAME, MPMS MultiVu Application, Revision 1.60,  Build 081

INFO, NAME,
INFO, WEIGHT, 1.000
INFO, AREA, 1.000
INFO, LENGTH, 1.000
INFO, SHAPE, 0
INFO, COMMENT,
INFO, SEQUENCE FILE: 190519_PlatedSn_onSi_3.seq


INFO, BACKGROUND DATA FILE:, None


STARTUPAXIS,X,8,LINEAR,AUTO,0.000000,0.000000
STARTUPAXIS,Y1,9,LINEAR,AUTO,0.000000,0.000000


STARTUPGROUP,Longitudinal
FIELDGROUP,Longitudinal,1,2,3,4,5,6,7,8,9,10,11,12,13,14,15,16,17,18,19,20,21,22
FIELDGROUP,Transverse,1,2,3,4,5,6,7,8,23,24,25,26,27,28,29,30,31,32,33,34,35,36

PLOT_APPEARANCE,ALL,HORZ_GRID_ON,VERT_GRID_ON,MARKERS_ONLY

[Data]
Time,Comment,Field (Oe),Start Temperature (K),End Temperature (K),Scan,Rejected,Position (cm),Long Voltage,Long Average Voltage,Long Detrended Voltage,Long Demeaned Voltage,Long Reg Fit,Long Detrended Fit,Long Demeaned Fit,Long Scaled Response,Long Avg. Scaled Response,Long Background Response,Long Response [w/ABS],Long Detrended Resp. [w/ABS],Long Fit [w/ABS],Long Detrended Fit [w/ABS],Trans Voltage,Trans Average Voltage,Trans Detrended Voltage,Trans Demeaned Voltage,Trans Reg Fit,Trans Detrended Fit,Trans Demeaned Fit,Trans Scaled Response,Trans Avg. Scaled Response,Trans Background Response,Trans Response [w/ABS],Trans Detrended Resp. [w/ABS],Trans Adjusted Fit,Trans Detrended Fit [w/ABS],
1557464550.098,,1.000000e+001,1.812405e+000,1.813966e+000,1,0,2.034167e+000,-5.966369e-002,,,,,,,-1.354719e-006,,,,,,,,,,,,,,,,,,,,,
1557464550.098,,1.000000e+001,1.812405e+000,1.813966e+000,1,0,2.320726e+000,-8.636738e-002,,,,,,,-1.961051e-006,,,,,,,,,,,,,,,,,,,,,
1557464550.098,,1.000000e+001,1.814686e+000,1.814668e+000,2,0,1.324751e+000,-4.226813e-002,,,,,,,-9.597370e-007,,,,,,,,,,,,,,,,,,,,,
1557464550.098,,1.000000e+001,1.814686e+000,1.814668e+000,2,0,3.017390e+000,-9.018220e-002,,,,,,,-2.047670e-006,,,,,,,,,,,,,,,,,,,,,
1557464550.098,,1.000000e+001,1.814668e+000,1.814740e+000,3,0,6.686733e-001,-1.129185e-001,,,,,,,-2.563918e-006,,,,,,,,,,,,,,,,,,,,,
1557464550.098,,1.000000e+001,1.814668e+000,1.814740e+000,3,0,3.602951e+000,-1.135289e-001,,,,,,,-2.577777e-006,,,,,,,,,,,,,,,,,,,,,
1557464550.098,,1.000000e+001,1.814740e+000,1.813571e+000,4,0,1.850325e-001,-1.368755e-001,,,,,,,-3.107885e-006,,,,,,,,,,,,,,,,,,,,,
1557464550.098,,1.000000e+001,1.814740e+000,1.813571e+000,4,0,3.956720e+000,-1.220740e-001,,,,,,,-2.771804e-006,,,,,,,,,,,,,,,,,,,,,
1557464550.098,,1.000000e+001,1.813571e+000,1.813122e+000,5,0,-3.961216e-003,-9.247109e-002,,,,,,,-2.099641e-006,,,,,,,,,,,,,,,,,,,,,
1557464550.098,,1.000000e+001,1.813571e+000,1.813122e+000,5,0,3.955532e+000,-7.995849e-002,,,,,,,-1.815531e-006,,,,,,,,,,,,,,,,,,,,,
1557464550.098,,1.000000e+001,1.813122e+000,1.813248e+000,6,0,1.882945e-001,-1.312296e-001,,,,,,,-2.979689e-006,,,,,,,,,,,,,,,,,,,,,
1557464550.098,,1.000000e+001,1.813122e+000,1.813248e+000,6,0,3.593244e+000,-1.223792e-001,,,,,,,-2.778733e-006,,,,,,,,,,,,,,,,,,,,,
1557464550.098,,1.000000e+001,1.813248e+000,1.813679e+000,7,0,6.769985e-001,-8.957183e-002,,,,,,,-2.033811e-006,,,,,,,,,,,,,,,,,,,,,
1557464550.098,,1.000000e+001,1.813248e+000,1.813679e+000,7,0,3.023556e+000,-6.378368e-002,,,,,,,-1.448267e-006,,,,,,,,,,,,,,,,,,,,,
1557464550.098,,1.000000e+001,1.813679e+000,1.813338e+000,8,0,1.293161e+000,-5.752739e-002,-5.973998e-002,2.905552e-002,3.164303e-002,-5.772189e-002,3.107360e-002,3.366112e-002,-1.306212e-006,-1.356451e-006,,,,,,,,,,,,,,,,,,,,
1557464550.098,,1.000000e+001,1.813679e+000,1.813338e+000,8,0,2.377526e+000,-3.769036e-002,-4.137165e-002,4.428186e-002,5.001136e-002,-3.490968e-002,5.074384e-002,5.647333e-002,-8.557943e-007,-9.393815e-007,,,,,,,,,,,,,,,,,,,,
1557464672.108,,1.000000e+001,1.918930e+000,1.933909e+000,1,0,1.966858e+000,-1.068148e-002,,,,,,,-2.425328e-007,,,,,,,,,,,,,,,,,,,,,
1557464672.108,,1.000000e+001,1.933909e+000,1.948520e+000,2,0,1.680104e+000,-2.227851e-002,,,,,,,-5.058541e-007,,,,,,,,,,,,,,,,,,,,,
1557464672.108,,1.000000e+001,1.933909e+000,1.948520e+000,2,0,2.675648e+000,-5.737480e-002,,,,,,,-1.302748e-006,,,,,,,,,,,,,,,,,,,,,
1557464672.108,,1.000000e+001,1.948520e+000,1.960334e+000,3,0,9.827189e-001,-1.187170e-001,,,,,,,-2.695579e-006,,,,,,,,,,,,,,,,,,,,,
1557464672.108,,1.000000e+001,1.948520e+000,1.960334e+000,3,0,3.331405e+000,-1.390118e-001,,,,,,,-3.156391e-006,,,,,,,,,,,,,,,,,,,,,
1557464672.108,,1.000000e+001,1.963976e+000,1.977579e+000,4,0,3.971195e-001,-1.435896e-001,,,,,,,-3.260334e-006,,,,,,,,,,,,,,,,,,,,,
1557464672.108,,1.000000e+001,1.963976e+000,1.977579e+000,4,0,3.816505e+000,-1.379437e-001,,,,,,,-3.132138e-006,,,,,,,,,,,,,,,,,,,,,
1557464672.108,,1.000000e+001,1.977579e+000,1.996852e+000,5,0,4.582777e-002,-1.226844e-001,,,,,,,-2.785662e-006,,,,,,,,,,,,,,,,,,,,,
1557464672.108,,1.000000e+001,1.977579e+000,1.996852e+000,5,0,4.005742e+000,-1.164281e-001,,,,,,,-2.643608e-006,,,,,,,,,,,,,,,,,,,,,
1557464672.108,,1.000000e+001,1.996852e+000,2.016069e+000,6,0,4.576754e-002,-1.231422e-001,,,,,,,-2.796057e-006,,,,,,,,,,,,,,,,,,,,,
1557464672.108,,1.000000e+001,1.996852e+000,2.016069e+000,6,0,3.812901e+000,-1.075777e-001,,,,,,,-2.442652e-006,,,,,,,,,,,,,,,,,,,,,
1557464672.108,,1.000000e+001,2.019122e+000,2.037834e+000,7,0,4.068795e-001,-1.264992e-001,,,,,,,-2.872281e-006,,,,,,,,,,,,,,,,,,,,,
1557464672.108,,1.000000e+001,2.019122e+000,2.037834e+000,7,0,3.322958e+000,-1.147496e-001,,,,,,,-2.605495e-006,,,,,,,,,,,,,,,,,,,,,
1557464672.108,,1.000000e+001,2.037834e+000,2.064172e+000,8,0,9.769874e-001,-1.327555e-001,-1.000244e-001,1.360558e-003,4.861310e-003,-1.003231e-001,1.061916e-003,4.562669e-003,-3.014336e-006,-2.271147e-006,,,,,,,,,,,,,,,,,,,,
1557464672.108,,1.000000e+001,2.037834e+000,2.064172e+000,8,0,2.707710e+000,-1.094089e-001,-7.730720e-002,1.949986e-002,2.757853e-002,-7.853521e-002,1.827186e-002,2.635052e-002,-2.484229e-006,-1.755331e-006,,,,,,,,,,,,,,,,,,,,
1557464731.588,,1.000000e+001,2.071451e+000,2.097146e+000,1,0,1.622709e+000,-3.677480e-002,,,,,,,-8.350058e-007,,,,,,,,,,,,,,,,,,,,,
1557464731.588,,1.000000e+001,2.101743e+000,2.132708e+000,2,0,2.034369e+000,-6.103702e-002,,,,,,,-1.385902e-006,,,,,,,,,,,,,,,,,,,,,
1557464731.588,,1.000000e+001,2.101743e+000,2.132708e+000,2,0,2.321371e+000,-7.522812e-002,,,,,,,-1.708124e-006,,,,,,,,,,,,,,,,,,,,,
1557464731.588,,1.000000e+001,2.132708e+000,2.163823e+000,3,0,1.324496e+000,-6.942961e-002,,,,,,,-1.576463e-006,,,,,,,,,,,,,,,,,,,,,
1557464731.588,,1.000000e+001,2.132708e+000,2.163823e+000,3,0,3.017585e+000,-1.081881e-001,,,,,,,-2.456511e-006,,,,,,,,,,,,,,,,,,,,,
1557464731.588,,1.000000e+001,2.163823e+000,2.204072e+000,4,0,6.687948e-001,-1.106296e-001,,,,,,,-2.511947e-006,,,,,,,,,,,,,,,,,,,,,
1557464731.588,,1.000000e+001,2.163823e+000,2.204072e+000,4,0,3.602932e+000,-1.142918e-001,,,,,,,-2.595101e-006,,,,,,,,,,,,,,,,,,,,,
1557464731.588,,1.000000e+001,2.204072e+000,2.246492e+000,5,0,1.833868e-001,-1.399274e-001,,,,,,,-3.177180e-006,,,,,,,,,,,,,,,,,,,,,
1557464731.588,,1.000000e+001,2.204072e+000,2.246492e+000,5,0,3.955644e+000,-1.229896e-001,,,,,,,-2.792592e-006,,,,,,,,,,,,,,,,,,,,,
1557464731.588,,1.000000e+001,2.246492e+000,2.283653e+000,6,0,-3.201093e-003,-1.275674e-001,,,,,,,-2.896535e-006,,,,,,,,,,,,,,,,,,,,,
1557464731.588,,1.000000e+001,2.246492e+000,2.283653e+000,6,0,3.956280e+000,-1.124607e-001,,,,,,,-2.553524e-006,,,,,,,,,,,,,,,,,,,,,
1557464731.588,,1.000000e+001,2.283653e+000,2.314656e+000,7,0,1.885920e-001,-1.466414e-001,,,,,,,-3.329629e-006,,,,,,,,,,,,,,,,,,,,,
1557464731.588,,1.000000e+001,2.283653e+000,2.314656e+000,7,0,3.593484e+000,-1.309244e-001,,,,,,,-2.972759e-006,,,,,,,,,,,,,,,,,,,,,
1557464731.588,,1.000000e+001,2.318498e+000,2.348263e+000,8,0,6.774815e-001,-7.141331e-002,-1.175153e-001,-2.075831e-002,-1.629923e-002,-1.174219e-001,-2.066485e-002,-1.620577e-002,-1.621505e-006,-2.668294e-006,,,,,,,,,,,,,,,,,,,,
1557464731.588,,1.000000e+001,2.318498e+000,2.348263e+000,8,0,3.023851e+000,-5.325480e-002,-9.744941e-002,-7.009416e-003,3.766686e-003,-1.007741e-001,-1.033411e-002,4.419908e-004,-1.209199e-006,-2.212679e-006,,,,,,,,,,,,,,,,,,,,
1557464792.098,,1.000000e+001,2.359079e+000,2.391917e+000,1,0,1.293747e+000,-3.723258e-002,,,,,,,-8.454001e-007,,,,,,,,,,,,,,,,,,,,,
1557464792.098,,1.000000e+001,2.359079e+000,2.391917e+000,1,0,2.378095e+000,-1.998962e-002,,,,,,,-4.538828e-007,,,,,,,,,,,,,,,,,,,,,
1557464792.098,,1.000000e+001,2.391917e+000,2.415220e+000,2,0,1.966881e+000,-8.697775e-003,,,,,,,-1.974910e-007,,,,,,,,,,,,,,,,,,,,,
1557464792.098,,1.000000e+001,2.423450e+000,2.446276e+000,3,0,1.679613e+000,-2.334666e-002,,,,,,,-5.301074e-007,,,,,,,,,,,,,,,,,,,,,
1557464792.098,,1.000000e+001,2.423450e+000,2.446276e+000,3,0,2.675532e+000,-6.500442e-002,,,,,,,-1.475985e-006,,,,,,,,,,,,,,,,,,,,,
1557464792.098,,1.000000e+001,2.449840e+000,2.475371e+000,4,0,9.824725e-001,-1.159703e-001,,,,,,,-2.633213e-006,,,,,,,,,,,,,,,,,,,,,
1557464792.098,,1.000000e+001,2.449840e+000,2.475371e+000,4,0,3.331386e+000,-1.406903e-001,,,,,,,-3.194504e-006,,,,,,,,,,,,,,,,,,,,,
1557464792.098,,1.000000e+001,2.475371e+000,2.501344e+000,5,0,3.973553e-001,-1.254311e-001,,,,,,,-2.848028e-006,,,,,,,,,,,,,,,,,,,,,
1557464792.098,,1.000000e+001,2.475371e+000,2.501344e+000,5,0,3.816629e+000,-1.098666e-001,,,,,,,-2.494623e-006,,,,,,,,,,,,,,,,,,,,,
1557464792.098,,1.000000e+001,2.501344e+000,2.525386e+000,6,0,4.444791e-002,-1.304666e-001,,,,,,,-2.962365e-006,,,,,,,,,,,,,,,,,,,,,
1557464792.098,,1.000000e+001,2.501344e+000,2.525386e+000,6,0,4.004658e+000,-1.216163e-001,,,,,,,-2.761409e-006,,,,,,,,,,,,,,,,,,,,,
1557464792.098,,1.000000e+001,2.525386e+000,2.549150e+000,7,0,4.582259e-002,-1.565600e-001,,,,,,,-3.554838e-006,,,,,,,,,,,,,,,,,,,,,
1557464792.098,,1.000000e+001,2.525386e+000,2.549150e+000,7,0,3.812854e+000,-1.472518e-001,,,,,,,-3.343488e-006,,,,,,,,,,,,,,,,,,,,,
1557464792.098,,1.000000e+001,2.549150e+000,2.575447e+000,8,0,4.074301e-001,-1.361126e-001,-1.341670e-001,-3.657762e-002,-3.359997e-002,-1.300231e-001,-3.243375e-002,-2.945610e-002,-3.090561e-006,-3.046385e-006,,,,,,,,,,,,,,,,,,,,
1557464792.098,,1.000000e+001,2.549150e+000,2.575447e+000,8,0,3.323421e+000,-1.203955e-001,-1.174772e-001,-2.448962e-002,-1.691015e-002,-1.215125e-001,-2.852490e-002,-2.094543e-002,-2.733691e-006,-2.667428e-006,,,,,,,,,,,,,,,,,,,,
1557464852.928,,1.000000e+001,2.581209e+000,2.604106e+000,1,0,9.768233e-001,-6.775109e-002,,,,,,,-1.538351e-006,,,,,,,,,,,,,,,,,,,,,
1557464852.928,,1.000000e+001,2.581209e+000,2.604106e+000,1,0,2.707333e+000,-4.867702e-002,,,,,,,-1.105257e-006,,,,,,,,,,,,,,,,,,,,,
1557464852.928,,1.000000e+001,2.604106e+000,2.629926e+000,2,0,1.623466e+000,-1.678518e-002,,,,,,,-3.811230e-007,,,,,,,,,,,,,,,,,,,,,
1557464852.928,,1.000000e+001,2.629926e+000,2.656348e+000,3,0,2.033617e+000,-1.403851e-002,,,,,,,-3.187574e-007,,,,,,,,,,,,,,,,,,,,,
1557464852.928,,1.000000e+001,2.629926e+000,2.656348e+000,3,0,2.320944e+000,-3.677480e-002,,,,,,,-8.350058e-007,,,,,,,,,,,,,,,,,,,,,
1557464852.928,,1.000000e+001,2.656348e+000,2.678364e+000,4,0,1.325659e+000,-3.204443e-002,,,,,,,-7.275984e-007,,,,,,,,,,,,,,,,,,,,,
1557464852.928,,1.000000e+001,2.656348e+000,2.678364e+000,4,0,3.017952e+000,-7.126072e-002,,,,,,,-1.618040e-006,,,,,,,,,,,,,,,,,,,,,
1557464852.928,,1.000000e+001,2.682279e+000,2.707393e+000,5,0,6.689126e-001,-1.014740e-001,,,,,,,-2.304062e-006,,,,,,,,,,,,,,,,,,,,,
1557464852.928,,1.000000e+001,2.682279e+000,2.707393e+000,5,0,3.603065e+000,-1.081881e-001,,,,,,,-2.456511e-006,,,,,,,,,,,,,,,,,,,,,
1557464852.928,,1.000000e+001,2.707393e+000,2.731848e+000,6,0,1.845613e-001,-1.196326e-001,,,,,,,-2.716367e-006,,,,,,,,,,,,,,,,,,,,,
1557464852.928,,1.000000e+001,2.707393e+000,2.731848e+000,6,0,3.956422e+000,-1.062044e-001,,,,,,,-2.411469e-006,,,,,,,,,,,,,,,,,,,,,
1557464852.928,,1.000000e+001,2.731848e+000,2.755670e+000,7,0,-3.566003e-003,-1.388592e-001,,,,,,,-3.152926e-006,,,,,,,,,,,,,,,,,,,,,
1557464852.928,,1.000000e+001,2.731848e+000,2.755670e+000,7,0,3.955908e+000,-1.315348e-001,,,,,,,-2.986618e-006,,,,,,,,,,,,,,,,,,,,,
1557464852.928,,1.000000e+001,2.755670e+000,2.778733e+000,8,0,1.886575e-001,-1.315348e-001,-1.216544e-001,-3.761153e-002,-3.417467e-002,-1.160185e-001,-3.197567e-002,-2.853881e-002,-2.986618e-006,-2.762275e-006,,,,,,,,,,,,,,,,,,,,
1557464852.928,,1.000000e+001,2.755670e+000,2.778733e+000,8,0,3.593482e+000,-1.098666e-001,-1.084742e-001,-3.027401e-002,-2.099448e-002,-1.110775e-001,-3.287731e-002,-2.359779e-002,-2.494623e-006,-2.463007e-006,,,,,,,,,,,,,,,,,,,,
1557464913.198,,1.000000e+001,2.782502e+000,2.809290e+000,1,0,6.770165e-001,-1.118503e-001,,,,,,,-2.539665e-006,,,,,,,,,,,,,,,,,,,,,
1557464913.198,,1.000000e+001,2.782502e+000,2.809290e+000,1,0,3.023474e+000,-9.460738e-002,,,,,,,-2.148148e-006,,,,,,,,,,,,,,,,,,,,,
1557464913.198,,1.000000e+001,2.809290e+000,2.832088e+000,2,0,1.293402e+000,-6.408887e-002,,,,,,,-1.455197e-006,,,,,,,,,,,,,,,,,,,,,
1557464913.198,,1.000000e+001,2.809290e+000,2.832088e+000,2,0,2.377605e+000,-4.959258e-002,,,,,,,-1.126045e-006,,,,,,,,,,,,,,,,,,,,,
1557464913.198,,1.000000e+001,2.836214e+000,2.853032e+000,3,0,1.966458e+000,-3.326517e-002,,,,,,,-7.553165e-007,,,,,,,,,,,,,,,,,,,,,
1557464913.198,,1.000000e+001,2.853032e+000,2.876786e+000,4,0,1.680431e+000,-2.243110e-002,,,,,,,-5.093189e-007,,,,,,,,,,,,,,,,,,,,,
1557464913.198,,1.000000e+001,2.853032e+000,2.876786e+000,4,0,2.676123e+000,-6.286813e-002,,,,,,,-1.427479e-006,,,,,,,,,,,,,,,,,,,,,
1557464913.198,,1.000000e+001,2.880004e+000,2.900481e+000,5,0,9.834589e-001,-1.138340e-001,,,,,,,-2.584707e-006,,,,,,,,,,,,,,,,,,,,,
1557464913.198,,1.000000e+001,2.880004e+000,2.900481e+000,5,0,3.331443e+000,-1.379437e-001,,,,,,,-3.132138e-006,,,,,,,,,,,,,,,,,,,,,
1557464913.198,,1.000000e+001,2.900481e+000,2.920581e+000,6,0,3.974486e-001,-1.197852e-001,,,,,,,-2.719832e-006,,,,,,,,,,,,,,,,,,,,,
1557464913.198,,1.000000e+001,2.900481e+000,2.920581e+000,6,0,3.816766e+000,-1.092563e-001,,,,,,,-2.480764e-006,,,,,,,,,,,,,,,,,,,,,
1557464913.198,,1.000000e+001,2.920581e+000,2.940537e+000,7,0,4.574690e-002,-1.355022e-001,,,,,,,-3.076702e-006,,,,,,,,,,,,,,,,,,,,,
1557464913.198,,1.000000e+001,2.920581e+000,2.940537e+000,7,0,4.005719e+000,-1.257363e-001,,,,,,,-2.854958e-006,,,,,,,,,,,,,,,,,,,,,
1557464913.198,,1.000000e+001,2.944419e+000,2.965290e+000,8,0,4.541104e-002,-1.452681e-001,-1.360553e-001,-3.502246e-002,-3.217801e-002,-1.299955e-001,-2.896262e-002,-2.611817e-002,-3.298446e-006,-3.089262e-006,,,,,,,,,,,,,,,,,,,,
1557464913.198,,1.000000e+001,2.944419e+000,2.965290e+000,8,0,3.812466e+000,-1.333659e-001,-1.236190e-001,-2.795899e-002,-1.974171e-002,-1.246864e-001,-2.902637e-002,-2.080910e-002,-3.028195e-006,-2.806884e-006,,,,,,,,,,,,,,,,,,,,
1557465019.618,,1.000000e+001,2.974864e+000,2.992033e+000,1,0,4.079091e-001,-1.467940e-001,,,,,,,-3.333094e-006,,,,,,,,,,,,,,,,,,,,,
1557465019.618,,1.000000e+001,2.974864e+000,2.992033e+000,1,0,3.323777e+000,-1.298563e-001,,,,,,,-2.948506e-006,,,,,,,,,,,,,,,,,,,,,
1557465019.618,,1.000000e+001,3.028489e+000,3.021340e+000,2,0,9.764814e-001,-1.208533e-001,,,,,,,-2.744085e-006,,,,,,,,,,,,,,,,,,,,,
1557465019.618,,1.000000e+001,3.028489e+000,3.021340e+000,2,0,2.707103e+000,-9.964294e-002,,,,,,,-2.262484e-006,,,,,,,,,,,,,,,,,,,,,
1557465019.618,,1.000000e+001,3.021340e+000,3.011220e+000,3,0,1.622818e+000,-4.699850e-002,,,,,,,-1.067144e-006,,,,,,,,,,,,,,,,,,,,,
1557465019.618,,1.000000e+001,3.011220e+000,3.005675e+000,4,0,2.033398e+000,-2.822962e-002,,,,,,,-6.409796e-007,,,,,,,,,,,,,,,,,,,,,
1557465019.618,,1.000000e+001,3.011220e+000,3.005675e+000,4,0,2.320655e+000,-4.806665e-002,,,,,,,-1.091398e-006,,,,,,,,,,,,,,,,,,,,,
1557465019.618,,1.000000e+001,3.005675e+000,3.002206e+000,5,0,1.324693e+000,-6.897183e-002,,,,,,,-1.566069e-006,,,,,,,,,,,,,,,,,,,,,
1557465019.618,,1.000000e+001,3.005675e+000,3.002206e+000,5,0,3.017638e+000,-9.796441e-002,,,,,,,-2.224372e-006,,,,,,,,,,,,,,,,,,,,,
1557465019.618,,1.000000e+001,3.002206e+000,3.000058e+000,6,0,6.699281e-001,-1.391644e-001,,,,,,,-3.159856e-006,,,,,,,,,,,,,,,,,,,,,
1557465019.618,,1.000000e+001,3.002206e+000,3.000058e+000,6,0,3.603414e+000,-1.454207e-001,,,,,,,-3.301911e-006,,,,,,,,,,,,,,,,,,,,,
1557465019.618,,1.000000e+001,3.000058e+000,2.999325e+000,7,0,1.833065e-001,-1.594592e-001,,,,,,,-3.620668e-006,,,,,,,,,,,,,,,,,,,,,
1557465019.618,,1.000000e+001,3.000058e+000,2.999325e+000,7,0,3.955647e+000,-1.420637e-001,,,,,,,-3.225686e-006,,,,,,,,,,,,,,,,,,,,,
1557465019.618,,1.000000e+001,2.999325e+000,2.999273e+000,8,0,-4.341695e-003,-1.251259e-001,-1.453253e-001,-3.480206e-002,-3.263566e-002,-1.378462e-001,-2.732294e-002,-2.515654e-002,-2.841099e-006,-3.299745e-006,,,,,,,,,,,,,,,,,,,,
1557465019.618,,1.000000e+001,2.999325e+000,2.999273e+000,8,0,3.955389e+000,-1.130711e-001,-1.316111e-001,-2.569140e-002,-1.892141e-002,-1.310946e-001,-2.517495e-002,-1.840496e-002,-2.567383e-006,-2.988351e-006,,,,,,,,,,,,,,,,,,,,
1557465080.468,,1.000000e+001,2.998750e+000,2.999482e+000,1,0,1.886016e-001,-1.496933e-001,,,,,,,-3.398924e-006,,,,,,,,,,,,,,,,,,,,,
1557465080.468,,1.000000e+001,2.998750e+000,2.999482e+000,1,0,3.593444e+000,-1.362651e-001,,,,,,,-3.094026e-006,,,,,,,,,,,,,,,,,,,,,
1557465080.468,,1.000000e+001,2.999482e+000,3.000319e+000,2,0,6.784824e-001,-1.200903e-001,,,,,,,-2.726762e-006,,,,,,,,,,,,,,,,,,,,,
1557465080.468,,1.000000e+001,2.999482e+000,3.000319e+000,2,0,3.024452e+000,-9.857479e-002,,,,,,,-2.238231e-006,,,,,,,,,,,,,,,,,,,,,
1557465080.468,,1.000000e+001,3.000319e+000,3.000843e+000,3,0,1.292870e+000,-7.217627e-002,,,,,,,-1.638829e-006,,,,,,,,,,,,,,,,,,,,,
1557465080.468,,1.000000e+001,3.000319e+000,3.000843e+000,3,0,2.377257e+000,-4.577776e-002,,,,,,,-1.039426e-006,,,,,,,,,,,,,,,,,,,,,
1557465080.468,,1.000000e+001,3.000843e+000,3.000948e+000,4,0,1.966597e+000,-5.081332e-002,,,,,,,-1.153763e-006,,,,,,,,,,,,,,,,,,,,,
1557465080.468,,1.000000e+001,3.000948e+000,3.000791e+000,5,0,1.679101e+000,-2.014222e-002,,,,,,,-4.573476e-007,,,,,,,,,,,,,,,,,,,,,
1557465080.468,,1.000000e+001,3.000948e+000,3.000791e+000,5,0,2.675766e+000,-5.767998e-002,,,,,,,-1.309677e-006,,,,,,,,,,,,,,,,,,,,,
1557465080.468,,1.000000e+001,3.001734e+000,3.001367e+000,6,0,9.824000e-001,-1.229896e-001,,,,,,,-2.792592e-006,,,,,,,,,,,,,,,,,,,,,
1557465080.468,,1.000000e+001,3.001734e+000,3.001367e+000,6,0,3.331661e+000,-1.435896e-001,,,,,,,-3.260334e-006,,,,,,,,,,,,,,,,,,,,,
1557465080.468,,1.000000e+001,3.001367e+000,3.001315e+000,7,0,3.976065e-001,-1.109348e-001,,,,,,,-2.518876e-006,,,,,,,,,,,,,,,,,,,,,
1557465080.468,,1.000000e+001,3.001367e+000,3.001315e+000,7,0,3.816919e+000,-1.048311e-001,,,,,,,-2.380286e-006,,,,,,,,,,,,,,,,,,,,,
1557465080.468,,1.000000e+001,3.001315e+000,3.000791e+000,8,0,4.477577e-002,-1.478622e-001,-1.359218e-001,-3.143939e-002,-2.912652e-002,-1.333692e-001,-2.888674e-002,-2.657387e-002,-3.357347e-006,-3.086230e-006,,,,,,,,,,,,,,,,,,,,
1557465080.468,,1.000000e+001,3.001315e+000,3.000791e+000,8,0,4.005000e+000,-1.297037e-001,-1.243820e-001,-2.551655e-002,-1.758671e-002,-1.220077e-001,-2.314226e-002,-1.521242e-002,-2.945041e-006,-2.824208e-006,,,,,,,,,,,,,,,,,,,,
1557465141.028,,1.000000e+001,3.001629e+000,3.000110e+000,1,0,4.482168e-002,-1.373333e-001,,,,,,,-3.118279e-006,,,,,,,,,,,,,,,,,,,,,
1557465141.028,,1.000000e+001,3.001629e+000,3.000110e+000,1,0,3.811876e+000,-1.292459e-001,,,,,,,-2.934647e-006,,,,,,,,,,,,,,,,,,,,,
1557465141.028,,1.000000e+001,3.001262e+000,3.000215e+000,2,0,4.072088e-001,-1.220740e-001,,,,,,,-2.771804e-006,,,,,,,,,,,,,,,,,,,,,
1557465141.028,,1.000000e+001,3.001262e+000,3.000215e+000,2,0,3.322787e+000,-1.036103e-001,,,,,,,-2.352568e-006,,,,,,,,,,,,,,,,,,,,,
1557465141.028,,1.000000e+001,3.001734e+000,3.001158e+000,3,0,9.777244e-001,-9.338664e-002,,,,,,,-2.120430e-006,,,,,,,,,,,,,,,,,,,,,
1557465141.028,,1.000000e+001,3.001734e+000,3.001158e+000,3,0,2.707710e+000,-7.477035e-002,,,,,,,-1.697730e-006,,,,,,,,,,,,,,,,,,,,,
1557465141.028,,1.000000e+001,3.001158e+000,3.000582e+000,4,0,1.624458e+000,-5.005036e-002,,,,,,,-1.136439e-006,,,,,,,,,,,,,,,,,,,,,
1557465141.028,,1.000000e+001,3.000582e+000,3.001734e+000,5,0,2.033209e+000,-4.043702e-002,,,,,,,-9.181599e-007,,,,,,,,,,,,,,,,,,,,,
1557465141.028,,1.000000e+001,3.000582e+000,3.001734e+000,5,0,2.320857e+000,-5.966369e-002,,,,,,,-1.354719e-006,,,,,,,,,,,,,,,,,,,,,
1557465141.028,,1.000000e+001,3.001734e+000,3.001420e+000,6,0,1.325479e+000,-8.072146e-002,,,,,,,-1.832855e-006,,,,,,,,,,,,,,,,,,,,,
1557465141.028,,1.000000e+001,3.001734e+000,3.001420e+000,6,0,3.018073e+000,-1.089511e-001,,,,,,,-2.473835e-006,,,,,,,,,,,,,,,,,,,,,
1557465141.028,,1.000000e+001,3.001420e+000,3.001158e+000,7,0,6.687006e-001,-1.326029e-001,,,,,,,-3.010872e-006,,,,,,,,,,,,,,,,,,,,,
1557465141.028,,1.000000e+001,3.001420e+000,3.001158e+000,7,0,3.603220e+000,-1.364177e-001,,,,,,,-3.097490e-006,,,,,,,,,,,,,,,,,,,,,
1557465141.028,,1.000000e+001,3.001158e+000,3.000791e+000,8,0,1.838319e-001,-1.556444e-001,-1.416059e-001,-3.227083e-002,-3.025791e-002,-1.408045e-001,-3.146948e-002,-2.945656e-002,-3.534049e-006,-3.215292e-006,,,,,,,,,,,,,,,,,,,,
1557465141.028,,1.000000e+001,3.001158e+000,3.000791e+000,8,0,3.956051e+000,-1.516770e-001,-1.283113e-001,-2.467948e-002,-1.696329e-002,-1.279911e-001,-2.435927e-002,-1.664308e-002,-3.443966e-006,-2.913425e-006,,,,,,,,,,,,,,,,,,,,
1557465200.838,,1.000000e+001,3.001367e+000,3.001158e+000,1,0,-3.667176e-003,-1.322977e-001,,,,,,,-3.003942e-006,,,,,,,,,,,,,,,,,,,,,
1557465200.838,,1.000000e+001,3.001367e+000,3.001158e+000,1,0,3.955944e+000,-1.292459e-001,,,,,,,-2.934647e-006,,,,,,,,,,,,,,,,,,,,,
1557465200.838,,1.000000e+001,3.001158e+000,3.001210e+000,2,0,1.879405e-001,-1.216163e-001,,,,,,,-2.761409e-006,,,,,,,,,,,,,,,,,,,,,
1557465200.838,,1.000000e+001,3.001158e+000,3.001210e+000,2,0,3.592963e+000,-1.103244e-001,,,,,,,-2.505017e-006,,,,,,,,,,,,,,,,,,,,,
1557465200.838,,1.000000e+001,3.001210e+000,3.001053e+000,3,0,6.776946e-001,-1.373333e-001,,,,,,,-3.118279e-006,,,,,,,,,,,,,,,,,,,,,
1557465200.838,,1.000000e+001,3.001210e+000,3.001053e+000,3,0,3.023803e+000,-1.098666e-001,,,,,,,-2.494623e-006,,,,,,,,,,,,,,,,,,,,,
1557465200.838,,1.000000e+001,3.001053e+000,3.000686e+000,4,0,1.294419e+000,-9.262368e-002,,,,,,,-2.103106e-006,,,,,,,,,,,,,,,,,,,,,
1557465200.838,,1.000000e+001,3.001053e+000,3.000686e+000,4,0,2.378118e+000,-7.660146e-002,,,,,,,-1.739307e-006,,,,,,,,,,,,,,,,,,,,,
1557465200.838,,1.000000e+001,3.001315e+000,3.001315e+000,5,0,1.966924e+000,-3.570665e-002,,,,,,,-8.107525e-007,,,,,,,,,,,,,,,,,,,,,
1557465200.838,,1.000000e+001,3.001315e+000,3.000896e+000,6,0,1.679408e+000,-3.555406e-002,,,,,,,-8.072878e-007,,,,,,,,,,,,,,,,,,,,,
1557465200.838,,1.000000e+001,3.001315e+000,3.000896e+000,6,0,2.675695e+000,-7.141331e-002,,,,,,,-1.621505e-006,,,,,,,,,,,,,,,,,,,,,
1557465200.838,,1.000000e+001,3.000896e+000,3.000424e+000,7,0,9.842759e-001,-1.165807e-001,,,,,,,-2.647072e-006,,,,,,,,,,,,,,,,,,,,,
1557465200.838,,1.000000e+001,3.000896e+000,3.000424e+000,7,0,3.332167e+000,-1.368755e-001,,,,,,,-3.107885e-006,,,,,,,,,,,,,,,,,,,,,
1557465200.838,,1.000000e+001,3.000424e+000,3.000948e+000,8,0,3.979636e-001,-1.167333e-001,-1.401944e-001,-3.382545e-002,-3.193069e-002,-1.389564e-001,-3.258741e-002,-3.069264e-002,-2.650537e-006,-3.183243e-006,,,,,,,,,,,,,,,,,,,,
1557465200.838,,1.000000e+001,3.000424e+000,3.000948e+000,8,0,3.817119e+000,-1.083407e-001,-1.275674e-001,-2.764060e-002,-1.930366e-002,-1.292193e-001,-2.929250e-002,-2.095556e-002,-2.459976e-006,-2.896535e-006,,,,,,,,,,,,,,,,,,,,
1557465260.659,,1.000000e+001,3.000948e+000,2.999796e+000,1,0,4.452924e-002,-1.310770e-001,,,,,,,-2.976224e-006,,,,,,,,,,,,,,,,,,,,,
1557465260.659,,1.000000e+001,3.000948e+000,2.999796e+000,1,0,4.004851e+000,-1.239051e-001,,,,,,,-2.813380e-006,,,,,,,,,,,,,,,,,,,,,
1557465260.659,,1.000000e+001,3.000424e+000,2.999639e+000,2,0,4.552759e-002,-1.434370e-001,,,,,,,-3.256869e-006,,,,,,,,,,,,,,,,,,,,,
1557465260.659,,1.000000e+001,3.000424e+000,2.999639e+000,2,0,3.812216e+000,-1.338237e-001,,,,,,,-3.038590e-006,,,,,,,,,,,,,,,,,,,,,
1557465260.659,,1.000000e+001,3.001105e+000,3.001158e+000,3,0,4.076671e-001,-1.446577e-001,,,,,,,-3.284587e-006,,,,,,,,,,,,,,,,,,,,,
1557465260.659,,1.000000e+001,3.001105e+000,3.001158e+000,3,0,3.323173e+000,-1.315348e-001,,,,,,,-2.986618e-006,,,,,,,,,,,,,,,,,,,,,
1557465260.659,,1.000000e+001,3.001158e+000,2.999796e+000,4,0,9.770844e-001,-1.103244e-001,,,,,,,-2.505017e-006,,,,,,,,,,,,,,,,,,,,,
1557465260.659,,1.000000e+001,3.001158e+000,2.999796e+000,4,0,2.707141e+000,-8.041628e-002,,,,,,,-1.825926e-006,,,,,,,,,,,,,,,,,,,,,
1557465260.659,,1.000000e+001,2.999796e+000,3.000791e+000,5,0,1.624423e+000,-3.295999e-002,,,,,,,-7.483869e-007,,,,,,,,,,,,,,,,,,,,,
1557465260.659,,1.000000e+001,3.000791e+000,3.000582e+000,6,0,2.033192e+000,-4.074221e-002,,,,,,,-9.250894e-007,,,,,,,,,,,,,,,,,,,,,
1557465260.659,,1.000000e+001,3.000791e+000,3.000582e+000,6,0,2.320877e+000,-6.057924e-002,,,,,,,-1.375508e-006,,,,,,,,,,,,,,,,,,,,,
1557465260.659,,1.000000e+001,3.000582e+000,2.999796e+000,7,0,1.325867e+000,-7.736442e-002,,,,,,,-1.756630e-006,,,,,,,,,,,,,,,,,,,,,
1557465260.659,,1.000000e+001,3.000582e+000,2.999796e+000,7,0,3.018376e+000,-1.022370e-001,,,,,,,-2.321385e-006,,,,,,,,,,,,,,,,,,,,,
1557465260.659,,1.000000e+001,3.000634e+000,2.999482e+000,8,0,6.694098e-001,-1.240577e-001,-1.295320e-001,-2.038600e-002,-1.877822e-002,-1.311606e-001,-2.201456e-002,-2.040678e-002,-2.816845e-006,-2.941143e-006,,,,,,,,,,,,,,,,,,,,
1557465260.659,,1.000000e+001,3.000634e+000,2.999482e+000,8,0,3.603392e+000,-1.277200e-001,-1.339953e-001,-3.168241e-002,-2.324155e-002,-1.356465e-001,-3.333359e-002,-2.489273e-002,-2.899999e-006,-3.042487e-006,,,,,,,,,,,,,,,,,,,,
1557465321.439,,1.000000e+001,3.000843e+000,2.999378e+000,1,0,1.840019e-001,-1.480148e-001,,,,,,,-3.360812e-006,,,,,,,,,,,,,,,,,,,,,
1557465321.439,,1.000000e+001,3.000843e+000,2.999378e+000,1,0,3.956115e+000,-1.397748e-001,,,,,,,-3.173715e-006,,,,,,,,,,,,,,,,,,,,,
1557465321.439,,1.000000e+001,2.999378e+000,3.000372e+000,2,0,-4.706944e-003,-1.457259e-001,,,,,,,-3.308840e-006,,,,,,,,,,,,,,,,,,,,,
1557465321.439,,1.000000e+001,2.999378e+000,3.000372e+000,2,0,3.955124e+000,-1.367229e-001,,,,,,,-3.104420e-006,,,,,,,,,,,,,,,,,,,,,
1557465321.439,,1.000000e+001,3.000372e+000,2.999744e+000,3,0,1.880503e-001,-1.376385e-001,,,,,,,-3.125208e-006,,,,,,,,,,,,,,,,,,,,,
1557465321.439,,1.000000e+001,3.000372e+000,2.999744e+000,3,0,3.592863e+000,-1.197852e-001,,,,,,,-2.719832e-006,,,,,,,,,,,,,,,,,,,,,
1557465321.439,,1.000000e+001,2.999744e+000,2.999639e+000,4,0,6.775799e-001,-1.614429e-001,,,,,,,-3.665710e-006,,,,,,,,,,,,,,,,,,,,,
1557465321.439,,1.000000e+001,2.999744e+000,2.999639e+000,4,0,3.023549e+000,-1.321451e-001,,,,,,,-3.000477e-006,,,,,,,,,,,,,,,,,,,,,
1557465321.439,,1.000000e+001,2.999639e+000,3.000372e+000,5,0,1.294541e+000,-7.538072e-002,,,,,,,-1.711589e-006,,,,,,,,,,,,,,,,,,,,,
1557465321.439,,1.000000e+001,2.999639e+000,3.000372e+000,5,0,2.377959e+000,-5.737480e-002,,,,,,,-1.302748e-006,,,,,,,,,,,,,,,,,,,,,
1557465321.439,,1.000000e+001,3.000372e+000,2.999901e+000,6,0,1.967183e+000,-2.334666e-002,,,,,,,-5.301074e-007,,,,,,,,,,,,,,,,,,,,,
1557465321.439,,1.000000e+001,2.999901e+000,3.000791e+000,7,0,1.679014e+000,-6.134220e-002,,,,,,,-1.392831e-006,,,,,,,,,,,,,,,,,,,,,
1557465321.439,,1.000000e+001,2.999901e+000,3.000791e+000,7,0,2.675883e+000,-9.689627e-002,,,,,,,-2.200119e-006,,,,,,,,,,,,,,,,,,,,,
1557465321.439,,1.000000e+001,3.000791e+000,3.000634e+000,8,0,9.827507e-001,-8.575701e-002,-1.064333e-001,4.908597e-003,5.907983e-003,-1.095676e-001,1.774316e-003,2.773702e-003,-1.947192e-006,-2.416666e-006,,,,,,,,,,,,,,,,,,,,
1557465321.439,,1.000000e+001,3.000791e+000,3.000634e+000,8,0,3.331754e+000,-1.094089e-001,-1.274339e-001,-2.175514e-002,-1.509257e-002,-1.342774e-001,-2.859871e-002,-2.193613e-002,-2.484229e-006,-2.893503e-006,,,,,,,,,,,,,,,,,,,,
1557465380.479,,1.000000e+001,3.000634e+000,3.000372e+000,1,0,3.972341e-001,-1.533555e-001,,,,,,,-3.482078e-006,,,,,,,,,,,,,,,,,,,,,
1557465380.479,,1.000000e+001,3.000634e+000,3.000372e+000,1,0,3.816722e+000,-1.422163e-001,,,,,,,-3.229151e-006,,,,,,,,,,,,,,,,,,,,,
1557465380.479,,1.000000e+001,3.000372e+000,3.000372e+000,2,0,4.444120e-002,-1.496933e-001,,,,,,,-3.398924e-006,,,,,,,,,,,,,,,,,,,,,
1557465380.479,,1.000000e+001,3.000372e+000,3.000372e+000,2,0,4.004752e+000,-1.318400e-001,,,,,,,-2.993548e-006,,,,,,,,,,,,,,,,,,,,,
1557465380.479,,1.000000e+001,3.000372e+000,3.000267e+000,3,0,4.585381e-002,-1.339763e-001,,,,,,,-3.042054e-006,,,,,,,,,,,,,,,,,,,,,
1557465380.479,,1.000000e+001,3.000372e+000,3.000267e+000,3,0,3.812756e+000,-1.101718e-001,,,,,,,-2.501553e-006,,,,,,,,,,,,,,,,,,,,,
1557465380.479,,1.000000e+001,3.000582e+000,3.000739e+000,4,0,4.071585e-001,-1.373333e-001,,,,,,,-3.118279e-006,,,,,,,,,,,,,,,,,,,,,
1557465380.479,,1.000000e+001,3.000582e+000,3.000739e+000,4,0,3.322927e+000,-1.231422e-001,,,,,,,-2.796057e-006,,,,,,,,,,,,,,,,,,,,,
1557465380.479,,1.000000e+001,3.000739e+000,3.000319e+000,5,0,9.767156e-001,-9.475998e-002,,,,,,,-2.151613e-006,,,,,,,,,,,,,,,,,,,,,
1557465380.479,,1.000000e+001,3.000739e+000,3.000319e+000,5,0,2.707213e+000,-7.293924e-002,,,,,,,-1.656153e-006,,,,,,,,,,,,,,,,,,,,,
1557465380.479,,1.000000e+001,3.000319e+000,3.000058e+000,6,0,1.623869e+000,-4.852443e-002,,,,,,,-1.101792e-006,,,,,,,,,,,,,,,,,,,,,
1557465380.479,,1.000000e+001,3.000058e+000,2.999849e+000,7,0,2.033868e+000,-2.456740e-002,,,,,,,-5.578254e-007,,,,,,,,,,,,,,,,,,,,,
1557465380.479,,1.000000e+001,3.000058e+000,2.999849e+000,7,0,2.320910e+000,-4.806665e-002,,,,,,,-1.091398e-006,,,,,,,,,,,,,,,,,,,,,
1557465380.479,,1.000000e+001,2.999849e+000,2.999744e+000,8,0,1.324915e+000,-6.866664e-002,-7.118443e-002,3.680637e-002,3.763829e-002,-7.396225e-002,3.402855e-002,3.486047e-002,-1.559139e-006,-1.616308e-006,,,,,,,,,,,,,,,,,,,,
1557465380.479,,1.000000e+001,2.999849e+000,2.999744e+000,8,0,3.017661e+000,-9.887997e-002,-1.035150e-001,-2.595473e-003,5.307749e-003,-1.103640e-001,-9.444509e-003,-1.541287e-003,-2.245161e-006,-2.350403e-006,,,,,,,,,,,,,,,,,,,,
1557465496.809,,1.000000e+001,3.000058e+000,3.000634e+000,1,0,6.694636e-001,-1.284829e-001,,,,,,,-2.917323e-006,,,,,,,,,,,,,,,,,,,,,
1557465496.809,,1.000000e+001,3.000058e+000,3.000634e+000,1,0,3.603063e+000,-1.277200e-001,,,,,,,-2.899999e-006,,,,,,,,,,,,,,,,,,,,,
1557465496.809,,1.000000e+001,3.000634e+000,3.003098e+000,2,0,1.836319e-001,-1.619007e-001,,,,,,,-3.676104e-006,,,,,,,,,,,,,,,,,,,,,
1557465496.809,,1.000000e+001,3.000634e+000,3.003098e+000,2,0,3.955947e+000,-1.539659e-001,,,,,,,-3.495937e-006,,,,,,,,,,,,,,,,,,,,,
1557465496.809,,1.000000e+001,3.003098e+000,3.002993e+000,3,0,-4.512232e-003,-1.290933e-001,,,,,,,-2.931182e-006,,,,,,,,,,,,,,,,,,,,,
1557465496.809,,1.000000e+001,3.003098e+000,3.002993e+000,3,0,3.955234e+000,-1.222266e-001,,,,,,,-2.775268e-006,,,,,,,,,,,,,,,,,,,,,
1557465496.809,,1.000000e+001,3.002993e+000,3.001996e+000,4,0,1.879663e-001,-1.149022e-001,,,,,,,-2.608960e-006,,,,,,,,,,,,,,,,,,,,,
1557465496.809,,1.000000e+001,3.002993e+000,3.001996e+000,4,0,3.592943e+000,-1.103244e-001,,,,,,,-2.505017e-006,,,,,,,,,,,,,,,,,,,,,
1557465496.809,,1.000000e+001,3.001996e+000,3.001210e+000,5,0,6.774275e-001,-9.140294e-002,,,,,,,-2.075388e-006,,,,,,,,,,,,,,,,,,,,,
1557465496.809,,1.000000e+001,3.001996e+000,3.001210e+000,5,0,3.023626e+000,-8.163702e-002,,,,,,,-1.853644e-006,,,,,,,,,,,,,,,,,,,,,
1557465496.809,,1.000000e+001,3.001210e+000,3.001524e+000,6,0,1.293368e+000,-8.011109e-002,-7.054862e-002,2.978387e-002,3.317081e-002,-6.981927e-002,3.051322e-002,3.390016e-002,-1.818996e-006,-1.601871e-006,,,,,,,,,,,,,,,,,,,,
1557465496.809,,1.000000e+001,3.001210e+000,3.001524e+000,6,0,2.377401e+000,-6.714072e-002,-5.188147e-002,4.433831e-002,5.183797e-002,-4.659098e-002,4.962879e-002,5.712845e-002,-1.524492e-006,-1.178016e-006,,,,,,,,,,,,,,,,,,,,
1557465636.719,,1.000000e+001,3.000006e+000,3.001839e+000,1,0,1.966882e+000,-1.068148e-002,,,,,,,-2.425328e-007,,,,,,,,,,,,,,,,,,,,,
1557465636.719,,1.000000e+001,3.001839e+000,3.003203e+000,2,0,1.680618e+000,-4.165776e-002,,,,,,,-9.458780e-007,,,,,,,,,,,,,,,,,,,,,
1557465636.719,,1.000000e+001,3.001839e+000,3.003203e+000,2,0,2.676553e+000,-8.362071e-002,,,,,,,-1.898685e-006,,,,,,,,,,,,,,,,,,,,,
1557465636.719,,1.000000e+001,3.003203e+000,3.002993e+000,3,0,9.836750e-001,-7.461775e-002,,,,,,,-1.694265e-006,,,,,,,,,,,,,,,,,,,,,
1557465636.719,,1.000000e+001,3.003203e+000,3.002993e+000,3,0,3.332038e+000,-9.491257e-002,,,,,,,-2.155077e-006,,,,,,,,,,,,,,,,,,,,,
1557465636.719,,1.000000e+001,3.002993e+000,3.002259e+000,4,0,3.968505e-001,-1.243629e-001,,,,,,,-2.823775e-006,,,,,,,,,,,,,,,,,,,,,
1557465636.719,,1.000000e+001,3.002993e+000,3.002259e+000,4,0,3.816663e+000,-1.203955e-001,,,,,,,-2.733691e-006,,,,,,,,,,,,,,,,,,,,,
1557465636.719,,1.000000e+001,3.002259e+000,3.001629e+000,5,0,4.570693e-002,-1.408429e-001,,,,,,,-3.197968e-006,,,,,,,,,,,,,,,,,,,,,
1557465636.719,,1.000000e+001,3.002259e+000,3.001629e+000,5,0,4.005717e+000,-1.287881e-001,,,,,,,-2.924253e-006,,,,,,,,,,,,,,,,,,,,,
1557465636.719,,1.000000e+001,3.001629e+000,3.000739e+000,6,0,4.591264e-002,-1.101718e-001,,,,,,,-2.501553e-006,,,,,,,,,,,,,,,,,,,,,
1557465636.719,,1.000000e+001,3.001629e+000,3.000739e+000,6,0,3.812673e+000,-1.002533e-001,,,,,,,-2.276344e-006,,,,,,,,,,,,,,,,,,,,,
1557465636.719,,1.000000e+001,3.000739e+000,3.000843e+000,7,0,4.073835e-001,-1.162755e-001,,,,,,,-2.640143e-006,,,,,,,,,,,,,,,,,,,,,
1557465636.719,,1.000000e+001,3.000739e+000,3.000843e+000,7,0,3.323042e+000,-9.872738e-002,,,,,,,-2.241696e-006,,,,,,,,,,,,,,,,,,,,,
1557465636.719,,1.000000e+001,3.000843e+000,3.000477e+000,8,0,9.773453e-001,-8.529924e-002,-8.774071e-002,6.522385e-004,3.434643e-003,-8.682203e-002,1.570925e-003,4.353330e-003,-1.936798e-006,-1.992234e-006,,,,,,,,,,,,,,,,,,,,
1557465636.719,,1.000000e+001,3.000843e+000,3.000477e+000,8,0,2.707493e+000,-6.225776e-002,-6.769387e-002,1.706055e-002,2.348149e-002,-6.724460e-002,1.750982e-002,2.393076e-002,-1.413620e-006,-1.537052e-006,,,,,,,,,,,,,,,,,,,,
1557465745.739,,1.000000e+001,3.531114e+000,3.634353e+000,1,0,1.622767e+000,4.730369e-003,,,,,,,1.074074e-007,,,,,,,,,,,,,,,,,,,,,
1557465745.739,,1.000000e+001,3.634353e+000,3.712823e+000,2,0,2.034522e+000,-2.243110e-002,,,,,,,-5.093189e-007,,,,,,,,,,,,,,,,,,,,,
1557465745.739,,1.000000e+001,3.634353e+000,3.712823e+000,2,0,2.321777e+000,-3.952147e-002,,,,,,,-8.973714e-007,,,,,,,,,,,,,,,,,,,,,
1557465745.739,,1.000000e+001,3.712823e+000,3.813507e+000,3,0,1.324800e+000,-4.913480e-002,,,,,,,-1.115651e-006,,,,,,,,,,,,,,,,,,,,,
1557465745.739,,1.000000e+001,3.712823e+000,3.813507e+000,3,0,3.017573e+000,-8.529924e-002,,,,,,,-1.936798e-006,,,,,,,,,,,,,,,,,,,,,
1557465745.739,,1.000000e+001,3.813507e+000,3.773549e+000,4,0,6.698362e-001,-1.091037e-001,,,,,,,-2.477299e-006,,,,,,,,,,,,,,,,,,,,,
1557465745.739,,1.000000e+001,3.813507e+000,3.773549e+000,4,0,3.603470e+000,-1.103244e-001,,,,,,,-2.505017e-006,,,,,,,,,,,,,,,,,,,,,
1557465745.739,,1.000000e+001,3.773549e+000,3.808425e+000,5,0,1.845365e-001,-1.301614e-001,,,,,,,-2.955436e-006,,,,,,,,,,,,,,,,,,,,,
1557465745.739,,1.000000e+001,3.773549e+000,3.808425e+000,5,0,3.956401e+000,-1.190222e-001,,,,,,,-2.702508e-006,,,,,,,,,,,,,,,,,,,,,
1557465745.739,,1.000000e+001,3.808425e+000,3.840652e+000,6,0,-4.733815e-003,-1.126133e-001,,,,,,,-2.556989e-006,,,,,,,,,,,,,,,,,,,,,
1557465745.739,,1.000000e+001,3.808425e+000,3.840652e+000,6,0,3.955080e+000,-1.036103e-001,,,,,,,-2.352568e-006,,,,,,,,,,,,,,,,,,,,,
1557465745.739,,1.000000e+001,3.840652e+000,3.855718e+000,7,0,1.894185e-001,-1.136815e-001,,,,,,,-2.581242e-006,,,,,,,,,,,,,,,,,,,,,
1557465745.739,,1.000000e+001,3.840652e+000,3.855718e+000,7,0,3.594022e+000,-1.043733e-001,,,,,,,-2.369892e-006,,,,,,,,,,,,,,,,,,,,,
1557465745.739,,1.000000e+001,3.868417e+000,3.889012e+000,8,0,6.779309e-001,-9.872738e-002,-1.037248e-001,-2.142329e-002,-1.767362e-002,-1.036083e-001,-2.130682e-002,-1.755715e-002,-2.241696e-006,-2.355167e-006,,,,,,,,,,,,,,,,,,,,
1557465745.739,,1.000000e+001,3.868417e+000,3.889012e+000,8,0,3.023999e+000,-8.239997e-002,-8.348720e-002,-6.497726e-003,2.563968e-003,-8.672560e-002,-9.736128e-003,-6.744340e-004,-1.870967e-006,-1.895654e-006,,,,,,,,,,,,,,,,,,,,
1557465876.519,,1.000000e+001,4.018828e+000,4.250969e+000,1,0,1.294267e+000,-7.324442e-002,,,,,,,-1.663082e-006,,,,,,,,,,,,,,,,,,,,,
1557465876.519,,1.000000e+001,4.018828e+000,4.250969e+000,1,0,2.378199e+000,-5.462813e-002,,,,,,,-1.240382e-006,,,,,,,,,,,,,,,,,,,,,
1557465876.519,,1.000000e+001,4.250969e+000,4.492653e+000,2,0,1.966512e+000,-1.220740e-003,,,,,,,-2.771803e-008,,,,,,,,,,,,,,,,,,,,,
1557465876.519,,1.000000e+001,4.492653e+000,4.727084e+000,3,0,1.679132e+000,-8.697775e-003,,,,,,,-1.974910e-007,,,,,,,,,,,,,,,,,,,,,
1557465876.519,,1.000000e+001,4.492653e+000,4.727084e+000,3,0,2.675659e+000,-4.394665e-002,,,,,,,-9.978493e-007,,,,,,,,,,,,,,,,,,,,,
1557465876.519,,1.000000e+001,4.727084e+000,4.996240e+000,4,0,9.842889e-001,-7.065035e-002,,,,,,,-1.604181e-006,,,,,,,,,,,,,,,,,,,,,
1557465876.519,,1.000000e+001,4.727084e+000,4.996240e+000,4,0,3.332036e+000,-9.231850e-002,,,,,,,-2.096176e-006,,,,,,,,,,,,,,,,,,,,,
1557465876.519,,1.000000e+001,4.996240e+000,4.840712e+000,5,0,3.968644e-001,-9.491257e-002,,,,,,,-2.155077e-006,,,,,,,,,,,,,,,,,,,,,
1557465876.519,,1.000000e+001,4.996240e+000,4.840712e+000,5,0,3.816545e+000,-9.582812e-002,,,,,,,-2.175866e-006,,,,,,,,,,,,,,,,,,,,,
1557465876.519,,1.000000e+001,4.883575e+000,5.128246e+000,6,0,4.447325e-002,-1.033052e-001,,,,,,,-2.345639e-006,,,,,,,,,,,,,,,,,,,,,
1557465876.519,,1.000000e+001,4.883575e+000,5.128246e+000,6,0,4.004814e+000,-9.643849e-002,,,,,,,-2.189725e-006,,,,,,,,,,,,,,,,,,,,,
1557465876.519,,1.000000e+001,5.128246e+000,5.349916e+000,7,0,4.467288e-002,-1.222266e-001,,,,,,,-2.775268e-006,,,,,,,,,,,,,,,,,,,,,
1557465876.519,,1.000000e+001,5.128246e+000,5.349916e+000,7,0,3.811887e+000,-1.121555e-001,,,,,,,-2.546594e-006,,,,,,,,,,,,,,,,,,,,,
1557465876.519,,1.000000e+001,5.349916e+000,5.601910e+000,8,0,4.074283e-001,-1.435896e-001,-1.150739e-001,-3.336340e-002,-3.072038e-002,-1.143197e-001,-3.260922e-002,-2.996620e-002,-3.260334e-006,-2.612858e-006,,,,,,,,,,,,,,,,,,,,
1557465876.519,,1.000000e+001,5.349916e+000,5.601910e+000,8,0,3.323208e+000,-1.324503e-001,-1.038202e-001,-2.619436e-002,-1.946668e-002,-1.061606e-001,-2.853482e-002,-2.180714e-002,-3.007407e-006,-2.357332e-006,,,,,,,,,,,,,,,,,,,,
1557465935.760,,1.000000e+001,5.671923e+000,5.903071e+000,1,0,9.762915e-001,-9.445479e-002,,,,,,,-2.144683e-006,,,,,,,,,,,,,,,,,,,,,
1557465935.760,,1.000000e+001,5.671923e+000,5.903071e+000,1,0,2.707101e+000,-7.095553e-002,,,,,,,-1.611111e-006,,,,,,,,,,,,,,,,,,,,,
1557465935.760,,1.000000e+001,5.940054e+000,6.165850e+000,2,0,1.623013e+000,-3.540147e-002,,,,,,,-8.038230e-007,,,,,,,,,,,,,,,,,,,,,
1557465935.760,,1.000000e+001,6.165850e+000,6.419732e+000,3,0,2.033362e+000,-8.697775e-003,,,,,,,-1.974910e-007,,,,,,,,,,,,,,,,,,,,,
1557465935.760,,1.000000e+001,6.165850e+000,6.419732e+000,3,0,2.320636e+000,-2.716147e-002,,,,,,,-6.167263e-007,,,,,,,,,,,,,,,,,,,,,
1557465935.760,,1.000000e+001,6.452528e+000,6.666144e+000,4,0,1.324013e+000,-5.142369e-002,,,,,,,-1.167622e-006,,,,,,,,,,,,,,,,,,,,,
1557465935.760,,1.000000e+001,6.452528e+000,6.666144e+000,4,0,3.017494e+000,-7.950072e-002,,,,,,,-1.805137e-006,,,,,,,,,,,,,,,,,,,,,
1557465935.760,,1.000000e+001,6.666144e+000,6.906528e+000,5,0,6.702301e-001,-1.081881e-001,,,,,,,-2.456511e-006,,,,,,,,,,,,,,,,,,,,,
1557465935.760,,1.000000e+001,6.666144e+000,6.906528e+000,5,0,3.603549e+000,-1.138340e-001,,,,,,,-2.584707e-006,,,,,,,,,,,,,,,,,,,,,
1557465935.760,,1.000000e+001,6.906528e+000,7.204744e+000,6,0,1.836273e-001,-1.214637e-001,,,,,,,-2.757944e-006,,,,,,,,,,,,,,,,,,,,,
1557465935.760,,1.000000e+001,6.906528e+000,7.204744e+000,6,0,3.955802e+000,-1.121555e-001,,,,,,,-2.546594e-006,,,,,,,,,,,,,,,,,,,,,
1557465935.760,,1.000000e+001,7.204744e+000,7.442220e+000,7,0,-4.715019e-003,-1.313822e-001,,,,,,,-2.983154e-006,,,,,,,,,,,,,,,,,,,,,
1557465935.760,,1.000000e+001,7.204744e+000,7.442220e+000,7,0,3.955114e+000,-1.208533e-001,,,,,,,-2.744085e-006,,,,,,,,,,,,,,,,,,,,,
1557465935.760,,1.000000e+001,7.474225e+000,7.676000e+000,8,0,1.880894e-001,-8.896146e-002,-1.244392e-001,-3.877122e-002,-3.628623e-002,-1.174417e-001,-3.177372e-002,-2.928873e-002,-2.019952e-006,-2.825507e-006,,,,,,,,,,,,,,,,,,,,
1557465935.760,,1.000000e+001,7.474225e+000,7.676000e+000,8,0,3.593040e+000,-7.110813e-002,-1.105342e-001,-2.909070e-002,-2.238124e-002,-1.140735e-001,-3.262993e-002,-2.592047e-002,-1.614576e-006,-2.509782e-006,,,,,,,,,,,,,,,,,,,,
1557465995.970,,1.000000e+001,7.764310e+000,7.977565e+000,1,0,6.781484e-001,-1.113926e-001,,,,,,,-2.529271e-006,,,,,,,,,,,,,,,,,,,,,
1557465995.970,,1.000000e+001,7.764310e+000,7.977565e+000,1,0,3.024237e+000,-9.048738e-002,,,,,,,-2.054599e-006,,,,,,,,,,,,,,,,,,,,,
1557465995.970,,1.000000e+001,7.977565e+000,8.206757e+000,2,0,1.293087e+000,-4.135258e-002,,,,,,,-9.389484e-007,,,,,,,,,,,,,,,,,,,,,
1557465995.970,,1.000000e+001,7.977565e+000,8.206757e+000,2,0,2.377158e+000,-2.441481e-002,,,,,,,-5.543607e-007,,,,,,,,,,,,,,,,,,,,,
1557465995.970,,1.000000e+001,8.239004e+000,8.471773e+000,3,0,1.967562e+000,-1.663259e-002,,,,,,,-3.776582e-007,,,,,,,,,,,,,,,,,,,,,
1557465995.970,,1.000000e+001,8.471773e+000,8.693903e+000,4,0,1.679166e+000,-1.907407e-002,,,,,,,-4.330943e-007,,,,,,,,,,,,,,,,,,,,,
1557465995.970,,1.000000e+001,8.471773e+000,8.693903e+000,4,0,2.675694e+000,-5.569628e-002,,,,,,,-1.264635e-006,,,,,,,,,,,,,,,,,,,,,
1557465995.970,,1.000000e+001,8.693903e+000,8.928776e+000,5,0,9.841603e-001,-7.202368e-002,,,,,,,-1.635364e-006,,,,,,,,,,,,,,,,,,,,,
1557465995.970,,1.000000e+001,8.693903e+000,8.928776e+000,5,0,3.332201e+000,-9.430219e-002,,,,,,,-2.141218e-006,,,,,,,,,,,,,,,,,,,,,
1557465995.970,,1.000000e+001,8.928776e+000,9.161272e+000,6,0,3.972596e-001,-1.188696e-001,,,,,,,-2.699044e-006,,,,,,,,,,,,,,,,,,,,,
1557465995.970,,1.000000e+001,8.928776e+000,9.161272e+000,6,0,3.816809e+000,-1.130711e-001,,,,,,,-2.567383e-006,,,,,,,,,,,,,,,,,,,,,
1557465995.970,,1.000000e+001,9.161272e+000,9.386075e+000,7,0,4.469978e-002,-1.017792e-001,,,,,,,-2.310991e-006,,,,,,,,,,,,,,,,,,,,,
1557465995.970,,1.000000e+001,9.161272e+000,9.386075e+000,7,0,4.004911e+000,-7.736442e-002,,,,,,,-1.756630e-006,,,,,,,,,,,,,,,,,,,,,
1557465995.970,,1.000000e+001,9.420921e+000,9.601181e+000,8,0,4.531651e-002,-9.842220e-002,-1.156079e-001,-3.434671e-002,-3.035714e-002,-1.096395e-001,-2.837824e-002,-2.438867e-002,-2.234766e-006,-2.624985e-006,,,,,,,,,,,,,,,,,,,,
1557465995.970,,1.000000e+001,9.420921e+000,9.601181e+000,8,0,3.812294e+000,-8.697775e-002,-1.008065e-001,-2.708107e-002,-1.555566e-002,-1.022252e-001,-2.849986e-002,-1.697445e-002,-1.974910e-006,-2.288903e-006,,,,,,,,,,,,,,,,,,,,
1557466123.470,,1.000000e+001,9.730906e+000,9.997077e+000,1,0,4.079083e-001,-8.087405e-002,,,,,,,-1.836320e-006,,,,,,,,,,,,,,,,,,,,,
1557466123.470,,1.000000e+001,9.730906e+000,9.997077e+000,1,0,3.323533e+000,-6.515702e-002,,,,,,,-1.479450e-006,,,,,,,,,,,,,,,,,,,,,
1557466123.470,,1.000000e+001,9.997077e+000,1.004100e+001,2,0,9.774320e-001,-7.339701e-002,,,,,,,-1.666547e-006,,,,,,,,,,,,,,,,,,,,,
1557466123.470,,1.000000e+001,9.997077e+000,1.004100e+001,2,0,2.707805e+000,-4.852443e-002,,,,,,,-1.101792e-006,,,,,,,,,,,,,,,,,,,,,
1557466123.470,,1.000000e+001,1.001091e+001,1.000642e+001,3,0,1.623381e+000,-3.616443e-002,,,,,,,-8.211468e-007,,,,,,,,,,,,,,,,,,,,,
1557466123.470,,1.000000e+001,1.000642e+001,1.001238e+001,4,0,2.034186e+000,-3.540147e-002,,,,,,,-8.038230e-007,,,,,,,,,,,,,,,,,,,,,
1557466123.470,,1.000000e+001,1.000642e+001,1.001238e+001,4,0,2.321288e+000,-5.661184e-002,,,,,,,-1.285424e-006,,,,,,,,,,,,,,,,,,,,,
1557466123.470,,1.000000e+001,1.001238e+001,1.001099e+001,5,0,1.324502e+000,-5.996887e-002,,,,,,,-1.361649e-006,,,,,,,,,,,,,,,,,,,,,
1557466123.470,,1.000000e+001,1.001238e+001,1.001099e+001,5,0,3.017634e+000,-9.857479e-002,,,,,,,-2.238231e-006,,,,,,,,,,,,,,,,,,,,,
1557466123.470,,1.000000e+001,1.001099e+001,1.000601e+001,6,0,6.683446e-001,-1.069674e-001,,,,,,,-2.428793e-006,,,,,,,,,,,,,,,,,,,,,
1557466123.470,,1.000000e+001,1.001099e+001,1.000601e+001,6,0,3.602971e+000,-1.097140e-001,,,,,,,-2.491158e-006,,,,,,,,,,,,,,,,,,,,,
1557466123.470,,1.000000e+001,1.000959e+001,1.000936e+001,7,0,1.833384e-001,-1.182592e-001,,,,,,,-2.685185e-006,,,,,,,,,,,,,,,,,,,,,
1557466123.470,,1.000000e+001,1.000959e+001,1.000936e+001,7,0,3.955627e+000,-1.039155e-001,,,,,,,-2.359498e-006,,,,,,,,,,,,,,,,,,,,,
1557466123.470,,1.000000e+001,1.000936e+001,1.000222e+001,8,0,-4.205217e-003,-1.367229e-001,-1.185263e-001,-2.987227e-002,-2.852585e-002,-1.159397e-001,-2.728574e-002,-2.593932e-002,-3.104420e-006,-2.691248e-006,,,,,,,,,,,,,,,,,,,,
1557466123.470,,1.000000e+001,1.000936e+001,1.000222e+001,8,0,3.955417e+000,-1.361126e-001,-1.137005e-001,-2.790769e-002,-2.370012e-002,-1.103235e-001,-2.453063e-002,-2.032306e-002,-3.090561e-006,-2.581675e-006,,,,,,,,,,,,,,,,,,,,
1557466185.040,,1.000000e+001,1.000676e+001,1.000150e+001,1,0,1.893460e-001,-1.280251e-001,,,,,,,-2.906929e-006,,,,,,,,,,,,,,,,,,,,,
1557466185.040,,1.000000e+001,1.000676e+001,1.000150e+001,1,0,3.593914e+000,-1.158177e-001,,,,,,,-2.629748e-006,,,,,,,,,,,,,,,,,,,,,
1557466185.040,,1.000000e+001,1.000150e+001,1.000366e+001,2,0,6.774113e-001,-1.138340e-001,,,,,,,-2.584707e-006,,,,,,,,,,,,,,,,,,,,,
1557466185.040,,1.000000e+001,1.000150e+001,1.000366e+001,2,0,3.023385e+000,-9.308145e-002,,,,,,,-2.113500e-006,,,,,,,,,,,,,,,,,,,,,
1557466185.040,,1.000000e+001,1.000366e+001,1.000439e+001,3,0,1.294390e+000,-6.530961e-002,,,,,,,-1.482915e-006,,,,,,,,,,,,,,,,,,,,,
1557466185.040,,1.000000e+001,1.000366e+001,1.000439e+001,3,0,2.377922e+000,-4.669332e-002,,,,,,,-1.060215e-006,,,,,,,,,,,,,,,,,,,,,
1557466185.040,,1.000000e+001,1.000439e+001,1.000536e+001,4,0,1.966590e+000,-1.602222e-002,,,,,,,-3.637992e-007,,,,,,,,,,,,,,,,,,,,,
1557466185.040,,1.000000e+001,1.000536e+001,1.000440e+001,5,0,1.680149e+000,-3.082369e-002,,,,,,,-6.998804e-007,,,,,,,,,,,,,,,,,,,,,
1557466185.040,,1.000000e+001,1.000536e+001,1.000440e+001,5,0,2.676177e+000,-7.492294e-002,,,,,,,-1.701194e-006,,,,,,,,,,,,,,,,,,,,,
1557466185.040,,1.000000e+001,1.000440e+001,1.000537e+001,6,0,9.840789e-001,-1.019318e-001,,,,,,,-2.314456e-006,,,,,,,,,,,,,,,,,,,,,
1557466185.040,,1.000000e+001,1.000440e+001,1.000537e+001,6,0,3.332140e+000,-1.220740e-001,,,,,,,-2.771804e-006,,,,,,,,,,,,,,,,,,,,,
1557466185.040,,1.000000e+001,1.000537e+001,1.000321e+001,7,0,3.981149e-001,-1.132237e-001,,,,,,,-2.570848e-006,,,,,,,,,,,,,,,,,,,,,
1557466185.040,,1.000000e+001,1.000537e+001,1.000321e+001,7,0,3.817234e+000,-9.796441e-002,,,,,,,-2.224372e-006,,,,,,,,,,,,,,,,,,,,,
1557466185.040,,1.000000e+001,1.000393e+001,1.000587e+001,8,0,4.498604e-002,-1.329081e-001,-1.249733e-001,-3.106469e-002,-3.038800e-002,-1.221801e-001,-2.827151e-002,-2.759481e-002,-3.017801e-006,-2.837634e-006,,,,,,,,,,,,,,,,,,,,
1557466185.040,,1.000000e+001,1.000393e+001,1.000587e+001,8,0,4.005125e+000,-1.228370e-001,-1.186789e-001,-2.641366e-002,-2.409355e-002,-1.152401e-001,-2.297486e-002,-2.065475e-002,-2.789127e-006,-2.694713e-006,,,,,,,,,,,,,,,,,,,,
1557466244.040,,1.000000e+001,1.000635e+001,1.000104e+001,1,0,4.487716e-002,-9.109776e-002,,,,,,,-2.068458e-006,,,,,,,,,,,,,,,,,,,,,
1557466244.040,,1.000000e+001,1.000635e+001,1.000104e+001,1,0,3.811850e+000,-8.987702e-002,,,,,,,-2.040740e-006,,,,,,,,,,,,,,,,,,,,,
1557466244.040,,1.000000e+001,1.000104e+001,1.000515e+001,2,0,4.070702e-001,-9.216589e-002,,,,,,,-2.092712e-006,,,,,,,,,,,,,,,,,,,,,
1557466244.040,,1.000000e+001,1.000104e+001,1.000515e+001,2,0,3.322798e+000,-7.461775e-002,,,,,,,-1.694265e-006,,,,,,,,,,,,,,,,,,,,,
1557466244.040,,1.000000e+001,1.000515e+001,1.000419e+001,3,0,9.775562e-001,-9.384442e-002,,,,,,,-2.130824e-006,,,,,,,,,,,,,,,,,,,,,
1557466244.040,,1.000000e+001,1.000515e+001,1.000419e+001,3,0,2.707674e+000,-7.217627e-002,,,,,,,-1.638829e-006,,,,,,,,,,,,,,,,,,,,,
1557466244.040,,1.000000e+001,1.000419e+001,1.000250e+001,4,0,1.624289e+000,-3.814813e-002,,,,,,,-8.661886e-007,,,,,,,,,,,,,,,,,,,,,
1557466244.040,,1.000000e+001,1.000250e+001,1.000250e+001,5,0,2.033669e+000,1.525925e-004,,,,,,,3.464754e-009,,,,,,,,,,,,,,,,,,,,,
1557466244.040,,1.000000e+001,1.000250e+001,1.000250e+001,5,0,2.320968e+000,-1.602222e-002,,,,,,,-3.637992e-007,,,,,,,,,,,,,,,,,,,,,
1557466244.040,,1.000000e+001,1.000493e+001,1.000493e+001,6,0,1.324725e+000,-4.242073e-002,,,,,,,-9.632017e-007,,,,,,,,,,,,,,,,,,,,,
1557466244.040,,1.000000e+001,1.000493e+001,1.000493e+001,6,0,3.017467e+000,-7.736442e-002,,,,,,,-1.756630e-006,,,,,,,,,,,,,,,,,,,,,
1557466244.040,,1.000000e+001,1.000493e+001,1.000153e+001,7,0,6.697835e-001,-1.199377e-001,,,,,,,-2.723297e-006,,,,,,,,,,,,,,,,,,,,,
1557466244.040,,1.000000e+001,1.000493e+001,1.000153e+001,7,0,3.603353e+000,-1.194800e-001,,,,,,,-2.712903e-006,,,,,,,,,,,,,,,,,,,,,
1557466244.040,,1.000000e+001,1.000153e+001,1.000153e+001,8,0,1.840652e-001,-1.351970e-001,-1.184118e-001,-3.581225e-002,-3.396532e-002,-1.140766e-001,-3.147703e-002,-2.963009e-002,-3.069772e-006,-2.688649e-006,,,,,,,,,,,,,,,,,,,,
1557466244.040,,1.000000e+001,1.000153e+001,1.000153e+001,8,0,3.956141e+000,-1.176489e-001,-1.025994e-001,-2.523283e-002,-1.815291e-002,-1.017699e-001,-2.440331e-002,-1.732340e-002,-2.671326e-006,-2.329614e-006,,,,,,,,,,,,,,,,,,,,
1557466279.850,,1.000000e+001,1.000177e+001,1.000348e+001,1,0,-4.315821e-003,-1.107822e-001,,,,,,,-2.515412e-006,,,,,,,,,,,,,,,,,,,,,
1557466279.850,,1.000000e+001,1.000177e+001,1.000348e+001,1,0,3.955216e+000,-1.001007e-001,,,,,,,-2.272879e-006,,,,,,,,,,,,,,,,,,,,,
1557466279.850,,1.000000e+001,1.000348e+001,1.000373e+001,2,0,1.881050e-001,-1.210059e-001,,,,,,,-2.747550e-006,,,,,,,,,,,,,,,,,,,,,
1557466279.850,,1.000000e+001,1.000348e+001,1.000373e+001,2,0,3.592919e+000,-1.063570e-001,,,,,,,-2.414934e-006,,,,,,,,,,,,,,,,,,,,,
1557466279.850,,1.000000e+001,1.000471e+001,1.000447e+001,3,0,6.780687e-001,-1.118503e-001,,,,,,,-2.539665e-006,,,,,,,,,,,,,,,,,,,,,
1557466279.850,,1.000000e+001,1.000471e+001,1.000447e+001,3,0,3.024022e+000,-8.941923e-002,,,,,,,-2.030346e-006,,,,,,,,,,,,,,,,,,,,,
1557466279.850,,1.000000e+001,1.000447e+001,1.000154e+001,4,0,1.293208e+000,-7.950072e-002,-6.160924e-002,2.899637e-002,3.216811e-002,-6.115161e-002,2.945401e-002,3.262574e-002,-1.805137e-006,-1.398895e-006,,,,,,,,,,,,,,,,,,,,
1557466279.850,,1.000000e+001,1.000447e+001,1.000154e+001,4,0,2.377210e+000,-6.164739e-002,-4.352703e-002,4.322720e-002,5.025033e-002,-3.846598e-002,4.828824e-002,5.531137e-002,-1.399761e-006,-9.883212e-007,,,,,,,,,,,,,,,,,,,,
1557466279.850,,1.000000e+001,1.000447e+001,1.000154e+001,4,0,2.207005e+000,-4.745628e-002,-3.120518e-002,5.543577e-002,6.257217e-002,-2.429313e-002,6.234781e-002,6.948422e-002,-1.077539e-006,-7.085423e-007,,,,,,,,,,,,,,,,,,,,