File: 研究/MPMS/190510/190510_PlatedSn_onSi_4.rso.dat
[Header]
TITLE,MPMS RSO Measurement
BYAPP,MPMS Measurement,1.1,Summary
FILEOPENTIME, 1557474810.224000 5/10/2019, 4:53:30 PM

INFO, APPNAME, MPMS MultiVu Application, Revision 1.60,  Build 081

INFO, NAME,
INFO, WEIGHT, 1.000
INFO, AREA, 1.000
INFO, LENGTH, 1.000
INFO, SHAPE, 0
INFO, COMMENT,
INFO, SEQUENCE FILE: 190519_PlatedSn_onSi_5.seq


INFO, BACKGROUND DATA FILE:, None


STARTUPAXIS,X,4,LINEAR,AUTO,0.000000,0.000000
STARTUPAXIS,Y1,5,LINEAR,AUTO,0.000000,0.000000


STARTUPGROUP,Longitudinal
FIELDGROUP,Longitudinal,1,2,3,4,5,6,7,8,9,10,11,19,20,21,22,23,35
FIELDGROUP,Transverse,1,2,3,4,12,13,14,15,16,17,18,24,25,26,27,28,35

PLOT_APPEARANCE,ALL,HORZ_GRID_ON,VERT_GRID_ON,MARKERS_AND_LINES

[Data]
Time,Comment,Field (Oe),Temperature (K),Long Moment (emu),Long Scan Std Dev,Long Offset (cm),Long Offset Std Dev,Long Algorithm,Long Reg Fit,Long Reg Factor,Trans Moment (emu),Trans Scan Std Dev,Trans Offset (cm),Trans Offset Std Dev,Trans Algorithm,Trans Reg Fit,Trans Reg Factor,Long Moment [w/o ABS] (emu),Long Scan Std Dev [w/o ABS],Long Offset [w/o ABS] (cm),Long Offset Std Dev [w/o ABS],Long Reg Fit [w/o ABS],Trans Moment [w/o ABS] (emu),Trans Scan Std Dev [w/o ABS],Trans Offset [w/o ABS] (cm),Trans Offset Std Dev [w/o ABS],Trans Reg Fit [w/o ABS],RSO Position (deg),Amplitude (cm),Frequency,Cycles to Average,Scans per Measurement,Delta Temp (K),Error,EC Comp. Running,Using ABS,
1557474810.224,,1.000000e+001,3.900618e+002,7.561471e-007,5.150787e-009,-1.215079e-002,3.699120e-003,3,8.671821e-001,1.825000e+000,,,,,,,,,,,,,,,,,,0,4.000000e+000,1.500000e+000,2,2,2.349854e-002,0,,0,
1557474905.264,,1.000000e+001,3.877610e+002,6.649473e-007,1.790687e-008,-4.687182e-002,1.173779e-002,3,8.069021e-001,1.825000e+000,,,,,,,,,,,,,,,,,,0,4.000000e+000,1.500000e+000,2,2,3.016968e-001,0,,0,
1557474960.454,,1.000000e+001,3.854652e+002,7.384133e-007,2.613325e-008,-2.312232e-002,5.738202e-003,3,8.360075e-001,1.825000e+000,,,,,,,,,,,,,,,,,,0,4.000000e+000,1.500000e+000,2,2,7.797241e-001,0,,0,
1557474993.384,,1.000000e+001,3.828520e+002,7.171946e-007,1.257939e-008,-2.742324e-002,1.432796e-002,3,8.391756e-001,1.825000e+000,,,,,,,,,,,,,,,,,,0,4.000000e+000,1.500000e+000,2,2,1.175720e+000,0,,0,
1557475023.424,,1.000000e+001,3.795628e+002,6.683510e-007,9.103461e-009,-2.700689e-002,3.171009e-003,3,8.242332e-001,1.825000e+000,,,,,,,,,,,,,,,,,,0,4.000000e+000,1.500000e+000,2,2,1.355286e+000,0,,0,
1557475054.164,,1.000000e+001,3.756511e+002,7.311743e-007,2.410995e-008,-1.963165e-002,3.561969e-002,3,8.547083e-001,1.825000e+000,,,,,,,,,,,,,,,,,,0,4.000000e+000,1.500000e+000,2,2,1.739502e+000,0,,0,
1557475086.854,,1.000000e+001,3.706921e+002,7.643878e-007,1.303668e-008,-2.772929e-002,2.114871e-003,3,8.807359e-001,1.825000e+000,,,,,,,,,,,,,,,,,,0,4.000000e+000,1.500000e+000,2,2,1.902588e+000,0,,0,
1557475119.564,,1.000000e+001,3.653846e+002,7.125381e-007,1.187824e-008,-2.775514e-002,1.467067e-002,3,8.424070e-001,1.825000e+000,,,,,,,,,,,,,,,,,,0,4.000000e+000,1.500000e+000,2,2,1.744415e+000,0,,0,
1557475152.304,,1.000000e+001,3.597716e+002,7.177216e-007,2.116495e-008,-1.950332e-002,1.705900e-002,3,8.435949e-001,1.825000e+000,,,,,,,,,,,,,,,,,,0,4.000000e+000,1.500000e+000,2,2,1.648224e+000,0,,0,
1557475186.314,,1.000000e+001,3.537095e+002,7.642815e-007,1.166264e-008,-4.347965e-002,6.010343e-003,3,8.528109e-001,1.825000e+000,,,,,,,,,,,,,,,,,,0,4.000000e+000,1.500000e+000,2,2,2.146088e+000,0,,0,
1557475218.635,,1.000000e+001,3.477394e+002,7.371106e-007,6.239733e-008,-5.782639e-002,9.339241e-004,3,8.437943e-001,1.825000e+000,,,,,,,,,,,,,,,,,,0,4.000000e+000,1.500000e+000,2,2,2.161621e+000,0,,0,
1557475251.135,,1.000000e+001,3.415976e+002,7.043140e-007,3.810346e-009,-3.866678e-002,2.424164e-002,3,8.149617e-001,1.825000e+000,,,,,,,,,,,,,,,,,,0,4.000000e+000,1.500000e+000,2,2,2.204773e+000,0,,0,
1557475282.185,,1.000000e+001,3.356772e+002,7.813305e-007,5.082216e-009,-4.613135e-002,7.319195e-004,3,8.745446e-001,1.825000e+000,,,,,,,,,,,,,,,,,,0,4.000000e+000,1.500000e+000,2,2,2.133209e+000,0,,0,
1557475316.195,,1.000000e+001,3.293363e+002,7.903619e-007,3.638105e-008,-6.123953e-002,9.746530e-003,3,8.911405e-001,1.825000e+000,,,,,,,,,,,,,,,,,,0,4.000000e+000,1.500000e+000,2,2,2.223572e+000,0,,0,
1557475347.175,,1.000000e+001,3.234614e+002,7.416685e-007,5.412565e-008,-4.562230e-002,1.074859e-002,3,8.396981e-001,1.825000e+000,,,,,,,,,,,,,,,,,,0,4.000000e+000,1.500000e+000,2,2,2.028503e+000,0,,0,
1557475380.135,,1.000000e+001,3.174025e+002,7.533314e-007,1.709181e-008,-3.452843e-002,5.887577e-003,3,8.628331e-001,1.825000e+000,,,,,,,,,,,,,,,,,,0,4.000000e+000,1.500000e+000,2,2,2.239685e+000,0,,0,
1557475413.925,,1.000000e+001,3.110076e+002,7.287450e-007,1.548810e-008,-4.175299e-002,2.295698e-002,3,8.322122e-001,1.825000e+000,,,,,,,,,,,,,,,,,,0,4.000000e+000,1.500000e+000,2,2,2.219574e+000,0,,0,
1557475444.375,,1.000000e+001,3.054014e+002,7.470610e-007,1.481416e-008,-7.443805e-002,8.453320e-003,3,8.109071e-001,1.825000e+000,,,,,,,,,,,,,,,,,,0,4.000000e+000,1.500000e+000,2,2,2.020691e+000,0,,0,
1557475477.165,,1.000000e+001,2.994443e+002,7.689843e-007,4.746887e-008,-4.573239e-002,2.304287e-003,3,8.487067e-001,1.825000e+000,,,,,,,,,,,,,,,,,,0,4.000000e+000,1.500000e+000,2,2,2.194092e+000,0,,0,
1557475507.905,,1.000000e+001,2.941215e+002,7.567868e-007,1.758286e-008,-6.145083e-002,1.056336e-002,3,8.479717e-001,1.825000e+000,,,,,,,,,,,,,,,,,,0,4.000000e+000,1.500000e+000,2,2,1.956421e+000,0,,0,
1557475540.745,,1.000000e+001,2.884200e+002,7.288455e-007,8.871178e-009,-7.667910e-002,1.657798e-002,3,8.556254e-001,1.825000e+000,,,,,,,,,,,,,,,,,,0,4.000000e+000,1.500000e+000,2,2,2.152679e+000,0,,0,
1557475570.735,,1.000000e+001,2.833235e+002,8.538195e-007,2.363859e-008,-4.964601e-002,4.772735e-004,3,8.736611e-001,1.825000e+000,,,,,,,,,,,,,,,,,,0,4.000000e+000,1.500000e+000,2,2,2.149109e+000,0,,0,
1557475603.675,,1.000000e+001,2.776373e+002,7.779540e-007,3.908766e-008,-7.771881e-002,7.466367e-003,3,8.627523e-001,1.825000e+000,,,,,,,,,,,,,,,,,,0,4.000000e+000,1.500000e+000,2,2,1.680817e+000,0,,0,
1557475636.165,,1.000000e+001,2.724536e+002,7.434526e-007,2.338010e-008,-8.054823e-002,4.178085e-002,3,8.598319e-001,1.825000e+000,,,,,,,,,,,,,,,,,,0,4.000000e+000,1.500000e+000,2,2,1.850098e+000,0,,0,
1557475668.915,,1.000000e+001,2.672637e+002,8.097410e-007,5.664508e-008,-8.753131e-002,1.221312e-002,3,8.726146e-001,1.825000e+000,,,,,,,,,,,,,,,,,,0,4.000000e+000,1.500000e+000,2,2,1.818298e+000,0,,0,
1557475701.635,,1.000000e+001,2.621482e+002,7.351265e-007,6.204752e-008,-7.626228e-002,2.554593e-002,3,8.301157e-001,1.825000e+000,,,,,,,,,,,,,,,,,,0,4.000000e+000,1.500000e+000,2,2,1.789307e+000,0,,0,
1557475733.705,,1.000000e+001,2.572808e+002,7.465880e-007,6.594046e-008,-6.680536e-002,9.766618e-003,3,8.343606e-001,1.825000e+000,,,,,,,,,,,,,,,,,,0,4.000000e+000,1.500000e+000,2,2,1.772400e+000,0,,0,
1557475765.255,,1.000000e+001,2.524058e+002,7.435157e-007,4.677346e-008,-6.919009e-002,2.131493e-003,3,8.209434e-001,1.825000e+000,,,,,,,,,,,,,,,,,,0,4.000000e+000,1.500000e+000,2,2,1.716202e+000,0,,0,
1557475796.985,,1.000000e+001,2.478745e+002,7.779424e-007,2.608940e-008,-8.675449e-002,3.128929e-004,3,8.806661e-001,1.825000e+000,,,,,,,,,,,,,,,,,,0,4.000000e+000,1.500000e+000,2,2,1.684601e+000,0,,0,
1557475827.425,,1.000000e+001,2.434947e+002,8.173813e-007,3.551096e-008,-7.155511e-002,2.866381e-003,3,8.561271e-001,1.825000e+000,,,,,,,,,,,,,,,,,,0,4.000000e+000,1.500000e+000,2,2,1.650406e+000,0,,0,
1557475858.965,,1.000000e+001,2.390590e+002,7.796810e-007,2.739560e-008,-9.304594e-002,1.884701e-002,3,8.736597e-001,1.825000e+000,,,,,,,,,,,,,,,,,,0,4.000000e+000,1.500000e+000,2,2,1.627487e+000,0,,0,
1557475891.445,,1.000000e+001,2.347230e+002,7.787343e-007,3.598682e-008,-5.888270e-002,3.062364e-003,3,8.507048e-001,1.825000e+000,,,,,,,,,,,,,,,,,,0,4.000000e+000,1.500000e+000,2,2,1.436493e+000,0,,0,
1557475920.986,,1.000000e+001,2.307399e+002,8.146094e-007,2.863620e-008,-6.487633e-002,8.084403e-003,3,8.824605e-001,1.825000e+000,,,,,,,,,,,,,,,,,,0,4.000000e+000,1.500000e+000,2,2,1.405411e+000,0,,0,
1557475952.236,,1.000000e+001,2.267950e+002,7.585432e-007,1.052819e-008,-7.868290e-002,2.484832e-002,3,8.589253e-001,1.825000e+000,,,,,,,,,,,,,,,,,,0,4.000000e+000,1.500000e+000,2,2,1.728806e+000,0,,0,
1557475982.946,,1.000000e+001,2.228728e+002,7.952516e-007,6.240461e-008,-6.034150e-002,1.011041e-002,3,8.750108e-001,1.825000e+000,,,,,,,,,,,,,,,,,,0,4.000000e+000,1.500000e+000,2,2,1.380905e+000,0,,0,
1557476012.926,,1.000000e+001,2.190462e+002,8.028006e-007,8.189024e-008,-7.435022e-002,9.289028e-003,3,8.633245e-001,1.825000e+000,,,,,,,,,,,,,,,,,,0,4.000000e+000,1.500000e+000,2,2,1.652603e+000,0,,0,
1557476044.866,,1.000000e+001,2.152653e+002,7.739069e-007,3.936982e-008,-7.308343e-002,6.225843e-003,3,8.543305e-001,1.825000e+000,,,,,,,,,,,,,,,,,,0,4.000000e+000,1.500000e+000,2,2,1.459106e+000,0,,0,
1557476074.216,,1.000000e+001,2.118154e+002,7.676209e-007,2.366680e-008,-7.333018e-002,1.398396e-002,3,8.331906e-001,1.825000e+000,,,,,,,,,,,,,,,,,,0,4.000000e+000,1.500000e+000,2,2,1.447510e+000,0,,0,
1557476103.016,,1.000000e+001,2.084689e+002,7.528710e-007,2.659525e-008,-7.656793e-002,2.531248e-002,3,8.551499e-001,1.825000e+000,,,,,,,,,,,,,,,,,,0,4.000000e+000,1.500000e+000,2,2,1.409409e+000,0,,0,
1557476130.826,,1.000000e+001,2.053304e+002,8.064769e-007,5.997000e-010,-6.631634e-002,1.213650e-002,3,8.507563e-001,1.825000e+000,,,,,,,,,,,,,,,,,,0,4.000000e+000,1.500000e+000,2,2,1.097412e+000,0,,0,
1557476161.526,,1.000000e+001,2.018504e+002,8.274299e-007,5.114902e-008,-7.844609e-002,1.273520e-002,3,8.644789e-001,1.825000e+000,,,,,,,,,,,,,,,,,,0,4.000000e+000,1.500000e+000,2,2,1.338196e+000,0,,0,
1557476191.276,,1.000000e+001,1.985342e+002,8.195907e-007,2.644954e-008,-7.872387e-002,2.290502e-003,3,8.655899e-001,1.825000e+000,,,,,,,,,,,,,,,,,,0,4.000000e+000,1.500000e+000,2,2,1.250000e+000,0,,0,
1557476219.266,,1.000000e+001,1.952601e+002,8.224895e-007,1.934547e-008,-5.639548e-002,8.002438e-003,3,8.880996e-001,1.825000e+000,,,,,,,,,,,,,,,,,,0,4.000000e+000,1.500000e+000,2,2,1.447998e+000,0,,0,
1557476248.706,,1.000000e+001,1.917295e+002,7.975651e-007,7.083051e-010,-9.797978e-002,5.072884e-003,3,8.388337e-001,1.825000e+000,,,,,,,,,,,,,,,,,,0,4.000000e+000,1.500000e+000,2,2,1.387192e+000,0,,0,
1557476277.456,,1.000000e+001,1.880629e+002,8.086723e-007,2.241346e-008,-6.687279e-002,8.243508e-003,3,8.624173e-001,1.825000e+000,,,,,,,,,,,,,,,,,,0,4.000000e+000,1.500000e+000,2,2,1.601791e+000,0,,0,
1557476306.516,,1.000000e+001,1.842348e+002,8.101217e-007,3.802475e-008,-8.071312e-002,7.336528e-003,3,8.907390e-001,1.825000e+000,,,,,,,,,,,,,,,,,,0,4.000000e+000,1.500000e+000,2,2,1.515793e+000,0,,0,
1557476336.276,,1.000000e+001,1.803071e+002,7.914091e-007,5.167171e-008,-7.617811e-002,1.397857e-002,3,8.647263e-001,1.825000e+000,,,,,,,,,,,,,,,,,,0,4.000000e+000,1.500000e+000,2,2,1.729202e+000,0,,0,
1557476366.536,,1.000000e+001,1.761493e+002,8.294346e-007,3.815056e-008,-7.994308e-002,9.619170e-003,3,8.640020e-001,1.825000e+000,,,,,,,,,,,,,,,,,,0,4.000000e+000,1.500000e+000,2,2,1.455795e+000,0,,0,
1557476394.976,,1.000000e+001,1.720733e+002,8.297549e-007,6.659330e-008,-6.289455e-002,8.392020e-003,3,8.607582e-001,1.825000e+000,,,,,,,,,,,,,,,,,,0,4.000000e+000,1.500000e+000,2,2,1.694992e+000,0,,0,
1557476425.216,,1.000000e+001,1.677618e+002,7.894133e-007,4.123621e-009,-6.238677e-002,4.366332e-003,3,8.285728e-001,1.825000e+000,,,,,,,,,,,,,,,,,,0,4.000000e+000,1.500000e+000,2,2,1.546402e+000,0,,0,
1557476455.906,,1.000000e+001,1.632849e+002,8.235432e-007,1.722622e-008,-7.576945e-002,6.513163e-003,3,8.697950e-001,1.825000e+000,,,,,,,,,,,,,,,,,,0,4.000000e+000,1.500000e+000,2,2,1.796997e+000,0,,0,
1557476486.176,,1.000000e+001,1.587538e+002,8.080742e-007,3.297514e-008,-7.169437e-002,7.243500e-003,3,8.669242e-001,1.825000e+000,,,,,,,,,,,,,,,,,,0,4.000000e+000,1.500000e+000,2,2,1.843201e+000,0,,0,
1557476516.246,,1.000000e+001,1.539784e+002,8.075586e-007,2.223022e-008,-9.897313e-002,1.288102e-003,3,8.666281e-001,1.825000e+000,,,,,,,,,,,,,,,,,,0,4.000000e+000,1.500000e+000,2,2,1.522095e+000,0,,0,
1557476545.476,,1.000000e+001,1.494508e+002,7.838214e-007,4.588066e-009,-9.033367e-002,2.540405e-002,3,8.192853e-001,1.825000e+000,,,,,,,,,,,,,,,,,,0,4.000000e+000,1.500000e+000,2,2,1.774506e+000,0,,0,
1557476576.006,,1.000000e+001,1.447159e+002,8.354097e-007,2.460225e-008,-7.668494e-002,6.963813e-003,3,8.668855e-001,1.825000e+000,,,,,,,,,,,,,,,,,,0,4.000000e+000,1.500000e+000,2,2,1.843399e+000,0,,0,
1557476607.956,,1.000000e+001,1.395367e+002,8.194845e-007,3.241704e-008,-7.994679e-002,2.033510e-002,3,8.411914e-001,1.825000e+000,,,,,,,,,,,,,,,,,,0,4.000000e+000,1.500000e+000,2,2,2.152695e+000,0,,0,
1557476639.337,,1.000000e+001,1.341788e+002,8.393939e-007,5.380832e-008,-6.717589e-002,2.483503e-004,3,8.450940e-001,1.825000e+000,,,,,,,,,,,,,,,,,,0,4.000000e+000,1.500000e+000,2,2,1.793304e+000,0,,0,
1557476671.117,,1.000000e+001,1.286404e+002,8.162163e-007,3.622356e-008,-7.188734e-002,1.611938e-002,3,8.222573e-001,1.825000e+000,,,,,,,,,,,,,,,,,,0,4.000000e+000,1.500000e+000,2,2,2.055298e+000,0,,0,
1557476701.457,,1.000000e+001,1.232987e+002,8.412178e-007,1.541960e-008,-7.424690e-002,7.875955e-003,3,8.525297e-001,1.825000e+000,,,,,,,,,,,,,,,,,,0,4.000000e+000,1.500000e+000,2,2,1.933998e+000,0,,0,
1557476732.717,,1.000000e+001,1.176308e+002,7.892756e-007,1.542901e-009,-7.897024e-002,1.175791e-002,3,8.104850e-001,1.825000e+000,,,,,,,,,,,,,,,,,,0,4.000000e+000,1.500000e+000,2,2,2.267403e+000,0,,0,
1557476763.157,,1.000000e+001,1.120217e+002,8.376554e-007,3.474176e-008,-6.904472e-002,3.184574e-003,3,8.684541e-001,1.825000e+000,,,,,,,,,,,,,,,,,,0,4.000000e+000,1.500000e+000,2,2,2.093102e+000,0,,0,
1557476793.897,,1.000000e+001,1.059295e+002,8.272424e-007,3.644560e-008,-6.646816e-002,1.283311e-002,3,8.706521e-001,1.825000e+000,,,,,,,,,,,,,,,,,,0,4.000000e+000,1.500000e+000,2,2,2.111404e+000,0,,0,
1557476823.837,,1.000000e+001,1.001577e+002,7.907720e-007,4.032609e-008,-7.127877e-002,1.471887e-002,3,8.394198e-001,1.825000e+000,,,,,,,,,,,,,,,,,,0,4.000000e+000,1.500000e+000,2,2,2.336555e+000,0,,0,
1557476854.427,,1.000000e+001,9.392187e+001,7.960665e-007,2.740275e-008,-9.207527e-002,1.529467e-002,3,8.364308e-001,1.825000e+000,,,,,,,,,,,,,,,,,,0,4.000000e+000,1.500000e+000,2,2,2.474815e+000,0,,0,
1557476884.797,,1.000000e+001,8.715757e+001,8.444205e-007,4.004589e-008,-5.177235e-002,8.319398e-003,3,8.618654e-001,1.825000e+000,,,,,,,,,,,,,,,,,,0,4.000000e+000,1.500000e+000,2,2,2.338760e+000,0,,0,
1557476915.807,,1.000000e+001,8.034643e+001,7.961081e-007,1.866345e-009,-6.590518e-002,5.358737e-003,3,8.252433e-001,1.825000e+000,,,,,,,,,,,,,,,,,,0,4.000000e+000,1.500000e+000,2,2,2.152565e+000,0,,0,
1557476945.597,,1.000000e+001,7.376155e+001,8.280303e-007,9.412395e-009,-6.145396e-002,1.981549e-002,3,8.368904e-001,1.825000e+000,,,,,,,,,,,,,,,,,,0,4.000000e+000,1.500000e+000,2,2,2.417664e+000,0,,0,
1557476978.617,,1.000000e+001,6.697305e+001,8.065660e-007,1.983552e-009,-8.546031e-002,4.676920e-002,3,8.222347e-001,1.825000e+000,,,,,,,,,,,,,,,,,,0,4.000000e+000,1.500000e+000,2,2,2.340858e+000,0,,0,
1557477008.927,,1.000000e+001,6.084720e+001,8.166826e-007,1.860276e-009,-9.061143e-002,9.076319e-003,3,8.284539e-001,1.825000e+000,,,,,,,,,,,,,,,,,,0,4.000000e+000,1.500000e+000,2,2,1.913109e+000,0,,0,
1557477039.927,,1.000000e+001,5.519461e+001,8.428407e-007,3.071042e-008,-6.859944e-002,1.498408e-002,3,8.787726e-001,1.825000e+000,,,,,,,,,,,,,,,,,,0,4.000000e+000,1.500000e+000,2,2,2.072247e+000,0,,0,
1557477070.657,,1.000000e+001,4.973978e+001,8.401873e-007,6.221783e-008,-6.396479e-002,1.255460e-002,3,8.619733e-001,1.825000e+000,,,,,,,,,,,,,,,,,,0,4.000000e+000,1.500000e+000,2,2,2.077019e+000,0,,0,
1557477101.147,,1.000000e+001,4.381381e+001,8.439036e-007,4.931768e-008,-6.468934e-002,2.155232e-004,3,8.540033e-001,1.825000e+000,,,,,,,,,,,,,,,,,,0,4.000000e+000,1.500000e+000,2,2,2.508400e+000,0,,0,
1557477131.607,,1.000000e+001,3.741677e+001,8.349639e-007,2.355048e-008,-5.830456e-002,2.807746e-002,3,8.595591e-001,1.825000e+000,,,,,,,,,,,,,,,,,,0,4.000000e+000,1.500000e+000,2,2,2.532532e+000,0,,0,
1557477162.327,,1.000000e+001,2.894664e+001,7.934526e-007,5.163891e-009,-8.500044e-002,2.491790e-003,3,8.460343e-001,1.825000e+000,,,,,,,,,,,,,,,,,,0,4.000000e+000,1.500000e+000,2,2,3.867180e+000,0,,0,
1557477191.077,,1.000000e+001,1.334044e+001,7.628073e-007,2.913087e-009,-1.392173e-001,7.322346e-002,3,4.337659e-001,1.825000e+000,,,,,,,,,,,,,,,,,,0,4.000000e+000,1.500000e+000,2,2,1.122241e+001,0,,0,
1557479948.291,,1.000000e+001,9.997763e+000,8.320500e-007,4.219540e-008,-8.041056e-002,7.645701e-004,3,8.546579e-001,1.825000e+000,,,,,,,,,,,,,,,,,,0,4.000000e+000,1.500000e+000,2,2,3.244400e-003,0,,0,
1557479972.691,,1.000000e+001,9.999075e+000,8.044628e-007,5.010578e-008,-9.349603e-002,1.555338e-002,3,8.703908e-001,1.825000e+000,,,,,,,,,,,,,,,,,,0,4.000000e+000,1.500000e+000,2,2,2.255440e-003,0,,0,
1557479998.661,,1.000000e+001,9.998449e+000,8.842907e-007,2.037151e-008,-7.275310e-002,9.893462e-003,3,8.725100e-001,1.825000e+000,,,,,,,,,,,,,,,,,,0,4.000000e+000,1.500000e+000,2,2,1.996040e-003,0,,0,
1557480025.901,,1.000000e+001,9.995706e+000,8.293663e-007,3.264570e-008,-7.295507e-002,1.379225e-002,3,8.645509e-001,1.825000e+000,,,,,,,,,,,,,,,,,,0,4.000000e+000,1.500000e+000,2,2,4.988670e-003,0,,0,
1557480052.701,,1.000000e+001,9.996766e+000,8.756169e-007,1.916906e-008,-7.736596e-002,1.761266e-002,3,8.893642e-001,1.825000e+000,,,,,,,,,,,,,,,,,,0,4.000000e+000,1.500000e+000,2,2,5.487442e-003,0,,0,
1557480079.391,,1.000000e+001,1.000028e+001,8.385022e-007,3.868595e-008,-7.226263e-002,1.204042e-002,3,8.726147e-001,1.825000e+000,,,,,,,,,,,,,,,,,,0,4.000000e+000,1.500000e+000,2,2,5.292892e-003,0,,0,
1557480105.631,,1.000000e+001,1.000021e+001,8.599120e-007,5.231570e-008,-6.235708e-002,7.193476e-003,3,8.697770e-001,1.825000e+000,,,,,,,,,,,,,,,,,,0,4.000000e+000,1.500000e+000,2,2,4.023552e-003,0,,0,
1557480134.131,,1.000000e+001,9.998273e+000,8.470427e-007,1.395906e-008,-6.562351e-002,8.619162e-003,3,8.860013e-001,1.825000e+000,,,,,,,,,,,,,,,,,,0,4.000000e+000,1.500000e+000,2,2,6.020546e-003,0,,0,
1557480161.111,,1.000000e+001,9.998766e+000,8.517424e-007,1.364137e-008,-6.760491e-002,9.835747e-003,3,8.705903e-001,1.825000e+000,,,,,,,,,,,,,,,,,,0,4.000000e+000,1.500000e+000,2,2,4.013062e-003,0,,0,
1557480187.861,,1.000000e+001,9.999582e+000,8.072708e-007,1.246713e-008,-7.010999e-002,6.535680e-003,3,8.676034e-001,1.825000e+000,,,,,,,,,,,,,,,,,,0,4.000000e+000,1.500000e+000,2,2,3.775597e-003,0,,0,
1557480214.412,,1.000000e+001,9.999710e+000,7.958724e-007,7.790754e-009,-8.756661e-002,1.113706e-002,3,8.431921e-001,1.825000e+000,,,,,,,,,,,,,,,,,,0,4.000000e+000,1.500000e+000,2,2,4.545212e-003,0,,0,
1557480241.142,,1.000000e+001,9.997639e+000,8.597389e-007,3.175926e-008,-8.042882e-002,1.304449e-002,3,8.783704e-001,1.825000e+000,,,,,,,,,,,,,,,,,,0,4.000000e+000,1.500000e+000,2,2,9.975433e-004,0,,0,
1557480269.372,,1.000000e+001,9.998079e+000,8.134824e-007,3.137596e-008,-7.563205e-002,2.200691e-002,3,8.633339e-001,1.825000e+000,,,,,,,,,,,,,,,,,,0,4.000000e+000,1.500000e+000,2,2,4.262924e-003,0,,0,
1557480296.912,,1.000000e+001,9.998761e+000,8.406797e-007,3.118146e-008,-6.157557e-002,7.169468e-004,3,8.867116e-001,1.825000e+000,,,,,,,,,,,,,,,,,,0,4.000000e+000,1.500000e+000,2,2,9.984970e-004,0,,0,
1557480324.622,,1.000000e+001,9.998077e+000,8.265563e-007,1.146982e-008,-8.660856e-002,3.793612e-003,3,8.629580e-001,1.825000e+000,,,,,,,,,,,,,,,,,,0,4.000000e+000,1.500000e+000,2,2,4.002571e-003,0,,0,
1557480351.642,,1.000000e+001,9.999767e+000,8.443617e-007,1.891342e-008,-8.484031e-002,3.071942e-003,3,8.695212e-001,1.825000e+000,,,,,,,,,,,,,,,,,,0,4.000000e+000,1.500000e+000,2,2,4.273415e-003,0,,0,
1557480379.152,,1.000000e+001,9.998387e+000,8.467898e-007,1.162530e-008,-8.227195e-002,9.892493e-003,3,8.870020e-001,1.825000e+000,,,,,,,,,,,,,,,,,,0,4.000000e+000,1.500000e+000,2,2,2.744675e-003,0,,0,
1557480407.392,,1.000000e+001,9.998207e+000,8.332219e-007,3.954949e-008,-7.093009e-002,2.306857e-002,3,8.513301e-001,1.825000e+000,,,,,,,,,,,,,,,,,,0,4.000000e+000,1.500000e+000,2,2,5.510330e-003,0,,0,
1557480435.382,,1.000000e+001,9.998523e+000,8.052089e-007,5.364300e-008,-6.543098e-002,1.071541e-002,3,8.177732e-001,1.825000e+000,,,,,,,,,,,,,,,,,,0,4.000000e+000,1.500000e+000,2,2,7.530212e-003,0,,0,
1557480463.362,,1.000000e+001,9.998461e+000,8.430106e-007,2.290287e-008,-6.890028e-002,2.166796e-002,3,8.781241e-001,1.825000e+000,,,,,,,,,,,,,,,,,,0,4.000000e+000,1.500000e+000,2,2,6.031990e-003,0,,0,
1557480490.852,,1.000000e+001,9.999461e+000,8.264115e-007,8.502636e-009,-8.013881e-002,1.702385e-003,3,8.695724e-001,1.825000e+000,,,,,,,,,,,,,,,,,,0,4.000000e+000,1.500000e+000,2,2,5.272865e-003,0,,0,
1557480517.522,,1.000000e+001,9.999079e+000,8.650638e-007,4.068542e-008,-6.051923e-002,1.574893e-002,3,8.817241e-001,1.825000e+000,,,,,,,,,,,,,,,,,,0,4.000000e+000,1.500000e+000,2,2,4.262924e-003,0,,0,
1557480546.062,,1.000000e+001,1.000014e+001,8.152296e-007,3.254526e-008,-6.840390e-002,4.161258e-003,3,8.600514e-001,1.825000e+000,,,,,,,,,,,,,,,,,,0,4.000000e+000,1.500000e+000,2,2,3.752708e-003,0,,0,
1557480574.202,,1.000000e+001,1.000084e+001,8.239797e-007,1.717007e-008,-6.547753e-002,8.954204e-003,3,8.815997e-001,1.825000e+000,,,,,,,,,,,,,,,,,,0,4.000000e+000,1.500000e+000,2,2,4.036903e-003,0,,0,
1557480601.292,,1.000000e+001,9.999453e+000,8.599218e-007,8.902047e-009,-6.096896e-002,7.508385e-003,3,8.876495e-001,1.825000e+000,,,,,,,,,,,,,,,,,,0,4.000000e+000,1.500000e+000,2,2,3.015518e-003,0,,0,
1557480630.022,,1.000000e+001,9.999827e+000,8.276473e-007,3.968558e-008,-7.080043e-002,1.414772e-002,3,8.564690e-001,1.825000e+000,,,,,,,,,,,,,,,,,,0,4.000000e+000,1.500000e+000,2,2,2.017021e-003,0,,0,
1557480656.752,,1.000000e+001,9.999146e+000,8.639221e-007,7.760206e-009,-6.099694e-002,9.268793e-003,3,8.881128e-001,1.825000e+000,,,,,,,,,,,,,,,,,,0,4.000000e+000,1.500000e+000,2,2,6.272316e-003,0,,0,
1557480683.452,,1.000000e+001,1.000058e+001,8.313603e-007,1.819784e-008,-7.511583e-002,5.479101e-003,3,8.706325e-001,1.825000e+000,,,,,,,,,,,,,,,,,,0,4.000000e+000,1.500000e+000,2,2,2.017021e-003,0,,0,
1557480710.542,,1.000000e+001,9.998826e+000,8.462166e-007,2.640054e-008,-7.984087e-002,7.471641e-003,3,8.896668e-001,1.825000e+000,,,,,,,,,,,,,,,,,,0,4.000000e+000,1.500000e+000,2,2,2.753258e-003,0,,0,
1557480739.042,,1.000000e+001,9.998954e+000,8.022287e-007,9.741346e-009,-8.881452e-002,5.055989e-003,3,8.592830e-001,1.825000e+000,,,,,,,,,,,,,,,,,,0,4.000000e+000,1.500000e+000,2,2,5.512238e-003,0,,0,
1557480767.612,,1.000000e+001,1.000385e+001,8.141017e-007,7.872871e-010,-8.278494e-002,4.159098e-003,3,8.675411e-001,1.825000e+000,,,,,,,,,,,,,,,,,,0,4.000000e+000,1.500000e+000,2,2,6.037712e-003,0,,0,
1557480794.832,,1.000000e+001,9.998636e+000,8.411557e-007,8.657746e-009,-8.495758e-002,1.296731e-002,3,8.851563e-001,1.825000e+000,,,,,,,,,,,,,,,,,,0,4.000000e+000,1.500000e+000,2,2,2.492905e-003,0,,0,
1557480821.272,,1.000000e+001,9.999327e+000,8.509887e-007,1.508362e-008,-7.251029e-002,3.013305e-002,3,8.685480e-001,1.825000e+000,,,,,,,,,,,,,,,,,,0,4.000000e+000,1.500000e+000,2,2,2.005577e-003,0,,0,
1557480848.972,,1.000000e+001,1.000033e+001,8.417539e-007,6.800558e-008,-8.093656e-002,4.970346e-003,3,8.724908e-001,1.825000e+000,,,,,,,,,,,,,,,,,,0,4.000000e+000,1.500000e+000,2,2,1.257896e-003,0,,0,
1557480875.992,,1.000000e+001,9.999826e+000,8.197526e-007,1.380242e-008,-5.726909e-002,1.190675e-002,3,8.600309e-001,1.825000e+000,,,,,,,,,,,,,,,,,,0,4.000000e+000,1.500000e+000,2,2,3.005028e-003,0,,0,
1557480902.572,,1.000000e+001,9.998575e+000,8.544462e-007,8.952973e-009,-6.802408e-002,1.577188e-002,3,8.964216e-001,1.825000e+000,,,,,,,,,,,,,,,,,,0,4.000000e+000,1.500000e+000,2,2,9.984970e-004,0,,0,
1557480929.033,,1.000000e+001,9.999705e+000,8.517186e-007,4.020864e-008,-7.307287e-002,2.195797e-002,3,8.632302e-001,1.825000e+000,,,,,,,,,,,,,,,,,,0,4.000000e+000,1.500000e+000,2,2,5.014420e-003,0,,0,
1557480956.113,,1.000000e+001,9.999011e+000,8.307112e-007,3.556731e-008,-7.191034e-002,3.395903e-003,3,8.571432e-001,1.825000e+000,,,,,,,,,,,,,,,,,,0,4.000000e+000,1.500000e+000,2,2,1.494408e-003,0,,0,
1557480981.903,,1.000000e+001,9.998577e+000,8.130566e-007,1.491259e-008,-7.560100e-002,9.467457e-003,3,8.387818e-001,1.825000e+000,,,,,,,,,,,,,,,,,,0,4.000000e+000,1.500000e+000,2,2,4.003525e-003,0,,0,
1557481009.143,,1.000000e+001,9.999325e+000,8.395694e-007,2.347592e-008,-8.626427e-002,8.852408e-003,3,8.514783e-001,1.825000e+000,,,,,,,,,,,,,,,,,,0,4.000000e+000,1.500000e+000,2,2,5.502701e-003,0,,0,
1557481035.603,,1.000000e+001,1.000026e+001,8.122995e-007,3.118850e-008,-9.266194e-002,1.859844e-002,3,8.215172e-001,1.825000e+000,,,,,,,,,,,,,,,,,,0,4.000000e+000,1.500000e+000,2,2,3.756523e-003,0,,0,
1557481063.523,,1.000000e+001,9.999331e+000,8.290203e-007,4.746995e-009,-8.074895e-002,5.065988e-003,3,8.619245e-001,1.825000e+000,,,,,,,,,,,,,,,,,,0,4.000000e+000,1.500000e+000,2,2,7.512093e-003,0,,0,
1557481090.083,,1.000000e+001,1.000002e+001,8.265338e-007,1.490166e-008,-7.731543e-002,9.970959e-003,3,8.478791e-001,1.825000e+000,,,,,,,,,,,,,,,,,,0,4.000000e+000,1.500000e+000,2,2,5.265236e-003,0,,0,
1557481116.813,,1.000000e+001,9.999198e+000,8.214735e-007,1.855292e-008,-7.083397e-002,1.103158e-002,3,8.427309e-001,1.825000e+000,,,,,,,,,,,,,,,,,,0,4.000000e+000,1.500000e+000,2,2,2.494812e-003,0,,0,
1557481144.773,,1.000000e+001,9.999076e+000,7.980994e-007,7.010179e-009,-8.845302e-002,5.011645e-003,3,8.353139e-001,1.825000e+000,,,,,,,,,,,,,,,,,,0,4.000000e+000,1.500000e+000,2,2,2.755165e-003,0,,0,
1557481173.093,,1.000000e+001,1.000101e+001,8.298996e-007,9.772738e-009,-7.888342e-002,9.242399e-003,3,8.786385e-001,1.825000e+000,,,,,,,,,,,,,,,,,,0,4.000000e+000,1.500000e+000,2,2,3.256798e-003,0,,0,
1557481199.633,,1.000000e+001,9.999268e+000,8.253481e-007,1.982362e-008,-7.374755e-002,2.153146e-003,3,8.649099e-001,1.825000e+000,,,,,,,,,,,,,,,,,,0,4.000000e+000,1.500000e+000,2,2,7.500648e-003,0,,0,
1557481226.933,,1.000000e+001,9.999514e+000,8.136163e-007,3.945720e-009,-7.218575e-002,1.178134e-002,3,8.435641e-001,1.825000e+000,,,,,,,,,,,,,,,,,,0,4.000000e+000,1.500000e+000,2,2,4.255295e-003,0,,0,
1557481253.743,,1.000000e+001,9.999329e+000,8.500688e-007,1.956481e-008,-8.722480e-002,7.173019e-003,3,8.694186e-001,1.825000e+000,,,,,,,,,,,,,,,,,,0,4.000000e+000,1.500000e+000,2,2,5.002022e-003,0,,0,
1557481280.523,,1.000000e+001,1.000020e+001,8.257322e-007,1.708574e-008,-7.754406e-002,3.097199e-002,3,8.728354e-001,1.825000e+000,,,,,,,,,,,,,,,,,,0,4.000000e+000,1.500000e+000,2,2,7.581711e-004,0,,0,
1557481307.993,,1.000000e+001,9.998885e+000,8.131357e-007,2.767772e-008,-6.888834e-002,2.613090e-002,3,8.601809e-001,1.825000e+000,,,,,,,,,,,,,,,,,,0,4.000000e+000,1.500000e+000,2,2,2.243996e-003,0,,0,
1557481345.975,,1.000000e+001,1.000245e+001,8.588831e-007,6.390100e-009,-5.936106e-002,1.346354e-002,3,8.615476e-001,1.825000e+000,,,,,,,,,,,,,,,,,,0,4.000000e+000,1.500000e+000,2,2,4.509926e-003,0,,0,
1557481371.895,,1.000000e+001,1.000113e+001,8.502125e-007,4.877615e-008,-7.142198e-002,3.140528e-002,3,8.627958e-001,1.825000e+000,,,,,,,,,,,,,,,,,,0,4.000000e+000,1.500000e+000,2,2,2.259254e-003,0,,0,
1557481398.205,,1.000000e+001,9.999201e+000,8.419123e-007,9.153415e-008,-8.131386e-002,4.810310e-003,3,8.640850e-001,1.825000e+000,,,,,,,,,,,,,,,,,,0,4.000000e+000,1.500000e+000,2,2,3.504753e-003,0,,0,
1557481424.485,,1.000000e+001,9.999452e+000,8.697552e-007,6.005842e-009,-7.333395e-002,7.636793e-003,3,8.724473e-001,1.825000e+000,,,,,,,,,,,,,,,,,,0,4.000000e+000,1.500000e+000,2,2,4.505157e-003,0,,0,
1557481450.225,,1.000000e+001,9.999885e+000,8.499218e-007,5.276150e-008,-6.777134e-002,2.754086e-004,3,8.653766e-001,1.825000e+000,,,,,,,,,,,,,,,,,,0,4.000000e+000,1.500000e+000,2,2,9.975433e-004,0,,0,
1557481478.025,,1.000000e+001,9.999884e+000,8.170916e-007,5.439013e-008,-9.082896e-002,3.365623e-002,3,8.168861e-001,1.825000e+000,,,,,,,,,,,,,,,,,,0,4.000000e+000,1.500000e+000,2,2,1.247406e-003,0,,0,
1557481505.485,,1.000000e+001,9.999451e+000,8.591618e-007,6.759567e-009,-6.189146e-002,5.693842e-003,3,8.816367e-001,1.825000e+000,,,,,,,,,,,,,,,,,,0,4.000000e+000,1.500000e+000,2,2,4.505157e-003,0,,0,
1557481532.055,,1.000000e+001,9.999887e+000,8.478654e-007,6.299149e-008,-7.917212e-002,3.288045e-002,3,8.522177e-001,1.825000e+000,,,,,,,,,,,,,,,,,,0,4.000000e+000,1.500000e+000,2,2,3.754616e-003,0,,0,
1557481559.745,,1.000000e+001,9.999822e+000,8.049917e-007,4.401922e-008,-8.538122e-002,5.550008e-003,3,8.329688e-001,1.825000e+000,,,,,,,,,,,,,,,,,,0,4.000000e+000,1.500000e+000,2,2,1.497269e-003,0,,0,
1557481587.705,,1.000000e+001,9.998386e+000,8.828654e-007,5.663941e-008,-7.581930e-002,2.270573e-002,3,8.820051e-001,1.825000e+000,,,,,,,,,,,,,,,,,,0,4.000000e+000,1.500000e+000,2,2,4.742622e-003,0,,0,
1557481615.145,,1.000000e+001,9.999634e+000,8.186129e-007,1.266444e-008,-7.743075e-002,1.237431e-004,3,8.532604e-001,1.825000e+000,,,,,,,,,,,,,,,,,,0,4.000000e+000,1.500000e+000,2,2,7.467270e-004,0,,0,
1557481641.146,,1.000000e+001,9.998075e+000,8.472734e-007,2.690727e-008,-6.804359e-002,2.706842e-002,3,8.677209e-001,1.825000e+000,,,,,,,,,,,,,,,,,,0,4.000000e+000,1.500000e+000,2,2,4.242897e-003,0,,0,
1557481669.386,,1.000000e+001,9.999448e+000,8.126954e-007,4.034739e-008,-8.321200e-002,1.328811e-002,3,8.452960e-001,1.825000e+000,,,,,,,,,,,,,,,,,,0,4.000000e+000,1.500000e+000,2,2,3.495216e-003,0,,0,
1557481695.376,,1.000000e+001,9.999135e+000,8.539428e-007,5.670095e-008,-7.174316e-002,1.774025e-002,3,8.554798e-001,1.825000e+000,,,,,,,,,,,,,,,,,,0,4.000000e+000,1.500000e+000,2,2,1.745224e-003,0,,0,
1557481722.916,,1.000000e+001,9.999698e+000,8.640878e-007,9.249247e-009,-6.172869e-002,1.431252e-002,3,8.850662e-001,1.825000e+000,,,,,,,,,,,,,,,,,,0,4.000000e+000,1.500000e+000,2,2,2.495766e-003,0,,0,
1557481750.806,,1.000000e+001,1.000001e+001,7.917614e-007,2.876108e-009,-7.645562e-002,1.241109e-003,3,8.334961e-001,1.825000e+000,,,,,,,,,,,,,,,,,,0,4.000000e+000,1.500000e+000,2,2,3.746033e-003,0,,0,
1557481778.146,,1.000000e+001,9.999760e+000,8.284200e-007,5.087401e-009,-6.279875e-002,1.453822e-002,3,8.767900e-001,1.825000e+000,,,,,,,,,,,,,,,,,,0,4.000000e+000,1.500000e+000,2,2,3.245354e-003,0,,0,
1557481806.186,,1.000000e+001,9.998824e+000,8.619576e-007,7.097321e-009,-7.420368e-002,1.626476e-002,3,8.794279e-001,1.825000e+000,,,,,,,,,,,,,,,,,,0,4.000000e+000,1.500000e+000,2,2,3.993034e-003,0,,0,
1557481835.126,,1.000000e+001,1.000063e+001,8.280546e-007,3.177630e-008,-9.725972e-002,1.086425e-002,3,8.609905e-001,1.825000e+000,,,,,,,,,,,,,,,,,,0,4.000000e+000,1.500000e+000,2,2,2.747536e-003,0,,0,
1557481861.066,,1.000000e+001,9.999698e+000,8.694672e-007,2.974102e-009,-8.755016e-002,4.137187e-003,3,8.832735e-001,1.825000e+000,,,,,,,,,,,,,,,,,,0,4.000000e+000,1.500000e+000,2,2,5.244255e-003,0,,0,
1557481889.076,,1.000000e+001,1.000063e+001,8.961033e-007,4.454058e-009,-7.960225e-002,2.914571e-003,3,8.999244e-001,1.825000e+000,,,,,,,,,,,,,,,,,,0,4.000000e+000,1.500000e+000,2,2,7.495880e-004,0,,0,
1557481916.296,,1.000000e+001,9.999511e+000,8.389566e-007,5.754226e-009,-7.513805e-002,2.265676e-002,3,8.450434e-001,1.825000e+000,,,,,,,,,,,,,,,,,,0,4.000000e+000,1.500000e+000,2,2,3.495216e-003,0,,0,
1557481944.246,,1.000000e+001,1.000020e+001,8.279446e-007,3.108464e-008,-6.910939e-002,3.107336e-002,3,8.478346e-001,1.825000e+000,,,,,,,,,,,,,,,,,,0,4.000000e+000,1.500000e+000,2,2,4.495621e-003,0,,0,
1557481971.016,,1.000000e+001,1.000007e+001,8.537725e-007,6.749257e-008,-7.753791e-002,9.100927e-004,3,8.601494e-001,1.825000e+000,,,,,,,,,,,,,,,,,,0,4.000000e+000,1.500000e+000,2,2,7.486343e-004,0,,0,
1557481998.016,,1.000000e+001,1.000070e+001,7.781564e-007,3.038947e-008,-8.308852e-002,1.169023e-002,3,8.235471e-001,1.825000e+000,,,,,,,,,,,,,,,,,,0,4.000000e+000,1.500000e+000,2,2,2.497673e-003,0,,0,
1557482025.606,,1.000000e+001,9.999386e+000,8.081664e-007,6.556626e-009,-8.979097e-002,1.985813e-002,3,8.134055e-001,1.825000e+000,,,,,,,,,,,,,,,,,,0,4.000000e+000,1.500000e+000,2,2,4.493713e-003,0,,0,
1557482052.596,,1.000000e+001,9.999572e+000,8.344552e-007,4.722661e-008,-7.792500e-002,5.920937e-003,3,8.657404e-001,1.825000e+000,,,,,,,,,,,,,,,,,,0,4.000000e+000,1.500000e+000,2,2,3.245354e-003,0,,0,
1557482081.536,,1.000000e+001,9.998701e+000,8.334360e-007,1.164664e-008,-7.364216e-002,1.453126e-002,3,9.017584e-001,1.825000e+000,,,,,,,,,,,,,,,,,,0,4.000000e+000,1.500000e+000,2,2,7.987976e-003,0,,0,
1557482108.546,,1.000000e+001,1.000113e+001,8.579507e-007,2.095875e-008,-6.995173e-002,9.084310e-003,3,8.943492e-001,1.825000e+000,,,,,,,,,,,,,,,,,,0,4.000000e+000,1.500000e+000,2,2,2.750397e-003,0,,0,
1557482135.986,,1.000000e+001,9.999510e+000,8.577979e-007,8.514614e-009,-7.681333e-002,5.626931e-003,3,8.913910e-001,1.825000e+000,,,,,,,,,,,,,,,,,,0,4.000000e+000,1.500000e+000,2,2,2.993584e-003,0,,0,
1557482163.316,,1.000000e+001,1.000020e+001,8.322127e-007,6.078823e-008,-7.706745e-002,1.493861e-002,3,8.634150e-001,1.825000e+000,,,,,,,,,,,,,,,,,,0,4.000000e+000,1.500000e+000,2,2,4.494667e-003,0,,0,
1557482189.546,,1.000000e+001,1.000032e+001,8.440768e-007,1.931094e-008,-8.310464e-002,1.430686e-002,3,8.521947e-001,1.825000e+000,,,,,,,,,,,,,,,,,,0,4.000000e+000,1.500000e+000,2,2,2.747536e-003,0,,0,
1557482218.026,,1.000000e+001,1.000088e+001,8.669572e-007,1.268233e-008,-6.653075e-002,1.884735e-002,3,8.657323e-001,1.825000e+000,,,,,,,,,,,,,,,,,,0,4.000000e+000,1.500000e+000,2,2,2.248764e-003,0,,0,
1557482244.276,,1.000000e+001,9.999262e+000,8.007401e-007,5.280772e-008,-7.393274e-002,1.082257e-002,3,8.602690e-001,1.825000e+000,,,,,,,,,,,,,,,,,,0,4.000000e+000,1.500000e+000,2,2,6.492615e-003,0,,0,
1557482271.546,,1.000000e+001,1.000038e+001,8.475614e-007,1.370620e-008,-8.338593e-002,2.768669e-003,3,8.774570e-001,1.825000e+000,,,,,,,,,,,,,,,,,,0,4.000000e+000,1.500000e+000,2,2,4.745483e-003,0,,0,
1557482300.736,,1.000000e+001,9.999760e+000,8.349106e-007,1.002769e-009,-7.031402e-002,1.353003e-002,3,8.751712e-001,1.825000e+000,,,,,,,,,,,,,,,,,,0,4.000000e+000,1.500000e+000,2,2,3.746033e-003,0,,0,
1557482329.056,,1.000000e+001,9.999136e+000,8.511515e-007,3.894151e-009,-6.902307e-002,7.258926e-003,3,8.636161e-001,1.825000e+000,,,,,,,,,,,,,,,,,,0,4.000000e+000,1.500000e+000,2,2,6.992340e-003,0,,0,
1557482358.027,,1.000000e+001,1.000063e+001,8.480319e-007,1.657318e-008,-9.848374e-002,1.894791e-003,3,8.752041e-001,1.825000e+000,,,,,,,,,,,,,,,,,,0,4.000000e+000,1.500000e+000,2,2,3.746033e-003,0,,0,
1557482385.027,,1.000000e+001,1.000076e+001,8.593944e-007,1.367071e-008,-8.002266e-002,1.427662e-002,3,8.906829e-001,1.825000e+000,,,,,,,,,,,,,,,,,,0,4.000000e+000,1.500000e+000,2,2,2.246857e-003,0,,0,
1557482412.717,,1.000000e+001,9.999137e+000,8.232749e-007,1.244020e-008,-7.641359e-002,2.092675e-002,3,8.512932e-001,1.825000e+000,,,,,,,,,,,,,,,,,,0,4.000000e+000,1.500000e+000,2,2,5.743027e-003,0,,0,
1557482440.057,,1.000000e+001,9.998886e+000,8.317813e-007,1.022866e-009,-6.186266e-002,6.237373e-003,3,8.751751e-001,1.825000e+000,,,,,,,,,,,,,,,,,,0,4.000000e+000,1.500000e+000,2,2,4.491806e-003,0,,0,
1557482465.837,,1.000000e+001,9.999511e+000,7.971329e-007,2.124007e-008,-8.250442e-002,2.171806e-002,3,7.944107e-001,1.825000e+000,,,,,,,,,,,,,,,,,,0,4.000000e+000,1.500000e+000,2,2,5.243301e-003,0,,0,
1557482491.337,,1.000000e+001,9.998387e+000,8.890660e-007,1.709229e-008,-6.081030e-002,1.953118e-002,3,8.931293e-001,1.825000e+000,,,,,,,,,,,,,,,,,,0,4.000000e+000,1.500000e+000,2,2,4.242897e-003,0,,0,
1557482518.037,,1.000000e+001,9.999947e+000,8.368385e-007,3.291030e-008,-5.866714e-002,8.328086e-003,3,8.799117e-001,1.825000e+000,,,,,,,,,,,,,,,,,,0,4.000000e+000,1.500000e+000,2,2,2.745628e-003,0,,0,
1557482544.797,,1.000000e+001,9.998575e+000,8.176464e-007,1.729925e-008,-8.371381e-002,9.137568e-003,3,8.499081e-001,1.825000e+000,,,,,,,,,,,,,,,,,,0,4.000000e+000,1.500000e+000,2,2,1.996040e-003,0,,0,
1557482571.887,,1.000000e+001,1.000045e+001,8.446212e-007,1.772797e-008,-7.623246e-002,2.027912e-002,3,8.611283e-001,1.825000e+000,,,,,,,,,,,,,,,,,,0,4.000000e+000,1.500000e+000,2,2,4.245758e-003,0,,0,
1557482598.137,,1.000000e+001,9.999385e+000,7.992845e-007,2.382650e-008,-8.254549e-002,5.175111e-003,3,8.552512e-001,1.825000e+000,,,,,,,,,,,,,,,,,,0,4.000000e+000,1.500000e+000,2,2,3.993988e-003,0,,0,
1557482624.907,,1.000000e+001,9.999886e+000,8.374070e-007,1.322298e-008,-6.462976e-002,1.097014e-003,3,8.795459e-001,1.825000e+000,,,,,,,,,,,,,,,,,,0,4.000000e+000,1.500000e+000,2,2,6.241798e-003,0,,0,
1557482651.187,,1.000000e+001,9.999573e+000,8.526666e-007,3.238931e-008,-8.322334e-002,1.939636e-002,3,8.551515e-001,1.825000e+000,,,,,,,,,,,,,,,,,,0,4.000000e+000,1.500000e+000,2,2,4.995346e-003,0,,0,
1557482676.627,,1.000000e+001,1.000051e+001,8.354243e-007,2.615391e-008,-7.923785e-002,4.598859e-003,3,8.693067e-001,1.825000e+000,,,,,,,,,,,,,,,,,,0,4.000000e+000,1.500000e+000,2,2,3.746986e-003,0,,0,
1557482850.957,,1.000000e+001,1.000195e+001,8.553877e-007,1.477171e-008,-8.126128e-002,5.019684e-003,3,8.849443e-001,1.825000e+000,,,,,,,,,,,,,,,,,,0,4.000000e+000,1.500000e+000,2,2,3.499985e-003,0,,0,
1557482900.137,,1.000000e+001,9.302010e+000,8.363428e-007,3.433523e-009,-7.729660e-002,5.631730e-003,3,8.729336e-001,1.825000e+000,,,,,,,,,,,,,,,,,,0,4.000000e+000,1.500000e+000,2,2,4.228687e-002,0,,0,
1557482926.017,,1.000000e+001,9.212824e+000,8.100944e-007,4.023537e-009,-8.478433e-002,3.687075e-003,3,8.764687e-001,1.825000e+000,,,,,,,,,,,,,,,,,,0,4.000000e+000,1.500000e+000,2,2,6.081581e-002,0,,0,
1557482951.257,,1.000000e+001,9.014095e+000,8.727255e-007,5.575722e-008,-7.581248e-002,3.054188e-002,3,8.879355e-001,1.825000e+000,,,,,,,,,,,,,,,,,,0,4.000000e+000,1.500000e+000,2,2,1.042652e-001,0,,0,
1557482979.197,,1.000000e+001,8.772894e+000,8.497996e-007,2.237500e-009,-8.247071e-002,8.463509e-004,3,8.663796e-001,1.825000e+000,,,,,,,,,,,,,,,,,,0,4.000000e+000,1.500000e+000,2,2,9.107876e-002,0,,0,
1557483008.137,,1.000000e+001,8.531099e+000,8.516905e-007,1.749315e-008,-6.693329e-002,5.741491e-003,3,8.660455e-001,1.825000e+000,,,,,,,,,,,,,,,,,,0,4.000000e+000,1.500000e+000,2,2,8.268261e-002,0,,0,
1557483035.377,,1.000000e+001,8.306253e+000,8.403007e-007,4.905783e-008,-7.411167e-002,1.251986e-002,3,8.568192e-001,1.825000e+000,,,,,,,,,,,,,,,,,,0,4.000000e+000,1.500000e+000,2,2,8.067131e-002,0,,0,
1557483062.408,,1.000000e+001,8.089336e+000,8.356855e-007,9.805898e-009,-7.966820e-002,1.225698e-002,3,8.665863e-001,1.825000e+000,,,,,,,,,,,,,,,,,,0,4.000000e+000,1.500000e+000,2,2,8.357620e-002,0,,0,
1557483092.168,,1.000000e+001,7.855464e+000,8.345115e-007,2.894396e-008,-6.585678e-002,4.642264e-003,3,8.701273e-001,1.825000e+000,,,,,,,,,,,,,,,,,,0,4.000000e+000,1.500000e+000,2,2,8.654737e-002,0,,0,
1557483119.938,,1.000000e+001,7.648958e+000,8.276676e-007,1.154294e-008,-8.621988e-002,1.166312e-002,3,8.801705e-001,1.825000e+000,,,,,,,,,,,,,,,,,,0,4.000000e+000,1.500000e+000,2,2,8.491182e-002,0,,0,
1557483146.968,,1.000000e+001,7.421543e+000,8.595623e-007,1.493345e-008,-7.828556e-002,1.682136e-002,3,8.789545e-001,1.825000e+000,,,,,,,,,,,,,,,,,,0,4.000000e+000,1.500000e+000,2,2,9.591293e-002,0,,0,
1557483174.238,,1.000000e+001,7.201714e+000,8.567780e-007,1.800535e-008,-6.893513e-002,5.093747e-003,3,8.751172e-001,1.825000e+000,,,,,,,,,,,,,,,,,,0,4.000000e+000,1.500000e+000,2,2,9.753704e-002,0,,0,
1557483201.768,,1.000000e+001,6.976594e+000,8.799071e-007,1.974733e-008,-6.339499e-002,1.565872e-002,3,9.028223e-001,1.825000e+000,,,,,,,,,,,,,,,,,,0,4.000000e+000,1.500000e+000,2,2,9.848595e-002,0,,0,
1557483229.458,,1.000000e+001,6.753581e+000,8.346194e-007,4.048674e-008,-8.839138e-002,1.132022e-003,3,8.900098e-001,1.825000e+000,,,,,,,,,,,,,,,,,,0,4.000000e+000,1.500000e+000,2,2,9.746027e-002,0,,0,
1557483258.248,,1.000000e+001,6.578282e+000,8.466649e-007,1.506589e-008,-7.669304e-002,8.387292e-003,3,8.800884e-001,1.825000e+000,,,,,,,,,,,,,,,,,,0,4.000000e+000,1.500000e+000,2,2,9.191227e-002,0,,0,
1557483286.688,,1.000000e+001,6.354476e+000,8.379718e-007,7.265373e-009,-6.634568e-002,1.085544e-002,3,8.646944e-001,1.825000e+000,,,,,,,,,,,,,,,,,,0,4.000000e+000,1.500000e+000,2,2,1.076531e-001,0,,0,
1557483315.878,,1.000000e+001,6.105679e+000,8.198662e-007,1.127673e-008,-8.545841e-002,9.400181e-003,3,8.579240e-001,1.825000e+000,,,,,,,,,,,,,,,,,,0,4.000000e+000,1.500000e+000,2,2,9.594774e-002,0,,0,
1557483346.098,,1.000000e+001,5.859714e+000,8.313625e-007,1.037702e-008,-8.619574e-002,1.157603e-002,3,8.608843e-001,1.825000e+000,,,,,,,,,,,,,,,,,,0,4.000000e+000,1.500000e+000,2,2,9.427309e-002,0,,0,
1557483374.858,,1.000000e+001,5.641433e+000,8.001865e-007,6.116855e-008,-7.408784e-002,4.843716e-003,3,8.611148e-001,1.825000e+000,,,,,,,,,,,,,,,,,,0,4.000000e+000,1.500000e+000,2,2,8.560324e-002,0,,0,
1557483403.548,,1.000000e+001,5.396355e+000,8.430160e-007,8.341698e-009,-7.160354e-002,1.037476e-003,3,8.872942e-001,1.825000e+000,,,,,,,,,,,,,,,,,,0,4.000000e+000,1.500000e+000,2,2,1.070142e-001,0,,0,
1557483433.028,,1.000000e+001,5.152376e+000,8.443138e-007,1.087716e-008,-8.269882e-002,3.415739e-004,3,8.765837e-001,1.825000e+000,,,,,,,,,,,,,,,,,,0,4.000000e+000,1.500000e+000,2,2,1.063581e-001,0,,0,
1557483461.488,,1.000000e+001,4.908178e+000,8.480672e-007,2.114557e-008,-7.813336e-002,3.528002e-003,3,8.918171e-001,1.825000e+000,,,,,,,,,,,,,,,,,,0,4.000000e+000,1.500000e+000,2,2,8.925390e-002,0,,0,
1557483488.928,,1.000000e+001,4.681630e+000,8.649862e-007,9.141806e-009,-7.951725e-002,8.845464e-003,3,8.900170e-001,1.825000e+000,,,,,,,,,,,,,,,,,,0,4.000000e+000,1.500000e+000,2,2,9.991217e-002,0,,0,
1557483518.168,,1.000000e+001,4.436554e+000,8.286318e-007,1.678621e-008,-8.059987e-002,9.315075e-003,3,8.688858e-001,1.825000e+000,,,,,,,,,,,,,,,,,,0,4.000000e+000,1.500000e+000,2,2,9.115934e-002,0,,0,
1557483546.988,,1.000000e+001,4.099906e+000,8.104494e-007,3.145410e-009,-8.889911e-002,5.415312e-003,3,8.687931e-001,1.825000e+000,,,,,,,,,,,,,,,,,,0,4.000000e+000,1.500000e+000,2,2,2.064757e-001,0,,0,
1557483575.918,,1.000000e+001,3.960534e+000,8.478268e-007,1.820447e-008,-7.385099e-002,1.300968e-003,3,8.731861e-001,1.825000e+000,,,,,,,,,,,,,,,,,,0,4.000000e+000,1.500000e+000,2,2,1.824212e-001,0,,0,
1557483604.988,,1.000000e+001,3.732914e+000,8.444987e-007,1.512418e-008,-6.707457e-002,1.424052e-002,3,8.768157e-001,1.825000e+000,,,,,,,,,,,,,,,,,,0,4.000000e+000,1.500000e+000,2,2,9.403586e-002,0,,0,
1557483632.728,,1.000000e+001,3.508113e+000,8.344574e-007,2.790397e-008,-7.774422e-002,1.992468e-002,3,8.712653e-001,1.825000e+000,,,,,,,,,,,,,,,,,,0,4.000000e+000,1.500000e+000,2,2,9.844613e-002,0,,0,
1557483661.918,,1.000000e+001,3.257532e+000,8.511109e-007,4.621347e-009,-6.426692e-002,1.781521e-003,3,8.707702e-001,1.825000e+000,,,,,,,,,,,,,,,,,,0,4.000000e+000,1.500000e+000,2,2,9.741712e-002,0,,0,
1557483691.418,,1.000000e+001,3.014554e+000,8.716709e-007,2.189725e-008,-7.118684e-002,1.396824e-002,3,8.707467e-001,1.825000e+000,,,,,,,,,,,,,,,,,,0,4.000000e+000,1.500000e+000,2,2,8.776188e-002,0,,0,
1557483720.608,,1.000000e+001,2.773204e+000,8.258850e-007,6.685650e-009,-6.179511e-002,1.874049e-003,3,8.560458e-001,1.825000e+000,,,,,,,,,,,,,,,,,,0,4.000000e+000,1.500000e+000,2,2,9.419107e-002,0,,0,
1557483750.368,,1.000000e+001,2.534049e+000,8.427169e-007,4.285765e-009,-8.240287e-002,9.189135e-003,3,8.823527e-001,1.825000e+000,,,,,,,,,,,,,,,,,,0,4.000000e+000,1.500000e+000,2,2,8.762383e-002,0,,0,
1557483780.839,,1.000000e+001,2.300407e+000,8.433574e-007,5.766083e-009,-8.531075e-002,1.146089e-003,3,8.573565e-001,1.825000e+000,,,,,,,,,,,,,,,,,,0,4.000000e+000,1.500000e+000,2,2,8.673906e-002,0,,0,
1557483809.309,,1.000000e+001,2.110888e+000,8.355282e-007,1.580740e-008,-8.100376e-002,2.801322e-003,3,8.608123e-001,1.825000e+000,,,,,,,,,,,,,,,,,,0,4.000000e+000,1.500000e+000,2,2,6.068301e-002,0,,0,
1557483956.689,,1.000000e+001,1.876763e+000,8.389660e-007,3.103206e-009,-7.157128e-002,2.362895e-003,3,8.729314e-001,1.825000e+000,,,,,,,,,,,,,,,,,,0,4.000000e+000,1.500000e+000,2,2,1.578010e-001,0,,0,
1557483985.779,,1.000000e+001,1.809102e+000,8.359160e-007,3.953960e-009,-5.483171e-002,1.573598e-002,3,8.760519e-001,1.825000e+000,,,,,,,,,,,,,,,,,,0,4.000000e+000,1.500000e+000,2,2,5.869865e-004,0,,0,
1557484014.009,,1.000000e+001,1.807863e+000,8.394666e-007,2.933787e-009,-8.111995e-002,2.671887e-002,3,8.619771e-001,1.825000e+000,,,,,,,,,,,,,,,,,,0,4.000000e+000,1.500000e+000,2,2,1.313925e-003,0,,0,
1557484041.509,,1.000000e+001,1.808049e+000,8.397181e-007,3.808698e-008,-6.706012e-002,5.915774e-003,3,8.783005e-001,1.825000e+000,,,,,,,,,,,,,,,,,,0,4.000000e+000,1.500000e+000,2,2,2.839565e-004,0,,0,
1557484069.509,,1.000000e+001,1.807491e+000,8.491612e-007,3.154510e-008,-8.368994e-002,2.323419e-003,3,8.647465e-001,1.825000e+000,,,,,,,,,,,,,,,,,,0,4.000000e+000,1.500000e+000,2,2,1.738071e-003,0,,0,
1557484097.969,,1.000000e+001,1.807216e+000,8.486163e-007,2.296759e-008,-7.199033e-002,1.569644e-002,3,8.649465e-001,1.825000e+000,,,,,,,,,,,,,,,,,,0,4.000000e+000,1.500000e+000,2,2,6.209612e-004,0,,0,
1557484123.729,,1.000000e+001,1.806291e+000,8.480351e-007,0.000000e+000,-8.347394e-002,0.000000e+000,3,8.459837e-001,1.825000e+000,,,,,,,,,,,,,,,,,,0,4.000000e+000,1.500000e+000,2,1,1.184940e-003,0,,0,
1557484393.969,,5.000000e+001,1.930948e+000,1.430068e-006,6.159063e-009,-4.739525e-002,1.292573e-002,3,9.184409e-001,1.825000e+000,,,,,,,,,,,,,,,,,,0,4.000000e+000,1.500000e+000,2,2,5.654693e-002,0,,0,
1557484431.409,,5.000000e+001,2.179704e+000,1.439943e-006,3.483565e-009,-3.822089e-002,4.570878e-003,3,9.212864e-001,1.825000e+000,,,,,,,,,,,,,,,,,,0,4.000000e+000,1.500000e+000,2,2,1.266210e-001,0,,0,
1557484458.159,,5.000000e+001,2.479564e+000,1.437074e-006,1.383876e-008,-4.045603e-002,2.146889e-003,3,9.191552e-001,1.825000e+000,,,,,,,,,,,,,,,,,,0,4.000000e+000,1.500000e+000,2,2,1.159470e-001,0,,0,
1557484485.650,,5.000000e+001,2.741154e+000,1.428710e-006,1.526952e-008,-4.273056e-002,1.251190e-003,3,9.136885e-001,1.825000e+000,,,,,,,,,,,,,,,,,,0,4.000000e+000,1.500000e+000,2,2,9.896016e-002,0,,0,
1557484514.130,,5.000000e+001,2.958705e+000,1.430333e-006,1.061179e-008,-4.089661e-002,1.240882e-002,3,9.201731e-001,1.825000e+000,,,,,,,,,,,,,,,,,,0,4.000000e+000,1.500000e+000,2,2,8.419013e-002,0,,0,
1557484543.360,,5.000000e+001,3.188814e+000,1.422630e-006,1.286911e-008,-4.258564e-002,1.547349e-002,3,9.010227e-001,1.825000e+000,,,,,,,,,,,,,,,,,,0,4.000000e+000,1.500000e+000,2,2,8.023691e-002,0,,0,
1557484572.670,,5.000000e+001,3.402547e+000,1.418853e-006,9.920533e-009,-4.264297e-002,1.310659e-002,3,9.054993e-001,1.825000e+000,,,,,,,,,,,,,,,,,,0,4.000000e+000,1.500000e+000,2,2,7.485890e-002,0,,0,
1557484600.660,,5.000000e+001,3.602509e+000,1.429054e-006,1.098809e-008,-3.793631e-002,8.156627e-004,3,9.014279e-001,1.825000e+000,,,,,,,,,,,,,,,,,,0,4.000000e+000,1.500000e+000,2,2,9.518409e-002,0,,0,
1557484630.160,,5.000000e+001,3.806089e+000,1.417128e-006,7.129838e-009,-4.904483e-002,1.649133e-002,3,8.929363e-001,1.825000e+000,,,,,,,,,,,,,,,,,,0,4.000000e+000,1.500000e+000,2,2,1.016750e-001,0,,0,
1557484660.660,,5.000000e+001,4.039593e+000,1.404691e-006,3.055520e-008,-4.986407e-002,1.716575e-003,3,8.996798e-001,1.825000e+000,,,,,,,,,,,,,,,,,,0,4.000000e+000,1.500000e+000,2,2,1.595070e-001,0,,0,
1557484687.480,,5.000000e+001,4.426607e+000,1.420961e-006,2.852490e-008,-3.589250e-002,1.288960e-002,3,9.073099e-001,1.825000e+000,,,,,,,,,,,,,,,,,,0,4.000000e+000,1.500000e+000,2,2,5.665779e-002,0,,0,
1557484714.780,,5.000000e+001,4.650527e+000,1.438804e-006,5.545150e-008,-4.014987e-002,6.939671e-003,3,9.027464e-001,1.825000e+000,,,,,,,,,,,,,,,,,,0,4.000000e+000,1.500000e+000,2,2,8.644009e-002,0,,0,
1557484742.740,,5.000000e+001,4.889830e+000,1.419045e-006,1.216563e-008,-3.068792e-002,1.300890e-003,3,8.894954e-001,1.825000e+000,,,,,,,,,,,,,,,,,,0,4.000000e+000,1.500000e+000,2,2,9.172440e-002,0,,0,
1557484828.460,,5.000000e+001,5.003731e+000,1.439213e-006,1.467094e-008,-3.716867e-002,2.259479e-003,3,9.082152e-001,1.825000e+000,,,,,,,,,,,,,,,,,,0,4.000000e+000,1.500000e+000,2,2,2.034187e-003,0,,0,
1557484854.710,,5.000000e+001,5.002624e+000,1.421322e-006,1.672126e-008,-4.219405e-002,9.603704e-003,3,8.959148e-001,1.825000e+000,,,,,,,,,,,,,,,,,,0,4.000000e+000,1.500000e+000,2,2,1.014709e-003,0,,0,
1557484881.980,,5.000000e+001,5.000962e+000,1.409157e-006,1.123215e-008,-4.250508e-002,1.080540e-005,3,8.837678e-001,1.825000e+000,,,,,,,,,,,,,,,,,,0,4.000000e+000,1.500000e+000,2,2,1.939297e-003,0,,0,
1557484895.740,,5.000000e+001,5.000731e+000,1.394652e-006,1.016355e-008,-3.876126e-002,7.677117e-003,3,8.914582e-001,1.825000e+000,,,,,,,,,,,,,,,,,,0,4.000000e+000,1.500000e+000,2,2,1.107216e-003,0,,0,