File: 研究/抵抗測定/PPMS/180709_IrTe2_2.csv
[Header]
TITLE, default name
FILEOPENTIME,16338096.00,7/9/2018,7:33 PM
BYAPP, Resistivity, 2.1, 1.0
INFO, APPNAME, PPMS MultiVu Application, 1.5.11
INFO, , Sample1 Name
INFO, 1, Sample1 Cross Section
INFO, 1, Sample1 Length
INFO, Ohm-m, Sample1 Units
INFO, , Sample2 Name
INFO, 1, Sample2 Cross Section
INFO, 1, Sample2 Length
INFO, Ohm-m, Sample2 Units
INFO, , Sample3 Name
INFO, 1, Sample3 Cross Section
INFO, 1, Sample3 Length
INFO, Ohm-m, Sample3 Units
INFO, , Sample4 Name
INFO, 1, Sample4 Cross Section
INFO, 1, Sample4 Length
INFO, Ohm-m, Sample4 Units
FIELDGROUP, Resistivity,2,3,4,5,6,7,8,9,10,11,12,13,14,15,16,17,18,19,20,21,22,23,24,25,26,27,28,29,30,31,32,33,34,35,36,37,38,39,40,41
STARTUPGROUP, Resistivity
STARTUPAXIS, X, 2, LINEAR, AUTO
STARTUPAXIS, Y1, 7, LINEAR, AUTO
STARTUPAXIS, Y2, 9, LINEAR, AUTO
STARTUPAXIS, Y3, 11, LINEAR, AUTO
PLOT_APPEARANCE, ALL, HORZ_GRID_ON, VERT_GRID_ON, MARKERS_AND_LINES, ALL_LINES
DATATYPE, TIME, 2
DATATYPE, COMMENT, 1
[Data]
Comment,Time Stamp (sec),Status (code),Temperature (K),Magnetic Field (Oe),Sample Position (deg),Bridge 1 Resistivity (Ohm-m),Bridge 1 Excitation (uA),Bridge 2 Resistivity (Ohm-m),Bridge 2 Excitation (uA),Bridge 3 Resistivity (Ohm-m),Bridge 3 Excitation (uA),Bridge 4 Resistivity (Ohm-m),Bridge 4 Excitation (uA),Bridge 1 Std. Dev. (Ohm-m),Bridge 2 Std. Dev. (Ohm-m),Bridge 3 Std. Dev. (Ohm-m),Bridge 4 Std. Dev. (Ohm-m),Number of Readings,Bridge 1 Resistance (Ohms),Bridge 2 Resistance (Ohms),Bridge 3 Resistance (Ohms),Bridge 4 Resistance (Ohms),Signal 1 Vin (V),Signal 2 Vin (V),Digital Inputs (code),Drive 1 Iout (mA),Drive 1 Ipower (watts),Drive 2 Iout (mA),Drive 2 Ipower (watts),Pressure (),Map 20 (),Map 21 (),Map 22 (),Map 23 (),Map 24 (),Map 25 (),Map 26 (),Map 27 (),Map 28 (),Map 29 ()
,16338284.50,4370,299.997039794922,-0.0656490027904511,0,2.77684257924557e-005,99.9020004272461,,,,,,,2.22983655685995e-007,,,,25,0.0277684257924557,,,
,16338348.20,4370,302.145706176758,-0.0656490027904511,0,2.79364369809627e-005,99.9020004272461,,,,,,,2.6251738403498e-007,,,,25,0.0279364369809628,,,
,16338411.50,4370,304.281402587891,-0.0656490027904511,0,2.80761916190386e-005,99.9020004272461,,,,,,,2.59657864795043e-007,,,,25,0.0280761916190386,,,
,16338472.50,4370,306.318740844727,-0.0656490027904511,0,2.82503122091293e-005,99.9020004272461,,,,,,,2.23025008155284e-007,,,,25,0.0282503122091293,,,
,16338535.09,4370,308.409698486328,-0.0656490027904511,0,2.83717383444309e-005,99.9020004272461,,,,,,,1.73432218630356e-007,,,,25,0.0283717383444309,,,
,16338597.28,4370,310.488998413086,-0.0656490027904511,0,2.86420834809542e-005,99.9020004272461,,,,,,,2.07745767343503e-007,,,,25,0.0286420834809542,,,
,16338658.20,4370,312.528839111328,-0.0656490027904511,0,2.87566367536783e-005,99.9020004272461,,,,,,,2.31197141009195e-007,,,,25,0.0287566367536783,,,
,16338719.73,4370,314.584396362305,-0.0656490027904511,0,2.89383947849274e-005,99.9020004272461,,,,,,,2.14617007592426e-007,,,,25,0.0289383947849274,,,
,16338783.23,4370,316.698257446289,-0.0656490027904511,0,2.91361898183823e-005,99.9020004272461,,,,,,,2.06542938136766e-007,,,,25,0.0291361898183823,,,
,16338845.50,4370,318.769302368164,-0.0656490027904511,0,2.92820538580418e-005,99.9020004272461,,,,,,,2.13252832523012e-007,,,,25,0.0292820538580418,,,
,16338909.59,4370,320.915756225586,-0.0656490027904511,0,2.94500646740198e-005,99.9020004272461,,,,,,,2.45220436005617e-007,,,,25,0.0294500646740198,,,
,16338971.75,4370,322.997253417969,-0.0656490027904511,0,2.96325854957104e-005,99.9020004272461,,,,,,,2.85639335169772e-007,,,,25,0.0296325854957104,,,
,16339035.33,4370,325.112594604492,-0.0656490027904511,0,2.9796778485179e-005,99.9020004272461,,,,,,,2.47211055738156e-007,,,,25,0.0297967784851789,,,
,16339099.45,4370,327.253051757813,-0.0656490027904511,0,3.00793432444334e-005,99.9020004272461,,,,,,,2.37181535624186e-007,,,,25,0.0300793432444334,,,
,16339161.36,4370,329.316146850586,-0.0656490027904511,0,3.02000058442354e-005,99.9020004272461,,,,,,,2.44439469634697e-007,,,,25,0.0302000058442354,,,
,16339225.45,4370,331.454040527344,-0.0656490027904511,0,3.04390396922827e-005,99.9020004272461,,,,,,,2.0891482796999e-007,,,,25,0.0304390396922827,,,
,16339288.38,4370,333.548004150391,-0.0656490027904511,0,3.05688662081957e-005,99.9020004272461,,,,,,,2.29380498020852e-007,,,,25,0.0305688662081957,,,
,16339351.47,4370,335.653594970703,-0.0656490027904511,0,3.07720062881708e-005,99.9020004272461,,,,,,,2.05435699918444e-007,,,,25,0.0307720062881708,,,
,16339414.31,4370,337.760803222656,-0.0656490027904511,0,3.08819769322872e-005,99.9020004272461,,,,,,,2.09709331227318e-007,,,,25,0.0308819769322872,,,
,16339476.17,4370,339.818939208984,-0.0656490027904511,0,3.11149017512798e-005,99.9020004272461,,,,,,,2.6567768032218e-007,,,,25,0.0311149017512798,,,
,16339537.48,4370,341.851913452148,-0.0656490027904511,0,3.12432014942169e-005,99.9020004272461,,,,,,,1.81372317579717e-007,,,,25,0.0312432014942169,,,
,16339598.81,4370,343.920761108398,-0.0656490027904511,0,3.12363282591104e-005,99.9020004272461,,,,,,,2.28464551181487e-007,,,,25,0.0312363282591104,,,
,16339661.53,4370,346.020050048828,-0.0656490027904511,0,3.13997575640678e-005,99.9020004272461,,,,,,,2.31315864643505e-007,,,,25,0.0313997575640678,,,
,16339722.61,4370,348.04460144043,-0.0656490027904511,0,3.15265307575464e-005,99.9020004272461,,,,,,,2.74955488867135e-007,,,,25,0.0315265307575464,,,
,16339784.77,4370,350.081253051758,-0.0656490027904511,0,3.16922508180142e-005,99.9020004272461,,,,,,,2.25286505236948e-007,,,,25,0.0316922508180141,,,
,16339925.89,4370,349.261505126953,-0.0656490027904511,0,3.17854204028845e-005,99.9020004272461,,,,,,,3.00745163080345e-007,,,,25,0.0317854204028845,,,
,16339986.36,4370,347.029251098633,-0.0656490027904511,0,3.16105362772942e-005,99.9020004272461,,,,,,,2.25043705503989e-007,,,,25,0.0316105362772942,,,
,16340049.83,4370,344.857055664063,-0.0656490027904511,0,3.13860116153955e-005,99.9020004272461,,,,,,,1.98333342382198e-007,,,,25,0.0313860116153955,,,
,16340113.30,4370,342.874359130859,-0.0656490027904511,0,3.11133743077517e-005,99.9020004272461,,,,,,,2.2647456583295e-007,,,,25,0.0311133743077517,,,
,16340175.88,4370,340.770843505859,-0.0656490027904511,0,3.10263136774301e-005,99.9020004272461,,,,,,,1.87681051158708e-007,,,,25,0.0310263136774302,,,
,16340240.31,4370,338.594802856445,-0.0656490027904511,0,3.07468046993017e-005,99.9020004272461,,,,,,,1.78943862489833e-007,,,,25,0.0307468046993017,,,
,16340302.44,4370,336.526504516602,-0.0656490027904511,0,3.07353492826223e-005,99.9020004272461,,,,,,,1.88668718307989e-007,,,,25,0.0307353492826223,,,
,16340364.69,4370,334.435546875,-0.0656490027904511,0,3.05016616731882e-005,99.9020004272461,,,,,,,2.74023707353189e-007,,,,25,0.0305016616731882,,,
,16340427.16,4370,332.364944458008,-0.0656490027904511,0,3.02832476049662e-005,99.9020004272461,,,,,,,3.01132917082548e-007,,,,25,0.0302832476049662,,,
,16340488.45,4370,330.310211181641,-0.0656490027904511,0,3.00373405963182e-005,99.9020004272461,,,,,,,1.97714537593887e-007,,,,25,0.0300373405963182,,,
,16340550.34,4370,328.230407714844,-0.0656490027904511,0,2.99640264362097e-005,99.9020004272461,,,,,,,2.1212716709677e-007,,,,25,0.0299640264362097,,,
,16340612.44,4370,326.165893554688,-0.0656490027904511,0,2.98143432289362e-005,99.9020004272461,,,,,,,2.73225536693361e-007,,,,25,0.0298143432289362,,,
,16340674.19,4370,324.100494384766,-0.0656490027904511,0,2.96890982240439e-005,99.9020004272461,,,,,,,2.31352908870135e-007,,,,25,0.0296890982240438,,,
,16340736.92,4370,321.971496582031,-0.0656490027904511,0,2.93546038866043e-005,99.9020004272461,,,,,,,2.36133066025163e-007,,,,25,0.0293546038866043,,,
,16340800.19,4370,319.889099121094,-0.0656490027904511,0,2.92927452176809e-005,99.9020004272461,,,,,,,2.72664822278189e-007,,,,25,0.0292927452176809,,,
,16340862.72,4370,317.800155639648,-0.0656490027904511,0,2.91025874018669e-005,99.9020004272461,,,,,,,2.83836813874204e-007,,,,25,0.0291025874018669,,,
,16340924.91,4370,315.717895507813,-0.0656490027904511,0,2.89361035823822e-005,99.9020004272461,,,,,,,2.29678431902564e-007,,,,25,0.0289361035823822,,,
,16340988.08,4370,313.61540222168,-0.0656490027904511,0,2.87635100632906e-005,99.9020004272461,,,,,,,2.63061626714384e-007,,,,25,0.0287635100632906,,,
,16341051.56,4370,311.498901367188,-0.0656490027904511,0,2.8477890715003e-005,99.9020004272461,,,,,,,2.25319727383224e-007,,,,25,0.028477890715003,,,
,16341115.45,4370,309.369400024414,-0.0656490027904511,0,2.83847210556269e-005,99.9020004272461,,,,,,,2.07500568538081e-007,,,,25,0.0283847210556269,,,
,16341178.45,4370,307.272903442383,-0.0656490027904511,0,2.81388139724731e-005,99.9020004272461,,,,,,,2.49146711112024e-007,,,,25,0.0281388139724731,,,
,16341240.38,4370,305.204193115234,-0.0656490027904511,0,2.80548083782196e-005,99.9020004272461,,,,,,,2.80548673639194e-007,,,,25,0.0280548083782196,,,
,16341304.69,4370,303.052703857422,-0.0656490027904511,0,2.78195929527283e-005,99.9020004272461,,,,,,,2.540519020101e-007,,,,25,0.0278195929527283,,,
,16341367.88,4370,300.954452514648,-0.0656490027904511,0,2.76783107966185e-005,99.9020004272461,,,,,,,2.3160758072048e-007,,,,25,0.0276783107966185,,,
,16341431.08,4370,298.831253051758,-0.0656490027904511,0,2.74850979447365e-005,99.9020004272461,,,,,,,2.23435748507947e-007,,,,25,0.0274850979447365,,,
,16341493.42,4370,296.764297485352,-0.0656490027904511,0,2.73430518805981e-005,99.9020004272461,,,,,,,1.95053122194806e-007,,,,25,0.0273430518805981,,,
,16341562.00,4370,294.468139648438,-0.0656490027904511,0,2.71449362486601e-005,29.9950008392334,,,,,,,6.39749953649446e-007,,,,25,0.0271449362486601,,,
,16341624.45,4370,292.392456054688,-0.0656490027904511,0,2.70542679727078e-005,29.9950008392334,,,,,,,6.84490609340676e-007,,,,25,0.0270542679727077,,,
,16341686.81,4370,290.301498413086,-0.0656490027904511,0,2.70347432792187e-005,29.9950008392334,,,,,,,6.8593910226336e-007,,,,25,0.0270347432792187,,,
,16341750.16,4370,288.191192626953,-0.0656490027904511,0,2.66347013413906e-005,29.9950008392334,,,,,,,5.99430582922663e-007,,,,25,0.0266347013413906,,,
,16341812.86,4370,286.096557617188,-0.0656490027904511,0,2.65388772636652e-005,29.9950008392334,,,,,,,8.36684582941773e-007,,,,25,0.0265388772636652,,,
,16341876.45,4370,283.977493286133,-0.0656490027904511,0,2.6328255161643e-005,29.9950008392334,,,,,,,8.91235257873965e-007,,,,25,0.026328255161643,,,
,16341938.08,4370,281.925445556641,-0.0656490027904511,0,2.62381405383348e-005,29.9950008392334,,,,,,,8.53747076577052e-007,,,,25,0.0262381405383348,,,
,16341999.36,4370,279.868698120117,-0.0656490027904511,0,2.58784171193838e-005,29.9950008392334,,,,,,,8.038111760818e-007,,,,25,0.0258784171193838,,,
,16342062.81,4370,277.751312255859,-0.0656490027904511,0,4.12129580974579e-005,29.9950008392334,,,,,,,8.29127510290023e-007,,,,25,0.0412129580974579,,,
,16342126.84,4370,275.619400024414,-0.0656490027904511,0,4.43830139935017e-005,29.9950008392334,,,,,,,7.13348915958226e-007,,,,25,0.0443830139935017,,,
,16342190.13,4370,273.515151977539,-0.0656490027904511,0,4.41441375017166e-005,29.9950008392334,,,,,,,8.84235129977723e-007,,,,25,0.0441441375017166,,,
,16342251.23,4370,271.468994140625,-0.0656490027904511,0,4.32899911701679e-005,29.9950008392334,,,,,,,6.54873373724159e-007,,,,25,0.0432899911701679,,,
,16342314.31,4370,269.360900878906,-0.0656490027904511,0,4.39318622648716e-005,29.9950008392334,,,,,,,6.21547845224743e-007,,,,25,0.0439318622648716,,,
,16342376.31,4370,267.30046081543,-0.0656490027904511,0,4.42111040651798e-005,29.9950008392334,,,,,,,7.63112819410273e-007,,,,25,0.0442111040651798,,,
,16342437.02,4370,265.274658203125,-0.0656490027904511,0,4.40159739553928e-005,29.9950008392334,,,,,,,9.76703396853667e-007,,,,25,0.0440159739553928,,,
,16342498.69,4370,263.212753295898,-0.0656490027904511,0,4.38584026694298e-005,29.9950008392334,,,,,,,8.34921080585248e-007,,,,25,0.0438584026694298,,,
,16342562.22,4370,261.089889526367,-0.0656490027904511,0,4.34803599119186e-005,29.9950008392334,,,,,,,7.38897835830626e-007,,,,25,0.0434803599119186,,,
,16342624.81,4370,259.00309753418,-0.0656490027904511,0,4.3623086810112e-005,29.9950008392334,,,,,,,7.2452289707751e-007,,,,25,0.043623086810112,,,
,16342687.38,4370,256.920501708984,-0.0656490027904511,0,4.34150506556034e-005,29.9950008392334,,,,,,,6.14400536767374e-007,,,,25,0.0434150506556034,,,
,16342749.47,4370,254.83415222168,-0.0656490027904511,0,4.27836431562901e-005,29.9950008392334,,,,,,,6.43598047318183e-007,,,,25,0.0427836431562901,,,
,16342810.47,4370,252.810745239258,-0.0656490027904511,0,4.24165558815002e-005,29.9950008392334,,,,,,,7.88289552632617e-007,,,,25,0.0424165558815002,,,
,16342872.73,4370,250.731246948242,-0.0656490027904511,0,4.22380849719048e-005,29.9950008392334,,,,,,,5.81325498310739e-007,,,,25,0.0422380849719048,,,
,16342934.66,4370,248.679153442383,-0.0656490027904511,0,4.17250367999077e-005,29.9950008392334,,,,,,,8.09078581801125e-007,,,,25,0.0417250367999077,,,
,16342996.36,4370,246.619453430176,-0.0656490027904511,0,4.15334634482861e-005,29.9950008392334,,,,,,,7.9045520891443e-007,,,,25,0.0415334634482861,,,
,16343059.78,4370,244.500350952148,-0.0656490027904511,0,4.1309799849987e-005,29.9950008392334,,,,,,,7.44586728881516e-007,,,,25,0.041309799849987,,,
,16343120.52,4370,242.480697631836,-0.0656490027904511,0,4.09991602599621e-005,29.9950008392334,,,,,,,7.09164264874818e-007,,,,25,0.0409991602599621,,,
,16343182.38,4370,240.418952941895,-0.0656490027904511,0,4.06047943234444e-005,29.9950008392334,,,,,,,8.48117757810007e-007,,,,25,0.0406047943234444,,,
,16343242.34,4370,238.423004150391,-0.0656490027904511,0,4.03233253955841e-005,29.9950008392334,,,,,,,8.52769265539305e-007,,,,25,0.0403233253955841,,,
,16343304.53,4370,236.348747253418,-0.0656490027904511,0,4.04104365408421e-005,29.9950008392334,,,,,,,7.68219983539403e-007,,,,25,0.0404104365408421,,,
,16343366.41,4370,234.281600952148,-0.0656490027904511,0,3.99738000333309e-005,29.9950008392334,,,,,,,7.18001684426768e-007,,,,25,0.0399738000333309,,,
,16343428.23,4370,232.22200012207,-0.0656490027904511,0,3.93774518370628e-005,29.9950008392334,,,,,,,8.06019749940069e-007,,,,25,0.0393774518370628,,,
,16343490.08,4370,230.152755737305,-0.0656490027904511,0,3.91131816804409e-005,29.9950008392334,,,,,,,8.20989971868817e-007,,,,25,0.0391131816804409,,,
,16343552.80,4370,228.060249328613,-0.0656490027904511,0,3.88345377147198e-005,29.9950008392334,,,,,,,7.32149835021422e-007,,,,25,0.0388345377147198,,,
,16343615.25,4370,225.981544494629,-0.0656490027904511,0,3.8357974588871e-005,29.9950008392334,,,,,,,8.00324579842058e-007,,,,25,0.038357974588871,,,
,16343680.30,4370,223.820899963379,-0.0656490027904511,0,3.81199476122856e-005,29.9950008392334,,,,,,,6.53262248049794e-007,,,,25,0.0381199476122856,,,
,16343743.17,4370,221.72004699707,-0.0656490027904511,0,3.76252703368664e-005,29.9950008392334,,,,,,,6.83406714295067e-007,,,,25,0.0376252703368664,,,
,16343806.69,4370,219.603843688965,-0.0656490027904511,0,3.73264311254025e-005,29.9950008392334,,,,,,,6.18514694252219e-007,,,,25,0.0373264311254025,,,
,16343870.25,4370,217.490142822266,-0.0656490027904511,0,3.71965819597244e-005,29.9950008392334,,,,,,,6.26680667806202e-007,,,,25,0.0371965819597244,,,
,16343932.34,4370,215.419448852539,-0.0656490027904511,0,3.68159610033035e-005,29.9950008392334,,,,,,,9.70960157082864e-007,,,,25,0.0368159610033035,,,
,16343994.36,4370,213.348052978516,-0.0656490027904511,0,3.6399362385273e-005,29.9950008392334,,,,,,,8.43242504202429e-007,,,,25,0.036399362385273,,,
,16344055.27,4370,211.321800231934,-0.0656490027904511,0,3.5956769734621e-005,29.9950008392334,,,,,,,7.95486072675421e-007,,,,25,0.0359567697346211,,,
,16344117.42,4370,209.254150390625,-0.0656490027904511,0,3.57394483685493e-005,29.9950008392334,,,,,,,9.4150194328625e-007,,,,25,0.0357394483685493,,,
,16344179.52,4370,207.181304931641,-0.0656490027904511,0,3.53874473273754e-005,29.9950008392334,,,,,,,6.88699665426247e-007,,,,25,0.0353874473273754,,,
,16344240.81,4370,205.138847351074,-0.0656490027904511,0,3.47104951739311e-005,29.9950008392334,,,,,,,7.19052169378373e-007,,,,25,0.0347104951739311,,,
,16344303.28,4370,203.05290222168,-0.0656490027904511,0,3.45949216187e-005,29.9950008392334,,,,,,,5.66231949967027e-007,,,,25,0.0345949216187,,,
,16344365.86,4370,200.965194702148,-0.0656490027904511,0,3.44253642857075e-005,29.9950008392334,,,,,,,6.84867951074895e-007,,,,25,0.0344253642857075,,,
,16344428.28,4370,198.891052246094,-0.0656490027904511,0,3.38056021928787e-005,29.9950008392334,,,,,,,8.25212850470794e-007,,,,25,0.0338056021928787,,,
,16344491.53,4370,196.78784942627,-0.0656490027904511,0,3.35671453177929e-005,29.9950008392334,,,,,,,5.86903757699322e-007,,,,25,0.0335671453177929,,,
,16344555.02,4370,194.663055419922,-0.0656490027904511,0,3.34992629289627e-005,29.9950008392334,,,,,,,6.60947022498214e-007,,,,25,0.0334992629289627,,,
,16344616.09,4370,192.637153625488,-0.0656490027904511,0,3.28340244293213e-005,29.9950008392334,,,,,,,8.89515920149671e-007,,,,25,0.0328340244293213,,,
,16344676.88,4370,190.59880065918,-0.0656490027904511,0,3.26716448366642e-005,29.9950008392334,,,,,,,8.48684053431682e-007,,,,25,0.0326716448366642,,,
,16344738.28,4370,188.555053710938,-0.0656490027904511,0,3.21906773000956e-005,29.9950008392334,,,,,,,8.65423060388681e-007,,,,25,0.0321906773000956,,,
,16344801.19,4370,186.464950561523,-0.0656490027904511,0,3.18237759172916e-005,29.9950008392334,,,,,,,8.82449641095577e-007,,,,25,0.0318237759172916,,,
,16344862.56,4370,184.414604187012,-0.0656490027904511,0,3.18476781994104e-005,29.9950008392334,,,,,,,5.66233198432991e-007,,,,25,0.0318476781994104,,,
,16344923.97,4370,182.367050170898,-0.0656490027904511,0,3.13998821377754e-005,29.9950008392334,,,,,,,8.2569269260296e-007,,,,25,0.0313998821377754,,,
,16344986.36,4370,180.291702270508,-0.0656490027904511,0,3.13970382511616e-005,29.9950008392334,,,,,,,8.71851088324596e-007,,,,25,0.0313970382511616,,,
,16345049.44,4370,178.177352905273,-0.0656490027904511,0,3.19185981154442e-005,29.9950008392334,,,,,,,7.65215825510364e-007,,,,25,0.0319185981154442,,,
,16345113.09,4370,176.063095092773,-0.0656490027904511,0,3.12988729774952e-005,29.9950008392334,,,,,,,7.99403628669529e-007,,,,25,0.0312988729774952,,,
,16345174.38,4370,174.025550842285,-0.0656490027904511,0,3.08824323117733e-005,29.9950008392334,,,,,,,8.94881388069545e-007,,,,25,0.0308824323117733,,,
,16345237.83,4370,171.900650024414,-0.0656490027904511,0,3.10590723156929e-005,29.9950008392334,,,,,,,6.86099981678494e-007,,,,25,0.0310590723156929,,,
,16345301.16,4370,169.796348571777,-0.0656490027904511,0,3.09105005115271e-005,29.9950008392334,,,,,,,5.88327223602392e-007,,,,25,0.0309105005115271,,,
,16345365.38,4370,167.665748596191,-0.0656490027904511,0,3.07153238356114e-005,29.9950008392334,,,,,,,9.34273344871223e-007,,,,25,0.0307153238356113,,,
,16345428.03,4370,165.564147949219,-0.0656490027904511,0,3.0436539426446e-005,29.9950008392334,,,,,,,6.45962892711538e-007,,,,25,0.030436539426446,,,
,16345491.45,4370,163.458297729492,-0.0656490027904511,0,3.02768418192863e-005,29.9950008392334,,,,,,,7.54845945627394e-007,,,,25,0.0302768418192863,,,
,16345553.06,4370,161.396095275879,-0.0656490027904511,0,2.98714738339186e-005,29.9950008392334,,,,,,,5.97249354955243e-007,,,,25,0.0298714738339186,,,
,16345616.09,4370,159.292495727539,-0.0656490027904511,0,2.93946677446365e-005,29.9950008392334,,,,,,,7.55277961727538e-007,,,,25,0.0293946677446365,,,
,16345679.97,4370,157.16089630127,-0.0656490027904511,0,2.99294948577881e-005,29.9950008392334,,,,,,,7.71535541891245e-007,,,,25,0.0299294948577881,,,
,16345742.38,4370,155.090003967285,-0.0656490027904511,0,3.00871201604605e-005,29.9950008392334,,,,,,,8.09271321393195e-007,,,,25,0.0300871201604605,,,
,16345805.69,4370,152.982902526855,-0.0656490027904511,0,2.95797915756702e-005,29.9950008392334,,,,,,,6.05061715639052e-007,,,,25,0.0295797915756702,,,
,16345867.23,4370,150.927253723145,-0.0656490027904511,0,2.94130340963602e-005,29.9950008392334,,,,,,,7.2665845055324e-007,,,,25,0.0294130340963602,,,
,16345929.58,4370,148.844848632813,-0.0656490027904511,0,2.89953113347292e-005,29.9950008392334,,,,,,,5.34316378790345e-007,,,,25,0.0289953113347292,,,
,16345991.50,4370,146.793800354004,-0.0656490027904511,0,2.4934263676405e-005,29.9950008392334,,,,,,,5.46511013394412e-007,,,,25,0.024934263676405,,,
,16346052.92,4370,144.73974609375,-0.0656490027904511,0,2.44125265628099e-005,29.9950008392334,,,,,,,7.98519414020704e-007,,,,25,0.0244125265628099,,,
,16346117.41,4370,142.589096069336,-0.0656490027904511,0,2.43666045367718e-005,29.9950008392334,,,,,,,7.51953519166871e-007,,,,25,0.0243666045367718,,,
,16346179.50,4370,140.52579498291,-0.0656490027904511,0,2.38466926664114e-005,29.9950008392334,,,,,,,6.39463130179886e-007,,,,25,0.0238466926664114,,,
,16346241.38,4370,138.457252502441,-0.0656490027904511,0,2.35489372909069e-005,29.9950008392334,,,,,,,8.31600073324737e-007,,,,25,0.0235489372909069,,,
,16346302.42,4370,136.425903320313,-0.0656490027904511,0,2.29902154952288e-005,29.9950008392334,,,,,,,7.3441103347838e-007,,,,25,0.0229902154952288,,,
,16346364.27,4370,134.364646911621,-0.0656490027904511,0,2.24281237274408e-005,29.9950008392334,,,,,,,6.70775367776653e-007,,,,25,0.0224281237274408,,,
,16346426.64,4370,132.288452148438,-0.0656490027904511,0,2.21449928730726e-005,29.9950008392334,,,,,,,6.33945484606861e-007,,,,25,0.0221449928730726,,,
,16346489.47,4370,130.191200256348,-0.0656490027904511,0,2.21232260018587e-005,29.9950008392334,,,,,,,9.1687549921267e-007,,,,25,0.0221232260018587,,,
,16346551.31,4370,128.128555297852,-0.0656490027904511,0,2.14001809805632e-005,29.9950008392334,,,,,,,8.10025170331034e-007,,,,25,0.0214001809805632,,,
,16346613.72,4370,126.051300048828,-0.0656490027904511,0,2.11327575147152e-005,29.9950008392334,,,,,,,7.0117498621018e-007,,,,25,0.0211327575147152,,,
,16346676.80,4370,123.941551208496,-0.0656490027904511,0,2.07470624148846e-005,29.9950008392334,,,,,,,6.80761515860378e-007,,,,25,0.0207470624148846,,,
,16346739.19,4370,121.863349914551,-0.0656490027904511,0,2.02692668139935e-005,29.9950008392334,,,,,,,7.68539348769638e-007,,,,25,0.0202692668139935,,,
,16346801.56,4370,119.792049407959,-0.0656490027904511,0,1.99043576419353e-005,29.9950008392334,,,,,,,6.87972228052381e-007,,,,25,0.0199043576419354,,,
,16346865.58,4370,117.65795135498,-0.0656490027904511,0,1.99786959588528e-005,29.9950008392334,,,,,,,6.79874615833468e-007,,,,25,0.0199786959588528,,,
,16346927.25,4370,115.595798492432,-0.0656490027904511,0,1.93435537070036e-005,29.9950008392334,,,,,,,7.59479125607797e-007,,,,25,0.0193435537070036,,,
,16346991.59,4370,113.45044708252,-0.0656490027904511,0,1.9180563390255e-005,29.9950008392334,,,,,,,6.97123931743878e-007,,,,25,0.019180563390255,,,
,16347053.67,4370,111.383750915527,-0.0656490027904511,0,1.85076367855072e-005,29.9950008392334,,,,,,,6.63908945780796e-007,,,,25,0.0185076367855072,,,
,16347114.34,4370,109.36275100708,-0.0656490027904511,0,1.82556407153606e-005,29.9950008392334,,,,,,,8.60882786026448e-007,,,,25,0.0182556407153606,,,
,16347175.06,4370,107.33869934082,-0.0656490027904511,0,1.80173984915018e-005,29.9950008392334,,,,,,,5.5373205582514e-007,,,,25,0.0180173984915018,,,
,16347237.05,4370,105.273403167725,-0.0656490027904511,0,1.8007852435112e-005,29.9950008392334,,,,,,,6.67165564449765e-007,,,,25,0.018007852435112,,,
,16347299.66,4370,103.182350158691,-0.0656490027904511,0,1.75722063332796e-005,29.9950008392334,,,,,,,7.08284158072773e-007,,,,25,0.0175722063332796,,,
,16347362.14,4370,101.108348846436,-0.0656490027904511,0,1.7061055265367e-005,29.9950008392334,,,,,,,8.84031765999282e-007,,,,25,0.017061055265367,,,
,16347497.11,4370,100.202251434326,-0.0656490027904511,0,1.70755587518215e-005,29.9950008392334,,,,,,,9.01854201648632e-007,,,,25,0.0170755587518215,,,
,16347559.34,4370,102.400802612305,-0.0656490027904511,0,1.69389019533992e-005,29.9950008392334,,,,,,,2.35369212817425e-006,,,,25,0.0169389019533992,,,
,16347621.36,4370,104.466499328613,-0.0656490027904511,0,1.76235097646713e-005,29.9950008392334,,,,,,,5.84888092535931e-007,,,,25,0.0176235097646713,,,
,16347683.98,4370,106.55445098877,-0.0656490027904511,0,1.79845014959574e-005,29.9950008392334,,,,,,,8.71405688412724e-007,,,,25,0.0179845014959574,,,
,16347746.50,4370,108.642498016357,-0.0656490027904511,0,1.81264342367649e-005,29.9950008392334,,,,,,,8.53843605635706e-007,,,,25,0.0181264342367649,,,
,16347809.00,4370,110.719799041748,-0.0656490027904511,0,1.84958004206419e-005,29.9950008392334,,,,,,,8.05554274937535e-007,,,,25,0.0184958004206419,,,
,16347871.17,4370,112.784851074219,-0.0656490027904511,0,1.89171653240919e-005,29.9950008392334,,,,,,,7.71344283381908e-007,,,,25,0.0189171653240919,,,
,16347931.91,4370,114.817199707031,-0.0656490027904511,0,1.93169496953487e-005,29.9950008392334,,,,,,,7.77868734192191e-007,,,,25,0.0193169496953487,,,
,16347994.09,4370,116.888000488281,-0.0656490027904511,0,1.95937260240316e-005,29.9950008392334,,,,,,,7.58498384233436e-007,,,,25,0.0195937260240316,,,
,16348056.27,4370,118.968002319336,-0.0656490027904511,0,1.98183114826679e-005,29.9950008392334,,,,,,,7.36122827116268e-007,,,,25,0.0198183114826679,,,
,16348117.86,4370,121.00915145874,-0.0656490027904511,0,2.02883238345385e-005,29.9950008392334,,,,,,,7.40177587988565e-007,,,,25,0.0202883238345385,,,
,16348180.83,4370,123.112350463867,-0.0656490027904511,0,2.0320875570178e-005,29.9950008392334,,,,,,,8.70991449464654e-007,,,,25,0.020320875570178,,,
,16348241.69,4370,125.139850616455,-0.0656490027904511,0,2.05836524069309e-005,29.9950008392334,,,,,,,9.24824508179489e-007,,,,25,0.0205836524069309,,,
,16348304.44,4370,127.227897644043,-0.0656490027904511,0,2.10239812731743e-005,29.9950008392334,,,,,,,7.74900654901043e-007,,,,25,0.0210239812731743,,,
,16348366.22,4370,129.275947570801,-0.0656490027904511,0,2.14581197500229e-005,29.9950008392334,,,,,,,5.59666657990416e-007,,,,25,0.0214581197500229,,,
,16348428.03,4370,131.344947814941,-0.0656490027904511,0,2.15226896107197e-005,29.9950008392334,,,,,,,6.55499053251099e-007,,,,25,0.0215226896107197,,,
,16348492.28,4370,133.491401672363,-0.0656490027904511,0,2.20906490832567e-005,29.9950008392334,,,,,,,7.47705253176864e-007,,,,25,0.0220906490832567,,,
,16348553.13,4370,135.515754699707,-0.0656490027904511,0,2.21967123448849e-005,29.9950008392334,,,,,,,5.98855699231005e-007,,,,25,0.0221967123448849,,,
,16348614.86,4370,137.576202392578,-0.0656490027904511,0,2.24522038549185e-005,29.9950008392334,,,,,,,5.99746282730786e-007,,,,25,0.0224522038549185,,,
,16348678.92,4370,139.705055236816,-0.0656490027904511,0,2.26514675468206e-005,29.9950008392334,,,,,,,9.54473208545121e-007,,,,25,0.0226514675468206,,,
,16348739.23,4370,141.725151062012,-0.0656490027904511,0,2.30807887017727e-005,29.9950008392334,,,,,,,9.46712700184415e-007,,,,25,0.0230807887017727,,,
,16348800.95,4370,143.778648376465,-0.0656490027904511,0,2.30631776899099e-005,29.9950008392334,,,,,,,7.12382415541709e-007,,,,25,0.0230631776899099,,,
,16348862.77,4370,145.83895111084,-0.0656490027904511,0,2.36712570488453e-005,29.9950008392334,,,,,,,9.52305995458278e-007,,,,25,0.0236712570488453,,,
,16348925.20,4370,147.919296264648,-0.0656490027904511,0,2.38605485111475e-005,29.9950008392334,,,,,,,8.94126267308529e-007,,,,25,0.0238605485111475,,,
,16348986.63,4370,149.967948913574,-0.0656490027904511,0,2.38051164895296e-005,29.9950008392334,,,,,,,6.91695877132471e-007,,,,25,0.0238051164895296,,,
,16349050.66,4370,152.104202270508,-0.0656490027904511,0,2.4491093531251e-005,29.9950008392334,,,,,,,9.27734788497016e-007,,,,25,0.024491093531251,,,
,16349111.75,4370,154.13835144043,-0.0656490027904511,0,2.4844593256712e-005,29.9950008392334,,,,,,,7.72121111288346e-007,,,,25,0.024844593256712,,,
,16349175.86,4370,156.275398254395,-0.0656490027904511,0,2.47501596808434e-005,29.9950008392334,,,,,,,7.97317721749486e-007,,,,25,0.0247501596808434,,,
,16349236.94,4370,158.313255310059,-0.0656490027904511,0,2.51048526912928e-005,29.9950008392334,,,,,,,7.34909928618693e-007,,,,25,0.0251048526912928,,,
,16349298.45,4370,160.361396789551,-0.0656490027904511,0,2.56262677162886e-005,29.9950008392334,,,,,,,7.06722570246783e-007,,,,25,0.0256262677162886,,,
,16349359.50,4370,162.401252746582,-0.0656490027904511,0,2.60761710256338e-005,29.9950008392334,,,,,,,6.78876412113702e-007,,,,25,0.0260761710256338,,,
,16349422.86,4370,164.502494812012,-0.0656490027904511,0,2.62650344520807e-005,29.9950008392334,,,,,,,9.17715376438839e-007,,,,25,0.0262650344520807,,,
,16349483.66,4370,166.528251647949,-0.0656490027904511,0,2.64000959694386e-005,29.9950008392334,,,,,,,7.33397341481961e-007,,,,25,0.0264000959694386,,,
,16349543.92,4370,168.543800354004,-0.0656490027904511,0,2.68258152157068e-005,29.9950008392334,,,,,,,7.12161990484727e-007,,,,25,0.0268258152157068,,,
,16349606.27,4370,170.618453979492,-0.0656490027904511,0,2.68181842565537e-005,29.9950008392334,,,,,,,8.11897591902394e-007,,,,25,0.0268181842565536,,,
,16349667.84,4370,172.671546936035,-0.0656490027904511,0,2.73048990219831e-005,29.9950008392334,,,,,,,8.69897498423994e-007,,,,25,0.0273048990219831,,,
,16349729.20,4370,174.719352722168,-0.0656490027904511,0,2.77693507820368e-005,29.9950008392334,,,,,,,5.754905883705e-007,,,,25,0.0277693507820368,,,
,16349792.45,4370,176.821350097656,-0.0656490027904511,0,2.79288038611412e-005,29.9950008392334,,,,,,,7.26154184475241e-007,,,,25,0.0279288038611412,,,
,16349856.25,4370,178.957801818848,-0.0656490027904511,0,2.82764430344105e-005,29.9950008392334,,,,,,,1.50425070129568e-006,,,,25,0.0282764430344105,,,
,16349919.30,4370,181.04940032959,-0.0656490027904511,0,2.87990849465132e-005,29.9950008392334,,,,,,,8.52275097726855e-007,,,,25,0.0287990849465132,,,
,16349981.58,4370,183.125450134277,-0.0656490027904511,0,2.89823167771101e-005,29.9950008392334,,,,,,,7.50328566686559e-007,,,,25,0.0289823167771101,,,
,16350043.34,4370,185.183898925781,-0.0656490027904511,0,2.9080361649394e-005,29.9950008392334,,,,,,,8.08326404663214e-007,,,,25,0.029080361649394,,,
,16350104.16,4370,187.213302612305,-0.0656490027904511,0,2.93220197409391e-005,29.9950008392334,,,,,,,7.4422498350447e-007,,,,25,0.0293220197409391,,,
,16350164.98,4370,189.240852355957,-0.0656490027904511,0,2.96362246572971e-005,29.9950008392334,,,,,,,7.66373308593767e-007,,,,25,0.0296362246572971,,,
,16350226.98,4370,191.312347412109,-0.0656490027904511,0,2.99396807700395e-005,29.9950008392334,,,,,,,6.5793608174206e-007,,,,25,0.0299396807700396,,,
,16350295.17,4370,193.578094482422,-0.0656490027904511,0,3.02313173562288e-005,99.9020004272461,,,,,,,2.07539902567825e-007,,,,25,0.0302313173562288,,,
,16350357.03,4370,195.64769744873,-0.0656490027904511,0,3.05994134396315e-005,99.9020004272461,,,,,,,2.40561833219235e-007,,,,25,0.0305994134396315,,,
,16350418.73,4370,197.702194213867,-0.0656490027904511,0,3.09071787446737e-005,99.9020004272461,,,,,,,2.207886974703e-007,,,,25,0.0309071787446737,,,
,16350480.61,4370,199.758697509766,-0.0656490027904511,0,3.12011984735727e-005,99.9020004272461,,,,,,,3.00095700288988e-007,,,,25,0.0312011984735727,,,
,16350542.36,4370,201.815849304199,-0.0656490027904511,0,3.15593688935041e-005,99.9020004272461,,,,,,,2.06690637528195e-007,,,,25,0.0315593688935041,,,
,16350604.55,4370,203.891548156738,-0.0656490027904511,0,3.18831726908684e-005,99.9020004272461,,,,,,,1.95261450799674e-007,,,,25,0.0318831726908684,,,
,16350668.06,4370,206.009254455566,-0.0656490027904511,0,3.21825374662876e-005,99.9020004272461,,,,,,,2.49567965749799e-007,,,,25,0.0321825374662876,,,
,16350730.11,4370,208.072799682617,-0.0656490027904511,0,3.24345545470715e-005,99.9020004272461,,,,,,,2.21185407695955e-007,,,,25,0.0324345545470715,,,
,16350794.33,4370,210.213500976563,-0.0656490027904511,0,3.26308225095272e-005,99.9020004272461,,,,,,,2.42121766089597e-007,,,,25,0.0326308225095272,,,
,16350857.73,4370,212.329902648926,-0.0656490027904511,0,3.29882279038429e-005,99.9020004272461,,,,,,,2.04111026667079e-007,,,,25,0.0329882279038429,,,
,16350919.89,4370,214.410499572754,-0.0656490027904511,0,3.32807199656963e-005,99.9020004272461,,,,,,,2.76339005996137e-007,,,,25,0.0332807199656963,,,
,16350985.17,4370,216.581497192383,-0.0656490027904511,0,3.36724916100502e-005,99.9020004272461,,,,,,,2.45435419442735e-007,,,,25,0.0336724916100502,,,
,16351045.98,4370,218.61540222168,-0.0656490027904511,0,3.39183992147446e-005,99.9020004272461,,,,,,,2.09219242517792e-007,,,,25,0.0339183992147446,,,
,16351107.67,4370,220.662048339844,-0.0656490027904511,0,3.43674460053444e-005,99.9020004272461,,,,,,,2.95178061226437e-007,,,,25,0.0343674460053444,,,
,16351169.19,4370,222.719749450684,-0.0656490027904511,0,3.46141166985035e-005,99.9020004272461,,,,,,,2.188868256779e-007,,,,25,0.0346141166985035,,,
,16351230.59,4370,224.755798339844,-0.0656490027904511,0,3.51532806456089e-005,99.9020004272461,,,,,,,2.28550276776046e-007,,,,25,0.0351532806456089,,,
,16351291.25,4370,226.782600402832,-0.0656490027904511,0,3.54839563369751e-005,99.9020004272461,,,,,,,2.16479976849403e-007,,,,25,0.0354839563369751,,,
,16351353.98,4370,228.864601135254,-0.0656490027904511,0,3.58383065462113e-005,99.9020004272461,,,,,,,2.20831138349146e-007,,,,25,0.0358383065462112,,,
,16351414.92,4370,230.902648925781,-0.0656490027904511,0,3.63049203157425e-005,99.9020004272461,,,,,,,2.65708265215062e-007,,,,25,0.0363049203157425,,,
,16351476.70,4370,232.956451416016,-0.0656490027904511,0,3.71907964348793e-005,99.9020004272461,,,,,,,2.37265400957824e-007,,,,25,0.0371907964348793,,,
,16351539.31,4370,235.047103881836,-0.0656490027904511,0,4.43824380636215e-005,99.9020004272461,,,,,,,1.91902232595421e-007,,,,25,0.0443824380636215,,,
,16351601.33,4370,237.113395690918,-0.0656490027904511,0,4.45932149887085e-005,99.9020004272461,,,,,,,2.36355112761594e-007,,,,25,0.0445932149887085,,,
,16351663.78,4370,239.204948425293,-0.0656490027904511,0,4.5171325802803e-005,99.9020004272461,,,,,,,2.34359389466086e-007,,,,25,0.045171325802803,,,
,16351726.33,4370,241.276145935059,-0.0656490027904511,0,4.55294966697693e-005,99.9020004272461,,,,,,,2.50655743021399e-007,,,,25,0.0455294966697693,,,
,16351789.83,4370,243.398002624512,-0.0656490027904511,0,4.66673895716667e-005,99.9020004272461,,,,,,,2.38809898026021e-007,,,,25,0.0466673895716667,,,
,16351853.03,4370,245.508850097656,-0.0656490027904511,0,4.74509313702583e-005,99.9020004272461,,,,,,,2.1464236469187e-007,,,,25,0.0474509313702583,,,
,16351914.59,4370,247.566947937012,-0.0656490027904511,0,4.77541182935238e-005,99.9020004272461,,,,,,,2.56336836223949e-007,,,,25,0.0477541182935238,,,
,16351978.75,4370,249.697601318359,-0.0656490027904511,0,4.80290462076664e-005,99.9020004272461,,,,,,,1.88685127837848e-007,,,,25,0.0480290462076664,,,
,16352040.45,4370,251.753456115723,-0.0656490027904511,0,4.82268407940864e-005,99.9020004272461,,,,,,,2.00894029425252e-007,,,,25,0.0482268407940865,,,
,16352101.84,4370,253.793701171875,-0.0656490027904511,0,4.83856871724129e-005,99.9020004272461,,,,,,,1.76865112031783e-007,,,,25,0.0483856871724129,,,
,16352163.61,4370,255.8583984375,-0.0656490027904511,0,4.86270114779472e-005,99.9020004272461,,,,,,,2.46427632246504e-007,,,,25,0.0486270114779472,,,
,16352224.22,4370,257.881805419922,-0.0656490027904511,0,4.89385947585106e-005,99.9020004272461,,,,,,,2.68786572407665e-007,,,,25,0.0489385947585106,,,
,16352286.97,4370,259.969100952148,-0.0656490027904511,0,4.94044429063797e-005,99.9020004272461,,,,,,,8.02174454838204e-007,,,,25,0.0494044429063797,,,
,16352347.53,4370,261.99284362793,-0.0656490027904511,0,4.93891686201095e-005,99.9020004272461,,,,,,,2.2617957928783e-007,,,,25,0.0493891686201096,,,
,16352410.41,4370,264.080749511719,-0.0656490027904511,0,4.95602339506149e-005,99.9020004272461,,,,,,,2.06242896257208e-007,,,,25,0.0495602339506149,,,
,16352471.31,4370,266.126602172852,-0.0656490027904511,0,4.97656653821468e-005,99.9020004272461,,,,,,,2.19219172700807e-007,,,,25,0.0497656653821468,,,
,16352532.91,4370,268.172546386719,-0.0656490027904511,0,4.99061842262745e-005,99.9020004272461,,,,,,,2.45421685547346e-007,,,,25,0.0499061842262745,,,
,16352596.00,4370,270.289810180664,-0.0656490027904511,0,5.01788240671158e-005,99.9020004272461,,,,,,,2.02146567528224e-007,,,,25,0.0501788240671158,,,
,16352658.41,4370,272.367141723633,-0.0656490027904511,0,5.05644862353802e-005,99.9020004272461,,,,,,,2.69900083432284e-007,,,,25,0.0505644862353802,,,
,16352719.94,4370,274.421249389648,-0.0656490027904511,0,5.06064891815185e-005,99.9020004272461,,,,,,,2.35190033191272e-007,,,,25,0.0506064891815186,,,
,16352780.91,4370,276.454040527344,-0.0656490027904511,0,5.0831776112318e-005,99.9020004272461,,,,,,,2.41261462555467e-007,,,,25,0.050831776112318,,,
,16352844.80,4370,278.586700439453,-0.0656490027904511,0,5.07653355598449e-005,99.9020004272461,,,,,,,1.97931350298498e-007,,,,25,0.050765335559845,,,
,16352906.78,4370,280.657150268555,-0.0656490027904511,0,5.01062725484371e-005,99.9020004272461,,,,,,,1.5791030393044e-007,,,,25,0.0501062725484371,,,
,16352970.14,4370,282.780853271484,-0.0656490027904511,0,4.85651530325413e-005,99.9020004272461,,,,,,,2.27926245025409e-007,,,,25,0.0485651530325413,,,
,16353032.05,4370,284.832748413086,-0.0656490027904511,0,2.97952511161566e-005,99.9020004272461,,,,,,,2.75086959938313e-007,,,,25,0.0297952511161566,,,
,16353095.05,4370,286.933059692383,-0.0656490027904511,0,2.75736853480339e-005,99.9020004272461,,,,,,,2.42179397526894e-007,,,,25,0.0275736853480339,,,
,16353159.59,4370,289.094909667969,-0.0656490027904511,0,2.81243040412664e-005,99.9020004272461,,,,,,,2.14779309272151e-007,,,,25,0.0281243040412664,,,
,16353223.39,4370,291.208099365234,-0.0656490027904511,0,2.84045769274235e-005,99.9020004272461,,,,,,,2.07624428036406e-007,,,,25,0.0284045769274235,,,
,16353284.64,4370,293.262390136719,-0.0656490027904511,0,2.84924007952213e-005,99.9020004272461,,,,,,,2.53509319395862e-007,,,,25,0.0284924007952213,,,
,16353345.84,4370,295.296142578125,-0.0656490027904511,0,2.86527750641108e-005,99.9020004272461,,,,,,,2.26371397483286e-007,,,,25,0.0286527750641108,,,
,16353407.94,4370,297.384658813477,-0.0656490027904511,0,2.88627893477678e-005,99.9020004272461,,,,,,,2.56563053486406e-007,,,,25,0.0288627893477678,,,
,16353468.88,4370,299.425201416016,-0.0656490027904511,0,2.91239707916975e-005,99.9020004272461,,,,,,,2.30190510087462e-007,,,,25,0.0291239707916975,,,
,16353529.55,4370,301.433547973633,-0.0656490027904511,0,2.91094605624676e-005,99.9020004272461,,,,,,,2.23743446583554e-007,,,,25,0.0291094605624676,,,
,16353591.86,4370,303.525497436523,-0.0656490027904511,0,2.9349258095026e-005,99.9020004272461,,,,,,,2.21684477740442e-007,,,,25,0.029349258095026,,,
,16353653.75,4370,305.589309692383,-0.0656490027904511,0,2.95317793637514e-005,99.9020004272461,,,,,,,2.77881378023887e-007,,,,25,0.0295317793637514,,,
,16353716.09,4370,307.670501708984,-0.0656490027904511,0,2.97815046459437e-005,99.9020004272461,,,,,,,2.8252946605102e-007,,,,25,0.0297815046459436,,,
,16353778.09,4370,309.718002319336,-0.0656490027904511,0,2.98319081217051e-005,99.9020004272461,,,,,,,2.26361479919723e-007,,,,25,0.0298319081217051,,,
,16353842.50,4370,311.877960205078,-0.0656490027904511,0,3.00915624946356e-005,99.9020004272461,,,,,,,2.44160359673773e-007,,,,25,0.0300915624946356,,,
,16353905.27,4370,313.976287841797,-0.0656490027904511,0,3.02496456354856e-005,99.9020004272461,,,,,,,2.82976301316251e-007,,,,25,0.0302496456354856,,,
,16353967.11,4370,316.047897338867,-0.0656490027904511,0,3.05115897208452e-005,99.9020004272461,,,,,,,1.93524345547187e-007,,,,25,0.0305115897208452,,,
,16354028.73,4370,318.086700439453,-0.0656490027904511,0,3.0601704493165e-005,99.9020004272461,,,,,,,2.16453034392112e-007,,,,25,0.030601704493165,,,
,16354092.20,4370,320.215347290039,-0.0656490027904511,0,3.08651762455702e-005,99.9020004272461,,,,,,,2.30431215060577e-007,,,,25,0.0308651762455702,,,
,16354155.25,4370,322.320846557617,-0.0656490027904511,0,3.10415878891945e-005,99.9020004272461,,,,,,,2.52382708456809e-007,,,,25,0.0310415878891945,,,
,16354216.94,4370,324.383697509766,-0.0656490027904511,0,3.11767609417439e-005,99.9020004272461,,,,,,,2.45718121270511e-007,,,,25,0.0311767609417439,,,
,16354280.56,4370,326.504409790039,-0.0656490027904511,0,3.14020486176014e-005,99.9020004272461,,,,,,,2.16898808932405e-007,,,,25,0.0314020486176014,,,
,16354342.63,4370,328.574157714844,-0.0656490027904511,0,3.1720507144928e-005,99.9020004272461,,,,,,,2.18024510839631e-007,,,,25,0.031720507144928,,,
,16354405.05,4370,330.662551879883,-0.0656490027904511,0,3.18755358457565e-005,99.9020004272461,,,,,,,2.71677032667912e-007,,,,25,0.0318755358457565,,,
,16354467.61,4370,332.740951538086,-0.0656490027904511,0,3.2032091319561e-005,99.9020004272461,,,,,,,2.28613898051553e-007,,,,25,0.032032091319561,,,
,16354531.77,4370,334.875442504883,-0.0656490027904511,0,3.2234467715025e-005,99.9020004272461,,,,,,,1.58258137537522e-007,,,,25,0.0322344677150249,,,
,16354593.66,4370,336.946746826172,-0.0656490027904511,0,3.24223351478577e-005,99.9020004272461,,,,,,,1.77383466984908e-007,,,,25,0.0324223351478577,,,
,16354654.63,4370,338.986862182617,-0.0656490027904511,0,3.26903903484345e-005,99.9020004272461,,,,,,,2.45349312959384e-007,,,,25,0.0326903903484344,,,
,16354714.56,4370,340.993545532227,-0.0656490027904511,0,3.28362545371056e-005,99.9020004272461,,,,,,,2.11936188065228e-007,,,,25,0.0328362545371056,,,
,16354777.86,4370,343.098709106445,-0.0656490027904511,0,3.30455043911934e-005,99.9020004272461,,,,,,,2.10303675520447e-007,,,,25,0.0330455043911934,,,
,16354845.94,4370,345.367599487305,-0.0656490027904511,0,3.32467374205589e-005,29.9950008392334,,,,,,,1.00340875411826e-006,,,,25,0.0332467374205589,,,
,16354908.23,4370,347.440399169922,-0.0656490027904511,0,3.34561604261398e-005,29.9950008392334,,,,,,,6.28868350404269e-007,,,,25,0.0334561604261398,,,
,16354968.92,4370,349.48664855957,-0.0656490027904511,0,3.32626406848431e-005,29.9950008392334,,,,,,,7.93407513040239e-007,,,,25,0.0332626406848431,,,
,16355085.91,4370,349.571243286133,-0.0656490027904511,0,3.37017466127872e-005,29.9950008392334,,,,,,,8.63082360113132e-007,,,,25,0.0337017466127872,,,
,16355150.00,4370,347.175354003906,-0.0656490027904511,0,3.29794356226921e-005,29.9950008392334,,,,,,,6.75406713935395e-007,,,,25,0.0329794356226921,,,
,16355213.67,4370,344.981140136719,-0.0656490027904511,0,3.31406539678574e-005,29.9950008392334,,,,,,,7.52125120751778e-007,,,,25,0.0331406539678574,,,
,16355276.31,4370,342.896347045898,-0.0656490027904511,0,3.27753114700317e-005,29.9950008392334,,,,,,,6.45513383396548e-007,,,,25,0.0327753114700317,,,
,16355339.11,4370,340.895950317383,-0.0656490027904511,0,3.28136745095253e-005,29.9950008392334,,,,,,,7.44003933312379e-007,,,,25,0.0328136745095253,,,
,16355401.61,4370,338.801651000977,-0.0656490027904511,0,3.25848944485187e-005,29.9950008392334,,,,,,,8.28798571657922e-007,,,,25,0.0325848944485188,,,
,16355463.70,4370,336.705307006836,-0.0656490027904511,0,3.23573526740074e-005,29.9950008392334,,,,,,,6.62858806327064e-007,,,,25,0.0323573526740074,,,
,16355527.75,4370,334.558197021484,-0.0656490027904511,0,3.19521808624267e-005,29.9950008392334,,,,,,,1.27408146871437e-006,,,,25,0.0319521808624268,,,
,16355589.94,4370,332.475997924805,-0.0656490027904511,0,3.20419194549322e-005,29.9950008392334,,,,,,,6.79413400529927e-007,,,,25,0.0320419194549322,,,
,16355654.83,4370,330.326705932617,-0.0656490027904511,0,3.14333476126194e-005,29.9950008392334,,,,,,,6.6856106146906e-007,,,,25,0.0314333476126194,,,
,16355717.95,4370,328.219848632813,-0.0656490027904511,0,3.13717996329069e-005,29.9950008392334,,,,,,,8.20272526372391e-007,,,,25,0.0313717996329069,,,
,16355779.91,4370,326.152252197266,-0.0656490027904511,0,3.13992831856012e-005,29.9950008392334,,,,,,,7.22890516687059e-007,,,,25,0.0313992831856012,,,
,16355844.14,4370,324.015060424805,-0.0656490027904511,0,3.09580443054438e-005,29.9950008392334,,,,,,,8.28070894626899e-007,,,,25,0.0309580443054438,,,
,16355906.67,4370,321.915542602539,-0.0656490027904511,0,3.07798931747675e-005,29.9950008392334,,,,,,,8.69198711378466e-007,,,,25,0.0307798931747675,,,
,16355968.89,4370,319.841598510742,-0.0656490027904511,0,3.05820775777102e-005,29.9950008392334,,,,,,,7.28367334366999e-007,,,,25,0.0305820775777102,,,
,16356031.98,4370,317.749252319336,-0.0656490027904511,0,3.04169335216284e-005,29.9950008392334,,,,,,,7.74815298605042e-007,,,,25,0.0304169335216284,,,
,16356094.14,4370,315.66259765625,-0.0656490027904511,0,3.02942609041929e-005,29.9950008392334,,,,,,,8.54474527945131e-007,,,,25,0.0302942609041929,,,
,16356156.97,4370,313.541702270508,-0.0656490027904511,0,3.00733514875173e-005,29.9950008392334,,,,,,,8.16525289314799e-007,,,,25,0.0300733514875174,,,
,16356218.08,4370,311.51335144043,-0.0656490027904511,0,2.9822288826108e-005,29.9950008392334,,,,,,,7.15967864015604e-007,,,,25,0.029822288826108,,,
,16356280.05,4370,309.455551147461,-0.0656490027904511,0,2.97079101204872e-005,29.9950008392334,,,,,,,6.64964706270686e-007,,,,25,0.0297079101204872,,,
,16356343.92,4370,307.317504882813,-0.0656490027904511,0,2.91993992775679e-005,29.9950008392334,,,,,,,8.22814354849505e-007,,,,25,0.0291993992775679,,,
,16356406.70,4370,305.224105834961,-0.0656490027904511,0,2.87917452305555e-005,29.9950008392334,,,,,,,7.41341964954984e-007,,,,25,0.0287917452305555,,,
,16356468.11,4370,303.172714233398,-0.0656490027904511,0,2.88013534992933e-005,29.9950008392334,,,,,,,6.22515358820552e-007,,,,25,0.0288013534992933,,,
,16356533.55,4370,300.996658325195,-0.0656490027904511,0,2.83844517916441e-005,29.9950008392334,,,,,,,8.32454429136596e-007,,,,25,0.0283844517916441,,,
,16356579.91,4373,299.760757446289,-0.0656490027904511,0,2.84542351216078e-005,29.9950008392334,,,,,,,7.04040670595357e-007,,,,25,0.0284542351216078,,,