File: 研究/抵抗測定/PPMS/180709_IrTe2_1.dat
[Header]
TITLE, default name
FILEOPENTIME,16307266.66,7/9/2018,10:59 AM
BYAPP, Resistivity, 2.1, 1.0
INFO, APPNAME, PPMS MultiVu Application, 1.5.11
INFO, , Sample1 Name
INFO, 1, Sample1 Cross Section
INFO, 1, Sample1 Length
INFO, Ohm-m, Sample1 Units
INFO, , Sample2 Name
INFO, 1, Sample2 Cross Section
INFO, 1, Sample2 Length
INFO, Ohm-m, Sample2 Units
INFO, , Sample3 Name
INFO, 1, Sample3 Cross Section
INFO, 1, Sample3 Length
INFO, Ohm-m, Sample3 Units
INFO, , Sample4 Name
INFO, 1, Sample4 Cross Section
INFO, 1, Sample4 Length
INFO, Ohm-m, Sample4 Units
FIELDGROUP, Resistivity,2,3,4,5,6,7,8,9,10,11,12,13,14,15,16,17,18,19,20,21,22,23,24,25,26,27,28,29,30,31,32,33,34,35,36,37,38,39,40,41
STARTUPGROUP, Resistivity
STARTUPAXIS, X, 2, LINEAR, AUTO
STARTUPAXIS, Y1, 7, LINEAR, AUTO
STARTUPAXIS, Y2, 9, LINEAR, AUTO
STARTUPAXIS, Y3, 11, LINEAR, AUTO
PLOT_APPEARANCE, ALL, HORZ_GRID_ON, VERT_GRID_ON, MARKERS_AND_LINES, ALL_LINES
DATATYPE, TIME, 2
DATATYPE, COMMENT, 1
[Data]
Comment,Time Stamp (sec),Status (code),Temperature (K),Magnetic Field (Oe),Sample Position (deg),Bridge 1 Resistivity (Ohm-m),Bridge 1 Excitation (uA),Bridge 2 Resistivity (Ohm-m),Bridge 2 Excitation (uA),Bridge 3 Resistivity (Ohm-m),Bridge 3 Excitation (uA),Bridge 4 Resistivity (Ohm-m),Bridge 4 Excitation (uA),Bridge 1 Std. Dev. (Ohm-m),Bridge 2 Std. Dev. (Ohm-m),Bridge 3 Std. Dev. (Ohm-m),Bridge 4 Std. Dev. (Ohm-m),Number of Readings,Bridge 1 Resistance (Ohms),Bridge 2 Resistance (Ohms),Bridge 3 Resistance (Ohms),Bridge 4 Resistance (Ohms),Signal 1 Vin (V),Signal 2 Vin (V),Digital Inputs (code),Drive 1 Iout (mA),Drive 1 Ipower (watts),Drive 2 Iout (mA),Drive 2 Ipower (watts),Pressure (),Map 20 (),Map 21 (),Map 22 (),Map 23 (),Map 24 (),Map 25 (),Map 26 (),Map 27 (),Map 28 (),Map 29 ()
,16307312.92,4370,300.020355224609,-0.14224000275135,0,2.63670601695776e-005,99.9020004272461,,,,,,,1.86242927435724e-007,,,,25,0.0263670601695776,,,
,16307366.50,4370,301.844848632813,-0.14224000275135,0,2.65114083141088e-005,29.9950008392334,,,,,,,1.17680587529221e-006,,,,25,0.0265114083141089,,,
,16307422.23,4370,303.697799682617,-0.14224000275135,0,2.62906911969185e-005,99.9020004272461,,,,,,,2.63637325551319e-007,,,,25,0.0262906911969185,,,
,16307478.08,4370,305.55940246582,-0.14224000275135,0,2.60833886265755e-005,29.9950008392334,,,,,,,1.85819981165878e-006,,,,25,0.0260833886265755,,,
,16307530.98,4370,307.331756591797,-0.14224000275135,0,2.62754175066948e-005,99.9020004272461,,,,,,,3.7006495150932e-007,,,,25,0.0262754175066948,,,
,16307585.67,4370,309.1484375,-0.14224000275135,0,2.63645702600479e-005,29.9950008392334,,,,,,,1.54198495331846e-006,,,,25,0.0263645702600479,,,
,16307638.25,4370,310.902557373047,-0.14224000275135,0,2.65052874386311e-005,99.9020004272461,,,,,,,2.50013720516169e-007,,,,25,0.0265052874386311,,,
,16307692.13,4370,312.712097167969,-0.14224000275135,0,2.66203726828098e-005,29.9950008392334,,,,,,,7.4152802240595e-007,,,,25,0.0266203726828098,,,
,16307746.25,4370,314.521560668945,-0.14224000275135,0,2.65663824230433e-005,99.9020004272461,,,,,,,2.08942902308765e-007,,,,25,0.0265663824230433,,,
,16307799.63,4370,316.288452148438,-0.14224000275135,0,2.6683454066515e-005,29.9950008392334,,,,,,,9.22596916795603e-007,,,,25,0.026683454066515,,,
,16307854.66,4370,318.131210327148,-0.14224000275135,0,2.67405027896166e-005,99.9020004272461,,,,,,,2.66798849367925e-007,,,,25,0.0267405027896166,,,
,16307909.03,4370,319.932510375977,-0.14224000275135,0,2.68418294936419e-005,29.9950008392334,,,,,,,9.12009348533522e-007,,,,25,0.0268418294936419,,,
,16307963.16,4370,321.73210144043,-0.14224000275135,0,2.67313385009766e-005,99.9020004272461,,,,,,,1.77490803231228e-007,,,,25,0.0267313385009766,,,
,16308017.66,4370,323.561859130859,-0.14224000275135,0,2.69696936011315e-005,29.9950008392334,,,,,,,8.45781420461142e-007,,,,25,0.0269696936011314,,,
,16308070.16,4370,325.325637817383,-0.14224000275135,0,2.69222600013018e-005,99.9020004272461,,,,,,,2.5046822941708e-007,,,,25,0.0269222600013018,,,
,16308124.86,4370,327.151397705078,-0.14224000275135,0,2.69714068621397e-005,29.9950008392334,,,,,,,8.56478014625973e-007,,,,25,0.0269714068621397,,,
,16308179.06,4370,328.962005615234,-0.14224000275135,0,2.70169572532177e-005,99.9020004272461,,,,,,,2.3870091693917e-007,,,,25,0.0270169572532177,,,
,16308232.56,4370,330.742111206055,-0.14224000275135,0,2.69859844446182e-005,29.9950008392334,,,,,,,7.59681445326352e-007,,,,25,0.0269859844446182,,,
,16308287.63,4370,332.574752807617,-0.14224000275135,0,2.70047383755446e-005,99.9020004272461,,,,,,,1.53696903367938e-007,,,,25,0.0270047383755445,,,
,16308342.14,4370,334.385696411133,-0.14224000275135,0,2.72573500871658e-005,29.9950008392334,,,,,,,6.0840019993717e-007,,,,25,0.0272573500871658,,,
,16308398.89,4370,336.288604736328,-0.14224000275135,0,2.71788591891527e-005,99.9020004272461,,,,,,,2.05209020202453e-007,,,,25,0.0271788591891527,,,
,16308453.47,4370,338.101852416992,-0.14224000275135,0,2.72991190105677e-005,29.9950008392334,,,,,,,7.88042076933503e-007,,,,25,0.0272991190105677,,,
,16308508.44,4370,339.93669128418,-0.14224000275135,0,2.73819999396801e-005,99.9020004272461,,,,,,,2.45094826159667e-007,,,,25,0.0273819999396801,,,
,16308562.44,4370,341.752395629883,-0.14224000275135,0,2.7395763322711e-005,29.9950008392334,,,,,,,8.54266170776311e-007,,,,25,0.027395763322711,,,
,16308618.25,4370,343.601303100586,-0.14224000275135,0,2.74102562665939e-005,99.9020004272461,,,,,,,2.06317200538022e-007,,,,25,0.0274102562665939,,,
,16308672.72,4370,345.428649902344,-0.14224000275135,0,2.73212921619415e-005,29.9950008392334,,,,,,,8.43518266637636e-007,,,,25,0.0273212921619415,,,
,16308729.00,4370,347.292953491211,-0.14224000275135,0,2.72804296016693e-005,99.9020004272461,,,,,,,2.45113924220176e-007,,,,25,0.0272804296016693,,,
,16308782.28,4370,349.088012695313,-0.14224000275135,0,2.73175908625126e-005,29.9950008392334,,,,,,,7.58550442216393e-007,,,,25,0.0273175908625126,,,
,16308919.97,4370,350.025146484375,-0.14224000275135,0,2.73957462608814e-005,99.9020004272461,,,,,,,2.10597822882381e-007,,,,25,0.0273957462608814,,,
,16308976.95,4370,348.447189331055,-0.14224000275135,0,2.74912927299738e-005,29.9950008392334,,,,,,,6.01316050189107e-007,,,,25,0.0274912927299738,,,
,16309032.44,4370,346.09245300293,-0.14224000275135,0,2.7436985373497e-005,99.9020004272461,,,,,,,2.43717965590958e-007,,,,25,0.027436985373497,,,
,16309088.78,4370,344.409286499023,-0.14224000275135,0,2.74198920279741e-005,29.9950008392334,,,,,,,8.0677325725848e-007,,,,25,0.0274198920279741,,,
,16309145.33,4370,342.667694091797,-0.14224000275135,0,2.74873889237642e-005,99.9020004272461,,,,,,,2.71540042327018e-007,,,,25,0.0274873889237642,,,
,16309199.83,4370,340.868011474609,-0.14224000275135,0,2.74359555542469e-005,29.9950008392334,,,,,,,9.67608904659784e-007,,,,25,0.0274359555542469,,,
,16309253.98,4370,339.035842895508,-0.14224000275135,0,2.73873457312584e-005,99.9020004272461,,,,,,,2.1526795888069e-007,,,,25,0.0273873457312584,,,
,16309307.80,4370,337.225051879883,-0.14224000275135,0,2.73804994672537e-005,29.9950008392334,,,,,,,8.73896642774309e-007,,,,25,0.0273804994672537,,,
,16309362.83,4370,335.373153686523,-0.14224000275135,0,2.72178070247173e-005,99.9020004272461,,,,,,,1.99730198535602e-007,,,,25,0.0272178070247173,,,
,16309416.50,4370,333.579849243164,-0.14224000275135,0,2.74709418416023e-005,29.9950008392334,,,,,,,1.07090571524875e-006,,,,25,0.0274709418416023,,,
,16309471.80,4370,331.737457275391,-0.14224000275135,0,2.72376631945372e-005,99.9020004272461,,,,,,,2.63990601538401e-007,,,,25,0.0272376631945372,,,
,16309526.83,4370,329.899551391602,-0.14224000275135,0,2.71760677546263e-005,29.9950008392334,,,,,,,7.79004991771985e-007,,,,25,0.0271760677546263,,,
,16309580.06,4370,328.117202758789,-0.14224000275135,0,2.71643489599228e-005,99.9020004272461,,,,,,,2.45748384065005e-007,,,,25,0.0271643489599228,,,
,16309634.72,4370,326.285003662109,-0.14224000275135,0,2.71152791380882e-005,29.9950008392334,,,,,,,8.82062560387819e-007,,,,25,0.0271152791380882,,,
,16309689.33,4370,324.447143554688,-0.14224000275135,0,2.71414382755756e-005,99.9020004272461,,,,,,,2.48931581971512e-007,,,,25,0.0271414382755756,,,
,16309744.00,4370,322.637756347656,-0.14224000275135,0,2.71063134819269e-005,29.9950008392334,,,,,,,5.68312795054347e-007,,,,25,0.0271063134819269,,,
,16309797.70,4370,320.838409423828,-0.14224000275135,0,2.70452137291431e-005,99.9020004272461,,,,,,,2.28090697784279e-007,,,,25,0.0270452137291431,,,
,16309850.22,4370,319.099304199219,-0.14224000275135,0,2.71182984113693e-005,29.9950008392334,,,,,,,8.24523537326899e-007,,,,25,0.0271182984113693,,,
,16309904.08,4370,317.296951293945,-0.14224000275135,0,2.70123750716448e-005,99.9020004272461,,,,,,,1.69194372794098e-007,,,,25,0.0270123750716448,,,
,16309957.97,4370,315.498992919922,-0.14224000275135,0,2.70349138975143e-005,29.9950008392334,,,,,,,8.84535785481446e-007,,,,25,0.0270349138975143,,,
,16310011.97,4370,313.700286865234,-0.14224000275135,0,2.70375769585371e-005,99.9020004272461,,,,,,,2.97675293290559e-007,,,,25,0.0270375769585371,,,
,16310068.13,4370,311.828887939453,-0.14224000275135,0,2.68866941332817e-005,29.9950008392334,,,,,,,7.37008891431138e-007,,,,25,0.0268866941332817,,,
,16310124.84,4370,309.925811767578,-0.14224000275135,0,2.70108476281166e-005,99.9020004272461,,,,,,,2.02145059077997e-007,,,,25,0.0270108476281166,,,
,16310178.72,4370,308.134750366211,-0.14224000275135,0,2.7025859951973e-005,29.9950008392334,,,,,,,7.97057570373656e-007,,,,25,0.027025859951973,,,
,16310232.75,4370,306.33039855957,-0.14224000275135,0,2.701466627419e-005,99.9020004272461,,,,,,,2.66770714571151e-007,,,,25,0.0270146662741899,,,
,16310287.92,4370,304.485244750977,-0.14224000275135,0,2.70783317834139e-005,29.9950008392334,,,,,,,7.11571463242117e-007,,,,25,0.0270783317834139,,,
,16310344.11,4370,302.61979675293,-0.14224000275135,0,2.70368133485317e-005,99.9020004272461,,,,,,,2.16092425696248e-007,,,,25,0.0270368133485317,,,
,16310397.56,4370,300.834899902344,-0.14224000275135,0,2.71242039650679e-005,29.9950008392334,,,,,,,7.75770132735868e-007,,,,25,0.0271242039650679,,,
,16310452.61,4370,298.997009277344,-0.14224000275135,0,2.72017698734999e-005,99.9020004272461,,,,,,,2.75525021528275e-007,,,,25,0.0272017698734999,,,
,16310506.44,4370,297.201950073242,-0.14224000275135,0,2.72507876157761e-005,29.9950008392334,,,,,,,9.72802748496307e-007,,,,25,0.0272507876157761,,,
,16310559.66,4370,295.421112060547,-0.14224000275135,0,2.73842909932137e-005,99.9020004272461,,,,,,,2.63926645091178e-007,,,,25,0.0273842909932137,,,
,16310615.16,4370,293.57585144043,-0.14224000275135,0,2.75232276320457e-005,29.9950008392334,,,,,,,8.64496327166565e-007,,,,25,0.0275232276320457,,,
,16310669.81,4370,291.751602172852,-0.14224000275135,0,2.74606598168611e-005,99.9020004272461,,,,,,,2.13198858747242e-007,,,,25,0.0274606598168612,,,
,16310724.84,4370,289.906600952148,-0.14224000275135,0,2.76150655001402e-005,29.9950008392334,,,,,,,6.77634202619662e-007,,,,25,0.0276150655001402,,,
,16310779.44,4370,288.089553833008,-0.14224000275135,0,2.77012212574482e-005,99.9020004272461,,,,,,,2.45921561112335e-007,,,,25,0.0277012212574482,,,
,16310834.73,4370,286.244155883789,-0.14224000275135,0,2.7905140593648e-005,29.9950008392334,,,,,,,8.17772892729835e-007,,,,25,0.027905140593648,,,
,16310891.88,4370,284.330688476563,-0.14224000275135,0,2.81044477969408e-005,99.9020004272461,,,,,,,2.67207612517896e-007,,,,25,0.0281044477969408,,,
,16310947.56,4370,282.47509765625,-0.14224000275135,0,2.86203046888113e-005,29.9950008392334,,,,,,,7.69784360218934e-007,,,,25,0.0286203046888113,,,
,16311003.69,4370,280.607055664063,-0.14224000275135,0,2.90002532303333e-005,99.9020004272461,,,,,,,2.52102788122179e-007,,,,25,0.0290002532303333,,,
,16311056.89,4370,278.836196899414,-0.14224000275135,0,2.98581855744124e-005,29.9950008392334,,,,,,,8.0058903453927e-007,,,,25,0.0298581855744123,,,
,16311111.70,4370,276.993759155273,-0.14224000275135,0,0.000253588408231735,99.9020004272461,,,,,,,4.11142857280634e-007,,,,25,0.253588408231735,,,
,16311167.30,4370,275.146148681641,-0.14224000275135,0,0.000256785516738892,29.9950008392334,,,,,,,7.81437708053384e-007,,,,25,0.256785516738892,,,
,16311221.95,4370,273.324951171875,-0.14224000275135,0,0.000270712569952011,99.9020004272461,,,,,,,6.25480182800672e-007,,,,25,0.270712569952011,,,
,16311278.52,4370,271.432952880859,-0.14224000275135,0,0.000288753246068955,29.9950008392334,,,,,,,6.84805123703313e-007,,,,25,0.288753246068954,,,
,16311333.39,4370,269.597595214844,-0.14224000275135,0,0.000298521465063095,99.9020004272461,,,,,,,4.7337361150507e-007,,,,25,0.298521465063095,,,
,16311388.70,4370,267.749755859375,-0.14224000275135,0,0.000305654151439667,29.9950008392334,,,,,,,6.82248758736441e-007,,,,25,0.305654151439667,,,
,16311443.59,4370,265.928344726563,-0.14224000275135,0,0.000311986794471741,99.9020004272461,,,,,,,2.32573283724673e-007,,,,25,0.311986794471741,,,
,16311497.91,4370,264.179992675781,-0.14224000275135,0,0.000315128229856491,29.9950008392334,,,,,,,6.0861629621759e-007,,,,25,0.315128229856491,,,
,16311554.45,4370,262.221252441406,-0.14224000275135,0,0.000317014122009277,99.9020004272461,,,,,,,3.58887910894967e-007,,,,25,0.317014122009277,,,
,16311608.89,4370,260.405349731445,-0.14224000275135,0,0.000312460732460022,29.9950008392334,,,,,,,9.71097330967589e-007,,,,25,0.312460732460022,,,
,16311662.42,4370,258.618850708008,-0.14224000275135,0,0.000310783979892731,99.9020004272461,,,,,,,2.36743249267623e-007,,,,25,0.310783979892731,,,
,16311716.11,4370,256.835998535156,-0.14224000275135,0,0.000310569696426392,29.9950008392334,,,,,,,7.99143192888061e-007,,,,25,0.310569696426392,,,
,16311771.59,4370,254.98860168457,-0.14224000275135,0,0.000310841264724732,99.9020004272461,,,,,,,2.45987752492933e-007,,,,25,0.310841264724731,,,
,16311826.55,4370,253.165100097656,-0.14224000275135,0,0.00031046498298645,29.9950008392334,,,,,,,6.11028132601389e-007,,,,25,0.31046498298645,,,
,16311880.67,4370,251.356246948242,-0.14224000275135,0,0.000310544954538345,99.9020004272461,,,,,,,2.32135476725519e-007,,,,25,0.310544954538345,,,
,16311935.28,4370,249.520347595215,-0.14224000275135,0,0.000311854434013367,29.9950008392334,,,,,,,1.14669011680617e-006,,,,25,0.311854434013367,,,
,16311990.36,4370,247.698051452637,-0.14224000275135,0,0.00031521793961525,99.9020004272461,,,,,,,2.60255896069684e-007,,,,25,0.31521793961525,,,
,16312045.59,4370,245.850402832031,-0.14224000275135,0,0.000315572488307953,29.9950008392334,,,,,,,8.38264117868374e-007,,,,25,0.315572488307953,,,
,16312098.64,4370,244.079498291016,-0.14224000275135,0,0.000315062144994736,99.9020004272461,,,,,,,2.15912529200969e-007,,,,25,0.315062144994736,,,
,16312151.61,4370,242.305244445801,-0.14224000275135,0,0.000315337555408478,29.9950008392334,,,,,,,1.03457520875695e-006,,,,25,0.315337555408478,,,
,16312207.27,4370,240.447700500488,-0.14224000275135,0,0.000316471905708313,99.9020004272461,,,,,,,3.12923349875993e-007,,,,25,0.316471905708313,,,
,16312262.08,4370,238.620597839355,-0.14224000275135,0,0.000318437118530273,29.9950008392334,,,,,,,9.32879461831675e-007,,,,25,0.318437118530273,,,
,16312317.78,4370,236.772850036621,-0.14224000275135,0,0.000319099744558334,99.9020004272461,,,,,,,2.39432579392578e-007,,,,25,0.319099744558334,,,
,16312372.70,4370,234.946144104004,-0.14224000275135,0,0.000320397250652313,29.9950008392334,,,,,,,7.58106006640492e-007,,,,25,0.320397250652313,,,
,16312426.55,4370,233.14924621582,-0.14224000275135,0,0.000322361466884613,99.9020004272461,,,,,,,2.26813577574535e-007,,,,25,0.322361466884613,,,
,16312480.92,4370,231.34049987793,-0.14224000275135,0,0.000328180581331253,29.9950008392334,,,,,,,8.06777711554197e-007,,,,25,0.328180581331253,,,
,16312536.61,4370,229.483200073242,-0.14224000275135,0,0.000330849105119705,99.9020004272461,,,,,,,2.35048049191225e-007,,,,25,0.330849105119705,,,
,16312590.83,4370,227.672500610352,-0.14224000275135,0,0.000332374497652054,29.9950008392334,,,,,,,7.87968525061554e-007,,,,25,0.332374497652054,,,
,16312643.92,4370,225.903602600098,-0.14224000275135,0,0.000334066509008408,99.9020004272461,,,,,,,2.10135639928538e-007,,,,25,0.334066509008408,,,
,16312698.00,4370,224.09595489502,-0.14224000275135,0,0.000335584679841995,29.9950008392334,,,,,,,6.25183297934673e-007,,,,25,0.335584679841995,,,
,16312753.17,4370,222.266098022461,-0.14224000275135,0,0.000337625283002853,99.9020004272461,,,,,,,2.42249104830234e-007,,,,25,0.337625283002853,,,
,16312807.67,4370,220.451599121094,-0.14224000275135,0,0.000338894848823547,29.9950008392334,,,,,,,5.2106937217051e-007,,,,25,0.338894848823547,,,
,16312861.00,4370,218.677200317383,-0.14224000275135,0,0.00034032261133194,99.9020004272461,,,,,,,1.89008038828784e-007,,,,25,0.34032261133194,,,
,16312915.97,4370,216.836700439453,-0.14224000275135,0,0.000341718317270279,29.9950008392334,,,,,,,8.12759007085914e-007,,,,25,0.341718317270279,,,
,16312971.00,4370,214.997451782227,-0.14224000275135,0,0.000342661061286926,99.9020004272461,,,,,,,2.1664293742856e-007,,,,25,0.342661061286926,,,
,16313025.98,4370,213.16934967041,-0.14224000275135,0,0.000344859741926193,29.9950008392334,,,,,,,6.31829088120143e-007,,,,25,0.344859741926193,,,
,16313082.06,4370,211.301551818848,-0.14224000275135,0,0.000346863617897034,99.9020004272461,,,,,,,2.84449430796503e-007,,,,25,0.346863617897034,,,
,16313135.34,4370,209.525444030762,-0.14224000275135,0,0.000348709509372711,29.9950008392334,,,,,,,7.23520159661914e-007,,,,25,0.348709509372711,,,
,16313189.91,4370,207.709747314453,-0.14224000275135,0,0.000350800420045853,99.9020004272461,,,,,,,2.8192472268997e-007,,,,25,0.350800420045853,,,
,16313243.17,4370,205.935997009277,-0.14224000275135,0,0.000374297913312912,29.9950008392334,,,,,,,8.29216746381419e-007,,,,25,0.374297913312912,,,
,16313297.45,4370,204.12174987793,-0.14224000275135,0,0.000374796983003616,99.9020004272461,,,,,,,2.11692589105981e-007,,,,25,0.374796983003616,,,
,16313351.67,4370,202.314651489258,-0.14224000275135,0,0.000374567532539368,29.9950008392334,,,,,,,7.92254341361275e-007,,,,25,0.374567532539368,,,
,16313408.73,4370,200.415748596191,-0.14224000275135,0,0.000375509502887726,99.9020004272461,,,,,,,2.83661368031456e-007,,,,25,0.375509502887726,,,
,16313462.66,4370,198.617195129395,-0.14224000275135,0,0.000374606913328171,29.9950008392334,,,,,,,7.19502549324999e-007,,,,25,0.374606913328171,,,
,16313517.66,4370,196.783950805664,-0.14224000275135,0,0.000373996654748917,99.9020004272461,,,,,,,2.78044702097637e-007,,,,25,0.373996654748917,,,
,16313571.39,4370,194.995651245117,-0.14224000275135,0,0.000373228517770767,29.9950008392334,,,,,,,8.38463596731333e-007,,,,25,0.373228517770767,,,
,16313625.70,4370,193.180152893066,-0.14224000275135,0,0.000372841190099716,99.9020004272461,,,,,,,2.01555603809054e-007,,,,25,0.372841190099716,,,
,16313681.38,4370,191.324653625488,-0.14224000275135,0,0.000373010078668594,29.9950008392334,,,,,,,7.56059168492028e-007,,,,25,0.373010078668594,,,
,16313736.61,4370,189.48314666748,-0.14224000275135,0,0.000372757179737091,99.9020004272461,,,,,,,1.78192200509361e-007,,,,25,0.372757179737091,,,
,16313790.63,4370,187.688346862793,-0.14224000275135,0,0.000373578357696533,29.9950008392334,,,,,,,8.22187297806632e-007,,,,25,0.373578357696533,,,
,16313844.08,4370,185.909698486328,-0.14224000275135,0,0.000373424632549286,99.9020004272461,,,,,,,2.18182296259788e-007,,,,25,0.373424632549286,,,
,16313898.47,4370,184.088302612305,-0.14224000275135,0,0.000373087077140808,29.9950008392334,,,,,,,8.41957968080022e-007,,,,25,0.373087077140808,,,
,16313952.41,4370,182.298347473145,-0.14224000275135,0,0.00037288091301918,99.9020004272461,,,,,,,2.3918615243043e-007,,,,25,0.37288091301918,,,
,16314007.11,4370,180.470199584961,-0.14224000275135,0,0.000372494382858276,29.9950008392334,,,,,,,8.33239292611358e-007,,,,25,0.372494382858276,,,
,16314062.69,4370,178.622856140137,-0.14224000275135,0,0.00037265408039093,99.9020004272461,,,,,,,2.26333586810051e-007,,,,25,0.37265408039093,,,
,16314114.88,4370,176.877746582031,-0.14224000275135,0,0.000371998989582062,29.9950008392334,,,,,,,8.52157844510405e-007,,,,25,0.371998989582062,,,
,16314170.06,4370,175.034202575684,-0.14224000275135,0,0.000372540298700333,99.9020004272461,,,,,,,2.3001945264988e-007,,,,25,0.372540298700333,,,
,16314222.55,4370,173.293151855469,-0.14224000275135,0,0.000372710797786713,29.9950008392334,,,,,,,6.97021182063979e-007,,,,25,0.372710797786713,,,
,16314276.52,4370,171.481704711914,-0.14224000275135,0,0.000372875541448593,99.9020004272461,,,,,,,1.93163667588037e-007,,,,25,0.372875541448593,,,
,16314330.48,4370,169.688903808594,-0.14224000275135,0,0.000372690074443817,29.9950008392334,,,,,,,9.87180325756008e-007,,,,25,0.372690074443817,,,
,16314384.91,4370,167.878150939941,-0.14224000275135,0,0.000372478449344635,99.9020004272461,,,,,,,2.0887847054979e-007,,,,25,0.372478449344635,,,
,16314437.66,4370,166.11669921875,-0.14224000275135,0,0.000372621419429779,29.9950008392334,,,,,,,6.97273750336532e-007,,,,25,0.372621419429779,,,
,16314493.42,4370,164.254905700684,-0.14224000275135,0,0.000372347083091736,99.9020004272461,,,,,,,2.02768478671304e-007,,,,25,0.372347083091736,,,
,16314549.84,4370,162.38045501709,-0.14224000275135,0,0.000372222220897675,29.9950008392334,,,,,,,8.90378487399391e-007,,,,25,0.372222220897675,,,
,16314604.17,4370,160.575500488281,-0.14224000275135,0,0.000372213438749313,99.9020004272461,,,,,,,2.16145636158443e-007,,,,25,0.372213438749313,,,
,16314657.14,4370,158.808799743652,-0.14224000275135,0,0.00037186675786972,29.9950008392334,,,,,,,6.7086126383632e-007,,,,25,0.37186675786972,,,
,16314711.61,4370,156.988899230957,-0.14224000275135,0,0.000371742242574692,99.9020004272461,,,,,,,3.05475060442232e-007,,,,25,0.371742242574692,,,
,16314765.89,4370,155.185447692871,-0.14224000275135,0,0.000371533286571503,29.9950008392334,,,,,,,6.89084234676387e-007,,,,25,0.371533286571503,,,
,16314818.70,4370,153.413345336914,-0.14224000275135,0,0.000371327574253082,99.9020004272461,,,,,,,2.18560733662443e-007,,,,25,0.371327574253082,,,
,16314872.94,4370,151.609451293945,-0.14224000275135,0,0.000371353039741516,29.9950008392334,,,,,,,8.88861598744961e-007,,,,25,0.371353039741516,,,
,16314927.69,4370,149.79460144043,-0.14224000275135,0,0.000370984668731689,99.9020004272461,,,,,,,2.37366824440641e-007,,,,25,0.370984668731689,,,
,16314981.95,4370,147.976097106934,-0.14224000275135,0,0.000370913920402527,29.9950008392334,,,,,,,7.58418440374644e-007,,,,25,0.370913920402527,,,
,16315037.34,4370,146.135353088379,-0.14224000275135,0,0.000370589847564697,99.9020004272461,,,,,,,2.16816343962103e-007,,,,25,0.370589847564697,,,
,16315092.30,4370,144.297546386719,-0.14224000275135,0,0.000370129699707031,29.9950008392334,,,,,,,6.35097668717566e-007,,,,25,0.370129699707031,,,
,16315147.73,4370,142.45189666748,-0.14224000275135,0,0.000370273671150207,99.9020004272461,,,,,,,2.01120840545027e-007,,,,25,0.370273671150208,,,
,16315201.88,4370,140.646751403809,-0.14224000275135,0,0.000370014964342117,29.9950008392334,,,,,,,7.93000878490963e-007,,,,25,0.370014964342117,,,
,16315255.61,4370,138.851600646973,-0.14224000275135,0,0.000370065962076187,99.9020004272461,,,,,,,2.17249841498953e-007,,,,25,0.370065962076187,,,
,16315310.39,4370,137.021202087402,-0.14224000275135,0,0.000369709565639496,29.9950008392334,,,,,,,7.8659102372623e-007,,,,25,0.369709565639496,,,
,16315363.69,4370,135.252403259277,-0.14224000275135,0,0.000369458829164505,99.9020004272461,,,,,,,1.85394710069392e-007,,,,25,0.369458829164505,,,
,16315417.72,4370,133.454299926758,-0.14224000275135,0,0.000369538340568542,29.9950008392334,,,,,,,7.88429020554405e-007,,,,25,0.369538340568542,,,
,16315472.84,4370,131.618301391602,-0.14224000275135,0,0.00036898687005043,99.9020004272461,,,,,,,2.07949913202554e-007,,,,25,0.36898687005043,,,
,16315528.34,4370,129.759651184082,-0.14224000275135,0,0.000368800917863846,29.9950008392334,,,,,,,7.01443688984171e-007,,,,25,0.368800917863846,,,
,16315583.47,4370,127.929004669189,-0.14224000275135,0,0.000368548513650894,99.9020004272461,,,,,,,2.15455603982166e-007,,,,25,0.368548513650894,,,
,16315637.67,4370,126.120151519775,-0.14224000275135,0,0.00036861248254776,29.9950008392334,,,,,,,6.73203724782085e-007,,,,25,0.36861248254776,,,
,16315694.47,4370,124.224300384521,-0.14224000275135,0,0.000368152928352356,99.9020004272461,,,,,,,2.00372034242517e-007,,,,25,0.368152928352356,,,
,16315748.92,4370,122.410549163818,-0.14224000275135,0,0.000367962971925736,29.9950008392334,,,,,,,7.56654397069057e-007,,,,25,0.367962971925735,,,
,16315803.30,4370,120.601249694824,-0.14224000275135,0,0.000367493864297867,99.9020004272461,,,,,,,2.15457713513559e-007,,,,25,0.367493864297867,,,
,16315856.61,4370,118.821998596191,-0.14224000275135,0,0.000367230809926987,29.9950008392334,,,,,,,7.37512719425414e-007,,,,25,0.367230809926987,,,
,16315911.55,4370,116.995300292969,-0.14224000275135,0,0.000366951653957367,99.9020004272461,,,,,,,2.0399670374564e-007,,,,25,0.366951653957367,,,
,16315967.39,4370,115.136302947998,-0.14224000275135,0,0.000366906179189682,29.9950008392334,,,,,,,7.73861083488279e-007,,,,25,0.366906179189682,,,
,16316023.98,4370,113.238899230957,-0.14224000275135,0,0.000366412487030029,99.9020004272461,,,,,,,2.62238462048284e-007,,,,25,0.366412487030029,,,
,16316078.75,4370,111.418949127197,-0.14224000275135,0,0.000366000838279724,29.9950008392334,,,,,,,7.96314390826623e-007,,,,25,0.366000838279724,,,
,16316132.44,4370,109.63245010376,-0.14224000275135,0,0.00036574120759964,99.9020004272461,,,,,,,2.65643001896859e-007,,,,25,0.36574120759964,,,
,16316186.08,4370,107.848251342773,-0.14224000275135,0,0.000365380485057831,29.9950008392334,,,,,,,7.83567049013427e-007,,,,25,0.365380485057831,,,
,16316240.91,4370,106.017402648926,-0.14224000275135,0,0.000364921772480011,99.9020004272461,,,,,,,2.38318020316754e-007,,,,25,0.364921772480011,,,
,16316294.83,4370,104.207450866699,-0.14224000275135,0,0.000364666558504105,29.9950008392334,,,,,,,8.16370947783162e-007,,,,25,0.364666558504105,,,
,16316349.56,4370,102.396598815918,-0.14224000275135,0,0.000364254307746887,99.9020004272461,,,,,,,3.17571693365053e-007,,,,25,0.364254307746887,,,
,16316406.53,4370,100.494300842285,-0.14224000275135,0,0.000363791501522064,29.9950008392334,,,,,,,5.14166078079511e-007,,,,25,0.363791501522064,,,
,16316536.06,4370,100.565250396729,-0.14224000275135,0,0.000363780056238174,99.9020004272461,,,,,,,8.76683650403646e-007,,,,25,0.363780056238174,,,
,16316589.95,4370,102.402297973633,-0.14224000275135,0,0.000364360830783844,29.9950008392334,,,,,,,6.4830237054152e-007,,,,25,0.364360830783844,,,
,16316645.06,4370,104.243450164795,-0.14224000275135,0,0.000364849216938019,99.9020004272461,,,,,,,2.09375482622531e-007,,,,25,0.364849216938019,,,
,16316699.81,4370,106.068050384521,-0.14224000275135,0,0.000365011324882507,29.9950008392334,,,,,,,6.05884009974163e-007,,,,25,0.365011324882507,,,
,16316754.38,4370,107.878700256348,-0.14224000275135,0,0.000365633511543274,99.9020004272461,,,,,,,2.24177232082139e-007,,,,25,0.365633511543274,,,
,16316807.83,4370,109.669448852539,-0.14224000275135,0,0.00036626705288887,29.9950008392334,,,,,,,6.98512431163997e-007,,,,25,0.36626705288887,,,
,16316862.70,4370,111.492500305176,-0.14224000275135,0,0.000366627848148346,99.9020004272461,,,,,,,2.30153322420721e-007,,,,25,0.366627848148346,,,
,16316916.50,4370,113.301197052002,-0.14224000275135,0,0.000366805694103241,29.9950008392334,,,,,,,7.9755707463282e-007,,,,25,0.366805694103241,,,
,16316972.50,4370,115.160049438477,-0.14224000275135,0,0.000367415972948074,99.9020004272461,,,,,,,2.55224735878782e-007,,,,25,0.367415972948074,,,
,16317026.31,4370,116.94750213623,-0.14224000275135,0,0.000367943843603134,29.9950008392334,,,,,,,6.76926239293416e-007,,,,25,0.367943843603134,,,
,16317081.17,4370,118.776149749756,-0.14224000275135,0,0.000368072737455368,99.9020004272461,,,,,,,2.14418429201872e-007,,,,25,0.368072737455368,,,
,16317135.08,4370,120.572902679443,-0.14224000275135,0,0.000368688354492187,29.9950008392334,,,,,,,8.99216543686302e-007,,,,25,0.368688354492188,,,
,16317189.80,4370,122.39245223999,-0.14224000275135,0,0.000368964724540711,99.9020004272461,,,,,,,2.24863830155912e-007,,,,25,0.36896472454071,,,
,16317243.59,4370,124.191398620605,-0.14224000275135,0,0.000369432111978531,29.9950008392334,,,,,,,2.39040468342256e-006,,,,25,0.369432111978531,,,
,16317299.25,4370,126.044200897217,-0.14224000275135,0,0.000369767346382141,99.9020004272461,,,,,,,2.39443584575713e-007,,,,25,0.369767346382141,,,
,16317352.56,4370,127.828948974609,-0.14224000275135,0,0.000370036350488663,29.9950008392334,,,,,,,7.21735443325926e-007,,,,25,0.370036350488663,,,
,16317408.03,4370,129.675453186035,-0.14224000275135,0,0.000370599011182785,99.9020004272461,,,,,,,2.19054603848396e-007,,,,25,0.370599011182785,,,
,16317461.50,4370,131.452499389648,-0.14224000275135,0,0.00037081699848175,29.9950008392334,,,,,,,7.96019847925918e-007,,,,25,0.37081699848175,,,
,16317517.61,4370,133.329948425293,-0.14224000275135,0,0.000371239731311798,99.9020004272461,,,,,,,2.56551123020359e-007,,,,25,0.371239731311798,,,
,16317571.67,4370,135.125450134277,-0.14224000275135,0,0.00037135143995285,29.9950008392334,,,,,,,2.21391808622666e-006,,,,25,0.37135143995285,,,
,16317626.88,4370,136.960952758789,-0.14224000275135,0,0.000372160742282867,99.9020004272461,,,,,,,8.5428473077978e-007,,,,25,0.372160742282867,,,
,16317680.47,4370,138.753005981445,-0.14224000275135,0,0.000373149658441544,29.9950008392334,,,,,,,2.50247505211052e-006,,,,25,0.373149658441544,,,
,16317733.67,4370,140.521499633789,-0.14224000275135,0,0.000378476427793503,99.9020004272461,,,,,,,2.38636970858207e-007,,,,25,0.378476427793503,,,
,16317788.39,4370,142.354751586914,-0.14224000275135,0,0.000381952798366547,29.9950008392334,,,,,,,8.46863951878009e-007,,,,25,0.381952798366547,,,
,16317844.47,4370,144.220100402832,-0.14224000275135,0,0.000388970273733139,99.9020004272461,,,,,,,3.11866078660067e-007,,,,25,0.388970273733139,,,
,16317899.73,4370,146.053756713867,-0.14224000275135,0,0.0003929170358181,29.9950008392334,,,,,,,6.72729579944659e-007,,,,25,0.3929170358181,,,
,16317952.92,4370,147.829444885254,-0.14224000275135,0,0.000395826632976532,99.9020004272461,,,,,,,2.12120040448485e-007,,,,25,0.395826632976532,,,
,16318007.84,4370,149.668998718262,-0.14224000275135,0,0.000398356852531433,29.9950008392334,,,,,,,6.10100188171795e-007,,,,25,0.398356852531433,,,
,16318062.69,4370,151.498352050781,-0.14224000275135,0,0.000402679234743118,99.9020004272461,,,,,,,3.07403206088126e-007,,,,25,0.402679234743118,,,
,16318117.36,4370,153.314399719238,-0.14224000275135,0,0.000403930170536041,29.9950008392334,,,,,,,6.59419941673063e-007,,,,25,0.403930170536041,,,
,16318170.63,4370,155.08740234375,-0.14224000275135,0,0.000403701806068421,99.9020004272461,,,,,,,2.97661869905853e-007,,,,25,0.40370180606842,,,
,16318223.91,4370,156.865303039551,-0.14224000275135,0,0.000403755795955658,29.9950008392334,,,,,,,8.60532252937687e-007,,,,25,0.403755795955658,,,
,16318277.88,4370,158.664398193359,-0.14224000275135,0,0.000403882033824921,99.9020004272461,,,,,,,2.96795963297647e-007,,,,25,0.403882033824921,,,
,16318330.92,4370,160.427352905273,-0.14224000275135,0,0.000404194805622101,29.9950008392334,,,,,,,7.34416309816986e-007,,,,25,0.404194805622101,,,
,16318386.38,4370,162.277648925781,-0.14224000275135,0,0.000416222422122955,99.9020004272461,,,,,,,6.56712791911792e-007,,,,25,0.416222422122955,,,
,16318439.83,4370,164.063652038574,-0.14224000275135,0,0.000420954349040985,29.9950008392334,,,,,,,1.96298664440794e-006,,,,25,0.420954349040985,,,
,16318494.50,4370,165.885055541992,-0.14224000275135,0,0.000421470502614975,99.9020004272461,,,,,,,2.47945025017388e-007,,,,25,0.421470502614975,,,
,16318548.97,4370,167.699645996094,-0.14224000275135,0,0.000421972724199295,29.9950008392334,,,,,,,8.61300912829158e-007,,,,25,0.421972724199295,,,
,16318602.75,4370,169.497398376465,-0.14224000275135,0,0.000422915409803391,99.9020004272461,,,,,,,2.92466387231216e-007,,,,25,0.42291540980339,,,
,16318658.73,4370,171.356452941895,-0.14224000275135,0,0.000424178812503815,29.9950008392334,,,,,,,7.09234080402656e-007,,,,25,0.424178812503815,,,
,16318712.08,4370,173.139450073242,-0.14224000275135,0,0.000425316424369812,99.9020004272461,,,,,,,1.94173076182596e-007,,,,25,0.425316424369812,,,
,16318768.42,4370,175.019554138184,-0.14224000275135,0,0.000426750583648682,29.9950008392334,,,,,,,8.81012352772386e-007,,,,25,0.426750583648682,,,
,16318823.83,4370,176.859802246094,-0.14224000275135,0,0.000428829392194748,99.9020004272461,,,,,,,1.85889537859479e-007,,,,25,0.428829392194748,,,
,16318877.91,4370,178.656105041504,-0.14224000275135,0,0.000434848288297653,29.9950008392334,,,,,,,9.63633353132042e-007,,,,25,0.434848288297653,,,
,16318931.66,4370,180.454154968262,-0.14224000275135,0,0.000440812420845032,99.9020004272461,,,,,,,2.93632212506355e-007,,,,25,0.440812420845032,,,
,16318986.80,4370,182.29460144043,-0.14224000275135,0,0.000442905501127243,29.9950008392334,,,,,,,8.169463438446e-007,,,,25,0.442905501127243,,,
,16319040.84,4370,184.088653564453,-0.14224000275135,0,0.000444181798696518,99.9020004272461,,,,,,,2.40726033435502e-007,,,,25,0.444181798696518,,,
,16319095.63,4370,185.91934967041,-0.14224000275135,0,0.000444912470579147,29.9950008392334,,,,,,,8.33784160991876e-007,,,,25,0.444912470579147,,,
,16319148.84,4370,187.691848754883,-0.14224000275135,0,0.000445973398685455,99.9020004272461,,,,,,,2.50301375921476e-007,,,,25,0.445973398685455,,,
,16319202.88,4370,189.500450134277,-0.14224000275135,0,0.000447111035585404,29.9950008392334,,,,,,,7.48113635491178e-007,,,,25,0.447111035585403,,,
,16319258.41,4370,191.341247558594,-0.14224000275135,0,0.000447763479948044,99.9020004272461,,,,,,,1.86163309055905e-007,,,,25,0.447763479948044,,,
,16319313.33,4370,193.170349121094,-0.14224000275135,0,0.000449773309230804,29.9950008392334,,,,,,,9.63551674094762e-007,,,,25,0.449773309230804,,,
,16319366.77,4370,194.955947875977,-0.14224000275135,0,0.000452745770215988,99.9020004272461,,,,,,,3.24930895165694e-007,,,,25,0.452745770215988,,,
,16319422.70,4370,196.820854187012,-0.14224000275135,0,0.0004563161277771,29.9950008392334,,,,,,,7.76543839273292e-007,,,,25,0.4563161277771,,,
,16319476.58,4370,198.613296508789,-0.14224000275135,0,0.000459889307022095,99.9020004272461,,,,,,,2.35548761847927e-007,,,,25,0.459889307022095,,,
,16319530.72,4370,200.416351318359,-0.14224000275135,0,0.000463564054965973,29.9950008392334,,,,,,,7.0244536578221e-007,,,,25,0.463564054965973,,,
,16319584.45,4370,202.209548950195,-0.14224000275135,0,0.000467343647480011,99.9020004272461,,,,,,,3.59403557483581e-007,,,,25,0.467343647480011,,,
,16319638.42,4370,204.014999389648,-0.14224000275135,0,0.000471050291061401,29.9950008392334,,,,,,,9.86280407584211e-007,,,,25,0.471050291061401,,,
,16319693.61,4370,205.855796813965,-0.14224000275135,0,0.000475001891851425,99.9020004272461,,,,,,,2.52127890844072e-007,,,,25,0.475001891851425,,,
,16319747.64,4370,207.650550842285,-0.14224000275135,0,0.00047944033741951,29.9950008392334,,,,,,,9.51104306479229e-007,,,,25,0.47944033741951,,,
,16319802.44,4370,209.476249694824,-0.14224000275135,0,0.000485040572881699,99.9020004272461,,,,,,,1.95672754507879e-007,,,,25,0.485040572881699,,,
,16319858.89,4370,211.356246948242,-0.14224000275135,0,0.000489822247028351,29.9950008392334,,,,,,,6.07774383369803e-007,,,,25,0.489822247028351,,,
,16319914.66,4370,213.218650817871,-0.14224000275135,0,0.000492409383058548,99.9020004272461,,,,,,,4.09568232798528e-007,,,,25,0.492409383058548,,,
,16319968.89,4370,215.025848388672,-0.14224000275135,0,0.000495746581554413,29.9950008392334,,,,,,,8.0356107189994e-007,,,,25,0.495746581554413,,,
,16320022.41,4370,216.808700561523,-0.14224000275135,0,0.000499063416719437,99.9020004272461,,,,,,,2.55795335920989e-007,,,,25,0.499063416719437,,,
,16320075.84,4370,218.582748413086,-0.14224000275135,0,0.000501788532733917,29.9950008392334,,,,,,,5.64491790318631e-007,,,,25,0.501788532733917,,,
,16320130.36,4370,220.409049987793,-0.14224000275135,0,0.00050317280292511,99.9020004272461,,,,,,,2.6321081211879e-007,,,,25,0.50317280292511,,,
,16320183.86,4370,222.187805175781,-0.14224000275135,0,0.000501407611370087,29.9950008392334,,,,,,,8.30539785076834e-007,,,,25,0.501407611370087,,,
,16320237.58,4370,223.981101989746,-0.14224000275135,0,0.000502750499248505,99.9020004272461,,,,,,,2.78763812119011e-007,,,,25,0.502750499248505,,,
,16320290.94,4370,225.764450073242,-0.14224000275135,0,0.000509177584648132,29.9950008392334,,,,,,,1.10776123728098e-006,,,,25,0.509177584648132,,,
,16320345.91,4370,227.597549438477,-0.14224000275135,0,0.0005211301445961,99.9020004272461,,,,,,,5.07581212183846e-007,,,,25,0.5211301445961,,,
,16320402.34,4370,229.479797363281,-0.14224000275135,0,0.000529963593482971,29.9950008392334,,,,,,,8.97576489125402e-007,,,,25,0.529963593482971,,,
,16320456.81,4370,231.283897399902,-0.14224000275135,0,0.000540411710739136,99.9020004272461,,,,,,,2.3358706527517e-007,,,,25,0.540411710739136,,,
,16320509.84,4370,233.060997009277,-0.14224000275135,0,0.000537981531620026,29.9950008392334,,,,,,,1.1322394914759e-006,,,,25,0.537981531620026,,,
,16320564.06,4370,234.866653442383,-0.14224000275135,0,0.000529747564792633,99.9020004272461,,,,,,,3.6616612783446e-007,,,,25,0.529747564792633,,,
,16320617.59,4370,236.646598815918,-0.14224000275135,0,0.000523772006034851,29.9950008392334,,,,,,,7.99953635972405e-007,,,,25,0.523772006034851,,,
,16320672.89,4370,238.484848022461,-0.14224000275135,0,0.000522780466079712,99.9020004272461,,,,,,,2.77346624344333e-007,,,,25,0.522780466079712,,,
,16320726.98,4370,240.296249389648,-0.14224000275135,0,0.000535251243114472,29.9950008392334,,,,,,,9.34993021494092e-007,,,,25,0.535251243114471,,,
,16320780.63,4370,242.080047607422,-0.14224000275135,0,0.000535556156635284,99.9020004272461,,,,,,,2.45084572604846e-007,,,,25,0.535556156635284,,,
,16320834.83,4370,243.891296386719,-0.14224000275135,0,0.000534641642570496,29.9950008392334,,,,,,,8.18954946043224e-007,,,,25,0.534641642570496,,,
,16320890.31,4370,245.737548828125,-0.14224000275135,0,0.000533979165554047,99.9020004272461,,,,,,,2.88435773607967e-007,,,,25,0.533979165554047,,,
,16320942.97,4370,247.490104675293,-0.14224000275135,0,0.000532743136882782,29.9950008392334,,,,,,,9.03941971061523e-007,,,,25,0.532743136882782,,,
,16320996.55,4370,249.276550292969,-0.14224000275135,0,0.000533231506347656,99.9020004272461,,,,,,,2.51258174081046e-007,,,,25,0.533231506347656,,,
,16321049.92,4370,251.047401428223,-0.14224000275135,0,0.000532809290885925,29.9950008392334,,,,,,,2.20411188285043e-006,,,,25,0.532809290885925,,,
,16321103.77,4370,252.852005004883,-0.14224000275135,0,0.000530806803703308,99.9020004272461,,,,,,,1.99790984629078e-007,,,,25,0.530806803703308,,,
,16321157.17,4370,254.622596740723,-0.14224000275135,0,0.00053154171705246,29.9950008392334,,,,,,,8.16669666696638e-007,,,,25,0.53154171705246,,,
,16321212.58,4370,256.464996337891,-0.14224000275135,0,0.000532920684814453,99.9020004272461,,,,,,,2.92235896923504e-007,,,,25,0.532920684814453,,,
,16321267.31,4370,258.308700561523,-0.14224000275135,0,0.000529720034599304,29.9950008392334,,,,,,,6.25798328794797e-007,,,,25,0.529720034599304,,,
,16321321.86,4370,260.118850708008,-0.14224000275135,0,0.000525970370769501,99.9020004272461,,,,,,,3.44369959655213e-007,,,,25,0.525970370769501,,,
,16321375.84,4370,261.941497802734,-0.14224000275135,0,0.000517488298416138,29.9950008392334,,,,,,,7.66935320338209e-007,,,,25,0.517488298416138,,,
,16321429.53,4370,263.722549438477,-0.14224000275135,0,0.000510310206413269,99.9020004272461,,,,,,,2.52445083828569e-007,,,,25,0.510310206413269,,,
,16321485.77,4370,265.600448608398,-0.14224000275135,0,0.000505999450683594,29.9950008392334,,,,,,,8.6094154779935e-007,,,,25,0.505999450683594,,,
,16321539.38,4370,267.386352539063,-0.14224000275135,0,0.000503023121356964,99.9020004272461,,,,,,,2.87730733980858e-007,,,,25,0.503023121356964,,,
,16321594.33,4370,269.218399047852,-0.14224000275135,0,0.000500706800222397,29.9950008392334,,,,,,,7.08907051421347e-007,,,,25,0.500706800222397,,,
,16321649.78,4370,271.071441650391,-0.14224000275135,0,0.000497460408210754,99.9020004272461,,,,,,,2.06795230713114e-007,,,,25,0.497460408210754,,,
,16321705.39,4370,272.921447753906,-0.14224000275135,0,0.000495504293441773,29.9950008392334,,,,,,,7.43637519822239e-007,,,,25,0.495504293441772,,,
,16321759.44,4370,274.721588134766,-0.14224000275135,0,0.000490991985797882,99.9020004272461,,,,,,,2.73006174233432e-007,,,,25,0.490991985797882,,,
,16321813.94,4370,276.550247192383,-0.14224000275135,0,0.000485322357416153,29.9950008392334,,,,,,,9.23570434975082e-007,,,,25,0.485322357416153,,,
,16321867.78,4370,278.339111328125,-0.14224000275135,0,0.000480051430463791,99.9020004272461,,,,,,,2.30580773015215e-007,,,,25,0.480051430463791,,,
,16321921.03,4370,280.116195678711,-0.14224000275135,0,0.000473962234258652,29.9950008392334,,,,,,,8.49743597386654e-007,,,,25,0.473962234258652,,,
,16321976.36,4370,281.967346191406,-0.14224000275135,0,0.000466611273288727,99.9020004272461,,,,,,,4.81059623067216e-007,,,,25,0.466611273288727,,,
,16322031.47,4370,283.800445556641,-0.14224000275135,0,0.000476369599103928,29.9950008392334,,,,,,,1.58634133723745e-006,,,,25,0.476369599103928,,,
,16322092.77,4370,285.921951293945,-0.14224000275135,0,-46.87861328125,2.24924001228996,,,,,,,0,,,,13,-46878.61328125,,,
,16322163.91,4370,288.295791625977,-0.14224000275135,0,,0.676080003753304,,,,,,,,,,,25,,,,
,16322225.92,4370,290.298355102539,-0.14224000275135,0,-0.000627003891170025,99.9020004272461,,,,,,,0.0040469409994607,,,,25,-0.627003891170025,,,
,16322279.22,4370,292.065460205078,-0.14224000275135,0,-0.000396476181745529,29.9950008392334,,,,,,,0.00406341609447724,,,,25,-0.396476181745529,,,
,16322333.69,4370,293.891448974609,-0.14224000275135,0,0.000518347394913435,99.9020004272461,,,,,,,0.0005276055564276,,,,25,0.518347394913435,,,
,16322389.11,4370,295.740051269531,-0.14224000275135,0,0.000536052468717098,29.9950008392334,,,,,,,0.000807976820267041,,,,25,0.536052468717098,,,
,16322443.61,4370,297.555999755859,-0.14224000275135,0,0.00052165326833725,99.9020004272461,,,,,,,8.19602061030177e-005,,,,25,0.52165326833725,,,
,16322498.13,4370,299.375350952148,-0.14224000275135,0,0.000541933023035526,29.9950008392334,,,,,,,0.000784999449156553,,,,25,0.541933023035526,,,
,16322552.28,4370,301.18244934082,-0.14224000275135,0,0.000489890753030777,99.9020004272461,,,,,,,0.000178543106710558,,,,25,0.489890753030777,,,
,16322606.53,4370,302.985549926758,-0.14224000275135,0,0.00102128687828779,29.9950008392334,,,,,,,0.00161816960815128,,,,25,1.02128687828779,,,
,16322659.66,4370,304.766799926758,-0.14224000275135,0,0.00051855496764183,99.9020004272461,,,,,,,0.000141989710622611,,,,25,0.51855496764183,,,
,16322715.61,4370,306.633911132813,-0.14224000275135,0,0.000587244705855846,29.9950008392334,,,,,,,0.000734521841232602,,,,25,0.587244705855846,,,
,16322770.53,4370,308.47314453125,-0.14224000275135,0,0.000494918862581253,99.9020004272461,,,,,,,0.000107567265827665,,,,25,0.494918862581253,,,
,16322827.06,4370,310.352600097656,-0.14224000275135,0,0.000389411639124155,29.9950008392334,,,,,,,0.000828021724299097,,,,25,0.389411639124155,,,
,16322881.67,4370,312.177459716797,-0.14224000275135,0,0.000567525074183941,99.9020004272461,,,,,,,0.000642314540317233,,,,25,0.567525074183941,,,
,16322936.59,4370,314.009902954102,-0.14224000275135,0,0.00204191748976707,29.9950008392334,,,,,,,0.00574017042798227,,,,25,2.04191748976707,,,
,16322990.39,4370,315.804962158203,-0.14224000275135,0,0.000424447047114372,99.9020004272461,,,,,,,0.000957510038189342,,,,25,0.424447047114372,,,
,16323044.86,4370,317.626052856445,-0.14224000275135,0,-6.61642462015152e-005,29.9950008392334,,,,,,,0.00170635126162031,,,,25,-0.0661642462015152,,,
,16323100.47,4370,319.483505249023,-0.14224000275135,0,-0.0021583500957489,99.706640625,,,,,,,0.0264554000887845,,,,25,-2.1583500957489,,,
,16323154.91,4370,321.30029296875,-0.14224000275135,0,0.0016649468726106,29.9950008392334,,,,,,,0.0292508255760266,,,,25,1.6649468726106,,,
,16323209.67,4370,323.122756958008,-0.14224000275135,0,0.00211961048126221,99.9020004272461,,,,,,,0.00930210312200793,,,,25,2.11961048126221,,,
,16323264.56,4370,324.976058959961,-0.14224000275135,0,0.00210725495219231,29.9950008392334,,,,,,,0.0340464496042972,,,,25,2.10725495219231,,,
,16323319.81,4370,326.811492919922,-0.14224000275135,0,-0.00233467889904976,98.280280456543,,,,,,,0.0317717185045237,,,,25,-2.33467889904976,,,
,16323380.84,4370,328.8291015625,-0.14224000275135,0,0.00888693783044815,29.9950008392334,,,,,,,0.0377621776070159,,,,25,8.88693783044815,,,
,16323451.03,4370,331.241195678711,-0.14224000275135,0,,2.24912001229823,,,,,,,,,,,25,,,,
,16323533.38,4370,334.001754760742,-0.14224000275135,0,,0.676080003753304,,,,,,,,,,,25,,,,
,16323617.16,4370,336.802001953125,-0.14224000275135,0,,1.26524000741541,,,,,,,,,,,25,,,,
,16323701.48,4370,339.597351074219,-0.14224000275135,0,,0.381000009551644,,,,,,,,,,,25,,,,
,16323775.48,4370,342.008895874023,-0.14224000275135,0,0.000440432866811752,99.9020004272461,,,,,,,2.92866824190483e-007,,,,25,0.440432866811752,,,
,16323829.36,4370,343.790145874023,-0.14224000275135,0,0.000438263462781906,29.9950008392334,,,,,,,9.16227364206714e-007,,,,25,0.438263462781906,,,
,16323884.64,4370,345.640640258789,-0.14224000275135,0,0.000434800649881363,99.9020004272461,,,,,,,2.27210177580742e-007,,,,25,0.434800649881363,,,
,16323938.05,4370,347.431396484375,-0.14224000275135,0,0.000431454840898514,29.9950008392334,,,,,,,8.9915599452441e-007,,,,25,0.431454840898514,,,
,16323993.63,4370,349.281799316406,-0.14224000275135,0,0.000426818598508835,99.9020004272461,,,,,,,2.26520471949611e-007,,,,25,0.426818598508835,,,
,16324099.44,4370,350.002395629883,-0.14224000275135,0,0.000418734468221664,29.9950008392334,,,,,,,9.69947291535437e-007,,,,25,0.418734468221664,,,
,16324154.41,4370,348.017395019531,-0.14224000275135,0,0.00041506698846817,99.9020004272461,,,,,,,2.45252505716887e-007,,,,25,0.41506698846817,,,
,16324207.38,4370,346.129150390625,-0.14224000275135,0,0.000411979510784149,29.9950008392334,,,,,,,5.1729546786865e-007,,,,25,0.411979510784149,,,
,16324263.91,4370,344.296890258789,-0.14224000275135,0,0.000409050667285919,99.9020004272461,,,,,,,2.59412438324183e-007,,,,25,0.409050667285919,,,
,16324318.55,4370,342.495407104492,-0.14224000275135,0,0.000406882275342941,29.9950008392334,,,,,,,7.96536514867425e-007,,,,25,0.406882275342941,,,
,16324373.52,4370,340.743103027344,-0.14224000275135,0,0.000405307061672211,99.9020004272461,,,,,,,2.9142380216097e-007,,,,25,0.405307061672211,,,
,16324430.73,4370,338.82958984375,-0.14224000275135,0,0.000403377939462662,29.9950008392334,,,,,,,5.89261505750222e-006,,,,25,0.403377939462662,,,
,16324486.63,4370,336.933944702148,-0.14224000275135,0,0.000402557799816132,99.9020004272461,,,,,,,2.93417078205285e-007,,,,25,0.402557799816132,,,
,16324540.91,4370,335.125549316406,-0.14224000275135,0,0.00040131382226944,29.9950008392334,,,,,,,7.41189112655314e-007,,,,25,0.40131382226944,,,
,16324594.27,4370,333.342346191406,-0.14224000275135,0,0.00040064244389534,99.9020004272461,,,,,,,1.86515678052129e-007,,,,25,0.40064244389534,,,
,16324648.78,4370,331.530258178711,-0.14224000275135,0,0.000400274739265442,29.9950008392334,,,,,,,8.27238959210721e-007,,,,25,0.400274739265442,,,
,16324704.63,4370,329.66569519043,-0.14224000275135,0,0.000399201374053955,99.9020004272461,,,,,,,2.45378446496649e-007,,,,25,0.399201374053955,,,
,16324757.98,4370,327.890747070313,-0.14224000275135,0,0.000397879806756973,29.9950008392334,,,,,,,7.34539526831685e-007,,,,25,0.397879806756973,,,
,16324813.36,4370,326.023986816406,-0.14224000275135,0,0.000397114976644516,99.9020004272461,,,,,,,2.36512845737822e-007,,,,25,0.397114976644516,,,
,16324868.03,4370,324.21110534668,-0.14224000275135,0,0.000396093879938126,29.9950008392334,,,,,,,8.82767148171639e-007,,,,25,0.396093879938126,,,
,16324922.53,4370,322.387802124023,-0.14224000275135,0,0.000395301994085312,99.9020004272461,,,,,,,3.07137915237002e-007,,,,25,0.395301994085312,,,
,16324975.73,4370,320.612258911133,-0.14224000275135,0,0.000394427946805954,29.9950008392334,,,,,,,6.90545532736087e-007,,,,25,0.394427946805954,,,
,16325031.70,4370,318.745895385742,-0.14224000275135,0,0.000393503495454788,99.9020004272461,,,,,,,2.47957010029634e-007,,,,25,0.393503495454788,,,
,16325087.53,4370,316.848709106445,-0.14224000275135,0,0.000392910891771316,29.9950008392334,,,,,,,8.27603784464641e-007,,,,25,0.392910891771317,,,
,16325141.75,4370,315.069702148438,-0.14224000275135,0,0.000391854710578918,99.9020004272461,,,,,,,2.34059995335109e-007,,,,25,0.391854710578918,,,
,16325195.78,4370,313.258544921875,-0.14224000275135,0,0.000391104053258896,29.9950008392334,,,,,,,7.76294866927646e-007,,,,25,0.391104053258896,,,
,16325280.45,4370,310.362747192383,-0.14224000275135,0,-0.146444356164932,20.2625599861145,,,,,,,1.07299505657139,,,,25,-146.444356164932,,,
,16325338.33,4370,308.510009765625,-0.14224000275135,0,0.00445503784418106,29.9950008392334,,,,,,,0.0251093566458555,,,,25,4.45503784418106,,,
,16325394.94,4370,306.610443115234,-0.14224000275135,0,0.00108038242816925,99.9020004272461,,,,,,,0.0153528075735129,,,,25,1.08038242816925,,,
,16325449.42,4370,304.787551879883,-0.14224000275135,0,0.000592638869285583,29.9950008392334,,,,,,,0.0410979001014872,,,,25,0.592638869285584,,,
,16325506.55,4370,302.903137207031,-0.14224000275135,0,0.00218260627985001,99.9020004272461,,,,,,,0.00993430280809362,,,,25,2.18260627985001,,,
,16325560.59,4370,301.09245300293,-0.14224000275135,0,0.000428147002458572,29.9950008392334,,,,,,,5.68000607289708e-006,,,,25,0.428147002458572,,,
,16325606.81,4373,299.753005981445,-0.14224000275135,0,0.0004196830701828,29.9950008392334,,,,,,,1.45190721480302e-006,,,,25,0.4196830701828,,,