File: 研究/抵抗測定/PPMS/180702_IrTe2_1.dat
[Header]
TITLE, default name
FILEOPENTIME,15700217.45,7/2/2018,10:21 AM
BYAPP, Resistivity, 2.1, 1.0
INFO, APPNAME, PPMS MultiVu Application, 1.5.11
INFO, , Sample1 Name
INFO, 1, Sample1 Cross Section
INFO, 1, Sample1 Length
INFO, Ohm-m, Sample1 Units
INFO, , Sample2 Name
INFO, 1, Sample2 Cross Section
INFO, 1, Sample2 Length
INFO, Ohm-m, Sample2 Units
INFO, , Sample3 Name
INFO, 1, Sample3 Cross Section
INFO, 1, Sample3 Length
INFO, Ohm-m, Sample3 Units
INFO, , Sample4 Name
INFO, 1, Sample4 Cross Section
INFO, 1, Sample4 Length
INFO, Ohm-m, Sample4 Units
FIELDGROUP, Resistivity,2,3,4,5,6,7,8,9,10,11,12,13,14,15,16,17,18,19,20,21,22,23,24,25,26,27,28,29,30,31,32,33,34,35,36,37,38,39,40,41
STARTUPGROUP, Resistivity
STARTUPAXIS, X, 2, LINEAR, AUTO
STARTUPAXIS, Y1, 7, LINEAR, AUTO
STARTUPAXIS, Y2, 9, LINEAR, AUTO
STARTUPAXIS, Y3, 11, LINEAR, AUTO
PLOT_APPEARANCE, ALL, HORZ_GRID_ON, VERT_GRID_ON, MARKERS_AND_LINES, ALL_LINES
DATATYPE, TIME, 2
DATATYPE, COMMENT, 1
[Data]
Comment,Time Stamp (sec),Status (code),Temperature (K),Magnetic Field (Oe),Sample Position (deg),Bridge 1 Resistivity (Ohm-m),Bridge 1 Excitation (uA),Bridge 2 Resistivity (Ohm-m),Bridge 2 Excitation (uA),Bridge 3 Resistivity (Ohm-m),Bridge 3 Excitation (uA),Bridge 4 Resistivity (Ohm-m),Bridge 4 Excitation (uA),Bridge 1 Std. Dev. (Ohm-m),Bridge 2 Std. Dev. (Ohm-m),Bridge 3 Std. Dev. (Ohm-m),Bridge 4 Std. Dev. (Ohm-m),Number of Readings,Bridge 1 Resistance (Ohms),Bridge 2 Resistance (Ohms),Bridge 3 Resistance (Ohms),Bridge 4 Resistance (Ohms),Signal 1 Vin (V),Signal 2 Vin (V),Digital Inputs (code),Drive 1 Iout (mA),Drive 1 Ipower (watts),Drive 2 Iout (mA),Drive 2 Ipower (watts),Pressure (),Map 20 (),Map 21 (),Map 22 (),Map 23 (),Map 24 (),Map 25 (),Map 26 (),Map 27 (),Map 28 (),Map 29 ()
,15702836.61,4370,299.993850708008,0.175063997507095,0,2.52742426097393e-005,29.9950008392334,,,,,,,8.83196728919516e-007,,,,25,0.0252742426097393,,,
,15702952.58,4370,296.206649780273,0.175063997507095,0,2.50251080095768e-005,29.9950008392334,,,,,,,4.41375477622749e-007,,,,25,0.0250251080095768,,,
,15703065.09,4370,292.461288452148,0.175063997507095,0,2.48782932758331e-005,29.9950008392334,,,,,,,7.62713833690661e-007,,,,25,0.0248782932758331,,,
,15703182.81,4370,288.541656494141,0.175063997507095,0,2.56704084575176e-005,29.9950008392334,,,,,,,8.26138878069438e-007,,,,25,0.0256704084575176,,,
,15703305.25,4370,284.454650878906,0.175063997507095,0,2.6577293202281e-005,29.9950008392334,,,,,,,9.0185826221753e-007,,,,25,0.026577293202281,,,
,15703428.30,4370,280.352493286133,0.175063997507095,0,2.64850452542305e-005,29.9950008392334,,,,,,,7.46420004453347e-007,,,,25,0.0264850452542305,,,
,15703554.45,4370,276.134506225586,0.175063997507095,0,2.72094818949699e-005,29.9950008392334,,,,,,,1.17701723834082e-006,,,,25,0.0272094818949699,,,
,15703670.47,4370,272.249053955078,0.175063997507095,0,3.15974871814251e-005,29.9950008392334,,,,,,,9.02792031977449e-007,,,,25,0.0315974871814251,,,
,15703788.25,4370,268.339141845703,0.175063997507095,0,3.24306085705757e-005,29.9950008392334,,,,,,,7.209435686703e-007,,,,25,0.0324306085705757,,,
,15703906.91,4370,264.349700927734,0.175063997507095,0,3.22760546952486e-005,29.9950008392334,,,,,,,7.18629417913747e-007,,,,25,0.0322760546952486,,,
,15704031.08,4370,260.245559692383,0.175063997507095,0,3.29575148224831e-005,29.9950008392334,,,,,,,9.03162699700561e-007,,,,25,0.0329575148224831,,,
,15704150.45,4370,256.255401611328,0.175063997507095,0,3.25707226246595e-005,29.9950008392334,,,,,,,9.23799743629422e-007,,,,25,0.0325707226246595,,,
,15704274.36,4370,252.13005065918,0.175063997507095,0,3.20736657083034e-005,29.9950008392334,,,,,,,8.67267431337262e-007,,,,25,0.0320736657083035,,,
,15704393.05,4370,248.167503356934,0.175063997507095,0,3.19784267246723e-005,29.9950008392334,,,,,,,6.56652070858919e-007,,,,25,0.0319784267246723,,,
,15704513.67,4370,244.130401611328,0.175063997507095,0,3.13246200978756e-005,29.9950008392334,,,,,,,8.36690851597454e-007,,,,25,0.0313246200978756,,,
,15704633.34,4370,240.160148620605,0.175063997507095,0,3.12527401745319e-005,29.9950008392334,,,,,,,8.16997580807116e-007,,,,25,0.0312527401745319,,,
,15704753.31,4370,236.150947570801,0.175063997507095,0,3.09351632744074e-005,29.9950008392334,,,,,,,7.89619250142625e-007,,,,25,0.0309351632744074,,,
,15704866.95,4370,232.357246398926,0.175063997507095,0,3.04023493081331e-005,29.9950008392334,,,,,,,5.77235762258677e-007,,,,25,0.0304023493081331,,,
,15704978.50,4370,228.642799377441,0.175063997507095,0,3.05651467293501e-005,29.9950008392334,,,,,,,9.16948360067489e-007,,,,25,0.0305651467293501,,,
,15705101.67,4370,224.537498474121,0.175063997507095,0,2.98857890069485e-005,29.9950008392334,,,,,,,6.49382926608943e-007,,,,25,0.0298857890069485,,,
,15705218.83,4370,220.640800476074,0.175063997507095,0,2.95578920841217e-005,29.9950008392334,,,,,,,7.68396934289201e-007,,,,25,0.0295578920841217,,,
,15705341.33,4370,216.556648254395,0.175063997507095,0,2.93415307253599e-005,29.9950008392334,,,,,,,7.46174970964283e-007,,,,25,0.0293415307253599,,,
,15705467.20,4370,212.362655639648,0.175063997507095,0,2.87648451328278e-005,29.9950008392334,,,,,,,7.50888069267135e-007,,,,25,0.0287648451328278,,,
,15705590.39,4370,208.247200012207,0.175063997507095,0,2.82087501138449e-005,29.9950008392334,,,,,,,7.75578264955907e-007,,,,25,0.0282087501138449,,,
,15705707.66,4370,204.333999633789,0.175063997507095,0,2.7696298584342e-005,29.9950008392334,,,,,,,7.98039021498069e-007,,,,25,0.027696298584342,,,
,15705824.17,4370,200.462394714355,0.175063997507095,0,2.75268214941025e-005,29.9950008392334,,,,,,,7.15373595652874e-007,,,,25,0.0275268214941025,,,
,15705935.81,4370,196.732849121094,0.175063997507095,0,2.70591479539871e-005,29.9950008392334,,,,,,,8.21108540690378e-007,,,,25,0.0270591479539871,,,
,15706058.56,4370,192.650047302246,0.175063997507095,0,2.62712895870209e-005,29.9950008392334,,,,,,,7.83259868594039e-007,,,,25,0.0262712895870209,,,
,15706178.45,4370,188.652450561523,0.175063997507095,0,2.54641310870647e-005,29.9950008392334,,,,,,,7.11321067192087e-007,,,,25,0.0254641310870647,,,
,15706293.00,4370,184.833999633789,0.175063997507095,0,2.50494408607483e-005,29.9950008392334,,,,,,,9.0377184228563e-007,,,,25,0.0250494408607483,,,
,15706410.13,4370,180.93384552002,0.175063997507095,0,2.433199852705e-005,29.9950008392334,,,,,,,1.03816197710862e-006,,,,25,0.02433199852705,,,
,15706532.45,4370,176.855751037598,0.175063997507095,0,2.363415338099e-005,29.9950008392334,,,,,,,6.81350050063153e-007,,,,25,0.02363415338099,,,
,15706652.83,4370,172.844802856445,0.175063997507095,0,2.30485016107559e-005,29.9950008392334,,,,,,,9.24537538719888e-007,,,,25,0.0230485016107559,,,
,15706772.53,4370,168.857749938965,0.175063997507095,0,2.2837665900588e-005,29.9950008392334,,,,,,,8.46020546341665e-007,,,,25,0.022837665900588,,,
,15706887.13,4370,165.02619934082,0.175063997507095,0,2.1851596608758e-005,29.9950008392334,,,,,,,6.6359618185786e-007,,,,25,0.021851596608758,,,
,15707001.19,4370,161.231651306152,0.175063997507095,0,2.16726336628199e-005,29.9950008392334,,,,,,,5.78105787990997e-007,,,,25,0.0216726336628199,,,
,15707123.39,4370,157.15739440918,0.175063997507095,0,2.070248298347e-005,29.9950008392334,,,,,,,7.06301062999367e-007,,,,25,0.02070248298347,,,
,15707244.20,4370,153.131698608398,0.175063997507095,0,2.03079636394978e-005,29.9950008392334,,,,,,,5.57526218836124e-007,,,,25,0.0203079636394978,,,
,15707367.42,4370,149.021598815918,0.175063997507095,0,1.98686181753874e-005,29.9950008392334,,,,,,,8.15777485579032e-007,,,,25,0.0198686181753874,,,
,15707483.78,4370,145.151802062988,0.175063997507095,0,1.94848345965147e-005,29.9950008392334,,,,,,,7.93458909414594e-007,,,,25,0.0194848345965147,,,
,15707600.92,4370,141.23494720459,0.175063997507095,0,1.85534822940826e-005,29.9950008392334,,,,,,,7.58267803276162e-007,,,,25,0.0185534822940826,,,
,15707723.42,4370,137.159744262695,0.175063997507095,0,1.83421248197556e-005,29.9950008392334,,,,,,,8.74706088576885e-007,,,,25,0.0183421248197556,,,
,15707843.34,4370,133.162704467773,0.175063997507095,0,1.76448327302933e-005,29.9950008392334,,,,,,,6.44013780665784e-007,,,,25,0.0176448327302933,,,
,15707961.31,4370,129.232299804688,0.175063997507095,0,1.69637997448444e-005,29.9950008392334,,,,,,,7.70336093021752e-007,,,,25,0.0169637997448444,,,
,15708077.77,4370,125.344097137451,0.175063997507095,0,1.65019310638309e-005,29.9950008392334,,,,,,,8.09231138348111e-007,,,,25,0.0165019310638309,,,
,15708201.25,4370,121.231899261475,0.175063997507095,0,1.58466708660126e-005,29.9950008392334,,,,,,,9.55292755597512e-007,,,,25,0.0158466708660126,,,
,15708326.39,4370,117.066997528076,0.175063997507095,0,1.53378524631262e-005,29.9950008392334,,,,,,,7.04211507607411e-007,,,,25,0.0153378524631262,,,
,15708446.48,4370,113.059146881104,0.175063997507095,0,1.44836654141545e-005,29.9950008392334,,,,,,,7.93503252498597e-007,,,,25,0.0144836654141545,,,
,15708567.33,4370,109.029949188232,0.175063997507095,0,1.39531492069364e-005,29.9950008392334,,,,,,,8.67531952312995e-007,,,,25,0.0139531492069364,,,
,15708683.81,4370,105.14879989624,0.175063997507095,0,1.3296194113791e-005,29.9950008392334,,,,,,,6.12067377328068e-007,,,,25,0.013296194113791,,,
,15708800.47,4370,101.253601074219,0.175063997507095,0,1.28966600820422e-005,29.9950008392334,,,,,,,7.44228341404106e-007,,,,25,0.0128966600820422,,,
,15708918.45,4370,97.3315010070801,0.175063997507095,0,1.22956389188766e-005,29.9950008392334,,,,,,,9.03753055613163e-007,,,,25,0.0122956389188766,,,
,15709041.52,4370,93.2272491455078,0.175063997507095,0,1.18104918673635e-005,29.9950008392334,,,,,,,6.58798940103412e-007,,,,25,0.0118104918673635,,,
,15709167.23,4370,89.0354995727539,0.175063997507095,0,1.08796980977058e-005,29.9950008392334,,,,,,,7.06306805418359e-007,,,,25,0.0108796980977058,,,
,15709292.39,4370,84.8658027648926,0.175063997507095,0,1.03907667845488e-005,29.9950008392334,,,,,,,7.21470407441029e-007,,,,25,0.0103907667845488,,,
,15709413.33,4370,80.8279495239258,0.175063997507095,0,9.72237598150969e-006,29.9950008392334,,,,,,,6.52104789472828e-007,,,,25,0.00972237598150969,,,
,15709538.30,4370,76.6171989440918,0.175063997507095,0,8.94671956077218e-006,29.9950008392334,,,,,,,8.41341585390597e-007,,,,25,0.00894671956077218,,,
,15709661.06,4370,72.5419998168945,0.175063997507095,0,8.37933324277401e-006,29.9950008392334,,,,,,,7.95584741246729e-007,,,,25,0.00837933324277401,,,
,15709774.25,4370,68.7658996582031,0.175063997507095,0,8.03319616243243e-006,29.9950008392334,,,,,,,7.29913192280213e-007,,,,25,0.00803319616243243,,,
,15709892.44,4370,64.8278007507324,0.175063997507095,0,7.28313393890858e-006,29.9950008392334,,,,,,,7.11632373047417e-007,,,,25,0.00728313393890858,,,
,15710015.63,4370,60.7270488739014,0.175063997507095,0,6.85032535344362e-006,29.9950008392334,,,,,,,7.65141106788294e-007,,,,25,0.00685032535344362,,,
,15710138.13,4370,56.6452503204346,0.175063997507095,0,6.1253172531724e-006,29.9950008392334,,,,,,,4.64439226438939e-007,,,,25,0.0061253172531724,,,
,15710263.61,4370,52.4571990966797,0.175063997507095,0,5.62427211552858e-006,29.9950008392334,,,,,,,6.78304372214877e-007,,,,25,0.00562427211552858,,,
,15710381.09,4370,48.5464000701904,0.175063997507095,0,4.88902793265879e-006,29.9950008392334,,,,,,,1.00335356430195e-006,,,,25,0.00488902793265879,,,
,15710497.61,4370,44.6499996185303,0.175063997507095,0,4.52793714590371e-006,29.9950008392334,,,,,,,7.9470376808243e-007,,,,25,0.00452793714590371,,,
,15710615.41,4370,40.7352504730225,0.175063997507095,0,4.22265571542084e-006,29.9950008392334,,,,,,,8.9683622860906e-007,,,,25,0.00422265571542084,,,
,15710741.53,4370,36.5270500183105,0.175063997507095,0,3.54844462126494e-006,29.9950008392334,,,,,,,7.98329025051101e-007,,,,25,0.00354844462126493,,,
,15710867.72,4370,32.3129482269287,0.175063997507095,0,3.48506261594594e-006,29.9950008392334,,,,,,,7.77017610854729e-007,,,,25,0.00348506261594594,,,
,15710990.42,4370,28.2329006195068,0.175063997507095,0,2.63028185348958e-006,29.9950008392334,,,,,,,5.85039222404988e-007,,,,25,0.00263028185348958,,,
,15711112.33,4370,24.1712503433228,0.175063997507095,0,2.61994009371847e-006,29.9950008392334,,,,,,,7.24376819979913e-007,,,,25,0.00261994009371847,,,
,15711233.50,4370,20.1288499832153,0.175063997507095,0,2.53607284277678e-006,29.9950008392334,,,,,,,9.21600451769956e-007,,,,25,0.00253607284277678,,,
,15711355.95,4370,16.0512499809265,0.175063997507095,0,2.19505613204092e-006,29.9950008392334,,,,,,,7.71721992913198e-007,,,,25,0.00219505613204092,,,
,15711481.36,4370,11.8608002662659,0.175063997507095,0,1.76527436822653e-006,29.9950008392334,,,,,,,7.3771210110422e-007,,,,25,0.00176527436822653,,,
,15711650.23,4375,9.15640020370483,0.175063997507095,0,2.4725745676551e-006,29.9950008392334,,,,,,,6.50119099240314e-007,,,,25,0.0024725745676551,,,
,15711786.03,4375,8.26064968109131,0.175063997507095,0,2.14936831966043e-006,29.9950008392334,,,,,,,6.87486647027811e-007,,,,25,0.00214936831966043,,,
,15711956.91,4375,7.18959999084473,0.175063997507095,0,1.98157065431587e-006,29.9950008392334,,,,,,,7.50872034334204e-007,,,,25,0.00198157065431587,,,
,15712215.41,4370,4.00390005111694,0.175063997507095,0,1.88752440037206e-006,29.9950008392334,,,,,,,9.21015254234272e-007,,,,25,0.00188752440037206,,,
,15712422.23,4370,2.63635003566742,0.175063997507095,0,2.12176618369995e-006,29.9950008392334,,,,,,,8.62343211393626e-007,,,,25,0.00212176618369995,,,
,15712545.95,4370,6.76454997062683,0.175063997507095,0,2.05034926068038e-006,29.9950008392334,,,,,,,6.47880137884291e-007,,,,25,0.00205034926068038,,,
,15712665.48,4370,10.7234501838684,0.175063997507095,0,1.92560847150162e-006,29.9950008392334,,,,,,,9.38862769237895e-007,,,,25,0.00192560847150162,,,
,15712788.52,4370,14.8414497375488,0.175063997507095,0,2.14940938865766e-006,29.9950008392334,,,,,,,7.98529137330603e-007,,,,25,0.00214940938865766,,,
,15712908.80,4370,18.8483505249023,0.175063997507095,0,2.44439837988466e-006,29.9950008392334,,,,,,,7.66058307313742e-007,,,,25,0.00244439837988466,,,
,15713031.38,4370,22.9462509155273,0.175063997507095,0,2.42670893669128e-006,29.9950008392334,,,,,,,7.78993253687875e-007,,,,25,0.00242670893669128,,,
,15713148.92,4370,26.8516502380371,0.175063997507095,0,2.95327799627557e-006,29.9950008392334,,,,,,,8.06224023779536e-007,,,,25,0.00295327799627557,,,
,15713269.38,4370,30.8790998458862,0.175063997507095,0,2.78025086503476e-006,29.9950008392334,,,,,,,8.77391710026822e-007,,,,25,0.00278025086503476,,,
,15713391.59,4370,34.9544982910156,0.175063997507095,0,3.44927361235022e-006,29.9950008392334,,,,,,,7.87376425807626e-007,,,,25,0.00344927361235023,,,
,15713514.80,4370,39.0722503662109,0.175063997507095,0,3.72948473785073e-006,29.9950008392334,,,,,,,6.90841149025232e-007,,,,25,0.00372948473785073,,,
,15713637.86,4370,43.1584510803223,0.175063997507095,0,4.42080306820571e-006,29.9950008392334,,,,,,,6.9871217840967e-007,,,,25,0.00442080306820571,,,
,15713763.41,4370,47.3534488677979,0.175063997507095,0,4.74107245914638e-006,29.9950008392334,,,,,,,8.55022632316755e-007,,,,25,0.00474107245914638,,,
,15713886.83,4370,51.4500999450684,0.175063997507095,0,5.28325604274869e-006,29.9950008392334,,,,,,,7.10397363397635e-007,,,,25,0.00528325604274869,,,
,15714012.91,4370,55.6601982116699,0.175063997507095,0,5.64395892433822e-006,29.9950008392334,,,,,,,9.18167854732649e-007,,,,25,0.00564395892433822,,,
,15714132.41,4370,59.6415996551514,0.175063997507095,0,6.6853216663003e-006,29.9950008392334,,,,,,,7.70825627502954e-007,,,,25,0.0066853216663003,,,
,15714252.97,4370,63.6606502532959,0.175063997507095,0,7.0383389480412e-006,29.9950008392334,,,,,,,8.82569534152017e-007,,,,25,0.0070383389480412,,,
,15714378.92,4370,67.8538513183594,0.175063997507095,0,7.49375177547336e-006,29.9950008392334,,,,,,,8.20651166409545e-007,,,,25,0.00749375177547336,,,
,15714492.14,4370,71.6259002685547,0.175063997507095,0,8.10408612713218e-006,29.9950008392334,,,,,,,6.69633791792939e-007,,,,25,0.00810408612713218,,,
,15714612.97,4370,75.6590003967285,0.175063997507095,0,8.74483706429601e-006,29.9950008392334,,,,,,,6.52249246738421e-007,,,,25,0.00874483706429601,,,
,15714739.41,4370,79.8798484802246,0.175063997507095,0,9.5084561035037e-006,29.9950008392334,,,,,,,8.46553315415897e-007,,,,25,0.0095084561035037,,,
,15714861.14,4370,83.9354515075684,0.175063997507095,0,1.03349052369595e-005,29.9950008392334,,,,,,,7.60789251741682e-007,,,,25,0.0103349052369595,,,
,15714984.95,4370,88.0548973083496,0.175063997507095,0,1.1121179535985e-005,29.9950008392334,,,,,,,8.22950135672043e-007,,,,25,0.011121179535985,,,
,15715110.69,4370,92.251049041748,0.175063997507095,0,1.13801695406437e-005,29.9950008392334,,,,,,,8.96871692754509e-007,,,,25,0.0113801695406437,,,
,15715237.77,4370,96.4789505004883,0.175063997507095,0,1.22550981119275e-005,29.9950008392334,,,,,,,6.33996112125048e-007,,,,25,0.0122550981119275,,,
,15715359.75,4370,100.551502227783,0.175063997507095,0,1.28816439956427e-005,29.9950008392334,,,,,,,8.60771458548193e-007,,,,25,0.0128816439956427,,,
,15715470.59,4370,104.238948822021,0.175063997507095,0,1.35623331740499e-005,29.9950008392334,,,,,,,5.74794040553375e-007,,,,25,0.0135623331740499,,,
,15715590.95,4370,108.257549285889,0.175063997507095,0,1.41763324290514e-005,29.9950008392334,,,,,,,8.46905340303333e-007,,,,25,0.0141763324290514,,,
,15715708.36,4370,112.175350189209,0.175063997507095,0,1.43823299184442e-005,29.9950008392334,,,,,,,6.85556479194153e-007,,,,25,0.0143823299184442,,,
,15715818.70,4370,115.850452423096,0.175063997507095,0,1.48935281857848e-005,29.9950008392334,,,,,,,7.32178426130457e-007,,,,25,0.0148935281857848,,,
,15715942.39,4370,119.975402832031,0.175063997507095,0,1.57391960173845e-005,29.9950008392334,,,,,,,8.61767495060706e-007,,,,25,0.0157391960173845,,,
,15716067.98,4370,124.157901763916,0.175063997507095,0,1.63871129229665e-005,29.9950008392334,,,,,,,6.64490274119414e-007,,,,25,0.0163871129229665,,,
,15716187.77,4370,128.147605895996,0.175063997507095,0,1.71933864429593e-005,29.9950008392334,,,,,,,7.96303476645924e-007,,,,25,0.0171933864429593,,,
,15716308.17,4370,132.16130065918,0.175063997507095,0,1.77987484633923e-005,29.9950008392334,,,,,,,5.8653617270636e-007,,,,25,0.0177987484633923,,,
,15716433.81,4370,136.353805541992,0.175063997507095,0,1.82239636778832e-005,29.9950008392334,,,,,,,5.65988230584111e-007,,,,25,0.0182239636778831,,,
,15716551.39,4370,140.27165222168,0.175063997507095,0,1.89963809400797e-005,29.9950008392334,,,,,,,8.38365391164781e-007,,,,25,0.0189963809400797,,,
,15716670.88,4370,144.246452331543,0.175063997507095,0,1.97951672971249e-005,29.9950008392334,,,,,,,7.79994878953232e-007,,,,25,0.0197951672971249,,,
,15716791.25,4370,148.260452270508,0.175063997507095,0,2.07915739715099e-005,29.9950008392334,,,,,,,8.47160410300998e-007,,,,25,0.0207915739715099,,,
,15716913.66,4370,152.33544921875,0.175063997507095,0,2.11022987961769e-005,29.9950008392334,,,,,,,7.50637691366921e-007,,,,25,0.0211022987961769,,,
,15717031.30,4370,156.268898010254,0.175063997507095,0,1.78396762162447e-005,29.9950008392334,,,,,,,7.87781954988424e-007,,,,25,0.0178396762162447,,,
,15717151.38,4370,160.26439666748,0.175063997507095,0,1.7448683232069e-005,29.9950008392334,,,,,,,7.03001625133212e-007,,,,25,0.017448683232069,,,
,15717274.42,4370,164.368751525879,0.175063997507095,0,1.74151374772191e-005,29.9950008392334,,,,,,,2.33733788943406e-006,,,,25,0.0174151374772191,,,
,15717394.33,4370,168.373001098633,0.175063997507095,0,1.7744367197156e-005,29.9950008392334,,,,,,,7.44743410503143e-007,,,,25,0.017744367197156,,,
,15717517.09,4370,172.45719909668,0.175063997507095,0,2.0025185495615e-005,29.9950008392334,,,,,,,6.89735308010182e-007,,,,25,0.020025185495615,,,
,15717642.78,4370,176.642951965332,0.175063997507095,0,2.16527641564608e-005,29.9950008392334,,,,,,,6.59455763793401e-007,,,,25,0.0216527641564608,,,
,15717759.98,4370,180.558250427246,0.175063997507095,0,2.26199375838041e-005,29.9950008392334,,,,,,,6.76923375284666e-007,,,,25,0.0226199375838041,,,
,15717880.52,4370,184.569198608398,0.175063997507095,0,2.3335347622633e-005,29.9950008392334,,,,,,,8.99578722890125e-007,,,,25,0.023335347622633,,,
,15718006.38,4370,188.760498046875,0.175063997507095,0,2.39443415403366e-005,29.9950008392334,,,,,,,8.51895332290832e-007,,,,25,0.0239443415403366,,,
,15718126.72,4370,192.775802612305,0.175063997507095,0,2.40708403289318e-005,29.9950008392334,,,,,,,8.48827016344887e-007,,,,25,0.0240708403289318,,,
,15718240.19,4370,196.554649353027,0.175063997507095,0,2.46176528185606e-005,29.9950008392334,,,,,,,7.73485349491702e-007,,,,25,0.0246176528185606,,,
,15718359.36,4370,200.523895263672,0.175063997507095,0,2.50262330472469e-005,29.9950008392334,,,,,,,7.93113255616961e-007,,,,25,0.0250262330472469,,,
,15718476.89,4370,204.450942993164,0.175063997507095,0,2.4760729521513e-005,29.9950008392334,,,,,,,9.09164297684805e-007,,,,25,0.024760729521513,,,
,15718597.00,4370,208.45059967041,0.175063997507095,0,2.57601727545261e-005,29.9950008392334,,,,,,,7.50054462330908e-007,,,,25,0.0257601727545261,,,
,15718716.80,4370,212.446098327637,0.175063997507095,0,2.60127443820238e-005,29.9950008392334,,,,,,,8.42618885875666e-007,,,,25,0.0260127443820238,,,
,15718830.75,4370,216.24690246582,0.175063997507095,0,2.60563766956329e-005,29.9950008392334,,,,,,,7.25984616938653e-007,,,,25,0.0260563766956329,,,
,15718953.98,4370,220.34854888916,0.175063997507095,0,2.68861152231693e-005,29.9950008392334,,,,,,,8.22200049422072e-007,,,,25,0.0268861152231693,,,
,15719073.91,4370,224.34349822998,0.175063997507095,0,3.08955330401659e-005,29.9950008392334,,,,,,,7.50854921041661e-007,,,,25,0.0308955330401659,,,
,15719193.81,4370,228.336654663086,0.175063997507095,0,3.38908456265926e-005,29.9950008392334,,,,,,,1.14299524646783e-006,,,,25,0.0338908456265926,,,
,15719313.98,4370,232.347846984863,0.175063997507095,0,4.20995035767555e-005,29.9950008392334,,,,,,,9.77968374575374e-007,,,,25,0.0420995035767555,,,
,15719433.64,4370,236.326347351074,0.175063997507095,0,4.05854390561581e-005,29.9950008392334,,,,,,,1.43772143962881e-006,,,,25,0.0405854390561581,,,
,15719551.39,4370,240.259742736816,0.175063997507095,0,4.01315049827099e-005,29.9950008392334,,,,,,,1.35877273913067e-006,,,,25,0.0401315049827099,,,
,15719668.58,4370,244.157897949219,0.175063997507095,0,3.95610657334328e-005,29.9950008392334,,,,,,,1.7344415682776e-006,,,,25,0.0395610657334328,,,
,15719785.08,4370,248.050498962402,0.175063997507095,0,3.9854501336813e-005,29.9950008392334,,,,,,,1.87229268955764e-006,,,,25,0.039854501336813,,,
,15719905.58,4370,252.062446594238,0.175063997507095,0,3.88605812191963e-005,29.9950008392334,,,,,,,1.11630649838573e-006,,,,25,0.0388605812191963,,,
,15720031.89,4370,256.286697387695,0.175063997507095,0,3.75456248223782e-005,29.9950008392334,,,,,,,7.85688178713584e-007,,,,25,0.0375456248223782,,,
,15720150.70,4370,260.237152099609,0.175063997507095,0,3.65021621435881e-005,29.9950008392334,,,,,,,2.12132026002169e-006,,,,25,0.0365021621435881,,,
,15720270.13,4370,264.236145019531,0.175063997507095,0,3.5098474919796e-005,29.9950008392334,,,,,,,1.0432300022289e-006,,,,25,0.035098474919796,,,
,15720384.70,4370,268.052993774414,0.175063997507095,0,3.46895989775658e-005,29.9950008392334,,,,,,,1.29550370710707e-006,,,,25,0.0346895989775658,,,
,15720501.53,4370,271.96305847168,0.175063997507095,0,3.76170529425144e-005,29.9950008392334,,,,,,,1.91320678983188e-006,,,,25,0.0376170529425144,,,
,15720624.83,4370,276.059799194336,0.175063997507095,0,3.90075746178627e-005,29.9950008392334,,,,,,,1.54716548037833e-006,,,,25,0.0390075746178627,,,
,15720743.72,4370,280.030838012695,0.175063997507095,0,3.43206703662872e-005,29.9950008392334,,,,,,,1.36284234849835e-006,,,,25,0.0343206703662872,,,
,15720858.00,4370,283.856048583984,0.175063997507095,0,2.77776870876551e-005,29.9950008392334,,,,,,,1.21860977388656e-006,,,,25,0.0277776870876551,,,
,15720972.30,4370,287.654449462891,0.175063997507095,0,3.83655890822411e-005,29.9950008392334,,,,,,,2.29440078898564e-006,,,,25,0.0383655890822411,,,
,15721092.64,4370,291.675247192383,0.175063997507095,0,4.03454335033893e-005,29.9950008392334,,,,,,,1.48616218292651e-006,,,,25,0.0403454335033894,,,
,15721211.75,4370,295.650451660156,0.175063997507095,0,4.37405568361282e-005,29.9950008392334,,,,,,,2.30692647059188e-006,,,,25,0.0437405568361282,,,
,15721335.34,4370,299.768142700195,0.175063997507095,0,4.43007244169712e-005,29.9950008392334,,,,,,,1.50291148272816e-006,,,,25,0.0443007244169712,,,
,15725194.25,4370,302.548004150391,0.175063997507095,0,4.47146409749985e-005,99.9020004272461,,,,,,,2.85616223819758e-007,,,,25,0.0447146409749985,,,
,15725299.73,4370,306.093002319336,0.175063997507095,0,4.51514704525471e-005,99.9020004272461,,,,,,,3.76108649869362e-007,,,,25,0.0451514704525471,,,
,15725408.03,4370,309.718948364258,0.175063997507095,0,4.5540951192379e-005,99.9020004272461,,,,,,,4.12664877643738e-007,,,,25,0.045540951192379,,,
,15725514.44,4370,313.268249511719,0.175063997507095,0,4.58762113749981e-005,99.9020004272461,,,,,,,3.54326402913506e-007,,,,25,0.0458762113749981,,,
,15725622.38,4370,316.853897094727,0.175063997507095,0,4.61098995804787e-005,99.9020004272461,,,,,,,3.59959769539916e-007,,,,25,0.0461098995804787,,,
,15725731.25,4370,320.500442504883,0.175063997507095,0,4.60671326518059e-005,99.9020004272461,,,,,,,4.65232884295904e-007,,,,25,0.0460671326518059,,,
,15725837.53,4370,324.062057495117,0.175063997507095,0,4.57662397623062e-005,99.9020004272461,,,,,,,4.39943913974297e-007,,,,25,0.0457662397623062,,,
,15725944.28,4370,327.612457275391,0.175063997507095,0,4.54943665862083e-005,99.9020004272461,,,,,,,4.26687118162918e-007,,,,25,0.0454943665862083,,,
,15726050.20,4370,331.142044067383,0.175063997507095,0,4.4994915574789e-005,99.9020004272461,,,,,,,7.63983681915894e-007,,,,25,0.044994915574789,,,
,15726157.03,4370,334.715255737305,0.175063997507095,0,4.47543533146381e-005,99.9020004272461,,,,,,,4.76625962633494e-007,,,,25,0.0447543533146381,,,
,15726263.70,4370,338.249649047852,0.175063997507095,0,4.4021213799715e-005,99.9020004272461,,,,,,,4.81441541147325e-007,,,,25,0.044021213799715,,,
,15726369.95,4370,341.800201416016,0.175063997507095,0,4.40593986213207e-005,99.9020004272461,,,,,,,3.95333012109229e-007,,,,25,0.0440593986213207,,,
,15726478.02,4370,345.424057006836,0.175063997507095,0,4.36943557858467e-005,99.9020004272461,,,,,,,3.77542917272733e-007,,,,25,0.0436943557858467,,,
,15726583.70,4370,348.953643798828,0.175063997507095,0,4.3182685226202e-005,99.9020004272461,,,,,,,3.47372820850907e-007,,,,25,0.043182685226202,,,
,15726737.91,4370,348.506851196289,0.175063997507095,0,4.19569669663906e-005,99.9020004272461,,,,,,,3.5681466075206e-007,,,,25,0.0419569669663906,,,
,15726845.13,4370,344.88069152832,0.175063997507095,0,4.15323568880558e-005,99.9020004272461,,,,,,,2.96998674063579e-007,,,,25,0.0415323568880558,,,
,15726953.66,4370,341.364791870117,0.175063997507095,0,4.12039719521999e-005,99.9020004272461,,,,,,,2.7384665995685e-007,,,,25,0.0412039719521999,,,
,15727063.48,4370,337.692642211914,0.175063997507095,0,4.10741457343102e-005,99.9020004272461,,,,,,,2.64541898131273e-007,,,,25,0.0410741457343101,,,
,15727173.30,4370,334.011505126953,0.175063997507095,0,4.09099534153938e-005,99.9020004272461,,,,,,,2.89005907321835e-007,,,,25,0.0409099534153938,,,
,15727278.86,4370,330.505401611328,0.175063997507095,0,4.05945511162281e-005,99.9020004272461,,,,,,,2.80507180496399e-007,,,,25,0.0405945511162281,,,
,15727386.19,4370,326.911102294922,0.175063997507095,0,4.03868278861046e-005,99.9020004272461,,,,,,,3.11472871526033e-007,,,,25,0.0403868278861046,,,
,15727495.80,4370,323.260299682617,0.175063997507095,0,3.97292910516262e-005,99.9020004272461,,,,,,,3.01774004099739e-007,,,,25,0.0397292910516262,,,
,15727602.55,4370,319.68440246582,0.175063997507095,0,3.90106625854969e-005,99.9020004272461,,,,,,,2.55550336560968e-007,,,,25,0.0390106625854969,,,
,15727714.75,4370,315.939086914063,0.175063997507095,0,3.83332718908787e-005,99.9020004272461,,,,,,,2.74396991336832e-007,,,,25,0.0383332718908787,,,
,15727823.67,4370,312.297698974609,0.175063997507095,0,3.77559252083301e-005,99.9020004272461,,,,,,,2.47466778142578e-007,,,,25,0.0377559252083302,,,
,15727932.56,4370,308.670791625977,0.175063997507095,0,3.73687361180782e-005,99.9020004272461,,,,,,,3.37819371345676e-007,,,,25,0.0373687361180782,,,
,15728041.00,4370,305.044845581055,0.175063997507095,0,3.6698218435049e-005,99.9020004272461,,,,,,,3.01132666912726e-007,,,,25,0.0366982184350491,,,
,15728149.69,4370,301.430358886719,0.175063997507095,0,3.62041135132313e-005,99.9020004272461,,,,,,,2.48317488441891e-007,,,,25,0.0362041135132313,,,
,15728255.95,4370,297.885498046875,0.175063997507095,0,3.58054681122303e-005,99.9020004272461,,,,,,,2.56546495105922e-007,,,,25,0.0358054681122303,,,
,15728362.16,4370,294.334289550781,0.175063997507095,0,3.51700815558434e-005,99.9020004272461,,,,,,,3.40304179878058e-007,,,,25,0.0351700815558434,,,
,15728469.31,4370,290.762451171875,0.175063997507095,0,3.49883238971233e-005,99.9020004272461,,,,,,,2.97936196029916e-007,,,,25,0.0349883238971233,,,
,15728576.72,4370,287.177047729492,0.175063997507095,0,3.47049956023693e-005,99.9020004272461,,,,,,,2.6268444681829e-007,,,,25,0.0347049956023693,,,
,15728684.30,4370,283.580551147461,0.175063997507095,0,3.46675750613213e-005,99.9020004272461,,,,,,,3.09929231302795e-007,,,,25,0.0346675750613213,,,
,15728791.39,4370,280.015808105469,0.175063997507095,0,3.55145038664341e-005,99.9020004272461,,,,,,,2.38074015051138e-007,,,,25,0.0355145038664341,,,
,15728899.42,4370,276.406600952148,0.175063997507095,0,4.69759193062782e-005,99.9020004272461,,,,,,,5.90688746839952e-007,,,,25,0.0469759193062782,,,
,15729007.88,4370,272.78889465332,0.175063997507095,0,4.04662518203259e-005,99.9020004272461,,,,,,,2.77782792455531e-007,,,,25,0.0404662518203259,,,
,15729114.02,4370,269.237762451172,0.175063997507095,0,3.90809215605259e-005,99.9020004272461,,,,,,,2.05307600914933e-007,,,,25,0.0390809215605259,,,
,15729221.45,4370,265.660446166992,0.175063997507095,0,3.84058217704296e-005,99.9020004272461,,,,,,,1.690500484958e-007,,,,25,0.0384058217704296,,,
,15729328.52,4370,262.087142944336,0.175063997507095,0,3.40520441532135e-005,99.9020004272461,,,,,,,2.22065484295807e-007,,,,25,0.0340520441532135,,,
,15729435.39,4370,258.52360534668,0.175063997507095,0,3.40596808493137e-005,99.9020004272461,,,,,,,2.68078675496804e-007,,,,25,0.0340596808493137,,,
,15729543.89,4370,254.907402038574,0.175063997507095,0,3.38679958879948e-005,99.9020004272461,,,,,,,1.92739792750987e-007,,,,25,0.0338679958879948,,,
,15729648.83,4370,251.399047851563,0.175063997507095,0,3.34945525228977e-005,99.9020004272461,,,,,,,2.5614223725243e-007,,,,25,0.0334945525228977,,,
,15729758.42,4370,247.738998413086,0.175063997507095,0,3.47691455483437e-005,99.9020004272461,,,,,,,2.92220372180532e-007,,,,25,0.0347691455483437,,,
,15729865.28,4370,244.185806274414,0.175063997507095,0,3.65065336227417e-005,99.9020004272461,,,,,,,1.78228324072577e-007,,,,25,0.0365065336227417,,,
,15729971.47,4370,240.647201538086,0.175063997507095,0,3.63331770896912e-005,99.9020004272461,,,,,,,2.24118142483668e-007,,,,25,0.0363331770896912,,,
,15730078.69,4370,237.076194763184,0.175063997507095,0,3.61598198115826e-005,99.9020004272461,,,,,,,2.06794858006418e-007,,,,25,0.0361598198115826,,,
,15730185.91,4370,233.494750976563,0.175063997507095,0,3.58955834805966e-005,99.9020004272461,,,,,,,2.41095929607377e-007,,,,25,0.0358955834805965,,,
,15730292.55,4370,229.947799682617,0.175063997507095,0,3.53105998039246e-005,99.9020004272461,,,,,,,2.33400674246532e-007,,,,25,0.0353105998039246,,,
,15730401.86,4370,226.307350158691,0.175063997507095,0,3.48951542377472e-005,99.9020004272461,,,,,,,2.31985518960021e-007,,,,25,0.0348951542377472,,,
,15730508.92,4370,222.73705291748,0.175063997507095,0,3.43338438868523e-005,99.9020004272461,,,,,,,2.61762610191688e-007,,,,25,0.0343338438868523,,,
,15730614.23,4370,219.230995178223,0.175063997507095,0,3.38206470012665e-005,99.9020004272461,,,,,,,2.52887782672863e-007,,,,25,0.0338206470012665,,,
,15730720.92,4370,215.667098999023,0.175063997507095,0,3.33189037442207e-005,99.9020004272461,,,,,,,2.33185876915504e-007,,,,25,0.0333189037442207,,,
,15730829.20,4370,212.070693969727,0.175063997507095,0,3.2782796472311e-005,99.9020004272461,,,,,,,1.73385603939654e-007,,,,25,0.032782796472311,,,
,15730936.45,4370,208.483596801758,0.175063997507095,0,3.23024362325668e-005,99.9020004272461,,,,,,,2.13212707069587e-007,,,,25,0.0323024362325668,,,
,15731042.75,4370,204.944953918457,0.175063997507095,0,3.16594120115042e-005,99.9020004272461,,,,,,,2.28359525873568e-007,,,,25,0.0316594120115042,,,
,15731148.17,4370,201.42414855957,0.175063997507095,0,3.11355210840702e-005,99.9020004272461,,,,,,,2.48697572536843e-007,,,,25,0.0311355210840702,,,
,15731253.69,4370,197.90625,0.175063997507095,0,3.08201184868812e-005,99.9020004272461,,,,,,,2.03957119572419e-007,,,,25,0.0308201184868813,,,
,15731362.02,4370,194.29759979248,0.175063997507095,0,3.04466765373945e-005,99.9020004272461,,,,,,,1.97122343071922e-007,,,,25,0.0304466765373945,,,
,15731468.47,4370,190.754447937012,0.175063997507095,0,2.98784931749105e-005,99.9020004272461,,,,,,,2.17314982164464e-007,,,,25,0.0298784931749105,,,
,15731574.64,4370,187.220695495605,0.175063997507095,0,2.93400938808918e-005,99.9020004272461,,,,,,,1.84100413353858e-007,,,,25,0.0293400938808918,,,
,15731681.80,4370,183.640350341797,0.175063997507095,0,2.88001669943333e-005,99.9020004272461,,,,,,,2.51329223006365e-007,,,,25,0.0288001669943333,,,
,15731788.42,4370,180.085151672363,0.175063997507095,0,2.82205282896757e-005,99.9020004272461,,,,,,,2.21490201989495e-007,,,,25,0.0282205282896757,,,
,15731894.89,4370,176.537200927734,0.175063997507095,0,2.75400833785534e-005,99.9020004272461,,,,,,,1.70605260816712e-007,,,,25,0.0275400833785534,,,
,15732003.42,4370,172.918197631836,0.175063997507095,0,2.70192482322455e-005,99.9020004272461,,,,,,,2.51727413211717e-007,,,,25,0.0270192482322454,,,
,15732109.80,4370,169.380195617676,0.175063997507095,0,2.64686303585768e-005,99.9020004272461,,,,,,,2.43116421351715e-007,,,,25,0.0264686303585768,,,
,15732216.84,4370,165.807548522949,0.175063997507095,0,2.82716953754425e-005,99.9020004272461,,,,,,,5.72204874846108e-007,,,,25,0.0282716953754425,,,
,15732324.50,4370,162.224647521973,0.175063997507095,0,2.77783533930778e-005,99.9020004272461,,,,,,,6.76207938022602e-007,,,,25,0.0277783533930779,,,
,15732432.50,4370,158.625099182129,0.175063997507095,0,2.71299831569195e-005,99.9020004272461,,,,,,,1.87980339159113e-006,,,,25,0.0271299831569195,,,
,15732540.64,4370,155.016647338867,0.175063997507095,0,2.78188290446997e-005,99.9020004272461,,,,,,,5.06545664787383e-006,,,,25,0.0278188290446997,,,
,15732648.39,4370,151.428695678711,0.175063997507095,0,2.59752885997295e-005,99.9020004272461,,,,,,,3.93231077298218e-006,,,,25,0.0259752885997295,,,
,15732755.02,4370,147.868148803711,0.175063997507095,0,2.53979412093759e-005,99.9020004272461,,,,,,,5.59267320412815e-006,,,,25,0.0253979412093759,,,
,15732861.86,4370,144.308395385742,0.175063997507095,0,2.48312849551439e-005,99.9020004272461,,,,,,,3.65067975059649e-006,,,,25,0.0248312849551439,,,
,15732970.83,4370,140.677200317383,0.175063997507095,0,2.42394278198481e-005,99.9020004272461,,,,,,,3.53709158806381e-006,,,,25,0.0242394278198481,,,
,15733078.28,4370,137.099601745605,0.175063997507095,0,2.21377608459443e-005,99.9020004272461,,,,,,,7.19529426716785e-006,,,,25,0.0221377608459443,,,
,15733185.44,4370,133.525497436523,0.175063997507095,0,2.18139577656984e-005,99.9020004272461,,,,,,,3.059970976831e-006,,,,25,0.0218139577656984,,,
,15733291.84,4370,129.971206665039,0.175063997507095,0,2.18765799328685e-005,99.9020004272461,,,,,,,3.58545466985646e-006,,,,25,0.0218765799328685,,,
,15733400.70,4370,126.35599899292,0.175063997507095,0,2.15680504590273e-005,99.9020004272461,,,,,,,4.07676835325807e-006,,,,25,0.0215680504590273,,,
,15733507.33,4370,122.794399261475,0.175063997507095,0,2.03766987472773e-005,99.9020004272461,,,,,,,3.65634882261162e-007,,,,25,0.0203766987472773,,,
,15733615.61,4370,119.185947418213,0.175063997507095,0,1.74135921895504e-005,99.9020004272461,,,,,,,2.33036238423377e-005,,,,25,0.0174135921895504,,,
,15733723.69,4370,115.585597991943,0.175063997507095,0,1.90058799833059e-005,99.9020004272461,,,,,,,1.96203344030061e-007,,,,25,0.0190058799833059,,,
,15733831.31,4370,112.003498077393,0.175063997507095,0,1.83934032171965e-005,99.9020004272461,,,,,,,1.9380185339988e-007,,,,25,0.0183934032171965,,,
,15733938.70,4370,108.42594909668,0.175063997507095,0,1.76931024342775e-005,99.9020004272461,,,,,,,2.38125994770348e-007,,,,25,0.0176931024342775,,,
,15734045.45,4370,104.862300872803,0.175063997507095,0,1.70034930109978e-005,99.9020004272461,,,,,,,2.02052485842862e-007,,,,25,0.0170034930109978,,,
,15734152.55,4370,101.292900085449,0.175063997507095,0,1.62627167254686e-005,99.9020004272461,,,,,,,2.44618374078134e-007,,,,25,0.0162627167254686,,,
,15734333.33,4370,101.600250244141,0.175063997507095,0,1.62588981539011e-005,99.9020004272461,,,,,,,1.91684128102037e-007,,,,25,0.0162588981539011,,,
,15734439.63,4370,105.156997680664,0.175063997507095,0,1.70241127163172e-005,99.9020004272461,,,,,,,2.14969475235574e-007,,,,25,0.0170241127163172,,,
,15734547.63,4370,108.758850097656,0.175063997507095,0,1.76152063906193e-005,99.9020004272461,,,,,,,1.72031421460691e-007,,,,25,0.0176152063906193,,,
,15734654.16,4370,112.313800811768,0.175063997507095,0,1.83827113360167e-005,99.9020004272461,,,,,,,2.9703789206456e-007,,,,25,0.0183827113360167,,,
,15734762.83,4370,115.93314743042,0.175063997507095,0,1.91471620649099e-005,99.9020004272461,,,,,,,2.82890090547023e-007,,,,25,0.0191471620649099,,,
,15734869.02,4370,119.471748352051,0.175063997507095,0,1.98298978805542e-005,99.9020004272461,,,,,,,2.33635965639331e-007,,,,25,0.0198298978805542,,,
,15734974.95,4370,122.997901916504,0.175063997507095,0,2.04339751601219e-005,99.9020004272461,,,,,,,2.05807443669367e-007,,,,25,0.0204339751601219,,,
,15735081.27,4370,126.541999816895,0.175063997507095,0,2.1073180809617e-005,99.9020004272461,,,,,,,5.51583124994538e-007,,,,25,0.021073180809617,,,
,15735190.42,4370,130.178146362305,0.175063997507095,0,0.000796429141759873,99.9020004272461,,,,,,,0.00332105704270356,,,,25,0.796429141759872,,,
,15735298.00,4370,133.761795043945,0.175063997507095,0,-0.000123128589391708,99.9020004272461,,,,,,,0.00499716472248059,,,,25,-0.123128589391708,,,
,15735404.84,4370,137.33065032959,0.175063997507095,0,-0.004784150775671,99.9020004272461,,,,,,,0.00799326932286007,,,,25,-4.78415077567101,,,
,15735513.33,4370,140.946952819824,0.175063997507095,0,0.000527479699850082,99.9020004272461,,,,,,,0.00615385372906843,,,,25,0.527479699850082,,,
,15735620.03,4370,144.509994506836,0.175063997507095,0,0.000390665902197361,99.9020004272461,,,,,,,0.00577342131387941,,,,25,0.390665902197361,,,
,15735728.14,4370,148.104705810547,0.175063997507095,0,0.00117862180054188,99.9020004272461,,,,,,,0.00446200330236596,,,,25,1.17862180054188,,,
,15735835.48,4370,151.683952331543,0.175063997507095,0,0.000210933379530907,99.9020004272461,,,,,,,0.00526881258256585,,,,25,0.210933379530907,,,
,15735942.50,4370,155.246543884277,0.175063997507095,0,-0.000984751682281494,99.9020004272461,,,,,,,0.00475828649903081,,,,25,-0.984751682281494,,,
,15736049.06,4370,158.800804138184,0.175063997507095,0,-0.0010366600549221,99.9020004272461,,,,,,,0.0037282634418002,,,,25,-1.0366600549221,,,
,15736156.64,4370,162.392654418945,0.175063997507095,0,-0.000837455402910709,99.6968807983398,,,,,,,0.00821076565716907,,,,25,-0.837455402910709,,,
,15736298.06,4370,167.171348571777,0.175063997507095,0,,1.26524000741541,,,,,,,,,,,25,,,,
,15736415.42,4370,171.007850646973,0.175063997507095,0,-8.21113109588619e-006,99.9020004272461,,,,,,,0.00242308880012794,,,,25,-0.00821113109588623,,,
,15736524.36,4370,174.639099121094,0.175063997507095,0,-0.00328052445173264,78.3488404846191,,,,,,,0.013270153690795,,,,25,-3.28052445173264,,,
,15736631.48,4370,178.215797424316,0.175063997507095,0,-0.00198705908179283,99.4722406005859,,,,,,,0.0133590509468283,,,,25,-1.98705908179283,,,
,15736738.06,4370,181.769599914551,0.175063997507095,0,7.48566567897796e-005,99.9020004272461,,,,,,,0.00493623548879092,,,,25,0.0748566567897797,,,
,15736859.45,4370,185.813446044922,0.175063997507095,0,-1.94561782592773,0.215479997396469,,,,,,,5.03343358103388,,,,25,-1945.61782592773,,,
,15737001.09,4370,190.607398986816,0.175063997507095,0,,2.24912001229823,,,,,,,,,,,25,,,,
,15737161.56,4370,195.875602722168,0.175063997507095,0,0.00203399135529995,99.9020004272461,,,,,,,0.020241032235959,,,,25,2.03399135529995,,,
,15737271.36,4370,199.544548034668,0.175063997507095,0,0.00196928493976593,99.9020004272461,,,,,,,0.0113889324497036,,,,25,1.96928493976593,,,
,15737390.83,4370,203.604293823242,0.175063997507095,0,-0.0259046394634247,50.8967601776123,,,,,,,0.0685882423119237,,,,25,-25.9046394634247,,,
,15737538.00,4370,208.431953430176,0.175063997507095,0,0.00104531973138452,99.9020004272461,,,,,,,0.0114303308510162,,,,25,1.04531973138452,,,
,15737681.45,4370,213.22859954834,0.175063997507095,0,266.55628156181,0.0193600002583116,,,,,,,986.593420124658,,,,24,266556.28156181,,,
,15737815.94,4370,217.692749023438,0.175063997507095,0,-0.0077992031468451,99.4819204711914,,,,,,,0.0265606692489679,,,,25,-7.7992031468451,,,
,15737940.45,4370,221.892601013184,0.175063997507095,0,-0.394200031938553,63.696160363555,,,,,,,5.40864216479006,,,,25,-394.200031938553,,,
,15738092.94,4370,226.920501708984,0.175063997507095,0,0.000419231407642365,99.9020004272461,,,,,,,0.0136713479984366,,,,25,0.419231407642365,,,
,15738200.48,4370,230.514701843262,0.175063997507095,0,-9.350636780262e-005,99.9020004272461,,,,,,,0.00449293053711098,,,,25,-0.0935063678026199,,,
,15738310.38,4370,234.156600952148,0.175063997507095,0,0.000250223126523197,99.9020004272461,,,,,,,0.000644790830389827,,,,25,0.250223126523197,,,
,15738417.34,4370,237.731651306152,0.175063997507095,0,2.31282645044848e-005,99.9020004272461,,,,,,,0.00019598845892091,,,,25,0.0231282645044848,,,
,15738522.92,4370,241.250953674316,0.175063997507095,0,5.60454678535461e-005,99.9020004272461,,,,,,,2.74934077742515e-007,,,,25,0.0560454678535461,,,
,15738629.14,4370,244.799003601074,0.175063997507095,0,5.64708411693573e-005,99.9020004272461,,,,,,,2.6967904974242e-007,,,,25,0.0564708411693573,,,
,15738736.61,4370,248.374450683594,0.175063997507095,0,5.69382160902023e-005,99.9020004272461,,,,,,,2.77172241868614e-007,,,,25,0.0569382160902023,,,
,15738843.91,4370,251.959403991699,0.175063997507095,0,5.71543398499489e-005,99.9020004272461,,,,,,,3.3393344558923e-007,,,,25,0.0571543398499489,,,
,15738951.95,4370,255.565399169922,0.175063997507095,0,5.74979993700981e-005,99.9020004272461,,,,,,,2.88185689235592e-007,,,,25,0.0574979993700981,,,
,15739057.27,4370,259.071899414063,0.175063997507095,0,5.7546111792326e-005,99.9020004272461,,,,,,,2.63739653154526e-007,,,,25,0.057546111792326,,,
,15739162.72,4370,262.585800170898,0.175063997507095,0,5.78561697900296e-005,99.9020004272461,,,,,,,2.51373485988746e-007,,,,25,0.0578561697900295,,,
,15739276.48,4370,266.380645751953,0.175063997507095,0,5.81581375002861e-005,29.9950008392334,,,,,,,7.64384499839023e-007,,,,25,0.0581581375002861,,,
,15739383.72,4370,269.964004516602,0.175063997507095,0,5.84213022887707e-005,29.9950008392334,,,,,,,7.45099478593779e-007,,,,25,0.0584213022887707,,,
,15739492.53,4370,273.594848632813,0.175063997507095,0,5.90663222968578e-005,29.9950008392334,,,,,,,7.00358761821613e-007,,,,25,0.0590663222968578,,,
,15739598.75,4370,277.145599365234,0.175063997507095,0,6.02997004985809e-005,29.9950008392334,,,,,,,7.78887907221797e-007,,,,25,0.0602997004985809,,,
,15739705.30,4370,280.693054199219,0.175063997507095,0,6.42458310723305e-005,29.9950008392334,,,,,,,7.51015793598435e-007,,,,25,0.0642458310723305,,,
,15739813.08,4370,284.298553466797,0.175063997507095,0,7.31601670384407e-005,29.9950008392334,,,,,,,8.95932780071192e-007,,,,25,0.0731601670384407,,,
,15739922.44,4370,287.937545776367,0.175063997507095,0,5.35743084549904e-005,29.9950008392334,,,,,,,6.8447814590539e-007,,,,25,0.0535743084549904,,,
,15740029.53,4370,291.510848999023,0.175063997507095,0,5.20814526081085e-005,29.9950008392334,,,,,,,9.99302548401394e-007,,,,25,0.0520814526081085,,,
,15740134.88,4370,295.028045654297,0.175063997507095,0,5.37705248594284e-005,29.9950008392334,,,,,,,8.61536277348225e-007,,,,25,0.0537705248594284,,,
,15740244.55,4370,298.706649780273,0.175063997507095,0,5.30564196407795e-005,29.9950008392334,,,,,,,6.87443525050405e-007,,,,25,0.0530564196407795,,,
,15740353.66,4370,302.334197998047,0.175063997507095,0,5.32310764491558e-005,29.9950008392334,,,,,,,7.4982176095862e-007,,,,25,0.0532310764491558,,,
,15740460.48,4370,305.895843505859,0.175063997507095,0,5.27780817449093e-005,29.9950008392334,,,,,,,9.06267163915795e-007,,,,25,0.0527780817449093,,,
,15740567.19,4370,309.464859008789,0.175063997507095,0,5.25649708509445e-005,29.9950008392334,,,,,,,7.50706436368399e-007,,,,25,0.0525649708509445,,,
,15740674.67,4370,313.042495727539,0.175063997507095,0,5.33402819931507e-005,29.9950008392334,,,,,,,7.29942595332369e-007,,,,25,0.0533402819931507,,,
,15740781.97,4370,316.623596191406,0.175063997507095,0,5.2854163646698e-005,29.9950008392334,,,,,,,7.29671424348503e-007,,,,25,0.052854163646698,,,
,15740887.58,4370,320.156951904297,0.175063997507095,0,5.27645815908909e-005,29.9950008392334,,,,,,,5.93341886556142e-007,,,,25,0.0527645815908909,,,
,15740996.16,4370,323.769195556641,0.175063997507095,0,5.28603771328926e-005,29.9950008392334,,,,,,,7.4341064708419e-007,,,,25,0.0528603771328926,,,
,15741102.52,4370,327.320709228516,0.175063997507095,0,5.24753591418266e-005,29.9950008392334,,,,,,,5.96953059542359e-007,,,,25,0.0524753591418266,,,
,15741208.86,4370,330.859039306641,0.175063997507095,0,5.15754829347134e-005,29.9950008392334,,,,,,,6.38324643986716e-007,,,,25,0.0515754829347134,,,
,15741317.72,4370,334.506698608398,0.175063997507095,0,5.0519757270813e-005,29.9950008392334,,,,,,,8.71247529578723e-007,,,,25,0.050519757270813,,,
,15741424.73,4370,338.076446533203,0.175063997507095,0,5.0522593408823e-005,29.9950008392334,,,,,,,7.72220624543968e-007,,,,25,0.050522593408823,,,
,15741531.36,4370,341.615493774414,0.175063997507095,0,4.9697605073452e-005,29.9950008392334,,,,,,,5.8868406717844e-007,,,,25,0.049697605073452,,,
,15741638.58,4370,345.216201782227,0.175063997507095,0,4.96500663459301e-005,29.9950008392334,,,,,,,6.98163824216432e-007,,,,25,0.0496500663459301,,,
,15741746.31,4370,348.801849365234,0.175063997507095,0,4.91415718197823e-005,29.9950008392334,,,,,,,8.92330314454787e-007,,,,25,0.0491415718197823,,,
,15741931.41,4370,348.903945922852,0.175063997507095,0,4.81660448014736e-005,29.9950008392334,,,,,,,9.22406272776509e-007,,,,25,0.0481660448014736,,,
,15742037.06,4370,345.253860473633,0.175063997507095,0,4.76938402652741e-005,29.9950008392334,,,,,,,6.85612901226962e-007,,,,25,0.047693840265274,,,
,15742143.02,4370,341.774459838867,0.175063997507095,0,4.74646294116974e-005,29.9950008392334,,,,,,,8.84838016346959e-007,,,,25,0.0474646294116974,,,
,15742253.50,4370,338.096496582031,0.175063997507095,0,4.66016955673695e-005,29.9950008392334,,,,,,,9.57549156884589e-007,,,,25,0.0466016955673695,,,
,15742360.91,4370,334.500793457031,0.175063997507095,0,4.49479603767395e-005,29.9950008392334,,,,,,,8.11609620231512e-007,,,,25,0.0449479603767395,,,
,15742469.11,4370,330.896408081055,0.175063997507095,0,4.44968712329864e-005,29.9950008392334,,,,,,,8.68773375044947e-007,,,,25,0.0444968712329865,,,
,15742576.34,4370,327.320159912109,0.175063997507095,0,4.41530318558216e-005,29.9950008392334,,,,,,,8.91701568405687e-007,,,,25,0.0441530318558216,,,
,15742682.00,4370,323.788208007813,0.175063997507095,0,4.46436959505081e-005,29.9950008392334,,,,,,,9.00662313862433e-007,,,,25,0.0446436959505081,,,
,15742789.55,4370,320.202346801758,0.175063997507095,0,4.45526976883411e-005,29.9950008392334,,,,,,,7.6570610159541e-007,,,,25,0.0445526976883411,,,
,15742895.44,4370,316.645599365234,0.175063997507095,0,4.47249631583691e-005,29.9950008392334,,,,,,,8.50273396898211e-007,,,,25,0.0447249631583691,,,
,15743001.56,4370,313.118453979492,0.175063997507095,0,4.42345760762692e-005,29.9950008392334,,,,,,,8.39670637822334e-007,,,,25,0.0442345760762691,,,
,15743111.05,4370,309.461761474609,0.175063997507095,0,4.39122381806374e-005,29.9950008392334,,,,,,,8.31901747362127e-007,,,,25,0.0439122381806374,,,
,15743218.95,4370,305.854644775391,0.175063997507095,0,4.38205908238888e-005,29.9950008392334,,,,,,,9.44886982846716e-007,,,,25,0.0438205908238888,,,
,15743325.64,4370,302.300094604492,0.175063997507095,0,4.38678480684757e-005,29.9950008392334,,,,,,,8.36171878349742e-007,,,,25,0.0438678480684757,,,
,15743418.48,4373,299.847854614258,0.175063997507095,0,4.38900776207447e-005,29.9950008392334,,,,,,,7.528414260505e-007,,,,25,0.0438900776207447,,,