File: 研究/抵抗測定/PPMS/190618/Log/190618.dat
[Header]
; Copyright 1997-99, Quantum Design, Inc. All rights reserved.
TITLE, PPMS Log Data File
FILEOPENTIME,14575207.69,6/18/2019,4:49 PM
BYAPP, LogData, 1.1, 2.0
INFO, APPNAME, PPMS MultiVu Application, 1.5.11
FIELDGROUP, Standard,2,3,4,5,6,7,8,9,10,11,12,13,14,15,16,17,18,19,20,21,22,23,24,25,26,27,28,29,30,31,32
FIELDGROUP, Diagnostic,2,32,33,34,35,36,37,38,39,40,41,42,43,44,45,46,47,48,49,50,51,52,53,54
FIELDGROUP, User,2,64,65,66,67,68,69,70,71,72,73,74,75,76,77,78,79,80,81,82,83,84,85,86,87,88,89,90,91,92,93
FIELDGROUP, MAP User,2,96,97,98,99,100,101,102,103,104,105,106,107,108,109,110,111,112,113,114,115,116,117,118,119,120,121,122,123,124,125
STARTUPGROUP, All
STARTUPAXIS, X, 2, LINEAR, AUTO
STARTUPAXIS, Y1, 4, LINEAR, AUTO
TIMEMODE, MINUTES, RELATIVE
PLOT_APPEARANCE, ALL, HORZ_GRID_ON, VERT_GRID_ON, MARKERS_AND_LINES, ALL_LINES
RECORDS, ALL_RECORDS
DATATYPE, TIME, 2
DATATYPE, COMMENT, 1
[Data]
Comment,Time Stamp (sec),Status (code),Temperature (K),Magnetic Field (Oe),Sample Position (deg),Bridge 1 Resistance (ohms),Bridge 1 Excitation (uA),Bridge 2 Resistance (ohms),Bridge 2 Excitation (uA),Bridge 3 Resistance (ohms),Bridge 3 Excitation (uA),Bridge 4 Resistance (ohms),Bridge 4 Excitation (uA),Signal 1 Vin (V),Signal 2 Vin (V),Digital Inputs (code),Drive 1 Iout (mA),Drive 1 Ipower (watts),Drive 2 Iout (mA),Drive 2 Ipower (watts),Pressure (),Map 20 (),Map 21 (),Map 22 (),Map 23 (),Map 24 (),Map 25 (),Map 26 (),Map 27 (),Map 28 (),Map 29 (),System Status (code),Setpoint (K),Magnet (Oe),Valve Position (deg),CIG/Cernox (K),CIG Excit (uA),Plat Therm (K),Plat Excit (uA),Neck Therm (K),Neck Excit (uA),Spare Therm (K),Spare Excit (uA),Flow Rate (l/min),Annulus Vacuum (V),Impedance (mode),Block Htr Cur (mA),Block Htr Pwr (W),Neck Htr Cur (mA),Neck Htr Pwr (W),Annulus Pres (Torr),System Pres (Torr),Tableless Map53 (),Tableless Map54 (),Redirected 55 (),Redirected 56 (),Redirected 57 (),Redirected 58 (),Redirected 59 (),Redirected 60 (),Redirected 61 (),Seq Stat (),Sys Temp (),He Level (),Map 67 (),Map 68 (),Map 69 (),PSU Field (Oe),Hi res (A) read,Mag (V) read,Mag adj/sc(I)set,Sw heater state,DAC <I> (cnts),Therm v,KRPMs,Pump temp (C),Pump power (W),High Vacuum mode,Flapper state,Regen htr flag,iso flag,BlockHeater(Ohm),NeckHeater(Ohm),Last 2 eng st,Hires enable,Mag (V) set,Map 89 (),Map 90 (),Map 91 (),Map 92 (),Map 93 (),MAP 1,MAP 2,MAP 3,MAP 4,MAP 5,MAP 6,MAP 7,MAP 8,MAP 9,MAP 10,MAP 11,MAP 12,MAP 13,MAP 14,MAP 15,MAP 16,MAP 17,MAP 18,MAP 19,MAP 20,MAP 21,MAP 22,MAP 23,MAP 24,MAP 25,MAP 26,MAP 27,MAP 28,MAP 29,MAP 30
,14575207.78,4374,274.9877,0.015373,0.000,-4.5451069,9.990,-4.0187473,9.990,,0.002,,0.002,0.0049,-0.0049,0,0.00,0.00,0.00,0.00,7.4227085,,399.9998474,399.9998474,439.8695679,,,,,,,4358,277.590,0.015,-0.9,276.9940796,116.268,274.9877319,911.089,252.0030060,122.130,,,0.261552,3.619932,0.0,888.40,19.99661,810.99,14.30225,-0.8250557,25.500275,,,,,,,,,,43.0,275.0385,73.4,,,,1.5373000e-2,120.0000000,5.0000000,0.00,0.00,0.00,2.5000000,,,,0.00,1.0000000,0.00,0.00,25.3360367,21.7457504,0.00,0.00,0.00,,,,,,,,,,,,,,,,,,,,,,,,,,,,,,,,,,,
,14575347.94,4374,297.6864,0.015373,0.000,-3.9916115,9.990,-3.1929073,9.990,,0.002,,0.002,0.0098,-0.0049,0,0.00,0.00,0.00,0.00,7.4972320,,399.9998474,399.9998474,439.8695679,,,,,,,4358,298.550,0.015,-0.9,299.7269897,121.886,297.6864014,837.811,274.4880371,134.343,,,0.259740,3.619932,0.0,888.16,19.98561,810.50,14.39262,-1.2375835,24.778324,,,,,,,,,,43.0,297.7454,73.4,,,,1.5373000e-2,120.0000000,5.0000000,0.00,0.00,0.00,2.5000000,,,,0.00,1.0000000,0.00,0.00,25.3499737,21.9095383,0.00,0.00,0.00,,,,,,,,,,,,,,,,,,,,,,,,,,,,,,,,,,,
,14575487.94,4373,300.1177,0.015373,0.000,,,,,,,,,0.0195,0.0147,0,0.00,0.00,0.00,0.00,7.6485310,,,,,,,,,,,4357,300.000,0.015,-0.9,300.7349854,127.748,300.1177368,828.041,287.6436157,140.938,,,0.266950,3.624817,0.0,433.70,5.12727,395.85,3.41799,-1.2375835,24.417349,,,,,,,,,,43.0,300.1165,73.4,,,,1.5373000e-2,120.0000000,5.0000000,0.00,0.00,0.00,2.5000000,,,,0.00,1.0000000,0.00,0.00,27.2589073,21.8128529,0.00,0.00,0.00,,,,,,,,,,,,,,,,,,,,,,,,,,,,,,,,,,,
,14575627.91,4369,300.0147,0.015373,0.000,,,,,,,,,0.0098,-0.0049,0,0.00,0.00,0.00,0.00,7.6485310,,,,,,,,,,,4353,300.000,0.015,-0.9,300.4489746,127.748,300.0147095,828.041,291.3903503,140.938,,,0.265157,3.624817,0.0,347.50,3.28484,317.22,2.18890,-1.2375835,24.056374,,,,,,,,,,43.0,300.0147,73.4,,,,1.5373000e-2,120.0000000,5.0000000,0.00,0.00,0.00,2.5000000,,,,0.00,1.0000000,0.00,0.00,27.1675625,21.7528095,0.00,0.00,0.00,,,,,,,,,,,,,,,,,,,,,,,,,,,,,,,,,,,
,14575767.75,4369,300.0043,0.015373,0.000,,,,,,,,,0.0049,0.0098,0,0.00,0.00,0.00,0.00,7.8812237,,,,,,,,,,,4353,300.000,0.015,-0.9,300.3761292,127.748,300.0042725,828.041,292.6294556,140.938,,,0.261552,3.634587,0.0,304.03,2.50635,277.41,1.67030,-1.2375835,24.056374,,,,,,,,,,43.0,300.0034,73.4,,,,1.5373000e-2,120.0000000,5.0000000,0.00,0.00,0.00,2.5000000,,,,0.00,1.0000000,0.00,0.00,27.1150570,21.7042446,0.00,0.00,0.00,,,,,,,,,,,,,,,,,,,,,,,,,,,,,,,,,,,
,14575907.86,6417,300.0348,0.015373,0.000,,,,,,,,,0.0000,0.0000,0,0.00,0.00,0.00,0.00,792.8679199,,,,,,,,,,,6401,300.000,0.015,-0.9,300.3909912,127.748,300.0348206,828.041,293.2503357,140.938,,,0.257921,3.634587,0.0,271.06,1.99953,247.86,1.33497,1.6501113,763.694580,,,,,,,,,,43.0,300.0348,73.4,,,,1.5373000e-2,120.0000000,5.0000000,0.00,0.00,0.00,2.5000000,,,,0.00,1.0000000,0.00,1.0000000,27.2138557,21.7294445,0.00,0.00,0.00,,,,,,,,,,,,,,,,,,,,,,,,,,,,,,,,,,,
,14576047.88,4369,299.9832,0.015373,0.000,,,,,,,,,-0.0049,0.0147,0,0.00,0.00,0.00,0.00,7.6485310,,,,,,,,,,,4353,300.000,0.015,0.0,300.3220825,127.748,299.9831543,828.041,293.2891846,140.938,,,0.261552,3.619932,0.0,257.39,1.79322,233.94,1.18734,2.0626390,24.417349,,,,,,,,,,43.0,299.9772,73.4,,,,1.5373000e-2,120.0000000,5.0000000,0.00,0.00,0.00,2.5000000,,,,0.00,1.0000000,0.00,0.00,27.1413517,21.7467079,0.00,0.00,0.00,,,,,,,,,,,,,,,,,,,,,,,,,,,,,,,,,,,
,14576187.91,4369,299.9998,0.015373,0.000,,,,,,,,,0.0098,0.0049,0,0.00,0.00,0.00,0.00,7.8028836,,,,,,,,,,,4353,300.000,0.015,0.0,300.3201294,127.748,299.9997559,828.041,294.1743469,140.938,,,0.254262,3.610161,0.0,248.35,1.67428,226.62,1.11814,0.0000000,24.417349,,,,,,,,,,43.0,299.9992,73.4,,,,1.5373000e-2,120.0000000,5.0000000,0.00,0.00,0.00,2.5000000,,,,0.00,1.0000000,0.00,0.00,27.1452713,21.7725563,0.00,0.00,0.00,,,,,,,,,,,,,,,,,,,,,,,,,,,,,,,,,,,
,14576327.81,6422,299.7686,0.015373,0.000,,,,,,,,,-0.0049,0.0000,256,0.00,0.00,0.00,0.00,743.3605347,,,,,,,,,,,6406,300.000,0.015,0.0,301.0067444,127.748,299.7686462,828.041,291.0354004,140.938,,,0.254262,3.610161,1.3,602.93,9.99452,172.16,0.62154,-16.5011120,744.562866,,,,,,,,,,43.0,299.8296,73.4,,,,1.5373000e-2,120.0000000,5.0000000,0.00,0.00,0.00,2.5000000,,,,0.00,1.0000000,0.00,1.0000000,27.3602142,21.4543076,0.00,0.00,0.00,,,,,,,,,,,,,,,,,,,,,,,,,,,,,,,,,,,
,14576467.91,6417,299.9909,0.015373,0.000,,,,,,,,,0.0049,0.0049,0,0.00,0.00,0.00,0.00,792.8679199,,,,,,,,,,,6401,300.000,0.015,9.6,300.3097839,127.748,299.9909363,828.041,293.8994446,140.938,,,0.256095,3.619932,0.0,225.40,1.37914,204.88,0.91582,6.6004453,763.694580,,,,,,,,,,43.0,299.9879,73.2,,,,1.5373000e-2,120.0000000,5.0000000,0.00,0.00,0.00,2.5000000,,,,0.00,1.0000000,0.00,1.0000000,27.1463928,21.8170071,0.00,0.00,0.00,,,,,,,,,,,,,,,,,,,,,,,,,,,,,,,,,,,
,14576607.70,4373,299.9526,0.015373,0.000,,,,,,,,,0.0049,0.0049,0,0.00,0.00,0.00,0.00,7.4972320,,,,,,,,,,,4357,300.000,0.015,14.4,300.2785645,127.748,299.9472046,828.041,293.9417114,140.938,,,0.328090,3.619932,0.0,237.12,1.52326,214.41,1.00438,15.2635298,23.334423,,,,,,,,,,43.0,299.9472,73.2,,,,1.5373000e-2,120.0000000,5.0000000,0.00,0.00,0.00,2.5000000,,,,0.00,1.0000000,0.00,0.00,27.0920944,21.8981628,0.00,0.00,0.00,,,,,,,,,,,,,,,,,,,,,,,,,,,,,,,,,,,
,14576747.81,4369,300.0065,0.015373,0.000,,,,,,,,,0.0098,0.0147,0,0.00,0.00,0.00,0.00,7.9603505,,,,,,,,,,,4353,300.000,0.015,-0.9,300.2875366,127.748,300.0065308,828.041,295.4847412,140.938,,,0.252420,3.634587,0.0,221.49,1.33359,202.20,0.89394,0.8250557,25.139299,,,,,,,,,,43.0,300.0065,73.2,,,,1.5373000e-2,120.0000000,5.0000000,0.00,0.00,0.00,2.5000000,,,,0.00,1.0000000,0.00,0.00,27.1841469,21.8652420,0.00,0.00,0.00,,,,,,,,,,,,,,,,,,,,,,,,,,,,,,,,,,,
,14576887.73,4369,300.0017,0.015373,0.000,,,,,,,,,0.0049,0.0000,0,0.00,0.00,0.00,0.00,7.5725036,,,,,,,,,,,4353,300.000,0.015,-0.9,300.2593689,127.748,300.0017090,828.041,296.1401978,140.938,,,0.261552,3.619932,0.0,203.91,1.12428,185.84,0.75252,1.2375835,23.334423,,,,,,,,,,43.0,300.0047,73.2,,,,1.5373000e-2,120.0000000,5.0000000,0.00,0.00,0.00,2.5000000,,,,0.00,1.0000000,0.00,0.00,27.1049404,21.8474407,0.00,0.00,0.00,,,,,,,,,,,,,,,,,,,,,,,,,,,,,,,,,,,
,14577027.70,4369,299.9965,0.015373,0.000,,,,,,,,,0.0195,0.0147,0,0.00,0.00,0.00,0.00,7.6485310,,,,,,,,,,,4353,300.000,0.015,-0.9,300.2854614,127.748,299.9964905,828.041,296.5663147,140.938,,,0.261552,3.629702,0.0,195.60,1.03679,178.27,0.69452,0.0000000,23.695398,,,,,,,,,,43.0,299.9968,73.2,,,,1.5373000e-2,120.0000000,5.0000000,0.00,0.00,0.00,2.5000000,,,,0.00,1.0000000,0.00,0.00,27.0977535,21.8546524,0.00,0.00,0.00,,,,,,,,,,,,,,,,,,,,,,,,,,,,,,,,,,,
,14577167.72,4369,300.0011,0.015373,0.000,15.4009199,9.990,,,,,,,-0.0049,-0.0049,0,0.00,0.00,0.00,0.00,7.9603505,,399.9998474,,439.8695679,,,,,,,4353,300.000,0.015,-0.9,300.2790833,127.748,300.0010986,828.041,296.8593750,140.938,,,0.257921,3.619932,0.0,191.21,0.99140,174.36,0.66745,0.0000000,24.417349,,,,,,,,,,43.0,300.0011,73.0,,,,1.5373000e-2,120.0000000,5.0000000,0.00,0.00,0.00,2.5000000,,,,0.00,1.0000000,0.00,0.00,27.0819664,21.9241219,0.00,0.00,0.00,,,,,,,,,,,,,,,,,,,,,,,,,,,,,,,,,,,
,14577307.86,4369,299.9950,0.015373,0.000,15.3623343,9.990,,,,,,,0.0049,0.0147,0,0.00,0.00,0.00,0.00,8.0402718,,399.9998474,,439.8695679,,,,,,,4353,300.000,0.015,-0.9,300.2599182,127.748,299.9949646,828.041,297.0910950,140.938,,,0.257921,3.629702,0.0,188.28,0.96347,171.67,0.64367,0.4125278,25.139299,,,,,,,,,,43.0,299.9952,73.0,,,,1.5373000e-2,120.0000000,5.0000000,0.00,0.00,0.00,2.5000000,,,,0.00,1.0000000,0.00,0.00,27.1142750,21.8403263,0.00,0.00,0.00,,,,,,,,,,,,,,,,,,,,,,,,,,,,,,,,,,,
,14577447.73,4373,300.0030,0.015373,0.000,15.5095215,9.990,,,,,,,0.0098,0.0147,0,0.00,0.00,0.00,0.00,7.8028836,,399.9998474,,439.8695679,,,,,,,4357,300.001,0.015,-0.9,300.2754822,127.748,300.0030212,828.041,297.2726440,140.938,,,0.252420,3.619932,0.0,183.88,0.91627,167.77,0.61468,1.6501113,25.139299,,,,,,,,,,2.2,300.0009,73.0,,,,1.5373000e-2,120.0000000,5.0000000,0.00,0.00,0.00,2.5000000,,,,0.00,1.0000000,0.00,0.00,27.0982494,21.8393955,0.00,0.00,0.00,,,,,,,,,,,,,,,,,,,,,,,,,,,,,,,,,,,
,14577587.78,4370,299.3746,0.015373,0.000,15.3449745,9.990,,,,,,,0.0049,0.0147,0,0.00,0.00,0.00,0.00,7.8812237,,399.9998474,,439.8695679,,,,,,,4354,299.359,0.015,15.0,299.5676270,127.748,299.3685913,828.041,297.2832642,140.938,,,0.480274,3.619932,0.0,81.81,0.17984,74.73,0.12481,8.2505560,24.417349,,,,,,,,,,2.2,299.3686,73.0,,,,1.5373000e-2,120.0000000,5.0000000,0.00,0.00,0.00,2.5000000,,,,0.00,1.0000000,0.00,0.00,26.8722324,21.7373352,0.00,0.00,0.00,,,,,,,,,,,,,,,,,,,,,,,,,,,,,,,,,,,
,14577727.72,4370,298.1596,0.015373,0.000,15.3420773,9.990,,,,,,,0.0049,0.0000,0,0.00,0.00,0.00,0.00,7.8028836,,399.9998474,,439.8695679,,,,,,,4354,298.197,0.015,31.6,298.3111877,127.748,298.1596069,828.041,297.2861938,140.938,,,1.385908,3.605276,0.0,232.23,1.46068,209.77,0.96583,56.5163116,24.417349,,,,,,,,,,2.2,298.1596,73.0,,,,1.5373000e-2,120.0000000,5.0000000,0.00,0.00,0.00,2.5000000,,,,0.00,1.0000000,0.00,0.00,27.0833759,21.9494820,0.00,0.00,0.00,,,,,,,,,,,,,,,,,,,,,,,,,,,,,,,,,,,
,14577867.70,4370,300.2386,0.015373,0.000,14.9332132,9.990,,,,,,,-0.0049,0.0049,0,0.00,0.00,0.00,0.00,7.8812237,,399.9998474,,439.8695679,,,,,,,4354,299.788,0.015,-0.9,300.9700317,127.748,300.2386169,828.041,297.9152832,140.938,,,0.257921,3.629702,0.0,505.49,7.05387,461.54,4.79646,0.4125278,24.417349,,,,,,,,,,2.0,300.2386,73.0,,,,1.5373000e-2,120.0000000,5.0000000,0.00,0.00,0.00,2.5000000,,,,0.00,1.0000000,0.00,0.00,27.3013535,22.1218052,0.00,0.00,0.00,,,,,,,,,,,,,,,,,,,,,,,,,,,,,,,,,,,
,14578007.80,4374,298.1808,0.015373,0.000,14.9142494,9.990,,,,,,,0.0195,0.0049,0,0.00,0.00,0.00,0.00,7.9603505,,399.9998474,,439.8695679,,,,,,,4358,296.886,0.015,26.3,298.2300720,127.748,298.1807556,828.041,299.3501282,140.938,,,1.114095,3.619932,0.0,0.00,0.00,0.00,0.00,32.1771698,25.139299,,,,,,,,,,2.2,298.1808,73.0,,,,1.5373000e-2,120.0000000,5.0000000,0.00,0.00,0.00,2.5000000,,,,0.00,1.0000000,0.00,0.00,46.2698021,21.5771732,0.00,0.00,0.00,,,,,,,,,,,,,,,,,,,,,,,,,,,,,,,,,,,
,14578147.72,4370,285.5487,0.015373,0.000,13.8122587,9.990,,,,,,,-0.0049,-0.0049,0,0.00,0.00,0.00,0.00,8.2025299,,399.9998474,,439.8695679,,,,,,,4354,285.814,0.015,90.0,285.0818481,125.305,285.5487366,828.041,297.1094360,140.938,,,2.652626,3.321934,0.0,426.62,4.88604,0.00,0.00,829.5934448,23.695398,,,,,,,,,,2.2,285.5487,73.0,,,,1.5373000e-2,120.0000000,5.0000000,0.00,0.00,0.00,2.5000000,,,,0.00,1.0000000,0.00,0.00,27.0312996,21.5771732,0.00,0.00,0.00,,,,,,,,,,,,,,,,,,,,,,,,,,,,,,,,,,,
,14578287.84,4370,274.5031,0.015373,0.000,12.9153662,9.990,,,,,,,-0.0049,0.0147,0,0.00,0.00,0.00,0.00,8.1209955,,399.9998474,,439.8695679,,,,,,,4354,274.127,0.015,23.0,274.1872253,121.397,274.5031128,867.123,289.4856567,140.938,,,1.089701,3.615047,0.0,207.33,1.22828,0.00,0.00,46.6156425,24.417349,,,,,,,,,,2.2,274.5031,73.0,,,,1.5373000e-2,120.0000000,5.0000000,0.00,0.00,0.00,2.5000000,,,,0.00,1.0000000,0.00,0.00,26.5974045,-150.0366364,0.00,0.00,0.00,,,,,,,,,,,,,,,,,,,,,,,,,,,,,,,,,,,
,14578427.86,4370,262.5692,0.015373,0.000,12.5463009,9.990,,,,,,,-0.0049,0.0049,0,0.00,0.00,0.00,0.00,8.0402718,,399.9998474,,439.8695679,,,,,,,4354,262.476,0.015,51.6,262.2528687,117.000,262.5691833,908.647,280.6897278,140.938,,,2.218770,3.595506,0.0,393.16,4.10064,0.00,0.00,300.7327881,23.695398,,,,,,,,,,2.2,262.5432,73.0,,,,1.5373000e-2,120.0000000,5.0000000,0.00,0.00,0.00,2.5000000,,,,0.00,1.0000000,0.00,0.00,26.5282173,-150.0366364,0.00,0.00,0.00,,,,,,,,,,,,,,,,,,,,,,,,,,,,,,,,,,,
,14578567.77,4370,250.8364,0.015373,0.000,19.0215855,9.990,,,,,,,0.0049,0.0195,0,0.00,0.00,0.00,0.00,8.2025299,,399.9998474,,439.8695679,,,,,,,4354,250.818,0.015,41.8,250.4171143,112.604,250.8053436,999.023,271.4056396,137.763,,,2.075895,3.615047,0.0,130.65,0.45088,0.00,0.00,169.5489349,24.417349,,,,,,,,,,2.2,250.8053,73.0,,,,1.5373000e-2,120.0000000,5.0000000,0.00,0.00,0.00,2.5000000,,,,0.00,1.0000000,0.00,0.00,26.0811348,-150.0366364,0.00,0.00,0.00,,,,,,,,,,,,,,,,,,,,,,,,,,,,,,,,,,,
,14578707.83,4370,239.1096,0.015373,0.000,12.0567350,9.990,,,,,,,0.0049,0.0147,0,0.00,0.00,0.00,0.00,8.0402718,,399.9998474,,439.8695679,,,,,,,4354,239.159,0.015,57.7,238.7931061,108.207,239.1096344,999.023,261.1574707,133.366,,,2.488841,3.595506,0.0,283.52,2.08794,0.00,0.00,317.2338867,24.417349,,,,,,,,,,2.2,239.1096,73.0,,,,1.5373000e-2,120.0000000,5.0000000,0.00,0.00,0.00,2.5000000,,,,0.00,1.0000000,0.00,0.00,25.9753361,-150.0366364,0.00,0.00,0.00,,,,,,,,,,,,,,,,,,,,,,,,,,,,,,,,,,,
,14578847.78,4370,227.5065,0.015373,0.000,11.2314329,9.990,,,,,,,-0.0049,0.0000,0,0.00,0.00,0.00,0.00,7.2035537,,399.9998474,,439.8695679,,,,,,,4354,227.510,0.015,45.6,227.1686859,103.566,227.5064697,999.023,250.1793213,128.481,,,2.204831,3.600391,0.0,191.94,0.95181,0.00,0.00,212.8643646,24.417349,,,,,,,,,,2.2,227.5065,73.0,,,,1.5373000e-2,120.0000000,5.0000000,0.00,0.00,0.00,2.5000000,,,,0.00,1.0000000,0.00,0.00,25.7042465,-150.0366364,0.00,0.00,0.00,,,,,,,,,,,,,,,,,,,,,,,,,,,,,,,,,,,
,14578988.30,4370,215.7603,0.015373,0.000,12.7330160,9.990,,,,,,,-0.0049,0.0049,0,0.00,0.00,0.00,0.00,6.9908690,,399.9998474,,439.8695679,,,,,,,4354,215.751,0.015,49.6,215.3652039,99.170,215.7602539,999.023,239.5818481,123.596,,,2.250133,3.615047,0.0,51.28,6.54491e-2,0.00,0.00,205.0263214,23.695398,,,,,,,,,,3.2,215.7310,73.0,,,,1.5373000e-2,120.0000000,5.0000000,0.00,0.00,0.00,2.5000000,,,,0.00,1.0000000,0.00,0.00,25.1257553,-150.0366364,0.00,0.00,0.00,,,,,,,,,,,,,,,,,,,,,,,,,,,,,,,,,,,
,14579127.83,4370,204.1835,0.015373,0.000,16.8004341,9.990,,,,,,,0.0000,0.0049,0,0.00,0.00,0.00,0.00,6.9213791,,399.9998474,,439.8695679,,,,,,,4354,204.137,0.015,53.6,203.9789734,94.529,204.1551208,999.023,227.6108246,118.222,,,2.379070,3.619932,0.0,287.91,2.11339,0.00,0.00,310.6334534,23.695398,,,,,,,,,,3.2,204.1151,73.0,,,,1.5373000e-2,120.0000000,5.0000000,0.00,0.00,0.00,2.5000000,,,,0.00,1.0000000,0.00,0.00,25.3242512,-150.0366364,0.00,0.00,0.00,,,,,,,,,,,,,,,,,,,,,,,,,,,,,,,,,,,
,14579267.77,4370,192.4670,0.015373,0.000,23.6433411,9.990,,,,,,,0.0000,0.0147,0,0.00,0.00,0.00,0.00,6.7170258,,399.9998474,,439.8695679,,,,,,,4354,192.486,0.015,48.1,192.1053314,89.888,192.4670105,999.023,216.5253448,113.092,,,2.257103,3.629702,0.0,30.53,2.19953e-2,0.00,0.00,221.1149139,23.695398,,,,,,,,,,2.2,192.4670,73.0,,,,1.5373000e-2,120.0000000,5.0000000,0.00,0.00,0.00,2.5000000,,,,0.00,1.0000000,0.00,0.00,23.6057644,-150.0366364,0.00,0.00,0.00,,,,,,,,,,,,,,,,,,,,,,,,,,,,,,,,,,,
,14579407.84,4370,180.8163,0.015373,0.000,39.6046371,9.990,,,,,,,-0.0049,0.0098,0,0.00,0.00,0.00,0.00,6.7844644,,399.9998474,,439.8695679,,,,,,,4354,180.784,0.015,53.0,180.5951385,85.247,180.8163300,999.023,203.9008331,107.230,,,2.375585,3.610161,0.0,249.82,1.56364,0.00,0.00,297.8450928,24.417349,,,,,,,,,,2.2,180.8163,73.0,,,,1.5373000e-2,120.0000000,5.0000000,0.00,0.00,0.00,2.5000000,,,,0.00,1.0000000,0.00,0.00,24.9086170,-150.0366364,0.00,0.00,0.00,,,,,,,,,,,,,,,,,,,,,,,,,,,,,,,,,,,
,14579547.72,4370,169.0194,0.015373,0.000,85.2099152,9.990,,,,,,,0.0098,-0.0049,0,0.00,0.00,0.00,0.00,6.5841532,,214.0146332,,191.1302948,,,,,,,4354,169.168,0.015,59.2,168.8224945,80.606,169.0193787,999.023,192.4252319,101.856,,,2.854743,3.575965,0.0,250.79,1.51810,0.00,0.00,514.8347168,25.139299,,,,,,,,,,2.2,168.9908,73.0,,,,1.5373000e-2,120.0000000,5.0000000,0.00,0.00,0.00,2.5000000,,,,0.00,1.0000000,0.00,0.00,24.6408749,-150.0366364,0.00,0.00,0.00,,,,,,,,,,,,,,,,,,,,,,,,,,,,,,,,,,,
,14579687.67,4370,157.4748,0.015373,0.000,137.3808899,9.990,,,,,,,0.0049,-0.0049,0,0.00,0.00,0.00,0.00,6.6502576,,123.7648239,,110.1636200,,,,,,,4354,157.493,0.015,53.7,157.2444153,75.965,157.4748230,999.023,179.8200684,95.994,,,2.426115,3.605276,0.0,158.73,0.61259,0.00,0.00,297.4325562,24.417349,,,,,,,,,,2.2,157.4748,73.0,,,,1.5373000e-2,120.0000000,5.0000000,0.00,0.00,0.00,2.5000000,,,,0.00,1.0000000,0.00,0.00,24.3136292,-150.0366364,0.00,0.00,0.00,,,,,,,,,,,,,,,,,,,,,,,,,,,,,,,,,,,
,14579849.22,4370,144.0246,0.015373,0.000,,9.331,,,,,,,0.0098,-0.0049,0,0.00,0.00,0.00,0.00,6.2633576,,,,,,,,,,,4354,144.019,0.015,59.2,143.9108582,70.591,143.9944305,999.023,165.6143799,89.399,,,2.734518,3.595506,0.0,247.62,1.48633,0.00,0.00,549.0745239,25.139299,,,,,,,,,,2.2,143.9944,73.0,,,,1.5373000e-2,120.0000000,5.0000000,0.00,0.00,0.00,2.5000000,,,,0.00,1.0000000,0.00,0.00,24.1930981,-150.0366364,0.00,0.00,0.00,,,,,,,,,,,,,,,,,,,,,,,,,,,,,,,,,,,
,14580047.78,4370,127.4494,0.015373,0.000,2.5254065e6,0.017,,,,,,,0.0049,0.0147,0,0.00,0.00,0.00,0.00,6.2010994,,1.8082041,,1.3920810,,,,,,,4354,127.478,0.015,55.5,127.2472229,63.752,127.4494019,999.023,148.2555542,81.094,,,2.555052,3.595506,0.0,61.29,8.97409e-2,0.00,0.00,451.3054504,24.417349,,,,,,,,,,2.2,127.4494,73.0,,,,1.5373000e-2,120.0000000,5.0000000,0.00,0.00,0.00,2.5000000,,,,0.00,1.0000000,0.00,0.00,23.3124657,-150.0366364,0.00,0.00,0.00,,,,,,,,,,,,,,,,,,,,,,,,,,,,,,,,,,,
,14580188.02,4370,115.7661,0.015373,0.000,,0.002,,,,,,,0.0049,0.0147,0,0.00,0.00,0.00,0.00,6.2633576,,,,,,,,,,,4354,115.795,0.015,59.0,115.6231308,59.111,115.7660522,999.023,135.1900177,74.988,,,2.703155,3.585735,0.0,162.15,0.61786,0.00,0.00,531.7483521,25.500275,,,,,,,,,,2.2,115.7661,73.0,,,,1.5373000e-2,120.0000000,5.0000000,0.00,0.00,0.00,2.5000000,,,,0.00,1.0000000,0.00,0.00,23.4997158,-150.0366364,0.00,0.00,0.00,,,,,,,,,,,,,,,,,,,,,,,,,,,,,,,,,,,
,14580328.53,4370,104.0808,0.015373,0.000,,0.002,,,,,,,0.0098,0.0147,0,0.00,0.00,0.00,0.00,6.0784326,,,,,,,,,,,4354,104.050,0.015,59.0,103.8727341,54.226,104.0224991,999.023,122.1678162,68.881,,,2.677019,3.600391,0.0,128.69,0.38654,0.00,0.00,535.8736572,24.417349,,,,,,,,,,3.2,104.0225,73.0,,,,1.5373000e-2,120.0000000,5.0000000,0.00,0.00,0.00,2.5000000,,,,0.00,1.0000000,0.00,0.00,23.1555595,-150.0366364,0.00,0.00,0.00,,,,,,,,,,,,,,,,,,,,,,,,,,,,,,,,,,,
,14580468.92,4370,92.3653,0.015373,0.000,,0.002,,,,,,,0.0195,0.0147,0,0.00,0.00,0.00,0.00,5.7248006,,,,,,,,,,,4354,92.371,0.015,59.0,92.2294083,49.487,92.3719635,999.023,109.0747147,62.775,,,2.664822,3.600391,0.0,88.16,0.18411,0.00,0.00,538.3488159,24.417349,,,,,,,,,,3.2,92.3095,73.0,,,,1.5373000e-2,120.0000000,5.0000000,0.00,0.00,0.00,2.5000000,,,,0.00,1.0000000,0.00,0.00,23.6899948,-150.0366364,0.00,0.00,0.00,,,,,,,,,,,,,,,,,,,,,,,,,,,,,,,,,,,
,14580608.36,4370,99.1850,0.015373,0.000,,0.002,,,,,,,0.0195,0.0049,0,0.00,0.00,0.00,0.00,5.6678953,,,,,,,,,,,4354,99.097,0.015,37.8,99.8209457,50.806,99.1847687,999.023,102.8089828,59.599,,,2.030592,3.619932,0.7,524.79,6.46049,3.42,1.52103e-4,-70.1297302,24.417349,,,,,,,,,,2.0,99.2088,73.0,,,,1.5373000e-2,120.0000000,5.0000000,0.00,0.00,0.00,2.5000000,,,,0.00,1.0000000,0.00,0.00,23.4584980,7.1446018,0.00,0.00,0.00,,,,,,,,,,,,,,,,,,,,,,,,,,,,,,,,,,,
,14580748.19,4369,100.0137,0.015373,0.000,,0.017,,,,,,,0.0098,0.0147,0,0.00,0.00,0.00,0.00,5.8989673,,,,,,,,,,,4353,100.000,0.015,-0.9,100.1220856,50.806,100.0136642,999.023,106.1243744,59.599,,,0.263357,3.610161,0.0,175.34,0.71308,10.74,1.96839e-3,-1.2375835,25.139299,,,,,,,,,,2.0,100.0137,73.0,,,,1.5373000e-2,120.0000000,5.0000000,0.00,0.00,0.00,2.5000000,,,,0.00,1.0000000,0.00,0.00,23.1950817,17.0496178,0.00,0.00,0.00,,,,,,,,,,,,,,,,,,,,,,,,,,,,,,,,,,,
,14580887.72,4373,100.0036,0.015373,0.000,,0.002,,,,,,,0.0098,0.0049,0,0.00,0.00,0.00,0.00,5.8989673,,,,,,,,,,,4357,100.000,0.015,0.7,100.0542297,50.806,100.0036469,999.023,107.8921814,59.599,,,0.263357,3.634587,0.0,63.49,9.15005e-2,0.00,0.00,-0.8250557,24.417349,,,,,,,,,,2.2,100.0036,73.0,,,,1.5373000e-2,120.0000000,5.0000000,0.00,0.00,0.00,2.5000000,,,,0.00,1.0000000,0.00,0.00,22.6978512,-150.0366364,0.00,0.00,0.00,,,,,,,,,,,,,,,,,,,,,,,,,,,,,,,,,,,
,14581028.05,4370,110.0945,0.015373,0.000,,0.002,,,,,,,0.0195,0.0147,0,0.00,0.00,0.00,0.00,5.7822771,,,,,,,,,,,4354,110.106,0.015,-0.9,110.7283783,53.249,110.0944901,999.023,112.8014603,62.531,,,0.259740,3.619932,0.0,468.13,5.17145,426.86,3.78483,-1.2375835,25.500275,,,,,,,,,,3.2,110.1534,73.0,,,,1.5373000e-2,120.0000000,5.0000000,0.00,0.00,0.00,2.5000000,,,,0.00,1.0000000,0.00,0.00,23.5980453,20.7597866,0.00,0.00,0.00,,,,,,,,,,,,,,,,,,,,,,,,,,,,,,,,,,,
,14581168.03,4370,121.7747,0.015373,0.000,,0.002,,,,,,,0.0195,0.0147,0,0.00,0.00,0.00,0.00,5.8989673,,,,,,,,,,,4354,121.749,0.015,-0.9,122.4744034,58.378,121.7746658,999.023,123.0244217,65.462,,,0.257921,3.629702,0.0,501.83,6.00629,457.88,4.36738,-0.8250557,24.417349,,,,,,,,,,2.2,121.8041,73.0,,,,1.5373000e-2,120.0000000,5.0000000,0.00,0.00,0.00,2.5000000,,,,0.00,1.0000000,0.00,0.00,23.8501053,20.8317547,0.00,0.00,0.00,,,,,,,,,,,,,,,,,,,,,,,,,,,,,,,,,,,
,14581307.78,4370,133.4022,0.015373,0.000,2.2226747e6,0.020,,,,,,,-0.0049,0.0147,0,0.00,0.00,0.00,0.00,6.0180120,,1.8082041,,1.3920810,,,,,,,4354,133.406,0.015,-0.9,134.1733551,63.996,133.4305878,999.023,133.5279694,72.057,,,0.256095,3.615047,0.0,522.10,6.57407,476.43,4.75387,-1.2375835,24.417349,,,,,,,,,,2.2,133.4306,73.0,,,,1.5373000e-2,120.0000000,5.0000000,0.00,0.00,0.00,2.5000000,,,,0.00,1.0000000,0.00,0.00,24.1172104,20.9430962,0.00,0.00,0.00,,,,,,,,,,,,,,,,,,,,,,,,,,,,,,,,,,,
,14581448.08,4370,145.1220,0.015373,0.000,6.9525856e5,0.066,,,,,,,0.0195,0.0000,0,0.00,0.00,0.00,0.00,6.0180120,,1.8082041,,1.3920810,,,,,,,4354,145.095,0.015,-0.9,145.9290314,67.171,145.1220093,999.023,144.0753479,75.476,,,0.259740,3.619932,0.0,536.75,7.01423,489.87,5.03746,0.4125278,23.695398,,,,,,,,,,2.2,145.1220,73.0,,,,1.5373000e-2,120.0000000,5.0000000,0.00,0.00,0.00,2.5000000,,,,0.00,1.0000000,0.00,0.00,24.3462543,20.9921646,0.00,0.00,0.00,,,,,,,,,,,,,,,,,,,,,,,,,,,,,,,,,,,
,14581588.05,4370,156.7840,0.015373,0.000,740.2064819,9.990,,,,,,,0.0049,-0.0049,0,0.00,0.00,0.00,0.00,6.0784326,,13.5807877,,13.9152317,,,,,,,4354,156.757,0.015,-0.9,157.6468201,73.766,156.7840271,999.023,154.5892639,79.140,,,0.263357,3.615047,0.0,550.43,7.44838,502.32,5.32503,-1.6501113,23.695398,,,,,,,,,,2.2,156.8148,73.0,,,,1.5373000e-2,120.0000000,5.0000000,0.00,0.00,0.00,2.5000000,,,,0.00,1.0000000,0.00,0.00,24.5845299,21.1038418,0.00,0.00,0.00,,,,,,,,,,,,,,,,,,,,,,,,,,,,,,,,,,,
,14581727.72,4370,168.4067,0.015373,0.000,95.7545013,9.990,,,,,,,-0.0049,0.0049,0,0.00,0.00,0.00,0.00,6.4539089,,187.5314026,,167.1994629,,,,,,,4354,168.410,0.015,-0.9,169.2883759,77.430,168.4364014,999.023,165.0172119,83.048,,,0.259740,3.615047,0.0,562.64,7.84724,513.55,5.58210,-1.6501113,23.695398,,,,,,,,,,2.2,168.4364,73.0,,,,1.5373000e-2,120.0000000,5.0000000,0.00,0.00,0.00,2.5000000,,,,0.00,1.0000000,0.00,0.00,24.7890377,21.1654167,0.00,0.00,0.00,,,,,,,,,,,,,,,,,,,,,,,,,,,,,,,,,,,
,14581868.11,4370,180.0952,0.015373,0.000,46.5790672,9.990,,,,,,,0.0000,0.0147,0,0.00,0.00,0.00,0.00,6.3897567,,399.9998474,,397.3399658,,,,,,,4354,180.097,0.015,-0.9,181.0260010,81.094,180.1330109,999.023,175.5124969,91.109,,,0.257921,3.615047,0.0,573.87,8.23520,523.81,5.83064,-1.6501113,25.139299,,,,,,,,,,2.2,180.1330,73.0,,,,1.5373000e-2,120.0000000,5.0000000,0.00,0.00,0.00,2.5000000,,,,0.00,1.0000000,0.00,0.00,25.0061073,21.2307224,0.00,0.00,0.00,,,,,,,,,,,,,,,,,,,,,,,,,,,,,,,,,,,
,14582008.13,4370,191.7819,0.015373,0.000,29.0296783,9.990,,,,,,,0.0195,-0.0049,0,0.00,0.00,0.00,0.00,6.5841532,,399.9998474,,439.8695679,,,,,,,4354,191.785,0.015,-0.9,192.7561646,85.002,191.8084106,999.023,186.0374603,95.506,,,0.257921,3.629702,0.0,582.17,8.56054,531.38,6.01599,-0.8250557,24.417349,,,,,,,,,,3.2,191.8084,73.0,,,,1.5373000e-2,120.0000000,5.0000000,0.00,0.00,0.00,2.5000000,,,,0.00,1.0000000,0.00,0.00,25.2578449,21.3057537,0.00,0.00,0.00,,,,,,,,,,,,,,,,,,,,,,,,,,,,,,,,,,,
,14582149.22,4370,203.5616,0.015373,0.000,17.3346691,9.990,,,,,,,0.0195,-0.0049,0,0.00,0.00,0.00,0.00,6.4539089,,399.9998474,,439.8695679,,,,,,,4354,203.593,0.015,-0.9,204.6130829,89.155,203.5904236,999.023,196.7336578,100.147,,,0.265157,3.615047,0.0,591.21,8.91001,539.44,6.22863,-0.4125278,23.695398,,,,,,,,,,3.2,203.6502,73.0,,,,1.5373000e-2,120.0000000,5.0000000,0.00,0.00,0.00,2.5000000,,,,0.00,1.0000000,0.00,0.00,25.4915600,21.3853111,0.00,0.00,0.00,,,,,,,,,,,,,,,,,,,,,,,,,,,,,,,,,,,
,14582288.17,4370,215.1170,0.015373,0.000,17.4286613,9.990,,,,,,,0.0098,0.0049,0,0.00,0.00,0.00,0.00,6.3897567,,399.9998474,,439.8695679,,,,,,,4354,215.121,0.015,-0.9,216.1782532,93.552,215.1466522,999.023,207.2217560,105.032,,,0.257921,3.615047,0.0,598.53,9.20672,546.28,6.40860,-1.2375835,24.417349,,,,,,,,,,2.2,215.1467,73.0,,,,1.5373000e-2,120.0000000,5.0000000,0.00,0.00,0.00,2.5000000,,,,0.00,1.0000000,0.00,0.00,25.7205677,21.4945164,0.00,0.00,0.00,,,,,,,,,,,,,,,,,,,,,,,,,,,,,,,,,,,
,14582428.11,4370,226.7656,0.015373,0.000,11.5167189,9.990,,,,,,,0.0195,-0.0049,0,0.00,0.00,0.00,0.00,6.5841532,,399.9998474,,439.8695679,,,,,,,4354,226.784,0.015,-0.9,227.8967438,98.192,226.7927551,999.023,217.8583221,110.161,,,0.257921,3.610161,0.0,607.81,9.58340,554.33,6.61823,-1.2375835,24.417349,,,,,,,,,,2.2,226.7928,73.0,,,,1.5373000e-2,120.0000000,5.0000000,0.00,0.00,0.00,2.5000000,,,,0.00,1.0000000,0.00,0.00,25.9404469,21.5471115,0.00,0.00,0.00,,,,,,,,,,,,,,,,,,,,,,,,,,,,,,,,,,,
,14582567.83,4370,238.4384,0.015373,0.000,10.9114504,9.990,,,,,,,0.0049,-0.0049,0,0.00,0.00,0.00,0.00,6.7844644,,399.9998474,,439.8695679,,,,,,,4354,238.412,0.015,-0.9,239.5362244,103.078,238.4383545,999.023,228.5021973,110.161,,,0.256095,3.624817,0.0,611.48,9.78304,558.00,6.73304,-0.4125278,24.417349,,,,,,,,,,2.2,238.4680,73.0,,,,1.5373000e-2,120.0000000,5.0000000,0.00,0.00,0.00,2.5000000,,,,0.00,1.0000000,0.00,0.00,26.1645355,21.6245365,0.00,0.00,0.00,,,,,,,,,,,,,,,,,,,,,,,,,,,,,,,,,,,
,14582708.06,4370,250.1254,0.015373,0.000,12.2105436,9.990,,,,,,,0.0195,0.0049,0,0.00,0.00,0.00,0.00,6.7844644,,399.9998474,,439.8695679,,,,,,,4354,250.129,0.015,-0.9,251.2831573,108.207,250.1254120,999.023,239.3215179,115.535,,,0.259740,3.619932,0.0,617.83,10.07326,563.86,6.90017,-1.2375835,23.695398,,,,,,,,,,2.2,250.1555,73.0,,,,1.5373000e-2,120.0000000,5.0000000,0.00,0.00,0.00,2.5000000,,,,0.00,1.0000000,0.00,0.00,26.3898449,21.7030067,0.00,0.00,0.00,,,,,,,,,,,,,,,,,,,,,,,,,,,,,,,,,,,
,14582848.23,4370,261.8310,0.015373,0.000,13.1309290,9.990,,,,,,,-0.0049,-0.0049,0,0.00,0.00,0.00,0.00,6.8525796,,399.9998474,,439.8695679,,,,,,,4354,261.792,0.015,-0.9,262.9460449,113.581,261.8309631,962.384,250.0742493,121.153,,,0.259740,3.610161,0.0,622.71,10.32020,568.50,7.04027,-1.2375835,23.695398,,,,,,,,,,2.2,261.8310,73.0,,,,1.5373000e-2,120.0000000,5.0000000,0.00,0.00,0.00,2.5000000,,,,0.00,1.0000000,0.00,0.00,26.6143436,21.7836704,0.00,0.00,0.00,,,,,,,,,,,,,,,,,,,,,,,,,,,,,,,,,,,
,14582987.64,4370,273.4118,0.015373,0.000,13.5265512,9.990,,,,,,,0.0195,-0.0049,0,0.00,0.00,0.00,0.00,6.9908690,,399.9998474,,439.8695679,,,,,,,4354,273.421,0.015,-0.9,274.6783752,113.581,273.4118042,918.417,260.7212219,127.015,,,0.257921,3.610161,0.0,627.84,10.58155,572.89,7.17866,-0.8250557,23.695398,,,,,,,,,,2.2,273.4424,73.0,,,,1.5373000e-2,120.0000000,5.0000000,0.00,0.00,0.00,2.5000000,,,,0.00,1.0000000,0.00,0.00,26.8443642,21.8723488,0.00,0.00,0.00,,,,,,,,,,,,,,,,,,,,,,,,,,,,,,,,,,,
,14583128.30,4370,285.1287,0.015373,0.000,14.3039036,9.990,,,,,,,0.0049,0.0000,0,0.00,0.00,0.00,0.00,6.8525796,,399.9998474,,439.8695679,,,,,,,4354,285.142,0.015,-0.9,286.3628235,119.199,285.1608276,876.893,271.5815430,133.122,,,0.257921,3.610161,0.0,631.50,10.77795,576.07,7.28880,-1.6501113,25.139299,,,,,,,,,,3.2,285.1608,73.0,,,,1.5373000e-2,120.0000000,5.0000000,0.00,0.00,0.00,2.5000000,,,,0.00,1.0000000,0.00,0.00,27.0472240,21.9638214,0.00,0.00,0.00,,,,,,,,,,,,,,,,,,,,,,,,,,,,,,,,,,,
,14583267.75,4370,296.7866,0.015373,0.000,15.2926788,9.990,,,,,,,0.0195,0.0049,0,0.00,0.00,0.00,0.00,6.9213791,,399.9998474,,439.8695679,,,,,,,4354,296.770,0.015,-0.9,298.0609436,125.061,296.7865906,840.254,282.3880310,133.122,,,0.257921,3.610161,0.0,635.16,11.00756,579.73,7.41303,-1.2375835,23.695398,,,,,,,,,,3.2,296.8130,73.0,,,,1.5373000e-2,120.0000000,5.0000000,0.00,0.00,0.00,2.5000000,,,,0.00,1.0000000,0.00,0.00,27.2654018,22.0357094,0.00,0.00,0.00,,,,,,,,,,,,,,,,,,,,,,,,,,,,,,,,,,,
,14583407.86,4370,308.4234,0.015373,0.000,16.3460369,9.990,,,,,,,0.0098,0.0049,0,0.00,0.00,0.00,0.00,7.0610571,,399.9998474,,439.8695679,,,,,,,4354,308.419,0.015,-0.9,309.7919006,125.061,308.4531860,808.500,293.1641846,139.717,,,0.263357,3.600391,0.0,637.61,11.18226,582.17,7.49403,0.4125278,23.695398,,,,,,,,,,2.2,308.4532,73.0,,,,1.5373000e-2,120.0000000,5.0000000,0.00,0.00,0.00,2.5000000,,,,0.00,1.0000000,0.00,0.00,27.5057621,22.1111031,0.00,0.00,0.00,,,,,,,,,,,,,,,,,,,,,,,,,,,,,,,,,,,
,14583548.00,4370,320.0724,0.015373,0.000,17.3974953,9.990,,,,,,,0.0195,-0.0049,0,0.00,0.00,0.00,0.00,7.4972320,,399.9998474,,439.8695679,,,,,,,4354,320.093,0.015,-0.9,321.4836731,131.168,320.1029358,776.746,303.9645691,146.556,,,0.257921,3.600391,0.0,641.76,11.41966,585.59,7.60955,-1.6501113,24.417349,,,,,,,,,,2.2,320.1029,73.0,,,,1.5373000e-2,120.0000000,5.0000000,0.00,0.00,0.00,2.5000000,,,,0.00,1.0000000,0.00,0.00,27.7274704,22.1905727,0.00,0.00,0.00,,,,,,,,,,,,,,,,,,,,,,,,,,,,,,,,,,,
,14583687.89,4370,331.7518,0.015373,0.000,18.4713039,9.990,,,,,,,0.0049,0.0049,0,0.00,0.00,0.00,0.00,7.4972320,,399.9998474,,439.8695679,,,,,,,4354,331.727,0.015,-0.9,333.2200012,137.518,331.7518005,749.878,314.8175354,146.556,,,0.257921,3.619932,0.0,648.35,11.74286,591.70,7.80451,-0.8250557,24.417349,,,,,,,,,,2.2,331.7834,72.9,,,,1.5373000e-2,120.0000000,5.0000000,0.00,0.00,0.00,2.5000000,,,,0.00,1.0000000,0.00,0.00,27.9540977,22.2918644,0.00,0.00,0.00,,,,,,,,,,,,,,,,,,,,,,,,,,,,,,,,,,,
,14583827.64,4370,343.4104,0.015373,0.000,19.8634911,9.990,,,,,,,0.0049,0.0147,0,0.00,0.00,0.00,0.00,7.6485310,,399.9998474,,439.8695679,,,,,,,4354,343.387,0.015,-0.9,344.9293823,137.518,343.4104309,723.009,325.5646667,153.639,,,0.263357,3.600391,0.0,651.04,11.93463,594.38,7.89801,0.4125278,23.695398,,,,,,,,,,2.2,343.4104,72.9,,,,1.5373000e-2,120.0000000,5.0000000,0.00,0.00,0.00,2.5000000,,,,0.00,1.0000000,0.00,0.00,28.1576653,22.3760471,0.00,0.00,0.00,,,,,,,,,,,,,,,,,,,,,,,,,,,,,,,,,,,
,14583967.83,4370,355.0571,0.015373,0.000,21.4767990,9.990,,,,,,,0.0098,0.0147,0,0.00,0.00,0.00,0.00,7.9603505,,399.9998474,,439.8695679,,,,,,,4354,355.055,0.015,-0.9,356.6058655,144.358,355.0570679,698.583,336.4332581,153.639,,,0.254262,3.595506,0.0,656.90,12.24264,599.51,8.07598,-0.4125278,23.695398,,,,,,,,,,2.2,355.0571,72.9,,,,1.5373000e-2,120.0000000,5.0000000,0.00,0.00,0.00,2.5000000,,,,0.00,1.0000000,0.00,0.00,28.3898315,22.4698448,0.00,0.00,0.00,,,,,,,,,,,,,,,,,,,,,,,,,,,,,,,,,,,
,14584107.89,4370,366.7565,0.015373,0.000,23.2030067,9.990,,,,,,,-0.0049,-0.0049,0,0.00,0.00,0.00,0.00,8.2848825,,399.9998474,,439.8695679,,,,,,,4354,366.751,0.015,-0.9,368.3340759,144.358,366.7564697,676.600,347.2020874,161.212,,,0.257921,3.610161,0.0,656.65,12.33433,599.51,8.10527,-0.8250557,24.417349,,,,,,,,,,2.2,366.7830,72.9,,,,1.5373000e-2,120.0000000,5.0000000,0.00,0.00,0.00,2.5000000,,,,0.00,1.0000000,0.00,0.00,28.6235752,22.5513325,0.00,0.00,0.00,,,,,,,,,,,,,,,,,,,,,,,,,,,,,,,,,,,
,14584247.86,4370,378.4111,0.015373,0.000,25.0576591,9.990,,,,,,,0.0195,0.0147,0,0.00,0.00,0.00,0.00,9.0642786,,399.9998474,,439.8695679,,,,,,,4354,378.415,0.015,-0.9,379.9342041,151.441,378.4110718,654.616,357.9524536,169.028,,,0.254262,3.610161,0.0,662.03,12.63737,604.40,8.26726,-1.2375835,25.500275,,,,,,,,,,3.2,378.4405,72.9,,,,1.5373000e-2,120.0000000,5.0000000,0.00,0.00,0.00,2.5000000,,,,0.00,1.0000000,0.00,0.00,28.8524914,22.6317883,0.00,0.00,0.00,,,,,,,,,,,,,,,,,,,,,,,,,,,,,,,,,,,
,14584388.03,4374,378.1990,0.015373,0.000,25.3328094,9.990,,,,,,,0.0049,-0.0049,0,0.00,0.00,0.00,0.00,9.3400431,,399.9998474,,439.8695679,,,,,,,4358,375.692,0.015,17.4,378.4403381,151.441,378.1990356,649.731,365.2922668,169.028,,,0.734934,3.605276,0.0,0.00,0.00,0.00,0.00,18.1512241,23.695398,,,,,,,,,,6.2,378.1990,72.9,,,,1.5373000e-2,120.0000000,5.0000000,0.00,0.00,0.00,2.5000000,,,,0.00,1.0000000,0.00,0.00,40.4918137,22.3102818,0.00,0.00,0.00,,,,,,,,,,,,,,,,,,,,,,,,,,,,,,,,,,,
,14584527.84,4374,363.3814,0.015373,0.000,23.1621647,9.990,,,,,,,0.0098,0.0049,0,0.00,0.00,0.00,0.00,9.6241961,,399.9998474,,439.8695679,,,,,,,4358,360.813,0.015,90.0,362.3751831,151.441,363.3814087,649.731,367.3767700,169.028,,,2.649141,3.297508,0.0,0.00,0.00,0.00,0.00,830.8309937,24.417349,,,,,,,,,,7.2,363.3209,72.9,,,,1.5373000e-2,120.0000000,5.0000000,0.00,0.00,0.00,2.5000000,,,,0.00,1.0000000,0.00,0.00,40.4918137,22.3102818,0.00,0.00,0.00,,,,,,,,,,,,,,,,,,,,,,,,,,,,,,,,,,,
,14584667.78,4374,337.3228,0.015373,0.000,19.6321278,9.990,,,,,,,0.0000,0.0147,0,0.00,0.00,0.00,0.00,10.0165615,,399.9998474,,439.8695679,,,,,,,4358,334.684,0.015,90.0,336.0175781,143.136,337.2524414,713.239,360.3490295,169.028,,,2.657853,3.297508,0.0,0.00,0.00,0.00,0.00,830.4185181,25.139299,,,,,,,,,,7.2,337.1800,72.9,,,,1.5373000e-2,120.0000000,5.0000000,0.00,0.00,0.00,2.5000000,,,,0.00,1.0000000,0.00,0.00,40.4918137,22.3102818,0.00,0.00,0.00,,,,,,,,,,,,,,,,,,,,,,,,,,,,,,,,,,,
,14584807.86,4374,309.2161,0.015373,0.000,16.1618214,9.990,,,,,,,0.0195,0.0049,0,0.00,0.00,0.00,0.00,10.1171265,,399.9998474,,439.8695679,,,,,,,4358,306.665,0.015,90.0,307.8347778,133.366,309.2160950,784.074,343.8651428,168.784,,,2.675277,3.297508,0.0,0.00,0.00,0.00,0.00,828.7683716,24.417349,,,,,,,,,,7.2,309.1198,72.9,,,,1.5373000e-2,120.0000000,5.0000000,0.00,0.00,0.00,2.5000000,,,,0.00,1.0000000,0.00,0.00,40.4918137,22.3102818,0.00,0.00,0.00,,,,,,,,,,,,,,,,,,,,,,,,,,,,,,,,,,,
,14584948.13,4373,299.9503,0.015373,0.000,14.8842344,9.990,,,,,,,0.0195,-0.0049,0,0.00,0.00,0.00,0.00,11.1800203,,399.9998474,,439.8695679,,,,,,,4357,300.000,0.015,17.9,300.0712280,129.702,299.9503174,784.074,325.3452148,160.967,,,0.656129,3.615047,0.0,491.82,6.60724,0.00,0.00,9.4881401,24.417349,,,,,,,,,,2.2,299.9503,72.9,,,,1.5373000e-2,120.0000000,5.0000000,0.00,0.00,0.00,2.5000000,,,,0.00,1.0000000,0.00,0.00,27.3155079,22.3102818,0.00,0.00,0.00,,,,,,,,,,,,,,,,,,,,,,,,,,,,,,,,,,,
,14585088.13,4374,289.6953,0.015373,0.000,14.0054407,9.990,,,,,,,0.0098,0.0147,0,0.00,0.00,0.00,0.00,11.1800203,,399.9998474,,439.8695679,,,,,,,4358,287.136,0.015,79.3,288.6124573,126.527,289.6238403,823.156,315.5787048,156.815,,,2.839062,3.346360,0.0,0.00,0.00,0.00,0.00,822.1679688,24.417349,,,,,,,,,,3.2,289.6238,72.9,,,,1.5373000e-2,120.0000000,5.0000000,0.00,0.00,0.00,2.5000000,,,,0.00,1.0000000,0.00,0.00,26.9383984,22.3102818,0.00,0.00,0.00,,,,,,,,,,,,,,,,,,,,,,,,,,,,,,,,,,,
,14585228.00,4374,263.6844,0.015373,0.000,14.4618368,9.990,,,,,,,0.0195,0.0049,0,0.00,0.00,0.00,0.00,10.8499308,,399.9998474,,439.8695679,,,,,,,4358,261.210,0.015,90.0,262.6029663,117.000,263.6843567,903.762,299.1852112,149.976,,,2.697928,3.297508,0.0,0.00,0.00,0.00,0.00,830.8309937,25.500275,,,,,,,,,,2.2,263.6844,72.9,,,,1.5373000e-2,120.0000000,5.0000000,0.00,0.00,0.00,2.5000000,,,,0.00,1.0000000,0.00,0.00,26.9383984,22.3102818,0.00,0.00,0.00,,,,,,,,,,,,,,,,,,,,,,,,,,,,,,,,,,,
,14585368.95,4374,238.6000,0.015373,0.000,9.6668510,9.990,,,,,,,0.0098,0.0098,0,0.00,0.00,0.00,0.00,9.5285311,,399.9998474,,439.8695679,,,,,,,4358,236.019,0.015,90.0,237.6153412,107.719,238.5363464,999.023,277.3796997,140.449,,,2.701413,3.312164,0.0,0.00,0.00,0.00,0.00,830.4185181,24.417349,,,,,,,,,,2.2,238.5363,72.9,,,,1.5373000e-2,120.0000000,5.0000000,0.00,0.00,0.00,2.5000000,,,,0.00,1.0000000,0.00,0.00,26.9383984,22.3102818,0.00,0.00,0.00,,,,,,,,,,,,,,,,,,,,,,,,,,,,,,,,,,,
,14585507.92,4374,215.1770,0.015373,0.000,10.7122793,9.990,,,,,,,0.0049,0.0049,0,0.00,0.00,0.00,0.00,7.5725036,,399.9998474,,439.8695679,,,,,,,4358,212.593,0.015,90.0,214.3565063,98.681,215.1770477,999.023,254.1144257,130.191,,,2.717094,3.302394,0.0,0.00,0.00,0.00,0.00,830.0059204,24.417349,,,,,,,,,,2.2,215.1189,72.9,,,,1.5373000e-2,120.0000000,5.0000000,0.00,0.00,0.00,2.5000000,,,,0.00,1.0000000,0.00,0.00,26.9383984,22.3102818,0.00,0.00,0.00,,,,,,,,,,,,,,,,,,,,,,,,,,,,,,,,,,,
,14585648.08,4374,193.3385,0.015373,0.000,22.7009220,9.990,,,,,,,0.0049,0.0049,0,0.00,0.00,0.00,0.00,7.2035537,,399.9998474,,439.8695679,,,,,,,4358,190.788,0.015,90.0,192.5904694,90.132,193.3384552,999.023,230.6180115,119.443,,,2.711867,3.312164,0.0,0.00,0.00,0.00,0.00,827.1182861,24.417349,,,,,,,,,,2.2,193.2826,72.9,,,,1.5373000e-2,120.0000000,5.0000000,0.00,0.00,0.00,2.5000000,,,,0.00,1.0000000,0.00,0.00,26.9383984,22.3102818,0.00,0.00,0.00,,,,,,,,,,,,,,,,,,,,,,,,,,,,,,,,,,,
,14585788.14,4374,173.0248,0.015373,0.000,66.2840424,9.990,,,,,,,0.0098,0.0049,0,0.00,0.00,0.00,0.00,6.9908690,,285.0281677,,255.8249054,,,,,,,4358,170.566,0.015,90.0,172.4660187,82.071,173.0248108,999.023,207.7953644,109.184,,,2.715352,3.302394,0.0,0.00,0.00,0.00,0.00,826.7056885,24.417349,,,,,,,,,,2.2,172.9758,72.9,,,,1.5373000e-2,120.0000000,5.0000000,0.00,0.00,0.00,2.5000000,,,,0.00,1.0000000,0.00,0.00,26.9383984,22.3102818,0.00,0.00,0.00,,,,,,,,,,,,,,,,,,,,,,,,,,,,,,,,,,,
,14585927.64,4374,154.1157,0.015373,0.000,221.8531342,9.990,,,,,,,-0.0049,0.0147,0,0.00,0.00,0.00,0.00,7.0610571,,68.9497452,,62.2988625,,,,,,,4358,151.574,0.015,90.0,153.6355743,74.499,154.1157379,999.023,186.0257416,98.925,,,2.731033,3.312164,0.0,0.00,0.00,0.00,0.00,827.9433594,23.695398,,,,,,,,,,2.2,154.0677,72.7,,,,1.5373000e-2,120.0000000,5.0000000,0.00,0.00,0.00,2.5000000,,,,0.00,1.0000000,0.00,0.00,26.9383984,22.3102818,0.00,0.00,0.00,,,,,,,,,,,,,,,,,,,,,,,,,,,,,,,,,,,
,14586092.83,4374,133.0889,0.015373,0.000,3.3350512e5,0.115,,,,,,,-0.0049,0.0000,0,0.00,0.00,0.00,0.00,6.6502576,,1.8082041,,1.3920810,,,,,,,4358,130.511,0.015,90.0,132.6591492,65.950,132.9862213,999.023,161.4890137,87.445,,,2.731033,3.317049,0.0,0.00,0.00,0.00,0.00,823.8180542,23.695398,,,,,,,,,,3.2,132.9862,72.7,,,,1.5373000e-2,120.0000000,5.0000000,0.00,0.00,0.00,2.5000000,,,,0.00,1.0000000,0.00,0.00,26.9383984,22.3102818,0.00,0.00,0.00,,,,,,,,,,,,,,,,,,,,,,,,,,,,,,,,,,,
,14586232.73,4374,116.3471,0.015373,0.000,3.5842242e4,0.071,,,,,,,0.0195,0.0049,0,0.00,0.00,0.00,0.00,6.3262415,,1.8082041,,1.3920810,,,,,,,4358,113.769,0.015,90.0,116.0692520,59.111,116.3471222,999.023,141.6162720,77.919,,,2.743230,3.331705,0.0,0.00,0.00,0.00,0.00,825.4681396,24.417349,,,,,,,,,,2.2,116.3471,72.7,,,,1.5373000e-2,120.0000000,5.0000000,0.00,0.00,0.00,2.5000000,,,,0.00,1.0000000,0.00,0.00,26.9383984,22.3102818,0.00,0.00,0.00,,,,,,,,,,,,,,,,,,,,,,,,,,,,,,,,,,,
,14586372.53,4374,100.2123,0.015373,0.000,4.1901281e5,0.010,,,,,,,0.0049,0.0000,0,0.00,0.00,0.00,0.00,6.1394596,,1.8082041,,1.3920810,,,,,,,4358,100.000,0.015,90.0,100.0452728,52.516,100.2122574,999.023,122.2686996,68.881,,,2.741488,3.317049,0.0,0.00,0.00,0.00,0.00,825.8806763,24.417349,,,,,,,,,,2.2,100.2123,72.7,,,,1.5373000e-2,120.0000000,5.0000000,0.00,0.00,0.00,2.5000000,,,,0.00,1.0000000,0.00,0.00,26.9383984,22.3102818,0.00,0.00,0.00,,,,,,,,,,,,,,,,,,,,,,,,,,,,,,,,,,,
,14586512.69,4373,100.0057,0.015373,0.000,3.4701862e5,0.010,,,,,,,0.0195,0.0000,0,0.00,0.00,0.00,0.00,6.0784326,,1.8082041,,1.3920810,,,,,,,4357,100.000,0.015,28.9,100.1459656,52.272,100.0056610,999.023,113.3809967,64.729,,,1.063565,3.619932,0.0,275.95,1.78100,0.00,0.00,19.3888073,24.417349,,,,,,,,,,5.2,100.0057,72.7,,,,1.5373000e-2,120.0000000,5.0000000,0.00,0.00,0.00,2.5000000,,,,0.00,1.0000000,0.00,0.00,23.3242798,22.3102818,0.00,0.00,0.00,,,,,,,,,,,,,,,,,,,,,,,,,,,,,,,,,,,
,14586652.33,4370,125.5561,0.015373,0.000,1.8816886e5,0.166,,,,,,,0.0195,-0.0049,0,0.00,0.00,0.00,0.00,6.0784326,,1.8082041,,1.3920810,,,,,,,4354,125.866,0.015,-0.9,127.7023926,60.088,125.5560989,999.023,120.5218658,64.485,,,0.256095,3.610161,0.0,894.51,19.43485,816.61,14.25170,-2.0626390,24.417349,,,,,,,,,,6.2,125.6633,72.7,,,,1.5373000e-2,120.0000000,5.0000000,0.00,0.00,0.00,2.5000000,,,,0.00,1.0000000,0.00,0.00,24.2893047,21.3718472,0.00,0.00,0.00,,,,,,,,,,,,,,,,,,,,,,,,,,,,,,,,,,,
,14586792.83,4374,161.1168,0.015373,0.000,545.9127808,9.990,,,,,,,0.0049,-0.0049,0,0.00,0.00,0.00,0.00,6.6502576,,20.7250500,,20.4271717,,,,,,,4358,163.643,0.015,-0.9,163.2829285,75.965,161.1981659,999.023,150.1925507,77.919,,,0.259740,3.615047,0.0,894.51,19.95923,816.61,14.39133,-0.8250557,25.139299,,,,,,,,,,7.2,161.2810,72.7,,,,1.5373000e-2,120.0000000,5.0000000,0.00,0.00,0.00,2.5000000,,,,0.00,1.0000000,0.00,0.00,24.9310131,21.5812283,0.00,0.00,0.00,,,,,,,,,,,,,,,,,,,,,,,,,,,,,,,,,,,
,14586932.80,4374,190.9050,0.015373,0.000,29.3484650,9.990,,,,,,,-0.0049,0.0049,0,0.00,0.00,0.00,0.00,6.7170258,,399.9998474,,439.8695679,,,,,,,4358,193.561,0.015,-0.9,193.1007690,87.689,190.9799652,999.023,177.9390259,89.643,,,0.259740,3.610161,0.0,890.84,19.99717,813.19,14.39067,-2.0626390,23.695398,,,,,,,,,,7.2,191.0514,72.7,,,,1.5373000e-2,120.0000000,5.0000000,0.00,0.00,0.00,2.5000000,,,,0.00,1.0000000,0.00,0.00,25.1980400,21.7620697,0.00,0.00,0.00,,,,,,,,,,,,,,,,,,,,,,,,,,,,,,,,,,,
,14587072.20,4374,217.4048,0.015373,0.000,10.9235325,9.990,,,,,,,0.0098,0.0000,0,0.00,0.00,0.00,0.00,6.9908690,,399.9998474,,439.8695679,,,,,,,4358,219.911,0.015,-0.9,219.4858704,96.238,217.4673615,999.023,203.3005066,103.566,,,0.256095,3.629702,0.0,890.11,19.99160,812.45,14.47693,-0.4125278,24.417349,,,,,,,,,,6.2,217.4674,72.7,,,,1.5373000e-2,120.0000000,5.0000000,0.00,0.00,0.00,2.5000000,,,,0.00,1.0000000,0.00,0.00,25.2325001,21.9320164,0.00,0.00,0.00,,,,,,,,,,,,,,,,,,,,,,,,,,,,,,,,,,,
,14587212.27,4374,241.8933,0.015373,0.000,8.7400246,9.990,,,,,,,0.0195,0.0049,0,0.00,0.00,0.00,0.00,6.9908690,,399.9998474,,439.8695679,,,,,,,4358,244.438,0.015,-0.9,243.9550323,105.765,241.8932648,999.023,227.0547485,114.069,,,0.259740,3.610161,0.0,889.13,19.99138,811.72,14.56301,-1.6501113,24.417349,,,,,,,,,,6.2,241.9539,72.4,,,,1.5373000e-2,120.0000000,5.0000000,0.00,0.00,0.00,2.5000000,,,,0.00,1.0000000,0.00,0.00,25.2876911,22.1022682,0.00,0.00,0.00,,,,,,,,,,,,,,,,,,,,,,,,,,,,,,,,,,,
,14587352.30,4374,264.7897,0.015373,0.000,10.3995266,9.990,,,,,,,0.0195,0.0049,0,0.00,0.00,0.00,0.00,7.3489261,,399.9998474,,439.8695679,,,,,,,4358,267.323,0.015,-0.9,266.8532104,110.894,264.7896729,950.171,249.6451874,119.687,,,0.259740,3.610161,0.0,888.64,20.00210,811.23,14.65332,0.0000000,23.695398,,,,,,,,,,6.2,264.8478,72.4,,,,1.5373000e-2,120.0000000,5.0000000,0.00,0.00,0.00,2.5000000,,,,0.00,1.0000000,0.00,0.00,25.3290749,22.2661228,0.00,0.00,0.00,,,,,,,,,,,,,,,,,,,,,,,,,,,,,,,,,,,
,14587492.28,4374,286.4398,0.015373,0.000,13.4485912,9.990,,,,,,,0.0098,0.0000,0,0.00,0.00,0.00,0.00,8.1209955,,399.9998474,,439.8695679,,,,,,,4358,288.999,0.015,-0.9,288.3631287,121.886,286.4398193,874.450,270.7311096,131.656,,,0.256095,3.634587,0.0,888.16,19.99111,810.74,14.73361,-0.4125278,25.500275,,,,,,,,,,6.2,286.4398,72.4,,,,1.5373000e-2,120.0000000,5.0000000,0.00,0.00,0.00,2.5000000,,,,0.00,1.0000000,0.00,0.00,25.3430042,22.4151115,0.00,0.00,0.00,,,,,,,,,,,,,,,,,,,,,,,,,,,,,,,,,,,
,14587632.16,4373,299.6295,0.015373,0.000,14.7964029,9.990,,,,,,,0.0098,0.0049,0,0.00,0.00,0.00,0.00,8.5369349,,399.9998474,,439.8695679,,,,,,,4357,300.000,0.015,-0.9,300.5483093,127.748,299.6295166,828.041,289.6027222,138.007,,,0.259740,3.619932,0.0,554.09,8.37091,500.12,5.57180,0.0000000,25.139299,,,,,,,,,,9.2,299.6391,72.4,,,,1.5373000e-2,120.0000000,5.0000000,0.00,0.00,0.00,2.5000000,,,,0.00,1.0000000,0.00,0.00,27.2653637,22.3635826,0.00,0.00,0.00,,,,,,,,,,,,,,,,,,,,,,,,,,,,,,,,,,,
,14587772.28,4369,300.0384,0.015373,0.000,14.8917351,9.990,,,,,,,0.0049,-0.0049,0,0.00,0.00,0.00,0.00,9.9169950,,399.9998474,,439.8695679,,,,,,,4353,300.000,0.015,-0.9,300.4453430,127.748,300.0402222,828.041,296.2752686,138.007,,,0.259740,3.610161,0.0,355.56,3.44352,324.54,2.35043,-1.2375835,24.417349,,,,,,,,,,10.0,300.0402,72.4,,,,1.5373000e-2,120.0000000,5.0000000,0.00,0.00,0.00,2.5000000,,,,0.00,1.0000000,0.00,0.00,27.2387962,22.3154583,0.00,0.00,0.00,,,,,,,,,,,,,,,,,,,,,,,,,,,,,,,,,,,
,14587912.14,4369,300.0123,0.015373,0.000,14.8614931,9.990,,,,,,,-0.0049,0.0049,0,0.00,0.00,0.00,0.00,10.5295868,,399.9998474,,439.8695679,,,,,,,4353,300.000,0.015,-0.9,300.3297729,127.748,300.0122986,828.041,298.1052246,144.846,,,0.265157,3.615047,0.0,287.67,2.25744,262.52,1.53251,0.4125278,24.417349,,,,,,,,,,10.0,300.0123,72.4,,,,1.5373000e-2,120.0000000,5.0000000,0.00,0.00,0.00,2.5000000,,,,0.00,1.0000000,0.00,0.00,27.2331142,22.2379894,0.00,0.00,0.00,,,,,,,,,,,,,,,,,,,,,,,,,,,,,,,,,,,
,14588052.20,4369,300.0052,0.015373,0.000,14.9018803,9.990,,,,,,,0.0049,0.0049,0,0.00,0.00,0.00,0.00,11.0688896,,399.9998474,,439.8695679,,,,,,,4353,300.000,0.015,-0.9,300.2925415,127.748,300.0051575,828.041,298.6692810,144.846,,,0.265157,3.619932,0.0,249.57,1.69166,226.62,1.14029,-0.8250557,24.417349,,,,,,,,,,10.0,300.0052,72.4,,,,1.5373000e-2,120.0000000,5.0000000,0.00,0.00,0.00,2.5000000,,,,0.00,1.0000000,0.00,0.00,27.1592751,22.2036991,0.00,0.00,0.00,,,,,,,,,,,,,,,,,,,,,,,,,,,,,,,,,,,
,14588192.08,4369,300.0018,0.015373,0.000,14.9428625,9.990,,,,,,,0.0049,0.0000,0,0.00,0.00,0.00,0.00,12.3545799,,399.9998474,,439.8695679,,,,,,,4353,300.000,0.015,-0.9,300.2716675,127.748,300.0018311,828.041,298.8431091,144.846,,,0.265157,3.629702,0.0,226.13,1.39341,205.13,0.93556,-0.8250557,24.056374,,,,,,,,,,10.0,300.0018,72.4,,,,1.5373000e-2,120.0000000,5.0000000,0.00,0.00,0.00,2.5000000,,,,0.00,1.0000000,0.00,0.00,27.1124516,22.1813984,0.00,0.00,0.00,,,,,,,,,,,,,,,,,,,,,,,,,,,,,,,,,,,
,14588332.31,4369,300.0084,0.015373,0.000,14.9337864,9.990,,,,,,,-0.0049,-0.0049,0,0.00,0.00,0.00,0.00,12.6039028,,399.9998474,,439.8695679,,,,,,,4353,300.000,0.015,-0.9,300.2722168,127.748,300.0083618,828.041,298.9330139,144.846,,,0.259740,3.619932,0.0,215.14,1.25595,196.34,0.85470,-0.8250557,23.695398,,,,,,,,,,10.0,300.0084,72.4,,,,1.5373000e-2,120.0000000,5.0000000,0.00,0.00,0.00,2.5000000,,,,0.00,1.0000000,0.00,0.00,27.1348896,22.1447105,0.00,0.00,0.00,,,,,,,,,,,,,,,,,,,,,,,,,,,,,,,,,,,
,14588472.23,4369,300.0041,0.015373,0.000,14.9420424,9.990,,,,,,,-0.0049,0.0049,0,0.00,0.00,0.00,0.00,12.9873543,,399.9998474,,439.8695679,,,,,,,4353,300.000,0.015,-0.9,300.2342224,127.748,300.0040894,828.041,299.0207214,144.846,,,0.259740,3.615047,0.0,196.34,1.04787,178.27,0.70322,0.4125278,23.695398,,,,,,,,,,10.0,300.0032,72.4,,,,1.5373000e-2,120.0000000,5.0000000,0.00,0.00,0.00,2.5000000,,,,0.00,1.0000000,0.00,0.00,27.1832561,22.1286926,0.00,0.00,0.00,,,,,,,,,,,,,,,,,,,,,,,,,,,,,,,,,,,
,14588612.13,6417,300.1790,0.015373,0.000,,0.002,,,,,,,-0.0049,0.0147,0,0.00,0.00,0.00,0.00,776.0092773,,,,,,,,,,,6401,300.000,0.015,-0.9,300.5759583,127.748,300.1790466,828.041,298.7084045,144.846,,,0.257921,3.629702,0.0,274.48,2.13460,252.99,1.45513,-8.2505560,747.450684,,,,,,,,,,10.0,300.1790,72.4,,,,1.5373000e-2,120.0000000,5.0000000,0.00,0.00,0.00,2.5000000,,,,0.00,1.0000000,0.00,1.0000000,27.1863537,22.2594948,0.00,0.00,0.00,,,,,,,,,,,,,,,,,,,,,,,,,,,,,,,,,,,
,14588752.08,4374,295.4344,0.015373,0.000,,0.088,,,,,,,0.0049,0.0147,0,0.00,0.00,0.00,0.00,7.1319494,,,,,,,,,,,4358,292.903,0.015,85.3,294.9772034,127.748,295.4344177,828.041,298.8305054,144.846,,,2.744972,3.336590,0.0,0.00,0.00,0.00,0.00,826.2932129,23.695398,,,,,,,,,,10.0,295.4344,72.4,,,,1.5373000e-2,120.0000000,5.0000000,0.00,0.00,0.00,2.5000000,,,,0.00,1.0000000,0.00,0.00,41.7664719,21.9040833,0.00,0.00,0.00,,,,,,,,,,,,,,,,,,,,,,,,,,,,,,,,,,,
,14588892.13,4374,273.2746,0.015373,0.000,,0.022,,,,,,,0.0098,0.0147,0,0.00,0.00,0.00,0.00,7.4227085,,,,,,,,,,,4358,270.790,0.015,90.0,272.3856506,120.664,273.2745972,867.123,293.7371216,144.846,,,2.727548,3.326820,0.0,0.00,0.00,0.00,0.00,829.1809082,24.056374,,,,,,,,,,10.0,273.2746,72.4,,,,1.5373000e-2,120.0000000,5.0000000,0.00,0.00,0.00,2.5000000,,,,0.00,1.0000000,0.00,0.00,41.7664719,21.9040833,0.00,0.00,0.00,,,,,,,,,,,,,,,,,,,,,,,,,,,,,,,,,,,
,14589032.13,4374,247.0627,0.015373,0.000,,0.283,,,,,,,0.0098,-0.0049,0,0.00,0.00,0.00,0.00,7.1319494,,,,,,,,,,,4358,244.583,0.015,90.0,246.1764984,110.894,247.0627441,999.023,278.3014526,140.938,,,2.753684,3.317049,0.0,0.00,0.00,0.00,0.00,827.1182861,25.139299,,,,,,,,,,10.0,246.9942,72.4,,,,1.5373000e-2,120.0000000,5.0000000,0.00,0.00,0.00,2.5000000,,,,0.00,1.0000000,0.00,0.00,41.7664719,21.9040833,0.00,0.00,0.00,,,,,,,,,,,,,,,,,,,,,,,,,,,,,,,,,,,
,14589172.20,4374,220.5919,0.015373,0.000,,1.207,,,,,,,0.0195,0.0147,0,0.00,0.00,0.00,0.00,6.8525796,,,,,,,,,,,4358,218.032,0.015,90.0,219.7756348,100.879,220.5290527,999.023,256.7151184,131.412,,,2.738003,3.331705,0.0,0.00,0.00,0.00,0.00,827.9433594,25.139299,,,,,,,,,,10.0,220.5291,72.4,,,,1.5373000e-2,120.0000000,5.0000000,0.00,0.00,0.00,2.5000000,,,,0.00,1.0000000,0.00,0.00,41.7664719,21.9040833,0.00,0.00,0.00,,,,,,,,,,,,,,,,,,,,,,,,,,,,,,,,,,,
,14589312.09,4374,195.3944,0.015373,0.000,,0.002,,,,,,,-0.0049,0.0049,0,0.00,0.00,0.00,0.00,6.5841532,,,,,,,,,,,4358,192.805,0.015,90.0,194.7436371,91.109,195.3944092,999.023,232.4146118,120.420,,,2.748457,3.331705,0.0,0.00,0.00,0.00,0.00,825.8806763,25.139299,,,,,,,,,,10.0,195.3944,72.4,,,,1.5373000e-2,120.0000000,5.0000000,0.00,0.00,0.00,2.5000000,,,,0.00,1.0000000,0.00,0.00,41.7664719,21.9040833,0.00,0.00,0.00,,,,,,,,,,,,,,,,,,,,,,,,,,,,,,,,,,,
,14589352.30,4374,188.5497,0.015373,0.000,,0.027,,,,,,,0.0049,0.0000,0,0.00,0.00,0.00,0.00,6.3897567,,,,,,,,,,,4358,186.028,0.015,90.0,187.9065704,88.178,188.4892273,999.023,225.2868042,117.000,,,2.739745,3.331705,0.0,0.00,0.00,0.00,0.00,826.2932129,24.417349,,,,,,,,,,10.0,188.4892,72.4,,,,1.5373000e-2,120.0000000,5.0000000,0.00,0.00,0.00,2.5000000,,,,0.00,1.0000000,0.00,0.00,41.7664719,21.9040833,0.00,0.00,0.00,,,,,,,,,,,,,,,,,,,,,,,,,,,,,,,,,,,